# Converted from schematic
# THIS TEMPLATE USES DEFAULTS!  Please edit for corrections.
# If you need help, consult template_rules.txt

weight=10
embed_into_distance=1
acceptable_target_blocks=1,2,3,12,13,162,163,164,165,166,167,168,169,170,171,172,254,255
dimensions=7,9,9
allowable_overhang=0
max_cut_in=2
cut_in_buffer=1
max_leveling=2
leveling_buffer=1
preserve_water=0
preserve_lava=0
preserve_plants=0


rule1=0,100,12
rule2=0,100,24-2
rule3=0,100,44-1
rule4=0,100,85
rule5=0,100,24


layer
1,1,1,1,1,1,1,1,1
1,1,1,1,1,1,1,1,1
1,1,1,1,1,1,1,1,1
1,1,1,1,1,1,1,1,1
1,1,1,1,1,1,1,1,1
1,1,1,1,1,1,1,1,1
1,1,1,1,1,1,1,1,1
1,1,1,1,1,1,1,1,1
1,1,1,1,1,1,1,1,1
endlayer

layer
0,3,3,3,3,3,3,3,2
3,2,2,2,2,2,2,2,3
3,2,0,0,0,0,0,2,3
3,2,0,0,0,0,0,2,3
3,2,0,0,0,0,0,2,3
0,0,0,0,0,0,0,2,3
0,0,0,0,0,0,0,2,3
0,0,2,0,0,2,2,2,3
0,3,3,3,0,3,3,3,2
endlayer

layer
0,0,0,0,0,0,0,0,0
0,4,0,0,0,0,0,4,0
0,0,0,0,0,0,0,0,0
0,0,0,0,0,0,0,0,0
0,0,0,0,0,0,0,0,0
0,0,0,0,0,0,0,0,0
0,0,0,0,0,0,0,0,0
0,0,0,0,0,0,0,4,0
0,0,0,0,0,0,0,0,0
endlayer

layer
0,0,0,0,0,0,0,0,0
0,4,0,0,0,0,0,4,0
0,0,0,0,0,0,0,0,0
0,0,0,0,0,0,0,0,0
0,0,0,0,0,0,0,0,0
0,0,0,0,0,0,0,0,0
0,0,0,0,0,0,0,0,0
0,0,0,0,0,0,0,0,0
0,0,0,0,0,0,0,0,0
endlayer

layer
0,0,0,0,0,0,0,0,0
0,4,0,0,0,0,0,4,0
0,0,0,0,0,0,0,0,0
0,0,0,0,0,0,0,0,0
0,0,0,0,0,0,0,0,0
0,0,0,0,0,0,0,0,0
0,0,0,0,0,0,0,0,0
0,0,0,0,0,0,0,0,0
0,0,0,0,0,0,0,0,0
endlayer

layer
0,0,0,0,0,0,0,0,0
0,0,0,0,0,0,0,4,0
0,0,0,0,0,0,0,0,0
0,0,0,0,0,0,0,0,0
0,0,0,0,0,0,0,0,0
0,0,0,0,0,0,0,0,0
0,0,0,0,0,0,0,0,0
0,0,0,0,0,0,0,0,0
0,0,0,0,0,0,0,0,0
endlayer

layer
0,0,0,0,0,0,0,0,0
0,3,3,3,3,3,3,3,0
0,3,5,5,5,5,5,3,0
0,0,0,0,0,0,5,3,0
0,0,0,0,0,0,5,3,0
0,0,0,0,0,0,5,3,0
0,0,0,0,0,0,0,3,0
0,0,0,0,0,0,0,3,0
0,0,0,0,0,0,0,0,0
endlayer

