#based on the Yorkville building in Downtown New Crafton by Antonove
#http://www.planetminecraft.com/project/downtown-new-crafton-finished/

weight=80
acceptable_target_blocks=1,2,3,12,13,24,162,163,164,165,166,167,168,169,170,171,172,254,255
embed_into_distance=1
dimensions=75,33,29
max_leveling=2
max_cut_in=25
preserve_plants=1


rule1=0,100,48
#main brick
rule2=0,96,45
rule3=0,100,24-1
rule4=0,100,24
#glass
rule5=0,95,20
rule6=0,100,118
rule7=0,100,109
#ladder
rule8=0,50,65-3
rule9=0,100,71
rule10=0,100,72
rule11=0,100,108-2
#ceiling
rule12=0,95,98
#ruined column ends
rule13=1,70,24-1
rule14=0,100,47
#detritus
rule15=1,2,HardMobSpawn,HardMobSpawn,HardMobSpawn,EasyChest,MediumChest,HardChest,35-7,35-12,35-7,35-12,30,30,30,30,103,86
rule16=0,100,61-5
#ladder
rule17=0,50,65-2
rule18=0,100,58
rule19=0,100,23-3
rule20=0,100,85
rule21=0,100,71-8
rule22=0,100,77-2
rule23=0,100,76-1
rule24=0,100,22
rule25=0,100,108-7
#ruined column
rule26=1,90,24
#ruined windowpane
rule27=2,70,102
rule28=0,100,77-1
rule29=0,100,70
rule30=0,100,44-8
rule31=0,100,108-6
rule32=0,100,108-1
rule33=0,100,5-3
rule34=0,100,30
rule35=0,100,44-5
#window decor
rule36=0,95,24-2
rule37=0,100,108-3
#ruined cement floor
rule38=2,50,48
#ruined window decor
rule39=2,70,24-2
rule40=0,100,108
rule41=0,100,109-1
rule42=0,100,76-4
rule43=0,100,109-5
rule44=0,100,44-13
rule45=0,100,109-4
#ruined edge
rule46=2,95,109-7
rule47=0,100,109-7
#ruined edge
rule48=2,95,109-6
rule49=0,100,109-6
rule50=0,100,43
rule51=0,100,53-3
rule52=0,100,4
rule53=0,100,53-1
#desks
rule54=0,100,5-2
rule55=0,100,64-2
rule56=0,100,64
rule57=0,100,44
rule58=0,100,53-2
rule59=0,100,23-5
rule60=0,100,98
rule61=0,100,126-9
rule62=0,100,53
rule63=0,100,64-3
rule64=0,100,109-2
#wallpaper
rule65=0,95,1
rule66=0,100,30
rule67=0,100,30
rule68=0,100,64-9
rule69=0,100,64-8
rule70=0,100,77-4
rule71=0,100,1
rule72=0,100,44-4
#plank floor
rule73=1,100,5-1
rule74=0,100,98-3
rule75=0,100,64-1
rule76=0,100,23-2
rule77=0,100,5
#windowpanes
rule78=0,95,102
rule79=0,100,117
rule80=0,100,69-2
rule81=0,100,1
rule82=0,100,1
#ruined floor
rule83=2,50,5-1
#1-thick plank floor
rule84=0,95,5-1
#ruined brick
rule85=2,70,45
#wallpaper
rule86=0,95,1
rule87=0,100,61-2
rule88=0,100,61-4
rule89=0,100,61-3
#wallpaper
rule90=0,95,4
rule91=0,100,109-3
rule92=0,100,44-1
rule93=0,100,5
#cobweb
rule94=0,50,30
#ruined brick column
rule95=1,95,45
#ruined roof slabs
rule96=2,95,44-5
#gold/books
rule97=0,100,41,47
#ruined edge
rule98=2,95,109-4
#ruined roof
rule99=2,50,98
#roof asphalt
rule100=0,95,1
#roof railing
rule101=0,100,101


layer
1,1,1,1,1,1,1,1,1,1,1,1,1,1,1,1,1,1,1,1,1,1,1,1,1,1,1,1,1
1,1,1,1,1,1,1,1,1,1,1,1,1,1,1,1,1,1,1,1,1,1,1,1,1,1,1,1,1
1,1,1,1,1,1,1,1,1,1,1,1,1,1,1,1,1,1,1,1,1,1,1,1,1,1,1,1,1
1,1,1,1,1,1,1,1,1,1,1,1,1,1,1,1,1,1,1,1,1,1,1,1,1,1,1,1,1
1,1,1,1,1,1,1,1,1,1,1,1,1,1,1,1,1,1,1,1,1,1,1,1,1,1,1,1,1
1,1,1,1,1,1,1,1,1,1,1,1,1,1,1,1,1,1,1,1,1,1,1,1,1,1,1,1,1
1,1,1,1,1,1,1,1,1,1,1,1,1,1,1,1,1,1,1,1,1,1,1,1,1,1,1,1,1
1,1,1,1,1,1,1,1,1,1,1,1,1,1,1,1,1,1,1,1,1,1,1,1,1,1,1,1,1
1,1,1,1,1,1,1,1,1,1,1,1,1,1,1,1,1,1,1,1,1,1,1,1,1,1,1,1,1
1,1,1,1,1,1,1,1,1,1,1,1,1,1,1,1,1,1,1,1,1,1,1,1,1,1,1,1,1
1,1,1,1,1,1,1,1,1,1,1,1,1,2,2,2,2,2,2,2,2,2,1,1,1,1,1,1,1
1,1,1,1,1,1,1,1,1,1,1,1,1,2,2,2,2,2,2,2,2,2,1,1,1,1,1,1,1
1,1,1,1,1,1,1,1,1,1,1,1,1,2,0,0,0,2,0,0,0,2,1,1,1,1,1,1,1
1,1,1,1,1,1,1,1,1,1,1,1,1,2,0,0,0,2,0,0,0,2,1,1,1,1,1,1,1
1,1,1,1,1,1,1,1,1,1,1,1,1,2,2,2,2,2,2,2,2,2,1,1,1,1,1,1,1
1,1,1,1,1,1,1,1,1,1,1,1,1,1,1,1,1,1,1,1,1,1,1,1,1,1,1,1,1
1,1,1,1,1,1,1,1,1,1,1,1,1,1,1,1,1,1,1,1,1,1,1,1,1,1,1,1,1
1,1,1,1,1,1,1,1,1,1,1,1,1,1,1,1,1,1,1,1,1,1,1,1,1,1,1,1,1
1,1,1,1,1,1,1,1,1,1,1,1,1,2,2,2,2,2,2,2,2,2,1,1,1,1,1,1,1
1,1,1,1,1,1,1,1,1,1,1,1,1,2,1,1,2,2,2,2,2,2,1,1,1,1,1,1,1
1,1,1,1,1,1,1,1,1,1,1,1,1,2,1,1,2,2,2,2,2,2,1,1,1,1,1,1,1
1,1,1,1,1,1,1,1,1,1,1,1,1,2,1,1,2,2,2,2,2,2,1,1,1,1,1,1,1
1,1,1,1,1,1,1,1,1,1,1,1,1,2,2,2,2,2,2,2,2,2,1,1,1,1,1,1,1
1,1,1,1,1,1,1,1,1,1,1,1,1,1,1,1,1,1,1,1,1,1,1,1,1,1,1,1,1
1,1,1,1,1,1,1,1,1,1,1,1,1,1,1,1,1,1,1,1,1,1,1,1,1,1,1,1,1
1,1,1,1,1,1,1,1,1,1,1,1,1,1,1,1,1,1,1,1,1,1,1,1,1,1,1,1,1
1,1,1,1,1,1,1,1,1,1,1,1,1,1,1,1,1,1,1,1,1,1,1,1,1,1,1,1,1
1,1,1,1,1,1,1,1,1,1,1,1,1,1,1,1,1,1,1,1,1,1,1,1,1,1,1,1,1
1,1,1,1,1,1,1,1,1,1,1,1,1,1,1,1,1,1,1,1,1,1,1,1,1,1,1,1,1
1,1,1,1,1,1,1,1,1,1,1,1,1,1,1,1,1,1,1,1,1,1,1,1,1,1,1,1,1
1,1,1,1,1,1,1,1,1,1,1,1,1,1,1,1,1,1,1,1,1,1,1,1,1,1,1,1,1
1,1,1,1,1,1,1,1,1,1,1,1,1,1,1,1,1,1,1,1,1,1,1,1,1,1,1,1,1
1,1,1,1,1,1,1,1,1,1,1,1,1,1,1,1,1,1,1,1,1,1,1,1,1,1,1,1,1
endlayer

layer
0,0,0,0,0,0,0,0,0,0,0,0,0,0,0,0,0,0,0,0,0,0,0,0,0,0,0,0,0
0,0,0,0,0,0,0,0,0,0,0,0,0,0,0,0,0,0,0,0,0,0,0,0,0,0,0,0,0
0,0,3,3,0,0,13,0,0,13,0,0,13,0,0,0,13,0,0,3,0,0,3,0,0,3,3,0,0
0,0,3,4,3,3,13,13,13,13,13,13,13,13,13,13,13,3,3,3,3,3,3,3,3,4,3,0,0
0,0,0,3,0,0,0,0,0,0,0,0,0,0,0,0,0,0,0,0,0,0,0,0,0,3,0,0,0
0,0,0,3,0,0,0,0,0,0,0,0,0,0,0,0,0,0,0,0,0,0,0,0,0,3,0,0,0
0,0,3,3,0,0,0,0,0,0,0,0,0,0,14,14,0,0,0,0,0,0,0,0,0,3,3,0,0
0,0,0,0,0,0,0,0,0,14,0,0,0,0,0,0,0,0,0,0,0,0,0,0,0,0,0,0,0
0,0,0,0,0,0,0,0,0,14,0,0,14,0,0,0,0,0,0,0,0,0,0,0,0,0,0,0,0
0,0,3,3,6,0,0,0,0,0,0,3,0,0,14,14,0,0,7,7,7,6,0,0,0,3,3,0,0
0,0,0,3,0,0,0,0,0,0,0,3,0,19,2,2,2,2,2,2,2,2,0,0,0,3,0,0,0
0,0,0,3,0,0,0,0,0,0,0,3,0,2,0,0,0,2,0,0,0,2,0,0,0,3,0,0,0
0,0,3,3,0,0,0,0,0,0,0,3,3,2,17,0,0,2,0,0,8,2,0,0,0,3,3,0,0
0,0,3,3,0,0,0,0,0,14,0,0,14,2,0,0,0,2,0,0,0,2,0,0,0,3,3,0,0
0,0,0,5,0,0,0,0,0,0,0,0,0,2,0,0,0,2,0,0,0,2,0,0,0,5,0,0,0
0,0,0,0,0,0,0,0,0,0,0,0,0,0,0,0,0,0,0,0,0,0,0,0,0,0,0,0,0
0,0,0,0,0,0,0,0,0,0,0,0,0,0,0,0,0,0,0,0,0,0,0,0,0,0,0,0,0
0,0,0,0,0,0,0,0,0,0,0,0,0,0,0,0,0,0,0,0,0,0,0,0,0,0,0,0,0
0,0,0,5,0,0,0,0,0,0,0,0,0,2,2,9,2,2,2,2,9,2,0,0,0,5,0,0,0
0,0,3,3,6,0,0,0,0,0,0,20,0,2,0,0,2,2,2,0,10,2,0,0,0,3,3,0,0
0,0,3,3,0,0,0,0,0,0,0,0,0,2,15,15,2,0,0,0,0,2,0,0,0,3,3,0,0
0,0,0,3,0,0,0,0,0,20,0,0,0,2,18,15,2,2,2,11,0,2,0,0,0,3,0,0,0
0,0,0,3,0,0,0,0,0,0,0,20,0,2,2,2,2,2,2,2,2,2,0,0,0,3,0,0,0
0,0,3,3,0,0,0,0,0,0,0,0,0,3,0,16,12,12,12,12,0,0,0,0,0,3,3,0,0
0,0,0,0,0,0,0,0,0,20,0,0,0,3,0,0,0,0,0,0,0,3,0,0,0,0,0,0,0
0,0,0,0,0,0,0,0,0,0,0,0,0,3,3,3,3,3,3,3,3,3,0,0,0,0,0,0,0
0,0,3,3,0,0,0,0,0,0,0,0,0,0,0,0,0,0,0,0,0,0,0,0,0,3,3,0,0
0,0,0,3,0,0,0,0,0,0,0,0,0,0,0,0,0,0,0,0,0,0,0,0,0,3,0,0,0
0,0,0,3,0,7,7,7,7,0,0,0,0,0,0,0,0,0,0,0,0,0,0,0,0,3,0,0,0
0,0,3,4,3,3,3,3,3,3,3,3,3,3,3,3,3,3,3,3,3,3,3,3,3,4,3,0,0
0,0,3,3,0,0,3,0,0,3,0,0,3,0,0,0,3,0,0,3,0,0,3,0,0,3,3,0,0
0,0,0,0,0,0,0,0,0,0,0,0,0,0,0,0,0,0,0,0,0,0,0,0,0,0,0,0,0
0,0,0,0,0,0,0,0,0,0,0,0,0,0,0,0,0,0,0,0,0,0,0,0,0,0,0,0,0
endlayer

layer
0,0,0,0,0,0,0,0,0,0,0,0,0,0,0,0,0,0,0,0,0,0,0,0,0,0,0,0,0
0,0,0,0,0,0,0,0,0,0,0,0,0,0,0,0,0,0,0,0,0,0,0,0,0,0,0,0,0
0,0,4,4,0,0,26,0,0,26,0,0,26,0,0,0,26,0,0,4,0,0,4,0,0,4,4,0,0
0,0,4,4,5,5,26,27,27,26,27,27,26,27,27,27,26,5,5,4,5,5,4,5,5,4,4,0,0
0,0,0,5,0,0,0,0,0,0,0,0,0,0,0,0,0,0,0,0,0,0,0,0,0,5,0,0,0
0,0,0,5,0,0,0,0,0,0,0,0,0,0,0,0,0,0,0,0,0,0,0,0,0,5,0,0,0
0,0,4,4,0,0,0,0,0,0,0,0,0,0,14,14,0,0,0,0,0,0,0,0,0,4,4,0,0
0,0,0,0,0,0,0,0,0,14,0,0,0,0,0,0,0,0,0,0,0,0,0,0,0,0,0,0,0
0,0,0,0,0,0,0,0,0,14,0,0,14,0,0,0,0,0,0,0,0,0,0,0,0,0,0,0,0
0,0,4,4,0,0,0,0,0,0,0,0,0,0,14,14,0,0,0,0,0,0,0,0,0,4,4,0,0
0,0,0,5,0,0,0,0,0,0,0,0,0,19,2,2,2,2,2,2,2,2,0,0,0,5,0,0,0
0,0,0,5,0,0,0,0,0,0,0,0,0,2,0,0,0,2,0,0,0,2,0,0,0,5,0,0,0
0,0,4,4,0,0,0,0,0,0,0,0,0,2,17,0,0,2,0,0,8,2,0,0,0,4,4,0,0
0,0,4,4,0,0,0,0,0,14,0,0,14,2,0,0,0,2,0,0,0,2,0,0,0,4,4,0,0
0,0,0,5,0,0,0,0,0,0,0,0,0,2,0,0,0,2,0,0,0,2,0,0,0,5,0,0,0
0,0,0,0,0,0,0,0,0,0,0,0,0,0,0,0,0,0,0,0,0,0,0,0,0,0,0,0,0
0,0,0,0,0,0,0,0,0,0,0,0,0,0,0,0,0,0,0,0,0,0,0,0,0,0,0,0,0
0,0,0,0,0,0,0,0,0,0,0,0,0,0,22,0,0,0,0,22,0,0,0,0,0,0,0,0,0
0,0,0,5,0,0,0,0,0,0,0,0,0,2,2,21,2,2,2,2,21,2,0,0,0,5,0,0,0
0,0,4,4,0,0,0,0,0,0,0,29,0,2,28,0,2,2,2,0,0,2,0,0,0,4,4,0,0
0,0,4,4,0,0,0,0,0,0,0,0,0,2,0,0,2,0,23,0,0,2,0,0,0,4,4,0,0
0,0,0,5,0,0,0,0,0,29,0,0,0,2,0,0,2,25,11,0,0,2,0,0,0,5,0,0,0
0,0,0,5,0,0,0,0,0,0,0,29,0,2,2,2,24,24,24,2,2,2,0,0,0,5,0,0,0
0,0,4,4,0,0,0,0,0,0,0,0,0,0,0,16,0,0,0,0,0,0,0,0,0,4,4,0,0
0,0,0,0,0,0,0,0,0,29,0,0,0,0,0,0,0,0,0,0,0,0,0,0,0,0,0,0,0
0,0,0,0,0,0,0,0,0,0,0,0,0,0,0,0,0,0,0,0,0,0,0,0,0,0,0,0,0
0,0,4,4,0,0,0,0,0,0,0,0,0,0,0,0,0,0,0,0,0,0,0,0,0,4,4,0,0
0,0,0,5,0,0,0,0,0,0,0,0,0,0,0,0,0,0,0,0,0,0,0,0,0,5,0,0,0
0,0,0,5,0,0,0,0,0,0,0,0,0,0,0,0,0,0,0,0,0,0,0,0,0,5,0,0,0
0,0,4,4,5,5,4,5,5,4,5,5,4,5,5,5,4,5,5,4,5,5,4,5,5,4,4,0,0
0,0,4,4,0,0,4,0,0,4,0,0,4,0,0,0,4,0,0,4,0,0,4,0,0,4,4,0,0
0,0,0,0,0,0,0,0,0,0,0,0,0,0,0,0,0,0,0,0,0,0,0,0,0,0,0,0,0
0,0,0,0,0,0,0,0,0,0,0,0,0,0,0,0,0,0,0,0,0,0,0,0,0,0,0,0,0
endlayer

layer
0,0,0,0,0,0,0,0,0,0,0,0,0,0,0,0,0,0,0,0,0,0,0,0,0,0,0,0,0
0,0,0,0,0,0,0,0,0,0,0,0,0,0,0,0,0,0,0,0,0,0,0,0,0,0,0,0,0
0,0,4,4,0,0,26,0,0,26,0,0,26,0,0,0,26,0,0,4,0,0,4,0,0,4,4,0,0
0,0,4,4,5,5,26,27,27,26,27,27,26,27,27,27,26,5,5,4,5,5,4,5,5,4,4,0,0
0,0,0,5,0,0,0,0,0,0,0,0,0,0,0,0,0,0,0,0,0,0,0,0,0,5,0,0,0
0,0,0,5,0,0,0,0,0,0,0,0,0,0,0,0,0,0,0,0,0,0,0,0,0,5,0,0,0
0,0,4,4,0,0,0,0,0,0,0,0,0,0,0,0,0,0,0,0,0,0,0,0,0,4,4,0,0
0,0,0,5,0,0,0,0,0,0,0,0,0,0,0,0,0,0,0,0,0,0,0,0,0,5,0,0,0
0,0,0,5,0,0,0,0,0,0,0,0,14,0,0,0,0,0,0,0,0,0,0,0,0,5,0,0,0
0,0,4,4,0,0,0,0,0,0,0,0,14,0,0,0,0,0,0,0,0,0,0,0,0,4,4,0,0
0,0,0,5,0,0,0,0,0,0,0,0,14,2,2,2,2,2,2,2,2,2,0,0,0,5,0,0,0
0,0,0,5,0,0,0,0,0,0,0,0,14,2,0,0,0,2,0,0,0,2,0,0,0,5,0,0,0
0,0,4,4,0,0,0,0,0,0,0,0,14,2,17,0,0,2,0,0,8,2,0,0,0,4,4,0,0
0,0,4,4,0,0,0,0,0,0,0,0,14,2,0,0,0,2,0,0,0,2,0,0,0,4,4,0,0
0,0,0,5,0,0,0,0,0,0,0,0,0,2,0,0,0,2,0,0,0,2,0,0,0,5,0,0,0
0,0,0,5,0,0,0,0,0,0,0,0,0,0,0,0,0,0,0,0,0,0,0,0,0,5,0,0,0
0,0,0,5,0,0,0,0,0,0,0,0,0,0,0,0,0,0,0,0,0,0,0,0,0,5,0,0,0
0,0,0,5,0,0,0,0,0,0,0,0,0,0,0,0,0,0,0,0,0,0,0,0,0,5,0,0,0
0,0,0,5,0,0,0,0,0,0,0,0,0,2,2,2,2,2,2,2,2,2,0,0,0,5,0,0,0
0,0,4,4,0,0,0,0,0,0,0,0,0,2,0,0,2,2,2,2,2,2,0,0,0,4,4,0,0
0,0,4,4,0,0,0,0,0,0,0,0,0,2,0,0,2,2,0,0,0,2,0,0,0,4,4,0,0
0,0,0,5,0,0,0,0,0,0,0,0,0,2,0,0,2,11,0,0,0,2,0,0,0,5,0,0,0
0,0,0,5,0,0,0,0,0,0,0,0,0,2,2,2,2,2,2,2,2,2,0,0,0,5,0,0,0
0,0,4,4,0,0,0,0,0,0,0,0,0,0,30,30,30,30,30,30,0,0,0,0,0,4,4,0,0
0,0,0,5,0,0,0,0,0,0,0,0,0,0,30,30,30,30,30,30,0,0,0,0,0,5,0,0,0
0,0,0,5,0,0,0,0,0,0,0,0,0,0,30,30,30,30,30,30,0,0,0,0,0,5,0,0,0
0,0,4,4,0,0,0,0,0,0,0,0,0,0,0,0,0,0,0,0,0,0,0,0,0,4,4,0,0
0,0,0,5,0,0,0,0,0,0,0,0,0,0,0,0,0,0,0,0,0,0,0,0,0,5,0,0,0
0,0,0,5,0,0,0,0,0,0,0,0,0,0,0,0,0,0,0,0,0,0,0,0,0,5,0,0,0
0,0,4,4,5,5,4,5,5,4,5,5,4,5,5,5,4,5,5,4,5,5,4,5,5,4,4,0,0
0,0,4,4,0,0,4,0,0,4,0,0,4,0,0,0,4,0,0,4,0,0,4,0,0,4,4,0,0
0,0,0,0,0,0,0,0,0,0,0,0,0,0,0,0,0,0,0,0,0,0,0,0,0,0,0,0,0
0,0,0,0,0,0,0,0,0,0,0,0,0,0,0,0,0,0,0,0,0,0,0,0,0,0,0,0,0
endlayer

layer
0,0,0,0,0,0,0,0,0,0,0,0,0,0,0,0,0,0,0,0,0,0,0,0,0,0,0,0,0
0,0,0,0,0,0,0,0,0,0,0,0,0,0,0,0,0,0,0,0,0,0,0,0,0,0,0,0,0
0,0,4,4,0,0,26,0,0,26,0,0,26,0,0,0,26,0,0,4,0,0,4,0,0,4,4,0,0
0,0,4,4,5,5,26,27,27,26,27,27,26,27,27,27,26,5,5,4,5,5,4,5,5,4,4,0,0
0,0,0,5,0,0,0,0,0,0,0,0,0,0,0,0,0,0,0,0,0,0,0,0,0,5,0,0,0
0,0,0,5,0,0,0,0,0,0,0,0,0,0,0,0,0,0,0,0,0,0,0,0,0,5,0,0,0
0,0,4,4,0,0,0,0,0,0,0,0,0,0,0,0,0,0,0,0,0,0,0,0,0,4,4,0,0
0,0,0,5,0,0,0,0,0,0,0,0,0,0,0,0,0,0,0,0,0,0,0,0,0,5,0,0,0
0,0,0,5,0,0,0,0,0,0,0,0,0,0,0,0,0,0,0,0,0,0,0,0,0,5,0,0,0
0,0,4,4,0,0,0,0,0,0,0,34,33,0,0,0,0,0,0,0,0,0,0,0,0,4,4,0,0
0,0,0,5,0,0,0,0,0,0,0,34,33,2,2,2,2,2,2,2,2,2,0,0,0,5,0,0,0
0,0,0,5,0,0,0,0,0,0,0,34,33,2,0,0,0,2,0,0,0,2,0,0,0,5,0,0,0
0,0,4,4,0,0,0,0,0,0,0,34,33,2,17,0,0,2,0,0,8,2,0,0,0,4,4,0,0
0,0,4,4,0,0,0,0,0,0,0,0,0,2,0,0,0,2,0,0,0,2,0,0,0,4,4,0,0
0,0,0,5,0,0,0,0,0,0,0,0,0,2,1,1,1,2,1,1,1,2,0,0,0,5,0,0,0
0,0,0,5,0,0,0,0,0,0,0,0,0,0,0,0,0,0,0,0,0,0,0,0,0,5,0,0,0
0,0,0,5,0,0,0,0,0,0,0,0,0,0,0,0,0,0,0,0,0,0,0,0,0,5,0,0,0
0,0,0,5,0,0,0,0,0,0,0,0,0,0,0,0,0,0,0,0,0,0,0,0,0,5,0,0,0
0,0,0,5,0,0,0,0,0,0,0,0,0,2,2,2,2,2,2,2,2,2,0,0,0,5,0,0,0
0,0,4,4,0,0,0,0,0,0,0,0,0,2,2,2,2,2,2,2,2,2,0,0,0,4,4,0,0
0,0,4,4,0,0,0,0,0,0,0,0,0,2,2,2,2,32,31,0,0,2,0,0,0,4,4,0,0
0,0,0,5,0,0,0,0,0,0,0,0,0,2,2,2,2,0,0,0,0,2,0,0,0,5,0,0,0
0,0,0,5,0,0,0,0,0,0,0,0,0,2,2,2,2,2,2,2,2,2,0,0,0,5,0,0,0
0,0,4,4,0,0,0,0,0,0,0,0,0,0,0,0,0,0,0,0,0,0,0,0,0,4,4,0,0
0,0,0,5,0,0,0,0,0,0,0,0,0,0,0,0,0,0,0,0,0,0,0,0,0,5,0,0,0
0,0,0,5,0,0,0,0,0,0,0,0,0,0,0,0,0,0,0,0,0,0,0,0,0,5,0,0,0
0,0,4,4,0,0,0,0,0,0,0,0,0,0,0,0,0,0,0,0,0,0,0,0,0,4,4,0,0
0,0,0,5,0,0,0,0,0,0,0,0,0,0,0,0,0,0,0,0,0,0,0,0,0,5,0,0,0
0,0,0,5,0,0,0,0,0,0,0,0,0,0,0,0,0,0,0,0,0,0,0,0,0,5,0,0,0
0,0,4,4,5,5,4,5,5,4,5,5,4,5,5,5,4,5,5,4,5,5,4,5,5,4,4,0,0
0,0,4,4,0,0,4,0,0,4,0,0,4,0,0,0,4,0,0,4,0,0,4,0,0,4,4,0,0
0,0,0,0,0,0,0,0,0,0,0,0,0,0,0,0,0,0,0,0,0,0,0,0,0,0,0,0,0
0,0,0,0,0,0,0,0,0,0,0,0,0,0,0,0,0,0,0,0,0,0,0,0,0,0,0,0,0
endlayer

layer
0,0,0,0,0,0,0,0,0,0,0,0,0,0,0,0,0,0,0,0,0,0,0,0,0,0,0,0,0
0,0,0,0,0,0,0,0,0,0,0,0,0,0,0,0,0,0,0,0,0,0,0,0,0,0,0,0,0
0,0,4,4,0,0,26,0,0,26,0,0,26,0,0,0,26,0,0,4,0,0,4,0,0,4,4,0,0
0,0,4,4,36,36,26,39,39,26,39,39,26,39,39,39,26,36,36,4,36,36,4,36,36,4,4,0,0
0,0,0,36,0,0,0,0,0,38,38,38,38,38,38,38,38,1,1,1,1,1,1,1,1,36,0,0,0
0,0,0,36,0,0,0,0,0,38,38,38,38,38,38,38,38,1,1,1,1,1,1,1,1,36,0,0,0
0,0,4,4,0,0,0,0,0,38,38,38,38,38,38,38,38,1,1,1,1,1,1,1,1,4,4,0,0
0,0,0,36,0,0,0,0,0,1,1,1,1,1,1,1,1,1,1,1,1,1,1,1,1,36,0,0,0
0,0,0,36,0,0,0,0,0,1,1,1,1,1,1,1,1,1,1,1,1,1,1,1,1,36,0,0,0
0,0,4,4,0,0,0,0,0,1,1,1,1,1,1,1,1,1,1,1,1,1,1,1,1,4,4,0,0
0,0,0,36,0,0,0,0,0,1,1,1,1,2,2,2,2,2,2,2,2,2,1,1,1,36,0,0,0
0,0,0,36,0,0,0,0,0,0,1,1,1,2,2,2,2,2,2,2,2,2,1,1,1,36,0,0,0
0,0,4,4,0,0,0,0,0,0,1,1,1,2,17,0,0,2,0,0,8,2,1,1,1,4,4,0,0
0,35,4,4,0,0,0,0,0,0,1,1,1,2,0,0,0,2,0,0,0,2,1,1,1,4,4,35,0
0,35,35,3,0,0,0,0,0,0,1,1,1,2,2,2,2,2,2,2,2,2,1,1,1,3,35,35,0
0,35,35,3,0,0,0,0,0,0,1,1,1,1,1,1,1,1,1,1,1,1,1,1,1,3,35,35,0
0,35,35,3,0,0,0,0,0,0,1,1,1,1,1,1,1,1,1,1,1,1,1,1,1,3,35,35,0
0,35,35,3,0,0,0,0,0,0,1,1,1,1,1,1,1,1,1,1,1,1,1,1,1,3,35,35,0
0,35,35,3,0,0,0,0,0,0,1,1,1,2,2,2,2,2,2,2,2,2,1,1,1,3,35,35,0
0,35,4,4,0,0,0,0,0,0,1,1,1,2,2,2,2,2,2,2,2,2,1,1,1,4,4,35,0
0,0,4,4,0,0,0,0,0,0,1,1,1,2,2,2,2,0,37,31,2,2,1,1,1,4,4,0,0
0,0,0,36,0,0,0,0,0,0,1,1,1,2,2,2,2,0,0,0,0,2,1,1,1,36,0,0,0
0,0,0,36,0,0,0,0,0,1,1,1,1,2,2,2,2,2,2,2,2,2,1,1,1,36,0,0,0
0,0,4,4,0,0,0,0,0,1,1,1,1,1,1,1,1,1,1,1,1,1,1,1,1,4,4,0,0
0,0,0,36,0,0,0,0,0,1,1,1,1,1,1,1,1,1,1,1,1,1,1,1,1,36,0,0,0
0,0,0,36,0,0,0,0,0,1,1,1,1,1,1,1,1,1,1,1,1,1,1,1,1,36,0,0,0
0,0,4,4,0,0,0,0,0,1,1,1,1,1,1,1,1,1,1,1,1,1,1,1,1,4,4,0,0
0,0,0,36,0,0,0,0,0,1,1,1,1,1,1,1,1,1,1,1,1,1,1,1,1,36,0,0,0
0,0,0,36,0,0,0,0,0,1,1,1,1,1,1,1,1,1,1,1,1,1,1,1,1,36,0,0,0
0,0,4,4,36,36,4,36,36,4,36,36,4,36,36,36,4,36,36,4,36,36,4,36,36,4,4,0,0
0,0,4,4,0,0,4,0,0,4,0,0,4,0,0,0,4,0,0,4,0,0,4,0,0,4,4,0,0
0,0,0,0,0,0,0,0,0,0,0,0,0,0,0,0,0,0,0,0,0,0,0,0,0,0,0,0,0
0,0,0,0,0,0,0,0,0,0,0,0,0,0,0,0,0,0,0,0,0,0,0,0,0,0,0,0,0
endlayer

layer
0,0,0,0,0,0,0,0,0,0,0,0,0,0,0,0,0,0,0,0,0,0,0,0,0,0,0,0,0
0,0,0,0,0,0,0,0,0,0,0,0,0,0,0,0,0,0,0,0,0,0,0,0,0,0,0,0,0
0,0,4,4,0,0,26,0,0,26,0,0,26,0,0,0,26,0,0,4,0,0,4,0,0,4,4,0,0
0,0,4,4,5,5,26,27,27,26,27,27,26,27,27,27,26,5,5,4,5,5,4,5,5,4,4,0,0
0,0,0,5,0,0,0,0,0,0,0,0,0,0,0,0,0,0,0,0,0,0,0,0,0,5,0,0,0
0,0,0,5,0,0,0,0,0,0,0,0,0,0,0,0,0,0,0,0,0,0,0,0,0,5,0,0,0
0,0,4,4,0,0,0,0,0,0,0,0,0,0,0,0,0,7,7,7,0,0,0,20,0,4,4,0,0
0,0,0,5,0,0,0,0,0,0,0,0,0,0,0,0,0,41,41,41,0,0,0,0,0,5,0,0,0
0,0,0,5,0,0,0,0,0,20,0,0,0,0,0,0,0,0,0,0,0,0,0,0,0,5,0,0,0
0,0,4,4,0,0,0,0,0,20,0,0,0,0,0,0,0,0,0,0,0,0,0,0,0,4,4,0,0
0,0,0,5,0,0,0,0,0,20,20,0,0,2,2,2,2,2,2,2,2,2,0,0,0,5,0,0,0
0,0,0,5,0,0,0,0,0,0,20,0,0,2,0,0,0,2,0,0,0,2,0,0,0,5,0,0,0
0,0,4,4,0,0,0,0,0,0,20,0,0,2,17,0,0,2,0,0,8,2,0,0,0,4,4,0,0
0,0,4,4,0,0,0,0,0,0,20,0,0,2,0,0,0,2,0,0,0,2,0,0,0,4,4,0,0
0,0,0,5,0,0,0,0,0,0,20,0,0,2,0,0,0,2,0,0,0,2,0,0,0,5,0,0,0
0,0,0,5,0,0,0,0,0,0,20,0,0,0,0,0,0,0,0,0,0,0,0,0,0,5,0,0,0
0,0,0,5,0,0,0,0,0,0,20,0,0,0,0,0,0,0,0,0,0,0,0,0,0,5,0,0,0
0,0,0,5,0,0,0,0,0,0,20,0,0,0,0,0,0,0,0,0,0,0,0,0,0,5,0,0,0
0,0,0,5,0,0,0,0,0,0,20,0,0,2,2,2,2,2,2,2,9,2,0,0,0,5,0,0,0
0,0,4,4,0,0,0,0,0,0,20,0,0,2,0,0,2,2,2,0,10,2,0,0,0,4,4,0,0
0,0,4,4,0,0,0,0,0,0,20,0,0,2,0,0,2,0,0,0,0,2,0,0,0,4,4,0,0
0,0,0,5,0,0,0,0,0,0,20,0,0,2,0,0,2,0,0,25,40,2,0,0,0,5,0,0,0
0,0,0,5,0,0,0,0,0,20,20,0,0,2,2,2,2,2,2,2,2,2,0,0,0,5,0,0,0
0,0,4,4,0,0,0,0,0,20,0,0,0,41,41,41,0,0,0,0,0,0,0,0,0,4,4,0,0
0,0,0,5,0,0,0,0,0,20,0,0,0,0,0,0,0,0,0,20,0,0,0,0,0,5,0,0,0
0,0,0,5,0,0,0,0,0,20,0,0,0,0,0,0,0,0,0,0,0,0,0,0,0,5,0,0,0
0,0,4,4,0,0,0,0,0,20,0,0,0,0,0,0,0,0,0,0,0,0,0,0,0,4,4,0,0
0,0,0,5,0,0,0,0,0,20,0,0,0,0,0,0,0,0,0,0,0,0,20,0,0,5,0,0,0
0,0,0,5,0,0,0,0,0,20,0,7,7,7,7,0,6,0,0,0,0,0,0,0,0,5,0,0,0
0,0,4,4,5,5,4,5,5,4,5,5,4,5,5,5,4,5,5,4,5,5,4,5,5,4,4,0,0
0,0,4,4,0,0,4,0,0,4,0,0,4,0,0,0,4,0,0,4,0,0,4,0,0,4,4,0,0
0,0,0,0,0,0,0,0,0,0,0,0,0,0,0,0,0,0,0,0,0,0,0,0,0,0,0,0,0
0,0,0,0,0,0,0,0,0,0,0,0,0,0,0,0,0,0,0,0,0,0,0,0,0,0,0,0,0
endlayer

layer
0,0,0,0,0,0,0,0,0,0,0,0,0,0,0,0,0,0,0,0,0,0,0,0,0,0,0,0,0
0,0,0,0,0,0,0,0,0,0,0,0,0,0,0,0,0,0,0,0,0,0,0,0,0,0,0,0,0
0,0,4,4,0,0,26,0,0,26,0,0,26,0,0,0,26,0,0,4,0,0,4,0,0,4,4,0,0
0,0,4,4,5,5,26,27,27,26,27,27,26,27,27,27,26,5,5,4,5,5,4,5,5,4,4,0,0
0,0,0,5,0,0,0,0,0,0,0,0,0,0,0,0,0,0,0,0,0,0,0,0,0,5,0,0,0
0,0,0,5,0,0,0,0,0,0,0,0,0,0,0,0,0,0,0,0,0,0,0,0,0,5,0,0,0
0,0,4,4,0,0,0,0,0,0,0,0,0,0,0,0,0,0,0,0,0,0,0,29,0,4,4,0,0
0,0,0,5,0,0,0,0,0,0,0,0,0,0,0,0,0,0,0,0,0,0,0,0,0,5,0,0,0
0,0,0,5,0,0,20,0,0,0,0,0,0,0,0,0,0,0,0,0,0,0,0,0,0,5,0,0,0
0,0,4,4,0,20,20,20,0,0,0,0,0,0,0,0,0,0,0,0,0,0,0,0,0,4,4,0,0
0,0,0,5,0,0,20,0,0,0,0,0,0,2,2,2,2,2,2,2,2,2,0,0,0,5,0,0,0
0,0,0,5,0,0,0,0,0,0,0,0,0,2,0,0,0,2,0,0,0,2,0,0,0,5,0,0,0
0,0,4,4,0,0,0,0,0,0,0,0,0,2,17,0,0,2,0,0,8,2,0,0,0,4,4,0,0
0,0,4,4,0,0,0,0,0,0,0,0,0,2,0,0,0,2,0,0,0,2,0,0,0,4,4,0,0
0,0,0,5,0,0,0,0,0,0,0,0,0,2,0,0,0,2,0,0,0,2,0,0,0,5,0,0,0
0,0,0,5,0,0,0,0,0,0,0,0,0,0,0,0,0,0,0,0,0,0,0,0,0,5,0,0,0
0,0,0,5,0,0,0,0,0,0,0,0,0,0,0,0,0,0,0,0,0,0,0,0,0,5,0,0,0
0,0,0,5,0,0,0,0,0,0,0,0,0,0,0,0,0,0,0,22,0,0,0,0,0,5,0,0,0
0,0,0,5,0,0,0,0,0,0,0,0,0,2,2,2,2,2,2,2,21,2,0,0,0,5,0,0,0
0,0,4,4,0,0,0,0,0,0,0,0,0,2,0,0,2,2,2,0,0,2,0,0,0,4,4,0,0
0,0,4,4,0,0,0,0,0,0,0,0,0,2,0,0,2,42,0,0,0,2,0,0,0,4,4,0,0
0,0,0,5,0,0,0,0,0,0,0,0,0,2,0,0,2,0,25,11,0,2,0,0,0,5,0,0,0
0,0,0,5,0,0,20,0,0,0,0,0,0,2,2,2,2,2,2,2,2,2,0,0,0,5,0,0,0
0,0,4,4,0,20,20,20,0,0,0,0,0,0,0,0,0,0,0,0,0,0,0,0,0,4,4,0,0
0,0,0,5,0,0,20,0,0,0,0,0,0,0,0,0,0,0,0,29,0,0,0,0,0,5,0,0,0
0,0,0,5,0,0,0,0,0,0,0,0,0,0,0,0,0,0,0,0,0,0,0,0,0,5,0,0,0
0,0,4,4,0,0,0,0,0,0,0,0,0,0,0,0,0,0,0,0,0,0,0,0,0,4,4,0,0
0,0,0,5,0,0,0,0,0,0,0,0,0,0,0,0,0,0,0,0,0,0,29,0,0,5,0,0,0
0,0,0,5,0,0,0,0,0,0,0,0,0,0,0,0,0,0,0,0,0,0,0,0,0,5,0,0,0
0,0,4,4,5,5,4,5,5,4,5,5,4,5,5,5,4,5,5,4,5,5,4,5,5,4,4,0,0
0,0,4,4,0,0,4,0,0,4,0,0,4,0,0,0,4,0,0,4,0,0,4,0,0,4,4,0,0
0,0,0,0,0,0,0,0,0,0,0,0,0,0,0,0,0,0,0,0,0,0,0,0,0,0,0,0,0
0,0,0,0,0,0,0,0,0,0,0,0,0,0,0,0,0,0,0,0,0,0,0,0,0,0,0,0,0
endlayer

layer
0,0,0,0,0,0,0,0,0,0,0,0,0,0,0,0,0,0,0,0,0,0,0,0,0,0,0,0,0
0,0,0,0,0,0,0,0,0,0,0,0,0,0,0,0,0,0,0,0,0,0,0,0,0,0,0,0,0
0,0,4,4,0,0,26,0,0,26,0,0,26,48,0,46,26,0,0,4,0,0,4,0,0,4,4,0,0
0,0,4,4,5,5,26,27,27,26,27,27,26,27,27,27,26,5,5,4,5,5,4,5,5,4,4,0,0
0,0,0,5,0,0,0,0,0,0,0,0,0,0,0,0,0,0,0,0,0,0,0,0,0,5,0,0,0
0,0,0,5,0,0,0,0,0,0,0,0,0,0,0,0,0,0,0,0,0,0,0,0,0,5,0,0,0
0,0,4,4,0,0,0,0,0,0,0,0,0,0,0,0,0,0,0,0,0,0,0,0,0,4,4,0,0
0,0,0,5,0,0,0,0,0,0,0,0,0,0,0,0,0,0,0,0,0,0,0,0,0,5,0,0,0
0,0,0,5,0,0,0,0,0,0,0,0,0,0,0,0,0,0,0,0,0,0,0,0,0,5,0,0,0
0,0,4,4,0,0,20,0,0,0,0,0,0,0,0,0,0,0,0,0,0,0,0,0,0,4,4,0,0
0,0,0,5,0,0,0,0,0,0,0,0,0,2,2,2,2,2,2,2,2,2,0,0,0,5,0,0,0
0,0,0,5,0,0,0,0,0,0,0,0,0,2,0,0,0,2,0,0,0,2,0,0,0,5,0,0,0
0,0,4,4,0,0,0,0,0,0,0,0,0,2,17,0,0,2,0,0,8,2,0,0,0,4,4,0,0
0,0,4,4,0,0,0,0,0,0,0,0,0,2,0,0,0,2,0,0,0,2,0,0,0,4,4,0,0
0,0,43,5,0,0,0,0,0,0,0,0,0,2,0,0,0,2,0,0,0,2,0,0,0,5,43,0,0
0,0,44,5,0,0,0,0,0,0,0,0,0,0,0,0,0,0,0,0,0,0,0,0,0,5,44,0,0
0,0,44,5,0,0,0,0,0,0,0,0,0,0,0,0,0,0,0,0,0,0,0,0,0,5,44,0,0
0,0,44,5,0,0,0,0,0,0,0,0,0,0,0,0,0,0,0,0,0,0,0,0,0,5,44,0,0
0,0,45,5,0,0,0,0,0,0,0,0,0,2,2,2,2,2,2,2,2,2,0,0,0,5,45,0,0
0,0,4,4,0,0,0,0,0,0,0,0,0,2,0,0,2,2,2,0,0,2,0,0,0,4,4,0,0
0,0,4,4,0,0,0,0,0,0,0,0,0,2,0,0,2,0,0,0,0,2,0,0,0,4,4,0,0
0,0,0,5,0,0,0,0,0,0,0,0,0,2,0,0,2,25,11,0,0,2,0,0,0,5,0,0,0
0,0,0,5,0,0,0,0,0,0,0,0,0,2,2,2,2,2,2,2,2,2,0,0,0,5,0,0,0
0,0,4,4,0,0,20,0,0,0,0,0,0,0,0,0,0,0,0,0,0,0,0,0,0,4,4,0,0
0,0,0,5,0,0,0,0,0,0,0,0,0,0,0,0,0,0,0,0,0,0,0,0,0,5,0,0,0
0,0,0,5,0,0,0,0,0,0,0,0,0,0,0,0,0,0,0,0,0,0,0,0,0,5,0,0,0
0,0,4,4,0,0,0,0,0,0,0,0,0,0,0,0,0,0,0,0,0,0,0,0,0,4,4,0,0
0,0,0,5,0,0,0,0,0,0,0,0,0,0,0,0,0,0,0,0,0,0,0,0,0,5,0,0,0
0,0,0,5,0,0,0,0,0,0,0,0,0,0,0,0,0,0,0,0,0,0,0,0,0,5,0,0,0
0,0,4,4,5,5,4,5,5,4,5,5,4,5,5,5,4,5,5,4,5,5,4,5,5,4,4,0,0
0,0,4,4,0,0,4,0,0,4,0,0,4,49,44,47,4,0,0,4,0,0,4,0,0,4,4,0,0
0,0,0,0,0,0,0,0,0,0,0,0,0,0,0,0,0,0,0,0,0,0,0,0,0,0,0,0,0
0,0,0,0,0,0,0,0,0,0,0,0,0,0,0,0,0,0,0,0,0,0,0,0,0,0,0,0,0
endlayer

layer
0,0,0,0,0,0,0,0,0,0,0,0,0,0,0,0,0,0,0,0,0,0,0,0,0,0,0,0,0
0,0,0,0,0,0,0,0,0,0,0,0,0,0,0,0,0,0,0,0,0,0,0,0,0,0,0,0,0
0,0,3,3,49,47,13,48,46,13,48,46,13,39,39,39,13,49,47,3,49,47,3,49,47,3,3,0,0
0,0,3,4,3,3,13,13,13,13,13,13,13,13,13,13,13,3,3,3,3,3,3,3,3,4,3,0,0
0,0,43,3,0,0,0,0,0,0,0,0,0,0,0,0,0,0,0,0,0,0,0,0,0,3,43,0,0
0,0,45,3,0,0,0,0,0,0,0,0,0,0,0,0,0,0,0,0,0,0,0,0,0,3,45,0,0
0,0,3,3,0,0,0,0,0,0,0,0,0,0,0,0,0,0,0,0,0,0,0,0,0,3,3,0,0
0,0,43,3,0,0,0,0,0,0,0,0,0,0,0,0,0,0,0,0,0,0,0,0,0,3,43,0,0
0,0,45,3,0,0,0,0,0,0,0,0,0,0,0,0,0,0,0,0,0,0,0,0,0,3,45,0,0
0,0,3,3,0,0,20,0,0,0,0,0,0,0,0,0,0,0,0,0,0,0,0,0,0,3,3,0,0
0,0,43,3,0,0,0,0,0,0,0,0,0,2,2,2,2,2,2,2,2,2,0,0,0,3,43,0,0
0,0,45,3,0,0,0,0,0,0,0,0,0,2,0,0,0,2,0,0,0,2,0,0,0,3,45,0,0
0,0,3,3,0,0,0,0,0,0,0,0,0,2,17,0,0,2,0,0,8,2,0,0,0,3,3,0,0
0,0,3,3,0,0,0,0,0,0,0,0,0,2,0,0,0,2,0,0,0,2,0,0,0,3,3,0,0
0,0,36,3,0,0,0,0,0,0,0,0,0,2,1,1,1,2,1,1,1,2,0,0,0,3,36,0,0
0,0,36,3,0,0,0,20,0,0,0,0,0,0,0,0,0,0,0,0,0,0,0,0,0,3,36,0,0
0,0,36,3,0,0,20,20,20,0,0,0,0,0,0,0,0,0,0,0,0,0,0,0,0,3,36,0,0
0,0,36,3,0,0,0,20,0,0,0,0,0,0,0,0,0,0,0,0,0,0,0,0,0,3,36,0,0
0,0,36,3,0,0,0,0,0,0,0,0,0,2,2,2,2,2,2,2,2,2,0,0,0,3,36,0,0
0,0,3,3,0,0,0,0,0,0,0,0,0,2,0,0,2,2,2,2,2,2,0,0,0,3,3,0,0
0,0,3,3,0,0,0,0,0,0,0,0,0,2,0,0,2,2,2,31,0,2,0,0,0,3,3,0,0
0,0,43,3,0,0,0,0,0,0,0,0,0,2,0,0,2,11,0,0,0,2,0,0,0,3,43,0,0
0,0,45,3,0,0,0,0,0,0,0,0,0,2,2,2,2,2,2,2,2,2,0,0,0,3,45,0,0
0,0,3,3,0,0,20,0,0,0,0,0,0,0,0,0,0,0,0,0,0,0,0,0,0,3,3,0,0
0,0,43,3,0,0,0,0,0,0,0,0,0,0,0,0,0,0,0,0,0,0,0,0,0,3,43,0,0
0,0,45,3,0,0,0,0,0,0,0,0,0,0,0,0,0,0,0,0,0,0,0,0,0,3,45,0,0
0,0,3,3,0,0,0,0,0,0,0,0,0,0,0,0,0,0,0,0,0,0,0,0,0,3,3,0,0
0,0,43,3,0,0,0,0,0,0,0,0,0,0,0,0,0,0,0,0,0,0,0,0,0,3,43,0,0
0,0,45,3,0,0,0,0,0,0,0,0,0,0,0,0,0,0,0,0,0,0,0,0,0,3,45,0,0
0,0,3,4,3,3,3,3,3,3,3,3,3,3,3,3,3,3,3,3,3,3,3,3,3,4,3,0,0
0,0,3,3,49,47,3,49,47,3,49,47,3,36,36,36,3,49,47,3,49,47,3,49,47,3,3,0,0
0,0,0,0,0,0,0,0,0,0,0,0,0,0,0,0,0,0,0,0,0,0,0,0,0,0,0,0,0
0,0,0,0,0,0,0,0,0,0,0,0,0,0,0,0,0,0,0,0,0,0,0,0,0,0,0,0,0
endlayer

layer
0,0,0,0,0,0,0,0,0,0,0,0,0,0,0,0,0,0,0,0,0,0,0,0,0,0,0,0,0
0,35,35,35,35,35,35,35,35,35,35,35,35,35,35,35,35,35,35,35,35,35,35,35,35,35,35,35,0
0,35,4,4,50,50,4,50,50,4,50,50,4,50,50,50,4,50,50,4,50,50,4,50,50,4,4,35,0
0,35,4,1,1,1,1,1,1,1,1,1,1,1,1,1,1,1,1,1,1,1,1,1,1,1,4,35,0
0,35,50,1,1,1,1,1,1,1,1,1,1,1,1,1,1,1,1,1,1,1,1,1,1,1,50,35,0
0,35,50,1,1,1,1,1,1,1,1,1,1,1,1,1,1,1,1,1,1,1,1,1,1,1,50,35,0
0,35,4,1,1,1,1,1,1,1,1,1,1,1,1,1,1,1,1,1,1,1,1,1,1,1,4,35,0
0,35,50,1,1,1,1,1,1,1,1,1,1,1,1,1,1,1,1,1,1,1,1,1,1,1,50,35,0
0,35,50,1,1,1,1,1,1,1,1,1,1,1,1,1,1,1,1,1,1,1,1,1,1,1,50,35,0
0,35,4,1,1,1,1,1,1,1,1,1,1,1,1,1,1,1,1,1,1,1,1,1,1,1,4,35,0
0,35,50,1,1,1,1,1,1,1,1,1,1,2,2,2,2,2,2,2,2,2,1,1,1,1,50,35,0
0,35,50,1,1,1,1,1,1,1,1,1,1,2,2,2,2,2,2,2,2,2,1,1,1,1,50,35,0
0,35,4,3,0,0,0,0,0,0,0,1,1,2,17,0,0,2,0,0,8,2,1,1,1,1,4,35,0
0,35,4,3,0,0,0,0,0,0,0,1,1,2,0,0,0,2,0,0,0,2,1,1,1,1,4,35,0
0,35,50,3,0,0,0,0,0,0,0,1,1,2,2,2,2,2,2,2,2,2,1,1,1,1,50,35,0
0,35,50,3,0,0,0,0,0,0,0,1,1,1,1,1,1,1,1,1,1,1,1,1,1,1,50,35,0
0,35,50,3,0,0,0,20,0,0,0,1,1,1,1,1,1,1,1,1,1,1,1,1,1,1,50,35,0
0,35,50,3,0,0,0,0,0,0,0,1,1,1,1,1,1,1,1,1,1,1,1,1,1,1,50,35,0
0,35,50,3,0,0,0,0,0,0,0,1,1,2,2,2,2,2,2,2,2,2,1,1,1,1,50,35,0
0,35,4,3,0,0,0,0,0,0,0,1,1,2,2,2,2,2,2,2,2,2,1,1,1,1,4,35,0
0,35,4,3,0,0,0,0,0,0,0,1,1,2,2,2,2,0,0,37,2,2,1,1,1,1,4,35,0
0,35,50,1,1,1,1,1,1,1,1,1,1,2,2,2,2,0,0,0,0,2,1,1,1,1,50,35,0
0,35,50,1,1,1,1,1,1,1,1,1,1,2,2,2,2,2,2,2,2,2,1,1,1,1,50,35,0
0,35,4,1,1,1,1,1,1,1,1,1,1,1,1,1,1,1,1,1,1,1,1,1,1,1,4,35,0
0,35,50,1,1,1,1,1,1,1,1,1,1,1,1,1,1,1,1,1,1,1,1,1,1,1,50,35,0
0,35,50,1,1,1,1,1,1,1,1,1,1,1,1,1,1,1,1,1,1,1,1,1,1,1,50,35,0
0,35,4,1,1,1,1,1,1,1,1,1,1,1,1,1,1,1,1,1,1,1,1,1,1,1,4,35,0
0,35,50,1,1,1,1,1,1,1,1,1,1,1,1,1,1,1,1,1,1,1,1,1,1,1,50,35,0
0,35,50,1,1,1,1,1,1,1,1,1,1,1,1,1,1,1,1,1,1,1,1,1,1,1,50,35,0
0,35,4,1,1,1,1,1,1,1,1,1,1,1,1,1,1,1,1,1,1,1,1,1,1,1,4,35,0
0,35,4,4,50,50,4,50,50,4,50,50,4,50,50,50,4,50,50,4,50,50,4,50,50,4,4,35,0
0,35,35,35,35,35,35,35,35,35,35,35,35,35,35,35,35,35,35,35,35,35,35,35,35,35,35,35,0
0,0,0,0,0,0,0,0,0,0,0,0,0,0,0,0,0,0,0,0,0,0,0,0,0,0,0,0,0
endlayer

layer
0,0,0,0,0,0,0,0,0,0,0,0,0,0,0,0,0,0,0,0,0,0,0,0,0,0,0,0,0
0,35,35,35,35,35,35,35,35,35,35,35,35,35,35,35,35,35,35,35,35,35,35,35,35,35,35,35,0
0,35,3,3,35,35,3,35,35,3,35,35,3,35,35,35,3,35,35,3,35,35,3,35,35,3,3,35,0
0,35,3,4,5,5,4,5,5,4,5,5,4,5,5,5,4,5,5,4,5,5,4,5,5,4,3,35,0
0,35,35,5,0,0,0,0,0,0,0,0,52,54,54,54,0,0,0,52,58,0,57,0,51,5,35,35,0
0,35,35,5,0,60,41,41,41,0,0,0,52,0,62,0,0,0,0,52,58,0,57,0,51,5,35,35,0
0,35,3,4,0,64,0,0,0,0,0,0,52,0,0,0,0,0,20,52,58,0,0,0,51,4,3,35,0
0,35,35,5,0,64,0,57,0,0,0,0,52,52,52,52,52,0,52,52,20,0,0,0,0,5,35,35,0
0,35,35,5,0,64,0,0,0,0,0,0,0,63,0,0,0,0,0,0,0,0,0,0,0,5,35,35,0
0,35,3,4,0,0,0,0,0,0,0,0,0,52,0,0,0,0,0,0,0,0,0,0,0,4,3,35,0
0,35,35,5,0,0,0,0,0,0,0,0,0,2,2,2,2,2,2,2,2,2,0,0,0,5,35,35,0
0,35,35,5,20,20,20,20,20,20,20,20,0,2,0,0,0,2,0,0,0,2,0,0,0,5,35,35,0
0,35,3,4,0,0,0,0,0,0,0,20,0,2,17,0,0,2,0,0,8,2,0,0,0,4,3,35,0
0,35,3,4,0,0,0,0,0,0,0,20,0,2,0,0,0,2,0,0,0,2,55,55,52,4,3,35,0
0,35,35,5,0,0,0,0,0,0,0,20,0,2,0,0,0,2,0,0,0,2,0,0,0,5,35,35,0
0,35,35,5,0,0,0,0,0,0,0,20,0,0,0,0,0,0,0,0,0,0,0,0,0,5,35,35,0
0,35,35,5,0,0,0,20,0,0,0,20,0,0,0,0,0,0,0,0,0,0,0,0,0,5,35,35,0
0,35,35,5,0,0,0,0,0,0,0,20,0,0,0,0,0,0,0,0,0,0,0,0,0,5,35,35,0
0,35,35,5,0,0,0,0,0,0,0,20,0,2,9,2,2,2,2,2,9,2,0,0,0,5,35,35,0
0,35,3,4,0,0,0,0,0,0,0,20,0,2,0,18,2,2,2,0,10,2,56,56,52,4,3,35,0
0,35,3,4,0,0,0,0,0,0,0,20,0,2,0,0,2,0,0,0,37,2,0,0,0,4,3,35,0
0,35,35,5,20,20,20,20,20,20,20,20,0,2,61,61,2,0,0,0,0,2,0,0,0,5,35,35,0
0,35,35,5,0,0,0,0,0,0,0,0,0,2,2,2,2,2,2,2,2,2,0,0,0,5,35,35,0
0,35,3,4,0,0,0,0,0,0,0,0,0,52,0,53,53,0,60,60,59,0,0,0,0,4,3,35,0
0,35,35,5,0,64,0,0,0,0,0,0,0,63,0,0,0,0,0,0,0,0,0,0,0,5,35,35,0
0,35,35,5,0,64,0,57,0,0,0,0,52,52,0,0,0,0,0,0,0,0,0,0,0,5,35,35,0
0,35,3,4,0,64,0,0,0,0,0,0,52,0,0,0,0,0,0,0,0,0,0,0,0,4,3,35,0
0,35,35,5,0,60,7,7,7,0,0,0,52,0,53,0,52,0,53,52,0,53,52,0,53,5,35,35,0
0,35,35,5,0,0,0,0,0,0,0,0,52,0,54,54,52,54,54,52,54,54,52,54,54,5,35,35,0
0,35,3,4,5,5,4,5,5,4,5,5,4,5,5,5,4,5,5,4,5,5,4,5,5,4,3,35,0
0,35,3,3,35,35,3,35,35,3,35,35,3,35,35,35,3,35,35,3,35,35,3,35,35,3,3,35,0
0,35,35,35,35,35,35,35,35,35,35,35,35,35,35,35,35,35,35,35,35,35,35,35,35,35,35,35,0
0,0,0,0,0,0,0,0,0,0,0,0,0,0,0,0,0,0,0,0,0,0,0,0,0,0,0,0,0
endlayer

layer
0,0,0,0,0,0,0,0,0,0,0,0,0,0,0,0,0,0,0,0,0,0,0,0,0,0,0,0,0
0,0,0,0,0,0,0,0,0,0,0,0,0,0,0,0,0,0,0,0,0,0,0,0,0,0,0,0,0
0,0,4,4,0,0,4,0,0,4,0,0,4,0,0,0,4,0,0,4,0,0,4,0,0,4,4,0,0
0,0,4,4,5,5,4,5,5,4,5,5,4,5,5,5,4,5,5,4,5,5,4,5,5,4,4,0,0
0,0,0,5,0,0,0,0,0,0,0,0,65,0,0,0,0,0,0,14,0,0,0,0,0,5,0,0,0
0,0,0,5,0,0,0,0,0,0,0,0,5,0,0,0,0,0,0,14,0,0,0,0,0,5,0,0,0
0,0,4,4,0,0,0,0,0,0,0,0,5,0,0,0,0,0,10,65,0,0,0,0,0,4,4,0,0
0,0,0,5,0,0,0,0,0,0,0,0,65,65,65,65,65,0,65,65,10,0,0,0,0,5,0,0,0
0,0,0,5,0,0,0,0,0,0,0,0,0,69,0,0,0,0,0,0,0,0,0,0,0,5,0,0,0
0,0,4,4,0,0,0,0,0,0,0,0,0,65,0,0,0,0,0,0,0,0,0,0,0,4,4,0,0
0,0,0,5,0,0,0,0,0,0,0,0,0,2,2,2,2,2,2,2,2,2,0,0,0,5,0,0,0
0,0,0,5,0,0,0,0,0,0,0,0,0,2,0,0,0,2,0,0,0,2,0,0,0,5,0,0,0
0,0,4,4,0,0,0,0,0,0,0,0,0,2,17,0,0,2,0,0,8,2,0,0,0,4,4,0,0
0,0,4,4,0,0,0,0,0,0,0,0,0,2,0,0,0,2,0,0,0,2,69,68,65,4,4,0,0
0,0,0,5,0,0,0,0,0,0,0,0,0,2,0,0,0,2,0,0,0,2,0,0,66,5,0,0,0
0,0,0,5,0,0,0,0,0,0,0,0,0,0,0,0,0,0,0,0,0,0,0,0,0,5,0,0,0
0,0,0,5,0,0,0,20,0,0,0,0,0,0,0,0,0,0,0,0,0,0,0,0,0,5,0,0,0
0,0,0,5,0,0,0,0,0,0,0,0,0,0,0,22,0,0,0,22,0,0,0,0,0,5,0,0,0
0,0,0,5,0,0,0,0,0,0,0,0,0,2,21,2,2,2,2,2,21,2,0,0,67,5,0,0,0
0,0,4,4,0,0,0,0,0,0,0,0,0,2,70,0,2,2,2,0,0,2,68,69,65,4,4,0,0
0,0,4,4,0,0,0,0,0,0,0,0,0,2,0,0,2,42,0,0,0,2,0,0,0,4,4,0,0
0,0,0,5,0,0,0,0,0,0,0,0,0,2,61,61,2,0,0,25,40,2,0,0,0,5,0,0,0
0,0,0,5,0,0,0,0,0,0,0,0,0,2,2,2,2,2,2,2,2,2,0,0,0,5,0,0,0
0,0,4,4,0,0,0,0,0,0,0,0,0,65,0,0,0,0,0,0,0,0,0,0,0,4,4,0,0
0,0,0,5,0,0,0,0,0,0,0,0,0,69,0,0,0,0,0,0,0,0,0,0,0,5,0,0,0
0,0,0,5,0,0,0,0,0,0,0,0,65,65,0,0,0,0,0,0,0,0,0,0,0,5,0,0,0
0,0,4,4,0,0,0,0,0,0,0,0,5,0,0,0,0,0,0,0,0,0,0,0,0,4,4,0,0
0,0,0,5,0,0,0,0,0,0,0,0,5,0,0,0,14,0,0,14,0,0,14,0,0,5,0,0,0
0,0,0,5,0,0,0,0,0,0,0,0,65,0,0,0,65,0,0,65,0,0,65,0,0,5,0,0,0
0,0,4,4,5,5,4,5,5,4,5,5,4,5,5,5,4,5,5,4,5,5,4,5,5,4,4,0,0
0,0,4,4,0,0,4,0,0,4,0,0,4,0,0,0,4,0,0,4,0,0,4,0,0,4,4,0,0
0,0,0,0,0,0,0,0,0,0,0,0,0,0,0,0,0,0,0,0,0,0,0,0,0,0,0,0,0
0,0,0,0,0,0,0,0,0,0,0,0,0,0,0,0,0,0,0,0,0,0,0,0,0,0,0,0,0
endlayer

layer
0,0,0,0,0,0,0,0,0,0,0,0,0,0,0,0,0,0,0,0,0,0,0,0,0,0,0,0,0
0,0,0,0,0,0,0,0,0,0,0,0,0,0,0,0,0,0,0,0,0,0,0,0,0,0,0,0,0
0,0,4,4,0,0,4,0,0,4,0,0,4,0,0,0,4,0,0,4,0,0,4,0,0,4,4,0,0
0,0,4,4,5,5,4,5,5,4,5,5,4,5,5,5,4,5,5,4,5,5,4,5,5,4,4,0,0
0,0,0,5,0,0,0,0,0,0,0,0,65,0,0,0,0,0,0,14,0,0,0,0,0,5,0,0,0
0,0,0,5,0,0,0,0,0,0,0,0,5,0,0,0,0,0,0,14,0,0,0,0,0,5,0,0,0
0,0,4,4,0,0,0,0,0,0,0,0,5,0,0,0,0,0,0,65,0,0,0,0,0,4,4,0,0
0,0,0,5,0,0,0,0,0,0,0,0,65,65,65,65,65,65,65,65,0,0,0,0,0,5,0,0,0
0,0,0,5,0,0,0,0,0,0,0,0,0,5,0,0,0,0,0,0,0,0,0,0,0,5,0,0,0
0,0,4,4,0,0,0,0,0,0,0,0,0,65,0,0,0,0,0,0,0,0,0,0,0,4,4,0,0
0,0,0,5,0,0,0,0,0,0,0,0,0,2,2,2,2,2,2,2,2,2,0,0,0,5,0,0,0
0,0,0,5,0,0,0,0,0,0,0,0,0,2,0,0,0,2,0,0,0,2,0,0,0,5,0,0,0
0,0,4,4,0,0,0,0,0,0,0,0,0,2,17,0,0,2,0,0,8,2,0,0,0,4,4,0,0
0,0,4,4,0,0,0,0,0,0,0,0,0,2,0,0,0,2,0,0,0,2,5,5,65,4,4,0,0
0,0,0,5,0,0,0,0,0,0,0,0,0,2,0,0,0,2,0,0,0,2,0,0,0,5,0,0,0
0,0,0,5,0,0,0,0,0,0,0,0,0,0,0,0,0,0,0,0,0,0,0,0,0,5,0,0,0
0,0,0,5,0,0,0,20,0,0,0,0,0,0,0,0,0,0,0,0,0,0,0,0,0,5,0,0,0
0,0,0,5,0,0,0,0,0,0,0,0,0,0,0,0,0,0,0,0,0,0,0,0,0,5,0,0,0
0,0,0,5,0,0,0,0,0,0,0,0,0,2,2,2,2,2,2,2,2,2,0,0,0,5,0,0,0
0,0,4,4,0,0,0,0,0,0,0,0,0,2,0,0,2,2,2,0,0,2,5,5,65,4,4,0,0
0,0,4,4,0,0,0,0,0,0,0,0,0,2,0,0,2,0,0,0,0,2,0,0,0,4,4,0,0
0,0,0,5,0,0,0,0,0,0,0,0,0,2,0,0,2,0,25,11,0,2,0,0,0,5,0,0,0
0,0,0,5,0,0,0,0,0,0,0,0,0,2,2,2,2,2,2,2,2,2,0,0,0,5,0,0,0
0,0,4,4,0,0,0,0,0,0,0,0,0,65,0,0,0,0,14,14,14,0,0,0,0,4,4,0,0
0,0,0,5,0,0,0,0,0,0,0,0,0,5,0,0,0,0,0,0,0,0,0,0,0,5,0,0,0
0,0,0,5,0,0,0,0,0,0,0,0,65,65,0,0,0,0,0,0,0,0,0,0,0,5,0,0,0
0,0,4,4,0,0,0,0,0,0,0,0,5,0,0,0,0,0,0,0,0,0,0,0,0,4,4,0,0
0,0,0,5,0,0,0,0,0,0,0,0,5,0,0,0,65,0,0,65,0,0,65,0,0,5,0,0,0
0,0,0,5,0,0,0,0,0,0,0,0,65,0,0,0,65,0,0,65,0,0,65,0,0,5,0,0,0
0,0,4,4,5,5,4,5,5,4,5,5,4,5,5,5,4,5,5,4,5,5,4,5,5,4,4,0,0
0,0,4,4,0,0,4,0,0,4,0,0,4,0,0,0,4,0,0,4,0,0,4,0,0,4,4,0,0
0,0,0,0,0,0,0,0,0,0,0,0,0,0,0,0,0,0,0,0,0,0,0,0,0,0,0,0,0
0,0,0,0,0,0,0,0,0,0,0,0,0,0,0,0,0,0,0,0,0,0,0,0,0,0,0,0,0
endlayer

layer
0,0,0,0,0,0,0,0,0,0,0,0,0,0,0,0,0,0,0,0,0,0,0,0,0,0,0,0,0
0,0,0,0,0,0,0,0,0,0,0,0,0,0,0,0,0,0,0,0,0,0,0,0,0,0,0,0,0
0,0,3,3,0,0,71,0,0,71,0,0,71,0,0,0,71,0,0,71,0,0,71,0,0,3,3,0,0
0,0,3,3,3,3,3,3,3,3,3,3,3,3,3,3,3,3,3,3,3,3,3,3,3,3,3,0,0
0,0,0,3,0,0,0,0,0,0,0,0,65,0,0,0,0,0,0,65,0,0,0,0,0,3,0,0,0
0,0,0,3,0,0,0,0,0,0,0,0,5,0,0,0,0,0,0,65,0,0,0,0,0,3,0,0,0
0,0,71,3,0,0,0,0,0,0,0,0,5,0,0,0,0,0,0,65,0,0,0,0,0,3,71,0,0
0,0,0,3,0,0,0,0,0,0,0,0,65,65,65,65,65,65,65,65,0,0,0,0,0,3,0,0,0
0,0,0,3,0,0,0,0,0,0,0,0,0,5,0,0,0,0,0,0,0,0,0,0,0,3,0,0,0
0,0,71,3,0,0,0,0,0,0,0,0,0,65,0,0,0,0,0,0,0,0,0,0,0,3,71,0,0
0,0,0,3,0,0,0,0,0,0,0,0,0,2,2,2,2,2,2,2,2,2,0,0,0,3,0,0,0
0,0,0,3,0,0,0,0,0,0,0,0,0,2,0,0,0,2,0,0,0,2,0,0,0,3,0,0,0
0,0,3,3,0,0,0,0,0,0,0,0,0,2,17,0,0,2,0,0,8,2,0,0,0,3,3,0,0
0,0,3,3,0,0,0,0,0,0,0,0,0,2,0,0,0,2,0,0,0,2,5,5,65,3,3,0,0
0,0,0,3,0,0,0,0,0,0,0,0,0,2,1,1,1,2,1,1,1,2,0,0,0,3,0,0,0
0,0,0,3,0,0,0,0,0,0,0,0,0,0,0,0,0,0,0,0,0,0,0,0,0,3,0,0,0
0,0,0,3,0,0,0,20,0,0,0,0,0,0,0,0,0,0,0,0,0,0,0,0,0,3,0,0,0
0,0,0,3,0,0,0,0,0,0,0,0,0,0,0,0,0,0,0,0,0,0,0,0,0,3,0,0,0
0,0,0,3,0,0,0,0,0,0,0,0,0,2,2,2,2,2,2,2,2,2,0,0,0,3,0,0,0
0,0,3,3,0,0,0,0,0,0,0,0,0,2,2,2,2,2,2,2,2,2,5,5,65,3,3,0,0
0,0,3,3,0,0,0,0,0,0,0,0,0,2,2,2,2,2,2,0,0,2,0,0,0,3,3,0,0
0,0,0,3,0,0,0,0,0,0,0,0,0,2,2,2,2,25,11,0,0,2,0,0,0,3,0,0,0
0,0,0,3,0,0,0,0,0,0,0,0,0,2,2,2,2,2,2,2,2,2,0,0,0,3,0,0,0
0,0,71,3,0,0,0,0,0,0,0,0,0,65,0,0,0,0,0,0,0,0,0,0,0,3,71,0,0
0,0,0,3,0,0,0,0,0,0,0,0,0,5,0,0,0,0,0,0,0,0,0,0,0,3,0,0,0
0,0,0,3,0,0,0,0,0,0,0,0,65,65,0,0,0,0,0,0,0,0,0,0,0,3,0,0,0
0,0,71,3,0,0,0,0,0,0,0,0,5,0,0,0,0,0,0,0,0,0,0,0,0,3,71,0,0
0,0,0,3,0,0,0,0,0,0,0,0,5,0,0,0,65,0,0,65,0,0,65,0,0,3,0,0,0
0,0,0,3,0,0,0,0,0,0,0,0,65,0,0,0,65,0,0,65,0,0,65,0,0,3,0,0,0
0,0,3,3,3,3,3,3,3,3,3,3,3,3,3,3,3,3,3,3,3,3,3,3,3,3,3,0,0
0,0,3,3,0,0,71,0,0,71,0,0,71,0,0,0,71,0,0,71,0,0,71,0,0,3,3,0,0
0,0,0,0,0,0,0,0,0,0,0,0,0,0,0,0,0,0,0,0,0,0,0,0,0,0,0,0,0
0,0,0,0,0,0,0,0,0,0,0,0,0,0,0,0,0,0,0,0,0,0,0,0,0,0,0,0,0
endlayer

layer
0,0,0,0,0,0,0,0,0,0,0,0,0,0,0,0,0,0,0,0,0,0,0,0,0,0,0,0,0
0,35,45,45,35,35,45,35,35,45,35,35,45,35,35,35,45,35,35,45,35,35,45,35,35,45,45,35,0
0,47,2,2,2,2,2,2,2,2,2,2,2,2,2,2,2,2,2,2,2,2,2,2,2,2,2,49,0
0,47,2,1,1,1,1,1,1,1,1,1,1,1,1,1,1,1,1,1,1,1,1,1,1,1,2,49,0
0,35,2,1,1,1,1,1,1,1,1,1,1,1,1,1,1,1,1,1,1,1,1,1,1,1,2,35,0
0,35,2,1,1,1,1,1,1,1,1,1,1,1,1,1,1,1,1,1,1,1,1,1,1,1,2,35,0
0,47,2,1,1,1,1,1,1,1,1,1,1,1,1,1,1,1,1,1,1,1,1,1,1,1,2,49,0
0,35,2,1,1,1,1,1,1,1,1,1,1,1,1,1,1,1,1,1,1,1,1,1,1,1,2,35,0
0,35,2,1,1,1,1,1,1,1,1,1,1,1,1,1,1,1,1,1,1,1,1,1,1,1,2,35,0
0,47,2,1,1,1,1,1,1,1,1,1,1,1,1,1,1,1,1,1,1,1,1,1,1,1,2,49,0
0,35,2,1,1,1,1,1,1,1,1,1,1,2,2,2,2,2,2,2,2,2,1,1,1,1,2,35,0
0,35,2,1,1,1,1,1,1,1,1,1,1,2,0,0,0,2,0,0,0,2,1,1,1,1,2,35,0
0,47,2,1,1,1,1,1,1,1,1,1,1,2,17,0,0,2,0,0,8,2,1,1,1,1,2,49,0
0,47,2,1,1,1,1,1,1,1,1,1,1,2,0,0,0,2,0,0,0,2,1,1,1,1,2,49,0
0,35,2,1,1,1,1,1,1,1,1,1,1,2,2,2,2,2,2,2,2,2,1,1,1,1,2,35,0
0,35,2,1,1,1,1,1,1,1,1,1,1,1,1,1,1,1,1,1,1,1,1,1,1,1,2,35,0
0,35,2,1,1,1,1,1,1,1,1,1,1,1,1,1,1,1,1,1,1,1,1,1,1,1,2,35,0
0,35,2,1,1,1,1,1,1,1,1,1,1,1,1,1,1,1,1,1,1,1,1,1,1,1,2,35,0
0,35,2,1,1,1,1,1,1,1,1,1,1,2,2,2,2,2,2,2,2,2,1,1,1,1,2,35,0
0,47,2,1,1,1,1,1,1,1,1,1,1,2,2,2,2,2,2,2,2,2,1,1,1,1,2,49,0
0,47,2,1,1,1,1,1,1,1,1,1,1,2,2,2,2,0,0,37,0,2,1,1,1,1,2,49,0
0,35,2,1,1,1,1,1,1,1,1,1,1,2,2,2,2,0,0,0,0,2,1,1,1,1,2,35,0
0,35,2,1,1,1,1,1,1,1,1,1,1,2,2,2,2,2,2,2,2,2,1,1,1,1,2,35,0
0,47,2,1,1,1,1,1,1,1,1,1,1,1,1,1,1,1,1,1,1,1,1,1,1,1,2,49,0
0,35,2,1,1,1,1,1,1,1,1,1,1,1,1,1,1,1,1,1,1,1,1,1,1,1,2,35,0
0,35,2,1,1,1,1,1,1,1,1,1,1,1,1,1,1,1,1,1,1,1,1,1,1,1,2,35,0
0,47,2,1,1,1,1,1,1,1,1,1,1,1,1,1,1,1,1,1,1,1,1,1,1,1,2,49,0
0,35,2,1,1,1,1,1,1,1,1,1,1,1,1,1,1,1,1,1,1,1,1,1,1,1,2,35,0
0,35,2,1,1,1,1,1,1,1,1,1,1,1,1,1,1,1,1,1,1,1,1,1,1,1,2,35,0
0,47,2,1,1,1,1,1,1,1,1,1,1,1,1,1,1,1,1,1,1,1,1,1,1,1,2,49,0
0,47,2,2,2,2,2,2,2,2,2,2,2,2,2,2,2,2,2,2,2,2,2,2,2,2,2,49,0
0,35,43,43,35,35,43,35,35,43,35,35,43,35,35,35,43,35,35,43,35,35,43,35,35,43,43,35,0
0,0,0,0,0,0,0,0,0,0,0,0,0,0,0,0,0,0,0,0,0,0,0,0,0,0,0,0,0
endlayer

layer
0,0,0,0,0,0,0,0,0,0,0,0,0,0,0,0,0,0,0,0,0,0,0,0,0,0,0,0,0
0,72,72,72,72,72,72,72,72,72,72,72,72,72,72,72,72,72,72,72,72,72,72,72,72,72,72,72,0
0,72,2,2,2,2,2,2,2,2,2,2,2,2,2,2,2,2,2,2,2,2,2,2,2,2,2,72,0
0,72,2,73,73,73,73,73,73,73,73,73,73,73,73,73,73,73,74,74,74,74,73,73,73,73,2,72,0
0,72,2,73,73,73,73,73,73,73,73,73,73,73,73,73,73,73,74,74,74,74,73,73,73,73,2,72,0
0,72,2,73,73,73,73,73,73,73,73,73,73,73,73,73,73,73,74,74,74,74,73,73,73,73,2,72,0
0,72,2,73,73,73,73,2,73,73,73,73,73,73,73,73,73,73,73,73,73,73,73,73,73,73,2,72,0
0,72,2,73,73,73,73,73,73,73,73,73,73,73,73,73,73,74,74,74,74,74,73,73,73,73,2,72,0
0,72,2,73,73,73,73,73,73,73,73,73,73,73,73,73,73,73,74,74,74,74,73,73,73,73,2,72,0
0,72,2,73,73,73,73,73,73,73,73,73,73,73,73,73,73,73,74,74,74,74,73,73,73,73,2,72,0
0,72,2,73,73,73,73,73,73,73,73,73,73,2,2,2,2,2,2,2,2,2,73,73,73,73,2,72,0
0,72,2,73,73,73,73,2,73,73,73,73,73,2,2,2,2,2,2,2,2,2,73,73,73,73,2,72,0
0,72,2,73,73,73,73,73,73,73,73,73,73,2,17,0,0,2,0,0,8,2,73,73,73,73,2,72,0
0,72,2,73,73,73,73,73,73,73,73,73,73,2,0,0,0,2,0,0,0,2,73,73,73,73,2,72,0
0,72,2,73,73,73,73,73,73,73,73,73,73,2,2,2,2,2,2,2,2,2,73,73,73,73,2,72,0
0,72,2,73,73,73,73,73,73,73,73,73,73,73,73,73,73,73,73,73,73,73,73,73,73,73,2,72,0
0,72,2,73,73,73,73,73,73,73,73,73,73,73,73,73,73,73,73,73,73,73,73,73,73,73,2,72,0
0,72,2,73,73,73,73,73,73,73,73,73,73,73,73,73,73,73,73,73,73,73,73,73,73,73,2,72,0
0,72,2,73,73,73,73,73,73,73,73,73,73,2,2,2,2,2,2,2,2,2,73,73,73,73,2,72,0
0,72,2,73,73,73,73,73,73,73,73,73,73,2,73,73,2,2,2,2,2,2,73,73,73,73,2,72,0
0,72,2,73,73,73,73,73,73,73,73,73,73,2,73,73,2,0,0,0,37,2,73,73,73,73,2,72,0
0,72,2,73,73,73,73,2,73,73,73,73,73,2,73,73,2,0,0,0,2,2,73,73,73,73,2,72,0
0,72,2,73,73,73,73,73,73,73,73,73,73,2,2,2,2,2,2,2,2,2,73,73,73,73,2,72,0
0,72,2,73,73,73,73,73,73,73,73,73,73,73,73,73,73,73,73,73,73,73,73,73,73,73,2,72,0
0,72,2,73,73,73,73,73,73,73,73,73,73,73,73,73,73,73,73,73,73,73,73,73,73,73,2,72,0
0,72,2,73,73,73,73,73,73,73,73,73,73,73,73,73,73,73,73,73,73,73,73,73,73,73,2,72,0
0,72,2,73,73,73,73,2,73,73,73,73,73,73,73,73,73,73,73,73,73,73,73,73,73,73,2,72,0
0,72,2,73,73,73,73,73,73,73,73,73,73,73,73,73,73,73,73,73,73,73,73,73,73,73,2,72,0
0,72,2,73,73,73,73,73,73,73,73,73,73,73,73,73,73,73,73,73,73,73,73,73,73,73,2,72,0
0,72,2,73,73,73,73,73,73,73,73,73,73,73,73,73,73,73,73,73,73,73,73,73,73,73,2,72,0
0,72,2,2,2,2,2,2,2,2,2,2,2,2,2,2,2,2,2,2,2,2,2,2,2,2,2,72,0
0,72,72,72,72,72,72,72,72,72,72,72,72,72,72,72,72,72,72,72,72,72,72,72,72,72,72,72,0
0,0,0,0,0,0,0,0,0,0,0,0,0,0,0,0,0,0,0,0,0,0,0,0,0,0,0,0,0
endlayer

layer
0,0,0,0,0,0,0,0,0,0,0,0,0,0,0,0,0,0,0,0,0,0,0,0,0,0,0,0,0
0,0,0,0,0,0,0,0,0,0,0,0,0,0,0,0,0,0,0,0,0,0,0,0,0,0,0,0,0
0,0,50,2,36,36,2,36,36,2,36,36,2,36,36,36,2,36,36,2,36,36,2,36,36,2,50,0,0
0,0,2,60,51,0,60,0,0,60,51,0,52,0,53,0,52,58,0,0,0,76,52,0,0,0,2,0,0
0,0,36,60,0,0,60,51,0,60,0,0,52,77,77,0,52,60,0,0,0,0,52,0,0,0,36,0,0
0,0,36,15,15,15,15,0,15,15,15,15,52,0,0,0,52,60,0,0,0,0,75,0,0,0,36,0,0
0,0,2,15,15,15,15,2,15,15,15,15,52,0,0,0,52,52,52,52,52,52,52,0,0,0,2,0,0
0,0,36,60,51,0,60,0,15,15,15,0,63,0,0,0,52,58,0,0,0,0,75,0,0,0,36,0,0
0,0,36,60,0,0,60,51,15,15,15,15,52,0,0,0,52,60,0,0,0,0,52,0,0,0,36,0,0
0,0,2,15,15,15,15,15,15,15,0,0,52,62,62,20,52,60,0,0,0,59,52,53,0,0,2,0,0
0,0,36,15,15,15,15,15,15,15,0,53,0,2,2,2,2,2,2,2,2,2,54,54,0,0,36,0,0
0,0,36,60,0,15,15,2,15,15,0,77,77,2,0,0,0,2,0,0,0,2,58,0,0,0,36,0,0
0,0,2,60,51,15,15,76,0,0,0,0,0,2,17,0,0,2,0,0,8,2,58,0,0,51,2,0,0
0,0,2,0,0,15,15,0,0,0,0,0,0,2,0,0,0,2,0,0,0,2,52,55,55,52,2,0,0
0,0,36,15,15,15,15,0,52,52,55,55,52,2,0,0,0,2,0,0,0,2,0,0,0,0,36,0,0
0,0,36,15,15,14,14,14,52,0,0,0,0,0,0,0,0,0,0,0,0,0,0,0,0,0,36,0,0
0,0,2,52,52,52,52,52,52,0,0,0,0,0,0,0,0,0,0,0,0,0,0,0,0,0,2,0,0
0,0,36,60,60,60,60,60,52,0,0,0,0,0,0,0,0,0,0,0,0,0,0,0,0,0,36,0,0
0,0,36,15,15,15,15,15,52,52,56,56,52,2,2,2,2,2,2,2,9,2,0,0,0,0,36,0,0
0,0,2,15,15,15,15,15,15,15,0,0,0,2,61,61,2,2,2,0,10,2,52,56,56,52,2,0,0
0,0,2,15,15,15,15,15,15,15,0,0,0,63,0,0,2,42,0,0,0,2,58,0,0,51,2,0,0
0,0,36,15,15,60,60,2,15,15,0,0,0,2,15,15,2,0,25,11,0,2,58,0,0,0,36,0,0
0,0,36,15,15,62,0,0,0,0,0,0,0,2,2,2,2,2,2,2,2,2,54,54,0,0,36,0,0
0,0,2,15,15,15,15,15,15,15,0,0,52,20,53,53,52,0,0,54,0,0,52,62,0,0,2,0,0
0,0,36,15,15,15,15,15,15,15,0,0,52,0,0,0,52,0,58,54,51,0,52,0,0,0,36,0,0
0,0,36,0,53,0,0,0,53,0,0,0,63,0,0,0,52,0,0,0,0,0,75,0,0,0,36,0,0
0,0,2,0,60,60,60,2,60,60,15,15,52,0,0,0,52,52,52,52,52,52,52,0,0,0,2,0,0
0,0,36,0,0,0,62,0,0,0,15,15,52,0,0,0,52,0,0,54,0,0,52,0,0,0,36,0,0
0,0,36,15,15,15,15,15,15,15,15,15,52,0,77,77,52,0,58,54,51,0,75,0,0,0,36,0,0
0,0,2,15,15,15,15,15,15,15,15,15,52,0,62,0,52,0,0,0,0,0,52,0,0,20,2,0,0
0,0,50,2,36,36,2,36,36,2,36,36,2,36,36,36,2,36,36,2,36,36,2,36,36,2,50,0,0
0,0,0,0,0,0,0,0,0,0,0,0,0,0,0,0,0,0,0,0,0,0,0,0,0,0,0,0,0
0,0,0,0,0,0,0,0,0,0,0,0,0,0,0,0,0,0,0,0,0,0,0,0,0,0,0,0,0
endlayer

layer
0,0,0,0,0,0,0,0,0,0,0,0,0,0,0,0,0,0,0,0,0,0,0,0,0,0,0,0,0
0,0,0,0,0,0,0,0,0,0,0,0,0,0,0,0,0,0,0,0,0,0,0,0,0,0,0,0,0
0,0,2,2,78,78,2,78,78,2,78,78,2,78,78,78,2,78,78,2,78,78,2,78,78,2,2,0,0
0,0,2,0,0,0,0,0,0,0,0,0,65,0,0,0,65,0,0,0,0,79,65,0,0,0,2,0,0
0,0,78,0,0,0,0,0,0,0,0,0,14,0,0,0,65,0,0,0,0,0,65,0,0,0,78,0,0
0,0,78,0,0,0,0,0,0,0,0,0,14,0,0,0,65,0,0,0,0,0,69,0,0,0,78,0,0
0,0,2,0,0,0,0,2,0,0,0,0,65,0,0,0,14,65,65,65,65,65,65,0,0,0,2,0,0
0,0,78,0,0,0,0,0,0,0,0,0,69,0,0,0,65,0,0,0,0,0,69,0,0,0,78,0,0
0,0,78,0,0,0,0,0,0,0,0,0,65,0,0,0,65,0,0,0,0,0,65,0,0,0,78,0,0
0,0,2,0,0,0,0,0,0,0,0,0,65,0,0,10,65,0,0,0,0,79,65,0,0,0,2,0,0
0,0,78,0,0,0,0,0,0,0,0,0,0,2,2,2,2,2,2,2,2,2,0,0,0,0,78,0,0
0,0,78,0,0,0,0,2,0,0,0,0,0,2,0,0,0,2,0,0,0,2,0,0,0,0,78,0,0
0,0,2,0,0,0,0,0,0,0,0,0,0,2,17,0,0,2,0,0,8,2,0,0,0,0,2,0,0
0,0,2,0,0,0,0,0,0,0,0,0,0,2,0,0,0,2,0,0,0,2,65,69,68,65,2,0,0
0,0,78,0,0,0,0,0,65,65,69,68,65,2,0,0,0,2,0,0,0,2,66,0,0,0,78,0,0
0,0,78,0,0,14,14,14,65,0,0,0,66,0,0,0,0,0,0,0,0,0,0,0,0,0,78,0,0
0,0,2,65,65,65,65,65,65,0,0,0,0,0,0,0,0,0,0,0,0,0,0,0,0,0,2,0,0
0,0,78,0,0,0,0,0,65,0,0,0,67,0,0,0,0,0,0,22,0,0,0,0,0,0,78,0,0
0,0,78,0,0,0,0,0,65,65,68,69,65,2,2,2,2,2,2,2,21,2,67,0,0,0,78,0,0
0,0,2,0,0,0,0,0,0,0,0,0,0,2,61,61,2,2,2,0,0,2,65,68,69,65,2,0,0
0,0,2,0,0,0,0,0,0,0,0,0,0,69,0,0,2,0,0,0,0,2,0,0,0,0,2,0,0
0,0,78,0,0,0,0,2,0,0,0,0,0,2,15,15,2,25,11,0,0,2,0,0,0,0,78,0,0
0,0,78,0,0,0,0,0,0,0,0,0,0,2,2,2,2,2,2,2,2,2,0,0,0,0,78,0,0
0,0,2,0,0,0,0,0,0,0,0,0,65,10,0,0,65,0,0,0,0,0,65,0,0,0,2,0,0
0,0,78,0,0,0,0,0,0,0,0,0,65,0,0,0,14,0,0,0,0,0,65,0,0,0,78,0,0
0,0,78,0,0,0,0,0,0,0,0,0,69,0,0,0,14,0,0,0,0,0,69,0,0,0,78,0,0
0,0,2,0,0,0,0,2,0,0,0,0,65,0,0,0,65,65,65,65,65,65,65,0,0,0,2,0,0
0,0,78,0,0,0,0,0,0,0,0,0,65,0,0,0,14,0,0,0,0,0,65,0,0,0,78,0,0
0,0,78,0,0,0,0,0,0,0,0,0,65,0,0,0,14,0,0,0,0,0,69,0,0,0,78,0,0
0,0,2,0,0,0,0,0,0,0,0,0,65,0,0,0,65,0,0,0,0,0,65,0,0,10,2,0,0
0,0,2,2,78,78,2,78,78,2,78,78,2,78,78,78,2,78,78,2,78,78,2,78,78,2,2,0,0
0,0,0,0,0,0,0,0,0,0,0,0,0,0,0,0,0,0,0,0,0,0,0,0,0,0,0,0,0
0,0,0,0,0,0,0,0,0,0,0,0,0,0,0,0,0,0,0,0,0,0,0,0,0,0,0,0,0
endlayer

layer
0,0,0,0,0,0,0,0,0,0,0,0,0,0,0,0,0,0,0,0,0,0,0,0,0,0,0,0,0
0,0,0,0,0,0,0,0,0,0,0,0,0,0,0,0,0,0,0,0,0,0,0,0,0,0,0,0,0
0,0,50,2,78,78,2,78,78,2,78,78,2,78,78,78,2,78,78,2,78,78,2,78,78,2,50,0,0
0,0,2,0,0,0,0,0,0,0,0,0,65,0,0,0,65,0,0,0,0,0,65,0,0,0,2,0,0
0,0,78,0,0,0,0,0,0,0,0,0,65,0,0,0,65,14,0,0,0,0,65,0,0,0,78,0,0
0,0,78,0,0,0,0,0,0,0,0,0,65,0,0,0,65,14,0,0,0,0,65,0,0,0,78,0,0
0,0,2,0,0,0,0,2,0,0,0,0,65,0,0,0,14,65,65,65,65,65,65,0,0,0,2,0,0
0,0,78,0,0,0,0,0,0,0,0,0,65,0,0,0,65,0,0,0,0,0,65,0,0,0,78,0,0
0,0,78,0,0,0,0,0,0,0,0,0,65,0,0,0,65,14,0,0,0,0,65,0,0,0,78,0,0
0,0,2,0,0,0,0,0,0,0,0,0,65,0,0,0,65,14,0,0,0,0,65,0,0,0,2,0,0
0,0,78,0,0,0,0,0,0,0,0,0,0,2,2,2,2,2,2,2,2,2,0,0,0,0,78,0,0
0,0,78,0,0,0,0,2,0,0,0,0,0,2,0,0,0,2,0,0,0,2,0,0,0,0,78,0,0
0,0,2,0,0,0,0,0,0,0,0,0,0,2,17,0,0,2,0,0,8,2,0,0,0,0,2,0,0
0,0,2,0,0,0,0,0,0,0,0,0,0,2,0,0,0,2,0,0,0,2,65,5,5,65,2,0,0
0,0,78,0,0,0,0,0,65,65,5,5,65,2,0,0,0,2,0,0,0,2,0,0,0,0,78,0,0
0,0,78,0,0,14,14,14,65,0,0,0,0,0,0,0,0,0,0,0,0,0,0,0,0,0,78,0,0
0,0,2,65,65,65,65,65,65,0,0,0,0,0,0,0,0,0,0,0,0,0,0,0,0,0,2,0,0
0,0,78,0,14,14,14,14,65,0,0,0,0,0,0,0,0,0,0,0,0,0,0,0,0,0,78,0,0
0,0,78,0,0,0,0,0,65,65,5,5,65,2,2,2,2,2,2,2,2,2,0,0,0,0,78,0,0
0,0,2,0,0,0,0,0,0,0,0,0,0,2,61,61,2,2,2,2,2,2,65,5,5,65,2,0,0
0,0,2,0,0,0,0,0,0,0,0,0,0,2,0,0,2,2,0,0,0,2,0,0,0,0,2,0,0
0,0,78,0,0,0,0,2,0,0,0,0,0,2,61,61,2,11,0,0,0,2,0,0,0,0,78,0,0
0,0,78,0,0,0,0,0,0,0,0,0,0,2,2,2,2,2,2,2,2,2,0,0,0,0,78,0,0
0,0,2,0,0,0,0,0,0,0,0,0,65,0,0,0,65,0,0,0,0,0,65,0,0,0,2,0,0
0,0,78,0,0,0,0,0,0,0,0,0,65,0,0,0,65,0,0,0,0,0,65,0,0,0,78,0,0
0,0,78,0,0,0,0,0,0,0,0,0,65,0,0,0,65,0,0,0,0,0,65,0,0,0,78,0,0
0,0,2,0,0,0,0,2,0,0,0,0,65,0,0,0,65,65,65,65,65,65,65,0,0,0,2,0,0
0,0,78,0,0,0,0,0,0,0,0,0,65,0,0,0,65,0,0,0,0,0,65,0,0,0,78,0,0
0,0,78,0,0,0,0,0,0,0,0,0,65,0,0,0,65,0,0,0,0,0,65,0,0,0,78,0,0
0,0,2,0,0,0,0,0,0,0,0,0,65,0,0,0,65,0,0,0,0,0,65,0,0,0,2,0,0
0,0,50,2,78,78,2,78,78,2,78,78,2,78,78,78,2,78,78,2,78,78,2,78,78,2,50,0,0
0,0,0,0,0,0,0,0,0,0,0,0,0,0,0,0,0,0,0,0,0,0,0,0,0,0,0,0,0
0,0,0,0,0,0,0,0,0,0,0,0,0,0,0,0,0,0,0,0,0,0,0,0,0,0,0,0,0
endlayer

layer
0,0,0,0,0,0,0,0,0,0,0,0,0,0,0,0,0,0,0,0,0,0,0,0,0,0,0,0,0
0,0,0,0,0,0,0,0,0,0,0,0,0,0,0,0,0,0,0,0,0,0,0,0,0,0,0,0,0
0,0,2,2,78,78,2,78,78,2,78,78,2,78,78,78,2,78,78,2,78,78,2,78,78,2,2,0,0
0,0,2,0,0,0,0,0,0,0,0,0,65,0,0,0,65,0,0,0,0,0,65,0,0,0,2,0,0
0,0,78,0,0,0,0,0,0,0,0,0,65,0,0,0,65,0,0,0,0,0,65,0,0,0,78,0,0
0,0,78,0,0,0,0,0,0,0,0,0,65,0,0,0,65,0,0,0,0,0,65,0,0,0,78,0,0
0,0,2,0,0,0,0,2,0,0,0,0,65,0,0,0,65,65,65,65,65,65,65,0,0,0,2,0,0
0,0,78,0,0,0,0,0,0,0,0,0,65,0,0,0,65,0,0,0,0,0,65,0,0,0,78,0,0
0,0,78,0,0,0,0,0,0,0,0,0,65,0,0,0,65,0,0,0,0,0,65,0,0,0,78,0,0
0,0,2,0,0,0,0,0,0,0,0,0,65,0,0,0,65,0,0,0,0,0,65,0,0,0,2,0,0
0,0,78,0,0,0,0,0,0,0,0,0,0,2,2,2,2,2,2,2,2,2,0,0,0,0,78,0,0
0,0,78,0,0,0,0,2,0,0,0,0,0,2,0,0,0,2,0,0,0,2,0,0,0,0,78,0,0
0,0,2,0,0,0,0,0,0,0,0,0,0,2,17,0,0,2,0,0,8,2,0,0,0,0,2,0,0
0,0,2,0,0,0,0,0,0,0,0,0,0,2,0,0,0,2,0,0,0,2,65,5,5,65,2,0,0
0,0,78,0,0,0,0,0,65,65,5,5,65,2,52,52,52,2,52,52,52,2,0,0,0,0,78,0,0
0,0,78,0,0,0,0,0,65,0,0,0,0,0,0,0,0,0,0,0,0,0,0,0,0,0,78,0,0
0,0,2,65,65,65,65,65,65,0,0,0,0,0,0,0,0,0,0,0,0,0,0,0,0,0,2,0,0
0,0,78,0,0,0,0,0,65,0,0,0,0,0,0,0,0,0,0,0,0,0,0,0,0,0,78,0,0
0,0,78,0,0,0,0,0,65,65,5,5,65,2,2,2,2,2,2,2,2,2,0,0,0,0,78,0,0
0,0,2,0,0,0,0,0,0,0,0,0,0,2,0,0,2,2,2,2,2,2,65,5,5,65,2,0,0
0,0,2,0,0,0,0,0,0,0,0,0,0,2,0,0,2,32,31,0,0,2,0,0,0,0,2,0,0
0,0,78,0,0,0,0,2,0,0,0,0,0,2,0,0,2,0,0,0,0,2,0,0,0,0,78,0,0
0,0,78,0,0,0,0,0,0,0,0,0,0,2,2,2,2,2,2,2,2,2,0,0,0,0,78,0,0
0,0,2,0,0,0,0,0,0,0,0,0,65,0,0,0,65,0,0,0,0,0,65,0,0,0,2,0,0
0,0,78,0,0,0,0,0,0,0,0,0,65,0,0,0,65,0,0,0,0,0,65,0,0,0,78,0,0
0,0,78,0,0,0,0,0,0,0,0,0,65,0,0,0,65,0,0,0,0,0,65,0,0,0,78,0,0
0,0,2,0,0,0,0,2,0,0,0,0,65,0,0,0,65,65,65,65,65,65,65,0,0,0,2,0,0
0,0,78,0,0,0,0,0,0,0,0,0,65,0,0,0,65,0,0,0,0,0,65,0,0,0,78,0,0
0,0,78,0,0,0,0,0,0,0,0,0,65,0,0,0,65,0,0,0,0,0,65,0,0,0,78,0,0
0,0,2,0,0,0,0,0,0,0,0,0,65,0,0,0,65,0,0,0,0,0,65,0,0,0,2,0,0
0,0,2,2,78,78,2,78,78,2,78,78,2,78,78,78,2,78,78,2,78,78,2,78,78,2,2,0,0
0,0,0,0,0,0,0,0,0,0,0,0,0,0,0,0,0,0,0,0,0,0,0,0,0,0,0,0,0
0,0,0,0,0,0,0,0,0,0,0,0,0,0,0,0,0,0,0,0,0,0,0,0,0,0,0,0,0
endlayer

layer
0,0,0,0,0,0,0,0,0,0,0,0,0,0,0,0,0,0,0,0,0,0,0,0,0,0,0,0,0
0,0,0,0,0,0,0,0,0,0,0,0,0,0,0,0,0,0,0,0,0,0,0,0,0,0,0,0,0
0,0,50,2,36,36,2,36,36,2,36,36,2,36,36,36,2,36,36,2,36,36,2,36,36,2,50,0,0
0,0,2,60,60,60,60,60,60,60,60,60,65,60,60,60,65,60,60,60,60,60,65,60,60,60,2,0,0
0,0,36,60,60,60,60,60,60,60,60,60,65,60,60,60,65,60,60,60,60,60,65,60,60,60,36,0,0
0,0,36,60,60,60,60,60,60,60,60,60,65,60,60,60,65,60,60,60,60,60,65,60,60,60,36,0,0
0,0,2,60,60,60,60,2,60,60,60,60,65,60,60,60,65,65,65,65,65,65,65,60,60,60,2,0,0
0,0,36,60,60,60,60,60,60,60,60,60,65,60,60,60,65,60,60,60,60,60,65,60,60,60,36,0,0
0,0,36,60,60,60,60,60,60,60,60,60,65,60,60,60,65,60,60,60,60,60,65,60,60,60,36,0,0
0,0,2,60,60,60,60,60,60,60,60,60,65,60,60,60,65,60,60,60,60,60,65,60,60,60,2,0,0
0,0,36,60,60,60,60,60,60,60,60,60,60,2,2,2,2,2,2,2,2,2,60,60,60,60,36,0,0
0,0,36,60,60,60,60,2,60,60,60,60,60,2,0,0,0,2,0,0,0,2,60,60,60,60,36,0,0
0,0,2,60,60,60,60,60,60,60,60,60,60,2,17,0,0,2,0,0,8,2,60,60,60,60,2,0,0
0,0,2,60,60,60,60,60,60,60,60,60,60,2,0,0,0,2,0,0,0,2,65,65,65,65,2,0,0
0,0,36,60,60,60,60,60,65,65,65,65,65,2,2,2,2,2,2,2,2,2,60,60,60,60,36,0,0
0,0,36,60,60,60,60,60,65,60,60,60,60,60,60,60,60,60,60,60,60,60,60,60,60,60,36,0,0
0,0,2,65,65,65,65,65,65,60,60,60,60,60,60,60,60,60,60,60,60,60,60,60,60,60,2,0,0
0,0,36,60,60,60,60,60,65,60,60,60,60,60,60,60,60,60,60,60,60,60,60,60,60,60,36,0,0
0,0,36,60,60,60,60,60,65,65,65,65,65,2,2,2,2,2,2,2,2,2,60,60,60,60,36,0,0
0,0,2,60,60,60,60,60,60,60,60,60,60,2,2,2,2,2,2,2,2,2,65,65,65,65,2,0,0
0,0,2,60,60,60,60,60,60,60,60,60,60,2,2,2,2,0,37,31,0,2,60,60,60,60,2,0,0
0,0,36,60,60,60,60,2,60,60,60,60,60,2,2,2,2,0,0,0,0,2,60,60,60,60,36,0,0
0,0,36,60,60,60,60,60,60,60,60,60,60,2,2,2,2,2,2,2,2,2,60,60,60,60,36,0,0
0,0,2,60,60,60,60,60,60,60,60,60,65,60,60,60,65,60,60,60,60,60,65,60,60,60,2,0,0
0,0,36,60,60,60,60,60,60,60,60,60,65,60,60,60,65,60,60,60,60,60,65,60,60,60,36,0,0
0,0,36,60,60,60,60,60,60,60,60,60,65,60,60,60,65,60,60,60,60,60,65,60,60,60,36,0,0
0,0,2,60,60,60,60,2,60,60,60,60,65,60,60,60,65,65,65,65,65,65,65,60,60,60,2,0,0
0,0,36,60,60,60,60,60,60,60,60,60,65,60,60,60,65,60,60,60,60,60,65,60,60,60,36,0,0
0,0,36,60,60,60,60,60,60,60,60,60,65,60,60,60,65,60,60,60,60,60,65,60,60,60,36,0,0
0,0,2,60,60,60,60,60,60,60,60,60,65,60,60,60,65,60,60,60,60,60,65,60,60,60,2,0,0
0,0,50,2,36,36,2,36,36,2,36,36,2,36,36,36,2,36,36,2,36,36,2,36,36,2,50,0,0
0,0,0,0,0,0,0,0,0,0,0,0,0,0,0,0,0,0,0,0,0,0,0,0,0,0,0,0,0
0,0,0,0,0,0,0,0,0,0,0,0,0,0,0,0,0,0,0,0,0,0,0,0,0,0,0,0,0
endlayer

layer
0,0,0,0,0,0,0,0,0,0,0,0,0,0,0,0,0,0,0,0,0,0,0,0,0,0,0,0,0
0,0,0,0,0,0,0,0,0,0,0,0,0,0,0,0,0,0,0,0,0,0,0,0,0,0,0,0,0
0,0,2,2,2,2,2,2,2,2,2,2,2,2,2,2,2,2,2,2,2,2,2,2,2,2,2,0,0
0,0,2,73,73,73,73,73,73,73,73,73,73,73,73,73,73,73,73,73,73,73,73,73,73,73,2,0,0
0,0,2,73,73,73,73,73,73,73,73,73,73,73,73,73,73,73,73,73,73,73,73,73,73,73,2,0,0
0,0,2,73,73,73,73,73,73,73,73,73,73,73,73,73,73,73,73,73,73,73,73,73,73,73,2,0,0
0,0,2,73,73,73,73,73,73,73,73,73,73,73,2,73,73,73,73,73,73,2,73,73,73,73,2,0,0
0,0,2,73,73,73,73,73,73,73,73,73,73,73,73,73,73,73,73,73,73,73,73,73,73,73,2,0,0
0,0,2,73,73,73,73,73,73,73,73,73,73,73,73,73,73,73,73,73,73,73,73,73,73,73,2,0,0
0,0,2,73,73,73,73,73,73,73,73,73,73,73,73,73,73,73,73,73,73,73,73,73,73,73,2,0,0
0,0,2,73,73,73,73,73,73,73,73,73,73,2,2,2,2,2,2,2,2,2,73,73,73,73,2,0,0
0,0,2,73,73,73,73,73,73,73,73,73,73,2,2,2,2,2,2,2,2,2,73,73,73,73,2,0,0
0,0,2,73,73,73,73,73,73,73,73,73,73,2,17,0,0,2,0,0,8,2,73,73,73,73,2,0,0
0,0,2,73,73,73,73,73,73,73,73,73,73,2,0,0,0,2,0,0,0,2,73,73,73,73,2,0,0
0,0,2,73,73,73,73,73,73,73,73,73,73,2,2,2,2,2,2,2,2,2,73,73,73,73,2,0,0
0,0,2,73,73,73,73,73,73,73,73,73,73,73,73,73,73,73,73,73,73,73,73,73,73,73,2,0,0
0,0,2,73,73,73,73,2,73,73,73,73,73,73,73,73,73,73,73,73,73,73,73,73,73,73,2,0,0
0,0,2,73,73,73,73,73,73,73,73,73,73,73,73,73,73,73,73,73,73,73,73,73,73,73,2,0,0
0,0,2,73,73,73,73,73,73,73,73,73,73,2,2,2,2,2,2,2,2,2,73,73,73,73,2,0,0
0,0,2,73,73,73,73,73,73,73,73,73,73,2,73,73,2,2,2,2,2,2,73,73,73,73,2,0,0
0,0,2,73,73,73,73,73,73,73,73,73,73,2,73,73,2,0,0,0,37,2,73,73,73,73,2,0,0
0,0,2,73,73,73,73,73,73,73,73,73,73,2,73,73,2,0,0,25,2,2,73,73,73,73,2,0,0
0,0,2,73,73,73,73,73,73,73,73,73,73,2,2,2,2,2,2,2,2,2,73,73,73,73,2,0,0
0,0,2,73,73,73,73,73,73,73,73,73,73,73,73,73,73,73,73,73,73,73,73,73,73,73,2,0,0
0,0,2,73,73,73,73,73,73,73,73,73,73,73,73,73,73,73,73,73,73,73,73,73,73,73,2,0,0
0,0,2,73,73,73,73,73,73,73,73,73,73,73,73,73,73,73,73,73,73,73,73,73,73,73,2,0,0
0,0,2,73,73,73,73,2,73,73,73,73,73,73,2,73,73,73,73,73,73,2,73,73,73,73,2,0,0
0,0,2,73,73,73,73,73,73,73,73,73,73,73,73,73,73,73,73,73,73,73,73,73,73,73,2,0,0
0,0,2,73,73,73,73,73,73,73,73,73,73,73,73,73,73,73,73,73,73,73,73,73,73,73,2,0,0
0,0,2,73,73,73,73,73,73,73,73,73,73,73,73,73,73,73,73,73,73,73,73,73,73,73,2,0,0
0,0,2,2,2,2,2,2,2,2,2,2,2,2,2,2,2,2,2,2,2,2,2,2,2,2,2,0,0
0,0,0,0,0,0,0,0,0,0,0,0,0,0,0,0,0,0,0,0,0,0,0,0,0,0,0,0,0
0,0,0,0,0,0,0,0,0,0,0,0,0,0,0,0,0,0,0,0,0,0,0,0,0,0,0,0,0
endlayer

layer
0,0,0,0,0,0,0,0,0,0,0,0,0,0,0,0,0,0,0,0,0,0,0,0,0,0,0,0,0
0,0,0,0,0,0,0,0,0,0,0,0,0,0,0,0,0,0,0,0,0,0,0,0,0,0,0,0,0
0,0,50,2,36,36,2,36,36,2,36,36,2,36,36,36,2,36,36,2,36,36,2,36,36,2,50,0,0
0,0,2,15,15,15,15,15,15,15,15,15,15,15,15,15,15,15,15,15,15,15,15,15,15,15,2,0,0
0,0,36,15,15,15,15,15,15,15,15,15,15,15,15,15,15,15,15,15,15,15,15,15,15,15,36,0,0
0,0,36,15,15,15,15,15,15,15,15,15,15,15,15,15,15,15,15,15,15,15,15,15,15,15,36,0,0
0,0,2,15,15,15,15,2,15,15,15,15,15,15,2,15,15,15,15,15,15,2,15,15,15,15,2,0,0
0,0,36,15,15,15,15,15,15,15,15,15,15,15,15,15,15,15,15,15,15,15,15,15,15,15,36,0,0
0,0,36,15,15,15,15,15,15,15,15,15,15,15,15,15,15,15,15,15,15,15,15,15,15,15,36,0,0
0,0,2,15,15,15,15,15,15,15,15,15,15,15,15,15,15,15,15,15,15,15,15,15,15,15,2,0,0
0,0,36,15,15,15,15,15,15,15,15,15,15,2,2,2,2,2,2,2,2,2,15,15,15,15,36,0,0
0,0,36,15,15,15,15,15,15,15,15,15,15,2,0,0,0,2,0,0,0,2,15,15,15,15,36,0,0
0,0,2,15,15,15,15,15,15,15,15,15,15,2,17,0,0,2,0,0,8,2,15,15,15,15,2,0,0
0,0,2,15,15,15,15,15,15,15,15,15,15,2,0,0,0,2,0,0,0,2,15,15,15,15,2,0,0
0,0,36,15,15,15,15,15,15,15,15,15,15,2,0,0,0,2,0,0,0,2,15,15,15,15,36,0,0
0,0,36,15,15,15,15,15,15,15,15,15,15,15,15,15,15,15,15,15,15,15,15,15,15,15,36,0,0
0,0,2,15,15,15,15,2,15,15,15,15,15,15,15,15,15,15,15,15,15,15,15,15,15,15,2,0,0
0,0,36,15,15,15,15,15,15,15,15,15,15,15,0,15,15,15,15,0,0,0,15,15,15,15,36,0,0
0,0,36,15,15,15,15,15,15,15,15,15,15,2,9,2,2,2,2,2,9,2,15,15,15,15,36,0,0
0,0,2,15,15,15,15,15,15,15,15,15,15,2,0,15,2,2,2,0,10,2,15,15,15,15,2,0,0
0,0,2,15,15,15,15,15,15,15,15,15,15,2,15,15,2,42,0,0,0,2,15,15,15,15,2,0,0
0,0,36,15,15,15,15,15,15,15,15,15,15,2,15,15,2,0,25,11,0,2,15,15,15,15,36,0,0
0,0,36,15,15,15,15,15,15,15,15,15,15,2,2,2,2,2,2,2,2,2,15,15,15,15,36,0,0
0,0,2,15,15,15,15,15,15,15,15,15,15,15,15,15,15,15,15,15,15,15,15,15,15,15,2,0,0
0,0,36,15,15,15,15,15,15,15,15,15,15,15,15,15,15,15,15,15,15,15,15,15,15,15,36,0,0
0,0,36,15,15,15,15,15,15,15,15,15,15,15,15,15,15,15,15,15,15,15,15,15,15,15,36,0,0
0,0,2,15,15,15,15,2,15,15,15,15,15,15,2,15,15,15,15,15,15,2,15,15,15,15,2,0,0
0,0,36,15,15,15,15,15,15,15,15,15,15,15,15,15,15,15,15,15,15,15,15,15,15,15,36,0,0
0,0,36,15,15,15,15,15,15,15,15,15,15,15,15,15,15,15,15,15,15,15,15,15,15,15,36,0,0
0,0,2,15,15,15,15,15,15,15,15,15,15,15,15,15,15,15,15,15,15,15,15,15,15,15,2,0,0
0,0,50,2,36,36,2,36,36,2,36,36,2,36,36,36,2,36,36,2,36,36,2,36,36,2,50,0,0
0,0,0,0,0,0,0,0,0,0,0,0,0,0,0,0,0,0,0,0,0,0,0,0,0,0,0,0,0
0,0,0,0,0,0,0,0,0,0,0,0,0,0,0,0,0,0,0,0,0,0,0,0,0,0,0,0,0
endlayer

layer
0,0,0,0,0,0,0,0,0,0,0,0,0,0,0,0,0,0,0,0,0,0,0,0,0,0,0,0,0
0,0,0,0,0,0,0,0,0,0,0,0,0,0,0,0,0,0,0,0,0,0,0,0,0,0,0,0,0
0,0,2,2,78,78,2,78,78,2,78,78,2,78,78,78,2,78,78,2,27,27,2,27,27,2,2,0,0
0,0,2,0,0,0,0,0,0,0,0,0,0,0,0,0,0,0,0,0,0,0,0,0,0,0,2,0,0
0,0,78,0,0,0,0,0,0,0,0,0,0,0,0,0,0,0,0,0,0,0,0,0,0,0,27,0,0
0,0,78,0,0,0,0,0,0,0,0,0,0,0,0,0,0,0,0,0,0,0,0,0,0,0,27,0,0
0,0,2,0,0,0,0,2,0,0,0,0,0,0,2,0,0,0,0,0,0,2,0,0,0,0,2,0,0
0,0,78,0,0,0,0,0,0,0,0,0,0,0,0,0,0,0,0,0,0,0,0,0,0,0,78,0,0
0,0,78,0,0,0,0,0,0,0,0,0,0,0,0,0,0,0,0,0,0,0,0,0,0,0,78,0,0
0,0,2,0,0,0,0,0,0,0,0,0,0,0,0,0,0,0,0,0,0,0,0,0,0,0,2,0,0
0,0,78,0,0,0,0,0,0,0,0,0,0,2,2,2,2,2,2,2,2,2,0,0,0,0,78,0,0
0,0,78,0,0,0,0,0,0,0,0,0,0,2,0,0,0,2,0,0,0,2,0,0,0,0,78,0,0
0,0,2,0,0,0,0,0,0,0,0,0,0,2,17,0,0,2,0,0,8,2,0,0,0,0,2,0,0
0,0,2,0,0,0,0,0,0,0,0,0,0,2,0,0,0,2,0,0,0,2,0,0,0,0,2,0,0
0,0,78,0,0,0,0,0,0,0,0,0,0,2,0,0,0,2,0,0,0,2,0,0,0,0,78,0,0
0,0,78,0,0,0,0,0,0,0,0,0,0,0,0,0,0,0,0,0,0,0,0,0,0,0,78,0,0
0,0,2,0,0,0,0,2,0,0,0,0,0,0,0,0,0,0,0,0,0,0,0,0,0,0,2,0,0
0,0,78,0,0,0,0,0,0,0,0,0,0,22,0,0,0,0,0,22,0,0,0,0,0,0,78,0,0
0,0,78,0,0,0,0,0,0,0,0,0,0,2,21,2,2,2,2,2,21,2,0,0,0,0,78,0,0
0,0,2,0,0,0,0,0,0,0,0,0,0,2,70,0,2,2,2,0,0,2,0,0,0,0,2,0,0
0,0,2,0,0,0,0,0,0,0,0,0,0,2,0,80,2,0,0,0,0,2,0,0,0,0,2,0,0
0,0,78,0,0,0,0,0,0,0,0,0,0,2,0,81,2,25,11,0,0,2,0,0,0,0,78,0,0
0,0,78,0,0,0,0,0,0,0,0,0,0,2,2,2,2,2,2,2,2,2,0,0,0,0,78,0,0
0,0,2,0,0,0,0,0,0,0,0,0,0,0,0,0,0,0,0,0,0,0,0,0,0,0,2,0,0
0,0,78,0,0,0,0,0,0,0,0,0,0,0,0,0,0,0,0,0,0,0,0,0,0,0,78,0,0
0,0,78,0,0,0,0,0,0,0,0,0,0,0,0,0,0,0,0,0,0,0,0,0,0,0,78,0,0
0,0,2,0,0,0,0,2,0,0,0,0,0,0,2,0,0,0,0,0,0,2,0,0,0,0,2,0,0
0,0,78,0,0,0,0,0,0,0,0,0,0,0,0,0,0,0,0,0,0,0,0,0,0,0,78,0,0
0,0,78,0,0,0,0,0,0,0,0,0,0,0,0,0,0,0,0,0,0,0,0,0,0,0,78,0,0
0,0,2,0,0,0,0,0,0,0,0,0,0,0,0,0,0,0,0,0,0,0,0,0,0,0,2,0,0
0,0,2,2,78,78,2,78,78,2,78,78,2,78,78,78,2,78,78,2,78,78,2,78,78,2,2,0,0
0,0,0,0,0,0,0,0,0,0,0,0,0,0,0,0,0,0,0,0,0,0,0,0,0,0,0,0,0
0,0,0,0,0,0,0,0,0,0,0,0,0,0,0,0,0,0,0,0,0,0,0,0,0,0,0,0,0
endlayer

layer
0,0,0,0,0,0,0,0,0,0,0,0,0,0,0,0,0,0,0,0,0,0,0,0,0,0,0,0,0
0,0,0,0,0,0,0,0,0,0,0,0,0,0,0,0,0,0,0,0,0,0,0,0,0,0,0,0,0
0,0,50,2,78,78,2,78,78,2,78,78,2,78,78,78,2,78,78,2,27,27,2,27,27,2,50,0,0
0,0,2,0,0,0,0,0,0,0,0,0,0,0,0,0,0,0,0,0,0,0,0,0,0,0,2,0,0
0,0,78,0,0,0,0,0,0,0,0,0,0,0,0,0,0,0,0,0,0,0,0,0,0,0,27,0,0
0,0,78,0,0,0,0,0,0,0,0,0,0,0,0,0,0,0,0,0,0,0,0,0,0,0,27,0,0
0,0,2,0,0,0,0,2,0,0,0,0,0,0,2,0,0,0,0,0,0,2,0,0,0,0,2,0,0
0,0,78,0,0,0,0,0,0,0,0,0,0,0,0,0,0,0,0,0,0,0,0,0,0,0,78,0,0
0,0,78,0,0,0,0,0,0,0,0,0,0,0,0,0,0,0,0,0,0,0,0,0,0,0,78,0,0
0,0,2,0,0,0,0,0,0,0,0,0,0,0,0,0,0,0,0,0,0,0,0,0,0,0,2,0,0
0,0,78,0,0,0,0,0,0,0,0,0,0,2,2,2,2,2,2,2,2,2,0,0,0,0,78,0,0
0,0,78,0,0,0,0,0,0,0,0,0,0,2,0,0,0,2,0,0,0,2,0,0,0,0,78,0,0
0,0,2,0,0,0,0,0,0,0,0,0,0,2,17,0,0,2,0,0,8,2,0,0,0,0,2,0,0
0,0,2,0,0,0,0,0,0,0,0,0,0,2,0,0,0,2,0,0,0,2,0,0,0,0,2,0,0
0,0,78,0,0,0,0,0,0,0,0,0,0,2,0,0,0,2,0,0,0,2,0,0,0,0,78,0,0
0,0,78,0,0,0,0,0,0,0,0,0,0,0,0,0,0,0,0,0,0,0,0,0,0,0,78,0,0
0,0,2,0,0,0,0,2,0,0,0,0,0,0,0,0,0,0,0,0,0,0,0,0,0,0,2,0,0
0,0,78,0,0,0,0,0,0,0,0,0,0,0,0,0,0,0,0,0,0,0,0,0,0,0,78,0,0
0,0,78,0,0,0,0,0,0,0,0,0,0,2,2,2,2,2,2,2,2,2,0,0,0,0,78,0,0
0,0,2,0,0,0,0,0,0,0,0,0,0,2,0,0,2,2,2,2,2,2,0,0,0,0,2,0,0
0,0,2,0,0,0,0,0,0,0,0,0,0,2,0,0,2,2,0,0,0,2,0,0,0,0,2,0,0
0,0,78,0,0,0,0,0,0,0,0,0,0,2,0,81,2,11,0,0,0,2,0,0,0,0,78,0,0
0,0,78,0,0,0,0,0,0,0,0,0,0,2,2,2,2,2,2,2,2,2,0,0,0,0,78,0,0
0,0,2,0,0,0,0,0,0,0,0,0,0,0,0,0,0,0,0,0,0,0,0,0,0,0,2,0,0
0,0,78,0,0,0,0,0,0,0,0,0,0,0,0,0,0,0,0,0,0,0,0,0,0,0,78,0,0
0,0,78,0,0,0,0,0,0,0,0,0,0,0,0,0,0,0,0,0,0,0,0,0,0,0,78,0,0
0,0,2,0,0,0,0,2,0,0,0,0,0,0,2,0,0,0,0,0,0,2,0,0,0,0,2,0,0
0,0,78,0,0,0,0,0,0,0,0,0,0,0,0,0,0,0,0,0,0,0,0,0,0,0,78,0,0
0,0,78,0,0,0,0,0,0,0,0,0,0,0,0,0,0,0,0,0,0,0,0,0,0,0,78,0,0
0,0,2,0,0,0,0,0,0,0,0,0,0,0,0,0,0,0,0,0,0,0,0,0,0,0,2,0,0
0,0,50,2,78,78,2,78,78,2,78,78,2,78,78,78,2,78,78,2,78,78,2,78,78,2,50,0,0
0,0,0,0,0,0,0,0,0,0,0,0,0,0,0,0,0,0,0,0,0,0,0,0,0,0,0,0,0
0,0,0,0,0,0,0,0,0,0,0,0,0,0,0,0,0,0,0,0,0,0,0,0,0,0,0,0,0
endlayer

layer
0,0,0,0,0,0,0,0,0,0,0,0,0,0,0,0,0,0,0,0,0,0,0,0,0,0,0,0,0
0,0,0,0,0,0,0,0,0,0,0,0,0,0,0,0,0,0,0,0,0,0,0,0,0,0,0,0,0
0,0,2,2,78,78,2,78,78,2,78,78,2,78,78,78,2,78,78,2,27,27,2,27,27,2,2,0,0
0,0,2,0,0,0,0,0,0,0,0,0,0,0,0,0,0,0,0,0,0,0,0,0,0,0,2,0,0
0,0,78,0,0,0,0,0,0,0,0,0,0,0,0,0,0,0,0,0,0,0,0,0,0,0,27,0,0
0,0,78,0,0,0,0,0,0,0,0,0,0,0,0,0,0,0,0,0,0,0,0,0,0,0,27,0,0
0,0,2,0,0,0,0,2,0,0,0,0,0,0,2,0,0,0,0,0,0,0,0,0,0,0,2,0,0
0,0,78,0,0,0,0,0,0,0,0,0,0,0,0,0,0,0,0,0,0,0,0,0,0,0,78,0,0
0,0,78,0,0,0,0,0,0,0,0,0,0,0,0,0,0,0,0,0,0,0,0,0,0,0,78,0,0
0,0,2,0,0,0,0,0,0,0,0,0,0,0,0,0,0,0,0,0,0,0,0,0,0,0,2,0,0
0,0,78,0,0,0,0,0,0,0,0,0,0,2,2,2,2,2,2,2,2,2,0,0,0,0,78,0,0
0,0,78,0,0,0,0,0,0,0,0,0,0,2,0,0,0,2,0,0,0,2,0,0,0,0,78,0,0
0,0,2,0,0,0,0,0,0,0,0,0,0,2,17,0,0,2,0,0,8,2,0,0,0,0,2,0,0
0,0,2,0,0,0,0,0,0,0,0,0,0,2,0,0,0,2,0,0,0,2,0,0,0,0,2,0,0
0,0,78,0,0,0,0,0,0,0,0,0,0,2,2,2,2,2,2,2,2,2,0,0,0,0,78,0,0
0,0,78,0,0,0,0,0,0,0,0,0,0,0,0,0,0,0,0,0,0,0,0,0,0,0,78,0,0
0,0,2,0,0,0,0,2,0,0,0,0,0,0,0,0,0,0,0,0,0,0,0,0,0,0,2,0,0
0,0,78,0,0,0,0,0,0,0,0,0,0,0,0,0,0,0,0,0,0,0,0,0,0,0,78,0,0
0,0,78,0,0,0,0,0,0,0,0,0,0,2,2,2,2,2,2,2,2,2,0,0,0,0,78,0,0
0,0,2,0,0,0,0,0,0,0,0,0,0,2,0,0,2,2,2,2,2,2,0,0,0,0,2,0,0
0,0,2,0,0,0,0,0,0,0,0,0,0,2,0,0,2,32,31,0,0,2,0,0,0,0,2,0,0
0,0,78,0,0,0,0,0,0,0,0,0,0,2,0,0,2,0,0,0,0,2,0,0,0,0,78,0,0
0,0,78,0,0,0,0,0,0,0,0,0,0,2,2,2,2,2,2,2,2,2,0,0,0,0,78,0,0
0,0,2,0,0,0,0,0,0,0,0,0,0,0,0,0,0,0,0,0,0,0,0,0,0,0,2,0,0
0,0,78,0,0,0,0,0,0,0,0,0,0,0,0,0,0,0,0,0,0,0,0,0,0,0,78,0,0
0,0,78,0,0,0,0,0,0,0,0,0,0,0,0,0,0,0,0,0,0,0,0,0,0,0,78,0,0
0,0,2,0,0,0,0,2,0,0,0,0,0,0,2,0,0,0,0,0,0,2,0,0,0,0,2,0,0
0,0,78,0,0,0,0,0,0,0,0,0,0,0,0,0,0,0,0,0,0,0,0,0,0,0,78,0,0
0,0,78,0,0,0,0,0,0,0,0,0,0,0,0,0,0,0,0,0,0,0,0,0,0,0,78,0,0
0,0,2,0,0,0,0,0,0,0,0,0,0,0,0,0,0,0,0,0,0,0,0,0,0,0,2,0,0
0,0,2,2,78,78,2,78,78,2,78,78,2,78,78,78,2,78,78,2,78,78,2,78,78,2,2,0,0
0,0,0,0,0,0,0,0,0,0,0,0,0,0,0,0,0,0,0,0,0,0,0,0,0,0,0,0,0
0,0,0,0,0,0,0,0,0,0,0,0,0,0,0,0,0,0,0,0,0,0,0,0,0,0,0,0,0
endlayer

layer
0,0,0,0,0,0,0,0,0,0,0,0,0,0,0,0,0,0,0,0,0,0,0,0,0,0,0,0,0
0,0,0,0,0,0,0,0,0,0,0,0,0,0,0,0,0,0,0,0,0,0,0,0,0,0,0,0,0
0,0,50,2,36,36,2,36,36,2,36,36,2,36,36,36,2,36,36,2,36,36,2,36,36,2,50,0,0
0,0,2,0,0,0,0,0,0,0,0,0,0,0,0,0,0,0,0,0,0,0,0,0,0,0,2,0,0
0,0,36,0,0,0,0,0,0,0,0,0,0,0,0,0,0,0,0,0,0,0,0,0,0,0,36,0,0
0,0,36,0,0,0,0,0,0,0,0,0,0,0,0,0,0,0,0,0,0,0,0,0,0,0,36,0,0
0,0,2,0,0,0,0,2,0,0,0,0,0,0,2,0,0,0,0,0,0,0,0,0,0,0,2,0,0
0,0,36,0,0,0,0,0,0,0,0,0,0,0,0,0,0,0,0,0,0,0,0,0,0,0,36,0,0
0,0,36,0,0,0,0,0,0,81,0,0,0,0,0,0,0,0,0,0,0,0,0,0,0,0,36,0,0
0,0,2,0,0,0,0,0,0,82,0,0,0,0,0,0,0,0,0,0,0,0,0,0,0,0,2,0,0
0,0,36,0,0,0,0,0,0,81,0,0,0,2,2,2,2,2,2,2,2,2,0,0,0,0,36,0,0
0,0,36,0,0,0,0,0,0,81,0,0,0,2,0,0,0,2,0,0,0,2,0,0,0,0,36,0,0
0,0,2,0,0,0,0,81,81,81,81,81,81,2,17,0,0,2,0,0,8,2,0,0,0,0,2,0,0
0,0,2,0,0,0,0,0,0,0,0,0,0,2,0,0,0,2,0,0,0,2,0,0,0,0,2,0,0
0,0,36,0,0,0,0,0,0,0,0,0,0,2,2,2,2,2,2,2,2,2,0,0,0,0,36,0,0
0,0,36,0,0,0,0,0,0,0,0,0,0,0,0,0,0,0,0,0,0,0,0,81,0,0,36,0,0
0,0,2,0,0,0,0,2,0,0,0,0,0,0,0,0,0,0,0,0,0,0,0,82,0,0,2,0,0
0,0,36,0,0,0,0,0,0,0,0,0,0,0,0,0,0,0,0,0,81,81,81,81,0,0,36,0,0
0,0,36,0,0,0,0,0,0,0,0,0,0,2,2,2,2,2,2,2,2,2,0,0,0,0,36,0,0
0,0,2,0,0,0,0,0,0,0,0,0,0,2,2,2,2,2,2,2,2,2,0,0,0,0,2,0,0
0,0,2,0,0,0,0,0,0,0,0,0,0,2,2,2,2,0,37,31,0,2,0,0,0,0,2,0,0
0,0,36,0,0,0,0,0,0,0,0,0,0,2,2,2,2,0,0,0,0,2,0,0,0,0,36,0,0
0,0,36,0,0,0,0,0,0,0,0,0,0,2,2,2,2,2,2,2,2,2,0,0,0,0,36,0,0
0,0,2,0,0,0,0,0,0,0,0,0,0,0,0,0,81,0,0,0,0,0,0,0,0,0,2,0,0
0,0,36,0,0,0,0,0,0,0,0,0,0,0,0,0,81,0,0,0,0,0,0,0,0,0,36,0,0
0,0,36,0,0,0,0,0,0,0,0,0,0,0,0,0,81,0,0,0,0,0,0,0,0,0,36,0,0
0,0,2,0,0,0,0,2,0,0,0,0,0,0,2,0,82,0,0,0,0,2,0,0,0,0,2,0,0
0,0,36,0,0,0,0,0,0,0,0,0,0,0,0,0,0,0,0,0,0,0,0,0,0,0,36,0,0
0,0,36,0,0,0,0,0,0,0,0,0,0,0,0,0,0,0,0,0,0,0,0,0,0,0,36,0,0
0,0,2,0,0,0,0,0,0,0,0,0,0,0,0,0,0,0,0,0,0,0,0,0,0,0,2,0,0
0,0,50,2,36,36,2,36,36,2,36,36,2,36,36,36,2,36,36,2,36,36,2,36,36,2,50,0,0
0,0,0,0,0,0,0,0,0,0,0,0,0,0,0,0,0,0,0,0,0,0,0,0,0,0,0,0,0
0,0,0,0,0,0,0,0,0,0,0,0,0,0,0,0,0,0,0,0,0,0,0,0,0,0,0,0,0
endlayer

layer
0,0,0,0,0,0,0,0,0,0,0,0,0,0,0,0,0,0,0,0,0,0,0,0,0,0,0,0,0
0,0,0,0,0,0,0,0,0,0,0,0,0,0,0,0,0,0,0,0,0,0,0,0,0,0,0,0,0
0,0,2,2,2,2,2,2,2,2,2,2,2,2,2,2,2,2,2,2,2,2,2,2,2,2,2,0,0
0,0,2,84,84,84,84,84,84,84,84,84,84,84,84,84,84,84,74,74,83,83,83,83,83,83,2,0,0
0,0,2,84,84,84,84,84,84,84,84,84,84,84,84,83,83,83,83,83,83,83,83,83,83,83,2,0,0
0,0,2,84,84,84,84,84,84,84,84,84,84,84,84,83,83,83,83,83,83,83,83,83,83,83,2,0,0
0,0,2,84,84,84,84,2,84,84,84,84,84,84,84,83,83,83,83,83,83,83,83,83,83,83,2,0,0
0,0,2,84,84,84,84,84,84,84,84,84,84,84,84,83,83,83,83,83,83,83,83,83,83,83,2,0,0
0,0,2,84,84,84,84,84,84,84,84,84,84,84,84,84,84,83,83,83,83,83,83,83,83,83,2,0,0
0,0,2,84,84,84,84,84,84,84,84,84,84,84,84,84,84,83,83,83,83,74,84,84,84,84,2,0,0
0,0,2,84,84,84,84,84,84,84,84,84,84,2,2,2,2,2,2,2,2,2,84,84,84,84,2,0,0
0,0,2,84,84,84,84,2,84,84,84,84,84,2,2,2,2,2,2,2,2,2,84,84,84,84,2,0,0
0,0,2,84,84,84,84,84,84,84,84,84,84,2,17,0,0,2,0,0,8,2,84,84,84,84,2,0,0
0,0,2,84,84,84,84,84,84,84,84,84,84,2,0,0,0,2,0,0,0,2,84,84,84,84,2,0,0
0,0,2,84,84,84,84,84,84,84,84,84,84,2,2,2,2,2,2,2,2,2,84,84,84,84,2,0,0
0,0,2,84,84,84,84,84,84,84,84,84,84,84,84,84,84,84,84,84,84,84,84,84,84,84,2,0,0
0,0,2,84,84,84,84,84,84,84,84,84,84,84,84,84,84,84,84,84,84,84,84,84,84,84,2,0,0
0,0,2,84,84,84,84,84,84,84,84,84,84,84,84,84,84,84,84,84,84,84,84,84,84,84,2,0,0
0,0,2,84,84,84,84,84,84,84,84,84,84,2,2,2,2,2,2,2,2,2,84,84,84,84,2,0,0
0,0,2,84,84,84,84,84,84,84,84,84,84,2,84,84,2,2,2,2,2,2,84,84,84,84,2,0,0
0,0,2,84,84,84,84,84,84,84,84,84,84,2,84,84,2,0,0,0,37,2,84,84,84,84,2,0,0
0,0,2,84,84,84,84,2,84,84,84,84,84,2,84,84,2,0,0,25,2,2,84,84,84,84,2,0,0
0,0,2,84,84,84,84,84,84,84,84,84,84,2,2,2,2,2,2,2,2,2,84,84,84,84,2,0,0
0,0,2,84,84,84,84,84,84,84,84,84,84,84,84,84,84,84,84,84,84,84,84,84,84,84,2,0,0
0,0,2,84,84,84,84,84,84,84,84,84,84,84,84,84,84,84,84,84,84,84,84,84,84,84,2,0,0
0,0,2,84,84,84,84,84,84,84,84,84,84,84,84,84,84,84,84,84,84,84,84,84,84,84,2,0,0
0,0,2,84,84,84,84,2,84,84,84,84,84,84,84,84,84,84,84,84,84,84,84,84,84,84,2,0,0
0,0,2,84,84,84,84,84,84,84,84,84,84,84,84,84,84,84,84,84,84,84,84,84,84,84,2,0,0
0,0,2,83,83,83,83,83,83,83,83,83,84,84,84,84,84,84,84,84,84,84,84,84,84,84,2,0,0
0,0,2,83,83,83,83,83,83,83,83,83,84,84,84,84,84,84,84,84,84,84,84,84,84,84,2,0,0
0,0,2,85,85,85,85,85,85,85,85,85,85,2,2,2,2,2,2,2,2,2,2,2,2,2,2,0,0
0,0,0,0,0,0,0,0,0,0,0,0,0,0,0,0,0,0,0,0,0,0,0,0,0,0,0,0,0
0,0,0,0,0,0,0,0,0,0,0,0,0,0,0,0,0,0,0,0,0,0,0,0,0,0,0,0,0
endlayer

layer
0,0,0,0,0,0,0,0,0,0,0,0,0,0,0,0,0,0,0,0,0,0,0,0,0,0,0,0,0
0,0,0,0,0,0,0,0,0,0,0,0,0,0,0,0,0,0,0,0,0,0,0,0,0,0,0,0,0
0,0,50,2,36,36,2,36,36,2,36,36,2,36,36,36,2,36,36,2,36,36,2,36,36,2,50,0,0
0,0,2,60,51,0,60,0,0,60,51,0,52,0,53,0,52,0,0,0,0,0,0,0,0,0,2,0,0
0,0,36,60,0,0,60,51,0,60,0,0,52,54,54,0,0,0,0,0,0,0,0,0,0,0,36,0,0
0,0,36,15,15,15,15,0,15,15,15,15,52,0,0,0,0,0,0,0,0,0,0,0,0,0,36,0,0
0,0,2,15,15,15,15,2,15,15,15,15,52,0,0,0,0,0,0,0,0,0,0,0,0,0,2,0,0
0,0,36,60,51,0,60,0,15,15,15,0,63,0,0,0,0,0,0,0,0,0,0,0,0,0,36,0,0
0,0,36,60,0,0,60,51,15,15,15,15,52,0,0,0,52,0,0,0,0,0,0,0,0,0,36,0,0
0,0,2,15,15,15,15,15,15,15,0,0,52,62,62,20,52,0,0,0,0,0,52,0,0,0,2,0,0
0,0,36,15,15,15,15,15,15,15,0,53,0,2,2,2,2,2,2,2,2,2,54,0,0,0,36,0,0
0,0,36,60,0,15,15,2,15,15,0,54,54,2,0,0,0,2,0,0,0,2,58,0,0,0,36,0,0
0,0,2,60,51,15,15,76,0,0,0,0,0,2,17,0,0,2,0,0,8,2,58,0,0,51,2,0,0
0,0,2,0,0,15,15,0,0,0,0,0,0,2,0,0,0,2,0,0,0,2,52,55,55,52,2,0,0
0,0,36,15,15,15,15,0,52,52,55,55,52,2,0,0,0,2,0,0,0,2,0,0,0,0,36,0,0
0,0,36,15,15,14,14,14,52,0,0,0,0,0,0,0,0,0,0,0,0,0,0,0,0,0,36,0,0
0,0,2,52,52,52,52,52,52,0,0,0,0,0,0,0,0,0,0,0,0,0,0,0,0,0,2,0,0
0,0,36,60,60,60,60,60,52,0,0,0,0,0,0,0,0,0,0,0,0,0,0,0,0,0,36,0,0
0,0,36,15,15,15,15,15,52,52,56,56,52,2,2,2,2,2,2,2,9,2,0,0,0,0,36,0,0
0,0,2,15,15,15,15,15,15,15,0,0,0,2,61,61,2,2,2,0,10,2,52,56,56,52,2,0,0
0,0,2,15,15,15,15,15,15,15,0,0,0,63,0,0,2,42,0,0,0,2,58,0,0,51,2,0,0
0,0,36,15,15,60,60,2,15,15,0,0,0,2,15,15,2,0,25,11,0,2,58,0,0,0,36,0,0
0,0,36,15,15,62,0,0,0,0,0,0,0,2,2,2,2,2,2,2,2,2,54,54,0,0,36,0,0
0,0,2,15,15,15,15,15,15,15,0,0,52,20,53,53,52,0,0,54,0,0,52,62,0,0,2,0,0
0,0,36,15,15,15,15,15,15,15,0,0,52,0,0,0,52,0,58,54,51,0,52,0,0,0,36,0,0
0,0,36,0,53,0,0,0,53,0,0,0,63,0,0,0,52,0,0,0,0,0,75,0,0,0,36,0,0
0,0,2,0,60,60,60,2,60,60,15,15,52,0,0,0,52,52,52,52,52,52,52,0,0,0,2,0,0
0,0,36,0,0,0,62,0,0,0,15,15,52,0,0,0,52,0,0,54,0,0,52,0,0,0,36,0,0
0,0,36,0,0,0,0,0,0,0,0,0,52,0,54,54,52,0,58,54,51,0,75,0,0,0,36,0,0
0,0,2,0,0,0,0,0,0,0,0,0,52,0,62,0,52,0,0,0,0,0,52,0,0,20,2,0,0
0,0,50,85,39,39,85,39,39,85,39,39,85,36,36,36,2,36,36,2,36,36,2,36,36,2,50,0,0
0,0,0,0,0,0,0,0,0,0,0,0,0,0,0,0,0,0,0,0,0,0,0,0,0,0,0,0,0
0,0,0,0,0,0,0,0,0,0,0,0,0,0,0,0,0,0,0,0,0,0,0,0,0,0,0,0,0
endlayer

layer
0,0,0,0,0,0,0,0,0,0,0,0,0,0,0,0,0,0,0,0,0,0,0,0,0,0,0,0,0
0,0,0,0,0,0,0,0,0,0,0,0,0,0,0,0,0,0,0,0,0,0,0,0,0,0,0,0,0
0,0,2,2,78,78,2,78,78,2,78,78,2,78,78,78,2,78,78,2,27,27,2,27,27,2,2,0,0
0,0,2,0,0,0,0,0,0,0,0,0,65,0,0,0,65,0,0,0,0,0,0,0,0,0,2,0,0
0,0,78,0,0,0,0,0,0,0,0,0,14,0,0,0,0,0,0,0,0,0,0,0,0,0,27,0,0
0,0,78,0,0,0,0,0,0,0,0,0,14,0,0,0,0,0,0,0,0,0,0,0,0,0,27,0,0
0,0,2,0,0,0,0,2,0,0,0,0,65,0,0,0,0,0,0,0,0,0,0,0,0,0,2,0,0
0,0,78,0,0,0,0,0,0,0,0,0,69,0,0,0,0,0,0,0,0,0,0,0,0,0,27,0,0
0,0,78,0,0,0,0,0,0,0,0,0,65,0,0,0,65,0,0,0,0,0,0,0,0,0,27,0,0
0,0,2,0,0,0,0,0,0,0,0,0,65,0,0,10,65,0,0,0,0,0,65,0,0,0,2,0,0
0,0,78,0,0,0,0,0,0,0,0,0,0,2,2,2,2,2,2,2,2,2,0,0,0,0,78,0,0
0,0,78,0,0,0,0,2,0,0,0,0,0,2,0,0,0,2,0,0,0,2,0,0,0,0,78,0,0
0,0,2,0,0,0,0,0,0,0,0,0,0,2,17,0,0,2,0,0,8,2,0,0,0,0,2,0,0
0,0,2,0,0,0,0,0,0,0,0,0,0,2,0,0,0,2,0,0,0,2,65,69,68,65,2,0,0
0,0,78,0,0,0,0,0,65,65,69,68,65,2,0,0,0,2,0,0,0,2,66,0,0,0,78,0,0
0,0,78,0,0,14,14,14,65,0,0,0,66,0,0,0,0,0,0,0,0,0,0,0,0,0,78,0,0
0,0,2,65,65,65,65,65,65,0,0,0,0,0,0,0,0,0,0,0,0,0,0,0,0,0,2,0,0
0,0,78,0,0,0,0,0,65,0,0,0,67,0,0,0,0,0,0,22,0,0,0,0,0,0,78,0,0
0,0,78,0,0,0,0,0,65,65,68,69,65,2,2,2,2,2,2,2,21,2,67,0,0,0,78,0,0
0,0,2,0,0,0,0,0,0,0,0,0,0,2,61,61,2,2,2,0,0,2,65,68,69,65,2,0,0
0,0,2,0,0,0,0,0,0,0,0,0,0,69,0,0,2,0,0,0,0,2,0,0,0,0,2,0,0
0,0,78,0,0,0,0,2,0,0,0,0,0,2,15,15,2,25,11,0,0,2,0,0,0,0,78,0,0
0,0,78,0,0,0,0,0,0,0,0,0,0,2,2,2,2,2,2,2,2,2,0,0,0,0,78,0,0
0,0,2,0,0,0,0,0,0,0,0,0,65,10,0,0,65,0,0,0,0,0,65,0,0,0,2,0,0
0,0,78,0,0,0,0,0,0,0,0,0,65,0,0,0,14,0,0,0,0,0,65,0,0,0,78,0,0
0,0,78,0,0,0,0,0,0,0,0,0,69,0,0,0,14,0,0,0,0,0,69,0,0,0,78,0,0
0,0,2,0,0,0,0,2,0,0,0,0,65,0,0,0,65,65,65,65,65,65,65,0,0,0,2,0,0
0,0,78,0,0,0,0,0,0,0,0,0,65,0,0,0,14,0,0,0,0,0,65,0,0,0,78,0,0
0,0,78,0,0,0,0,0,0,0,0,0,65,0,0,0,14,0,0,0,0,0,69,0,0,0,78,0,0
0,0,2,0,0,0,0,0,0,0,0,0,65,0,0,0,65,0,0,0,0,0,65,0,0,10,2,0,0
0,0,2,85,27,27,85,27,27,85,27,27,85,78,78,78,2,78,78,2,78,78,2,78,78,2,2,0,0
0,0,0,0,0,0,0,0,0,0,0,0,0,0,0,0,0,0,0,0,0,0,0,0,0,0,0,0,0
0,0,0,0,0,0,0,0,0,0,0,0,0,0,0,0,0,0,0,0,0,0,0,0,0,0,0,0,0
endlayer

layer
0,0,0,0,0,0,0,0,0,0,0,0,0,0,0,0,0,0,0,0,0,0,0,0,0,0,0,0,0
0,0,0,0,0,0,0,0,0,0,0,0,0,0,0,0,0,0,0,0,0,0,0,0,0,0,0,0,0
0,0,50,2,78,78,2,78,78,2,78,78,2,78,78,78,2,78,78,2,27,27,2,27,27,2,50,0,0
0,0,2,0,0,0,0,0,0,0,0,0,65,0,0,0,65,0,0,0,0,0,0,0,0,0,2,0,0
0,0,78,0,0,0,0,0,0,0,0,0,65,0,0,0,0,0,0,0,0,0,0,0,0,0,27,0,0
0,0,78,0,0,0,0,0,0,0,0,0,65,0,0,0,0,0,0,0,0,0,0,0,0,0,27,0,0
0,0,2,0,0,0,0,2,0,0,0,0,65,0,0,0,0,0,0,0,0,0,0,0,0,0,2,0,0
0,0,78,0,0,0,0,0,0,0,0,0,65,0,0,0,0,0,0,0,0,0,0,0,0,0,27,0,0
0,0,78,0,0,0,0,0,0,0,0,0,65,0,0,0,65,0,0,0,0,0,0,0,0,0,27,0,0
0,0,2,0,0,0,0,0,0,0,0,0,65,0,0,0,65,0,0,0,0,0,65,0,0,0,2,0,0
0,0,78,0,0,0,0,0,0,0,0,0,0,2,2,2,2,2,2,2,2,2,0,0,0,0,78,0,0
0,0,78,0,0,0,0,2,0,0,0,0,0,2,0,0,0,2,0,0,0,2,0,0,0,0,78,0,0
0,0,2,0,0,0,0,0,0,0,0,0,0,2,17,0,0,2,0,0,8,2,0,0,0,0,2,0,0
0,0,2,0,0,0,0,0,0,0,0,0,0,2,0,0,0,2,0,0,0,2,65,5,5,65,2,0,0
0,0,78,0,0,0,0,0,65,65,5,5,65,2,0,0,0,2,0,0,0,2,0,0,0,0,78,0,0
0,0,78,0,0,14,14,14,65,0,0,0,0,0,0,0,0,0,0,0,0,0,0,0,0,0,78,0,0
0,0,2,65,65,65,65,65,65,0,0,0,0,0,0,0,0,0,0,0,0,0,0,0,0,0,2,0,0
0,0,78,0,14,14,14,14,65,0,0,0,0,0,0,0,0,0,0,0,0,0,0,0,0,0,78,0,0
0,0,78,0,0,0,0,0,65,65,5,5,65,2,2,2,2,2,2,2,2,2,0,0,0,0,78,0,0
0,0,2,0,0,0,0,0,0,0,0,0,0,2,61,61,2,2,2,2,2,2,65,5,5,65,2,0,0
0,0,2,0,0,0,0,0,0,0,0,0,0,2,0,0,2,2,0,0,0,2,0,0,0,0,2,0,0
0,0,78,0,0,0,0,2,0,0,0,0,0,2,61,61,2,11,0,0,0,2,0,0,0,0,78,0,0
0,0,78,0,0,0,0,0,0,0,0,0,0,2,2,2,2,2,2,2,2,2,0,0,0,0,78,0,0
0,0,2,0,0,0,0,0,0,0,0,0,65,0,0,0,65,0,0,0,0,0,65,0,0,0,2,0,0
0,0,78,0,0,0,0,0,0,0,0,0,65,0,0,0,65,0,0,0,0,0,65,0,0,0,78,0,0
0,0,78,0,0,0,0,0,0,0,0,0,65,0,0,0,65,0,0,0,0,0,65,0,0,0,78,0,0
0,0,2,0,0,0,0,2,0,0,0,0,65,0,0,0,65,65,65,65,65,65,65,0,0,0,2,0,0
0,0,78,0,0,0,0,0,0,0,0,0,65,0,0,0,65,0,0,0,0,0,65,0,0,0,78,0,0
0,0,78,0,0,0,0,0,0,0,0,0,65,0,0,0,65,0,0,0,0,0,65,0,0,0,78,0,0
0,0,2,0,0,0,0,0,0,0,0,0,65,0,0,0,65,0,0,0,0,0,65,0,0,0,2,0,0
0,0,50,85,27,27,85,27,27,85,27,27,85,78,78,78,2,78,78,2,78,78,2,78,78,2,50,0,0
0,0,0,0,0,0,0,0,0,0,0,0,0,0,0,0,0,0,0,0,0,0,0,0,0,0,0,0,0
0,0,0,0,0,0,0,0,0,0,0,0,0,0,0,0,0,0,0,0,0,0,0,0,0,0,0,0,0
endlayer

layer
0,0,0,0,0,0,0,0,0,0,0,0,0,0,0,0,0,0,0,0,0,0,0,0,0,0,0,0,0
0,0,0,0,0,0,0,0,0,0,0,0,0,0,0,0,0,0,0,0,0,0,0,0,0,0,0,0,0
0,0,2,2,78,78,2,78,78,2,78,78,2,78,78,78,2,78,78,2,27,27,2,27,27,2,2,0,0
0,0,2,0,0,0,0,0,0,0,0,0,65,0,0,0,65,0,0,0,0,0,0,0,0,0,2,0,0
0,0,78,0,0,0,0,0,0,0,0,0,65,0,0,0,0,0,0,0,0,0,0,0,0,0,27,0,0
0,0,78,0,0,0,0,0,0,0,0,0,65,0,0,0,0,0,0,0,0,0,0,0,0,0,27,0,0
0,0,2,0,0,0,0,2,0,0,0,0,65,0,0,0,0,0,0,0,0,0,0,0,0,0,2,0,0
0,0,78,0,0,0,0,0,0,0,0,0,65,0,0,0,0,0,0,0,0,0,0,0,0,0,27,0,0
0,0,78,0,0,0,0,0,0,0,0,0,65,0,0,0,65,0,0,0,0,0,0,0,0,0,27,0,0
0,0,2,0,0,0,0,0,0,0,0,0,65,0,0,0,65,0,0,0,0,0,65,0,0,0,2,0,0
0,0,78,0,0,0,0,0,0,0,0,0,0,2,2,2,2,2,2,2,2,2,0,0,0,0,78,0,0
0,0,78,0,0,0,0,2,0,0,0,0,0,2,0,0,0,2,0,0,0,2,0,0,0,0,78,0,0
0,0,2,0,0,0,0,0,0,0,0,0,0,2,17,0,0,2,0,0,8,2,0,0,0,0,2,0,0
0,0,2,0,0,0,0,0,0,0,0,0,0,2,0,0,0,2,0,0,0,2,65,5,5,65,2,0,0
0,0,78,0,0,0,0,0,65,65,5,5,65,2,52,52,52,2,52,52,52,2,0,0,0,0,78,0,0
0,0,78,0,0,0,0,0,65,0,0,0,0,0,0,0,0,0,0,0,0,0,0,0,0,0,78,0,0
0,0,2,65,65,65,65,65,65,0,0,0,0,0,0,0,0,0,0,0,0,0,0,0,0,0,2,0,0
0,0,78,0,0,0,0,0,65,0,0,0,0,0,0,0,0,0,0,0,0,0,0,0,0,0,78,0,0
0,0,78,0,0,0,0,0,65,65,5,5,65,2,2,2,2,2,2,2,2,2,0,0,0,0,78,0,0
0,0,2,0,0,0,0,0,0,0,0,0,0,2,0,0,2,2,2,2,2,2,65,5,5,65,2,0,0
0,0,2,0,0,0,0,0,0,0,0,0,0,2,0,0,2,32,31,0,0,2,0,0,0,0,2,0,0
0,0,78,0,0,0,0,2,0,0,0,0,0,2,0,0,2,0,0,0,0,2,0,0,0,0,78,0,0
0,0,78,0,0,0,0,0,0,0,0,0,0,2,2,2,2,2,2,2,2,2,0,0,0,0,78,0,0
0,0,2,0,0,0,0,0,0,0,0,0,65,0,0,0,65,0,0,0,0,0,65,0,0,0,2,0,0
0,0,78,0,0,0,0,0,0,0,0,0,65,0,0,0,65,0,0,0,0,0,65,0,0,0,78,0,0
0,0,78,0,0,0,0,0,0,0,0,0,65,0,0,0,65,0,0,0,0,0,65,0,0,0,78,0,0
0,0,2,0,0,0,0,2,0,0,0,0,65,0,0,0,65,65,65,65,65,65,65,0,0,0,2,0,0
0,0,78,0,0,0,0,0,0,0,0,0,65,0,0,0,65,0,0,0,0,0,65,0,0,0,78,0,0
0,0,78,0,0,0,0,0,0,0,0,0,65,0,0,0,65,0,0,0,0,0,65,0,0,0,78,0,0
0,0,2,0,0,0,0,0,0,0,0,0,65,0,0,0,65,0,0,0,0,0,65,0,0,0,2,0,0
0,0,2,85,27,27,85,27,27,85,27,27,85,78,78,78,2,78,78,2,78,78,2,78,78,2,2,0,0
0,0,0,0,0,0,0,0,0,0,0,0,0,0,0,0,0,0,0,0,0,0,0,0,0,0,0,0,0
0,0,0,0,0,0,0,0,0,0,0,0,0,0,0,0,0,0,0,0,0,0,0,0,0,0,0,0,0
endlayer

layer
0,0,0,0,0,0,0,0,0,0,0,0,0,0,0,0,0,0,0,0,0,0,0,0,0,0,0,0,0
0,0,0,0,0,0,0,0,0,0,0,0,0,0,0,0,0,0,0,0,0,0,0,0,0,0,0,0,0
0,0,50,2,36,36,2,36,36,2,36,36,2,36,36,36,2,36,36,2,36,36,2,36,36,2,50,0,0
0,0,2,60,60,60,60,60,60,60,60,60,65,60,60,60,65,60,60,60,60,60,65,60,60,60,2,0,0
0,0,36,60,60,60,60,60,60,60,60,60,65,60,60,60,65,60,60,60,60,60,65,60,60,60,36,0,0
0,0,36,60,60,60,60,60,60,60,60,60,65,60,60,60,65,60,60,60,60,60,65,60,60,60,36,0,0
0,0,2,60,60,60,60,2,60,60,60,60,65,60,60,60,65,65,65,65,65,65,65,60,60,60,2,0,0
0,0,36,60,60,60,60,60,60,60,60,60,65,60,60,60,65,60,60,60,60,60,65,60,60,60,36,0,0
0,0,36,60,60,60,60,60,60,60,60,60,65,60,60,60,65,60,60,60,60,60,65,60,60,60,36,0,0
0,0,2,60,60,60,60,60,60,60,60,60,65,60,60,60,65,60,60,60,60,60,65,60,60,60,2,0,0
0,0,36,60,60,60,60,60,60,60,60,60,60,2,2,2,2,2,2,2,2,2,60,60,60,60,36,0,0
0,0,36,60,60,60,60,2,60,60,60,60,60,2,0,0,0,2,0,0,0,2,60,60,60,60,36,0,0
0,0,2,60,60,60,60,60,60,60,60,60,60,2,17,0,0,2,0,0,8,2,60,60,60,60,2,0,0
0,0,2,60,60,60,60,60,60,60,60,60,60,2,0,0,0,2,0,0,0,2,65,65,65,65,2,0,0
0,0,36,60,60,60,60,60,65,65,65,65,65,2,2,2,2,2,2,2,2,2,60,60,60,60,36,0,0
0,0,36,60,60,60,60,60,65,60,60,60,60,60,60,60,60,60,60,60,60,60,60,60,60,60,36,0,0
0,0,2,65,65,65,65,65,65,60,60,60,60,60,60,60,60,60,60,60,60,60,60,60,60,60,2,0,0
0,0,36,60,60,60,60,60,65,60,60,60,60,60,60,60,60,60,60,60,60,60,60,60,60,60,36,0,0
0,0,36,60,60,60,60,60,65,65,65,65,65,2,2,2,2,2,2,2,2,2,60,60,60,60,36,0,0
0,0,2,60,60,60,60,60,60,60,60,60,60,2,2,2,2,2,2,2,2,2,65,65,65,65,2,0,0
0,0,2,60,60,60,60,60,60,60,60,60,60,2,2,2,2,0,37,31,0,2,60,60,60,60,2,0,0
0,0,36,60,60,60,60,2,60,60,60,60,60,2,2,2,2,0,0,0,0,2,60,60,60,60,36,0,0
0,0,36,60,60,60,60,60,60,60,60,60,60,2,2,2,2,2,2,2,2,2,60,60,60,60,36,0,0
0,0,2,60,60,60,60,60,60,60,60,60,65,60,60,60,65,60,60,60,60,60,65,60,60,60,2,0,0
0,0,36,60,60,60,60,60,60,60,60,60,65,60,60,60,65,60,60,60,60,60,65,60,60,60,36,0,0
0,0,36,60,60,60,60,60,60,60,60,60,65,60,60,60,65,60,60,60,60,60,65,60,60,60,36,0,0
0,0,2,60,60,60,60,2,60,60,60,60,65,60,60,60,65,65,65,65,65,65,65,60,60,60,2,0,0
0,0,36,60,60,60,60,60,60,60,60,60,65,60,60,60,65,60,60,60,60,60,65,60,60,60,36,0,0
0,0,36,0,0,0,0,0,0,0,0,0,65,60,60,60,65,60,60,60,60,60,65,60,60,60,36,0,0
0,0,2,0,0,0,0,0,0,0,0,0,65,60,60,60,65,60,60,60,60,60,65,60,60,60,2,0,0
0,0,50,85,39,39,85,39,39,85,39,39,85,36,36,36,2,36,36,2,36,36,2,36,36,2,50,0,0
0,0,0,0,0,0,0,0,0,0,0,0,0,0,0,0,0,0,0,0,0,0,0,0,0,0,0,0,0
0,0,0,0,0,0,0,0,0,0,0,0,0,0,0,0,0,0,0,0,0,0,0,0,0,0,0,0,0
endlayer

layer
0,0,0,0,0,0,0,0,0,0,0,0,0,0,0,0,0,0,0,0,0,0,0,0,0,0,0,0,0
0,0,0,0,0,0,0,0,0,0,0,0,0,0,0,0,0,0,0,0,0,0,0,0,0,0,0,0,0
0,0,2,2,2,2,2,2,2,2,2,2,2,2,2,2,2,2,2,2,2,2,2,2,2,2,2,0,0
0,0,2,73,73,73,73,73,73,73,73,73,73,73,73,73,73,73,73,73,73,73,73,73,73,73,2,0,0
0,0,2,73,73,73,73,73,73,73,73,73,73,73,73,73,73,73,73,73,73,73,73,73,73,73,2,0,0
0,0,2,73,73,73,73,73,73,73,73,73,73,73,73,73,73,73,73,73,73,73,73,73,73,73,2,0,0
0,0,2,73,73,73,73,73,73,73,73,73,73,73,73,73,73,73,73,73,73,73,73,73,73,73,2,0,0
0,0,2,73,73,73,73,73,73,73,73,73,73,73,73,74,74,74,74,73,73,73,73,73,73,73,2,0,0
0,0,2,73,73,73,73,73,73,73,73,73,73,73,73,73,74,74,74,73,73,73,73,73,73,73,2,0,0
0,0,2,73,73,73,73,73,73,73,73,73,73,73,73,73,73,73,73,73,73,73,73,73,73,73,2,0,0
0,0,2,73,73,73,73,73,73,73,73,73,73,2,2,2,2,2,2,2,2,2,73,74,73,73,2,0,0
0,0,2,73,73,73,73,73,73,73,73,73,73,2,2,2,2,2,2,2,2,2,73,74,73,73,2,0,0
0,0,2,73,73,73,73,73,73,73,73,73,73,2,17,0,0,2,0,0,8,2,73,74,73,73,2,0,0
0,0,2,73,73,73,73,73,73,73,73,73,73,2,0,0,0,2,0,0,0,2,73,74,73,73,2,0,0
0,0,2,74,74,73,73,73,73,73,73,73,73,2,2,2,2,2,2,2,2,2,73,73,73,73,2,0,0
0,0,2,73,73,73,73,73,73,73,73,73,73,73,73,73,73,73,73,73,73,73,73,73,73,73,2,0,0
0,0,2,73,73,73,73,73,73,73,73,73,73,73,73,73,73,73,73,73,73,73,73,73,73,73,2,0,0
0,0,2,73,73,73,73,73,73,73,73,73,73,73,73,73,73,73,73,73,73,73,73,73,73,73,2,0,0
0,0,2,74,74,73,73,73,73,73,73,73,73,73,73,73,2,2,2,2,2,2,73,73,73,73,2,0,0
0,0,2,73,73,73,73,73,73,73,73,73,73,74,74,73,2,2,2,2,2,2,73,74,73,73,2,0,0
0,0,2,73,73,73,73,73,73,73,73,73,73,74,74,73,2,0,0,0,37,2,73,74,73,73,2,0,0
0,0,2,73,73,73,73,73,73,73,73,73,73,74,74,73,2,0,0,25,2,2,73,74,73,73,2,0,0
0,0,2,73,73,73,73,73,73,73,73,73,73,74,73,73,2,2,2,2,2,2,73,74,73,73,2,0,0
0,0,2,73,73,73,73,73,73,73,73,73,73,73,73,73,73,73,73,73,73,73,73,73,73,73,2,0,0
0,0,2,73,73,73,73,73,73,73,73,73,73,73,73,73,73,73,73,73,73,73,73,73,73,73,2,0,0
0,0,2,73,73,73,73,73,73,73,73,73,73,73,73,73,73,73,73,73,73,73,73,73,73,73,2,0,0
0,0,2,73,73,73,73,73,73,73,73,73,73,73,73,73,73,73,73,73,73,73,73,73,73,73,2,0,0
0,0,2,73,73,73,73,73,73,73,73,73,73,73,73,73,73,73,73,73,73,73,73,73,73,73,2,0,0
0,0,2,83,83,83,83,83,83,83,83,83,73,73,73,73,73,73,73,73,73,73,73,73,73,73,2,0,0
0,0,2,83,83,83,83,83,83,83,83,83,73,73,73,73,73,73,73,73,73,73,73,73,73,73,2,0,0
0,0,2,85,85,85,85,85,85,85,85,85,85,2,2,2,2,2,2,2,2,2,2,2,2,2,2,0,0
0,0,0,0,0,0,0,0,0,0,0,0,0,0,0,0,0,0,0,0,0,0,0,0,0,0,0,0,0
0,0,0,0,0,0,0,0,0,0,0,0,0,0,0,0,0,0,0,0,0,0,0,0,0,0,0,0,0
endlayer

layer
0,0,0,0,0,0,0,0,0,0,0,0,0,0,0,0,0,0,0,0,0,0,0,0,0,0,0,0,0
0,0,0,0,0,0,0,0,0,0,0,0,0,0,0,0,0,0,0,0,0,0,0,0,0,0,0,0,0
0,0,50,2,36,36,2,36,36,2,36,36,2,36,36,36,2,36,36,2,36,36,2,36,36,2,50,0,0
0,0,2,15,15,15,15,15,15,86,15,15,15,15,15,15,15,15,15,86,15,15,15,15,15,15,2,0,0
0,0,36,15,15,15,15,15,15,86,15,15,15,15,15,15,15,15,15,86,15,15,15,15,15,15,36,0,0
0,0,36,15,15,15,15,15,15,86,15,15,15,15,15,15,15,15,15,86,15,15,15,15,15,15,36,0,0
0,0,2,15,15,15,15,15,15,86,15,15,15,15,15,15,15,15,15,86,15,15,15,15,15,15,2,0,0
0,0,36,0,0,0,0,0,0,86,15,15,15,15,0,0,0,0,0,86,58,0,15,15,15,15,36,0,0
0,0,36,0,0,62,62,0,0,86,15,15,0,0,0,86,0,0,0,86,58,0,15,15,15,15,36,0,0
0,0,2,86,0,86,86,0,0,86,15,15,0,62,62,86,60,88,60,86,15,15,15,15,15,15,2,0,0
0,0,36,0,0,15,86,0,0,86,0,0,0,2,2,2,2,2,2,2,2,2,60,0,0,0,36,0,0
0,0,36,0,0,15,86,0,0,86,0,0,0,2,0,0,0,2,0,0,0,2,87,0,0,0,36,0,0
0,0,2,0,0,15,86,0,0,86,0,0,0,2,17,0,0,2,0,0,8,2,60,0,0,0,2,0,0
0,0,2,0,0,15,86,0,0,86,0,0,0,2,0,0,0,2,0,0,0,2,60,0,0,0,2,0,0
0,0,36,0,0,86,86,55,86,86,86,55,86,2,0,0,0,2,0,0,0,2,86,86,0,0,36,0,0
0,0,36,60,88,86,0,0,0,0,0,0,0,0,0,0,0,0,0,0,0,0,0,63,0,0,36,0,0
0,0,2,86,86,86,0,0,0,0,0,0,0,0,0,0,0,0,0,0,0,0,0,86,86,86,2,0,0
0,0,36,60,16,86,0,0,0,0,0,0,0,0,0,0,0,0,0,0,0,0,0,63,0,0,36,0,0
0,0,36,0,0,86,86,56,86,86,86,56,86,86,86,86,86,86,86,2,9,2,86,86,0,0,36,0,0
0,0,2,0,0,15,86,0,0,86,0,0,0,0,0,60,2,2,2,0,10,2,60,0,0,0,2,0,0
0,0,2,0,0,15,86,0,0,86,0,0,0,0,0,60,2,42,0,0,0,2,60,0,0,0,2,0,0
0,0,36,0,0,15,86,0,0,86,0,0,0,0,0,89,2,0,25,11,0,2,87,0,0,0,36,0,0
0,0,36,0,0,15,86,0,0,86,0,0,0,0,86,86,2,2,2,2,2,2,60,0,0,0,36,0,0
0,0,2,86,0,86,86,0,0,86,15,15,15,15,15,15,86,15,15,15,15,86,15,15,15,15,2,0,0
0,0,36,15,0,15,15,15,15,86,15,15,15,15,15,15,86,15,15,15,15,86,15,15,15,15,36,0,0
0,0,36,15,15,15,15,15,15,86,15,15,15,15,15,15,86,15,15,15,15,86,15,15,15,15,36,0,0
0,0,2,15,15,15,15,15,15,86,15,15,15,15,15,15,86,15,15,15,15,15,15,15,15,15,2,0,0
0,0,36,15,15,15,15,0,51,86,15,15,15,15,0,51,86,58,0,15,15,15,15,15,15,15,36,0,0
0,0,36,0,0,0,0,0,0,0,0,0,15,15,0,51,86,58,0,15,15,15,15,15,15,15,36,0,0
0,0,2,0,0,0,0,0,0,0,0,0,15,15,15,15,86,15,15,15,15,15,15,15,15,15,2,0,0
0,0,50,85,39,39,85,39,39,2,39,39,85,36,36,36,2,36,36,2,36,36,2,36,36,2,50,0,0
0,0,0,0,0,0,0,0,0,0,0,0,0,0,0,0,0,0,0,0,0,0,0,0,0,0,0,0,0
0,0,0,0,0,0,0,0,0,0,0,0,0,0,0,0,0,0,0,0,0,0,0,0,0,0,0,0,0
endlayer

layer
0,0,0,0,0,0,0,0,0,0,0,0,0,0,0,0,0,0,0,0,0,0,0,0,0,0,0,0,0
0,0,0,0,0,0,0,0,0,0,0,0,0,0,0,0,0,0,0,0,0,0,0,0,0,0,0,0,0
0,0,2,2,78,78,2,78,78,2,78,78,2,78,78,78,2,78,78,2,78,78,2,78,78,2,2,0,0
0,0,2,0,0,0,0,0,0,90,0,0,0,0,0,0,0,0,0,90,0,0,0,0,0,0,2,0,0
0,0,78,0,0,0,0,0,0,14,0,0,0,0,0,0,0,0,0,14,0,0,0,0,0,0,78,0,0
0,0,78,0,0,0,0,0,0,14,0,0,0,0,0,0,0,0,0,14,0,0,0,0,0,0,78,0,0
0,0,2,0,0,0,0,0,0,90,0,0,0,0,0,0,0,0,0,14,0,0,0,0,0,0,2,0,0
0,0,78,0,0,0,0,0,0,90,0,0,0,0,0,0,0,0,0,90,0,0,0,0,0,0,78,0,0
0,0,78,0,0,0,0,0,0,90,0,0,0,0,0,90,0,0,0,90,0,0,0,0,0,0,78,0,0
0,0,2,90,0,90,90,0,0,90,0,0,0,0,0,90,0,0,0,90,0,0,0,0,0,0,2,0,0
0,0,78,0,0,0,90,0,0,90,0,0,0,2,2,2,2,2,2,2,2,2,0,0,0,0,78,0,0
0,0,78,0,0,0,90,0,0,90,0,0,0,2,0,0,0,2,0,0,0,2,0,0,0,0,78,0,0
0,0,2,0,0,0,90,0,0,90,0,0,0,2,17,0,0,2,0,0,8,2,0,0,0,0,2,0,0
0,0,2,0,0,0,90,0,0,90,0,0,0,2,0,0,0,2,0,0,0,2,0,0,0,0,2,0,0
0,0,78,0,0,90,90,69,90,90,90,69,90,2,0,0,0,2,0,0,0,2,90,90,0,0,78,0,0
0,0,78,0,0,90,0,0,0,0,0,0,0,0,0,0,0,0,0,0,0,0,0,69,0,0,78,0,0
0,0,2,90,90,90,0,0,0,0,0,0,0,0,0,0,0,0,0,0,0,0,0,90,90,90,2,0,0
0,0,78,0,0,90,0,0,0,0,0,0,0,0,0,0,0,0,0,22,0,0,0,69,0,0,78,0,0
0,0,78,0,0,90,90,69,90,90,90,69,90,90,90,90,90,90,90,2,21,2,90,90,0,0,78,0,0
0,0,2,0,0,0,90,0,0,90,0,0,0,0,0,0,2,2,2,0,0,2,0,0,0,0,2,0,0
0,0,2,0,0,0,90,0,0,90,0,0,0,0,0,0,2,0,0,0,0,2,0,0,0,0,2,0,0
0,0,78,0,0,0,90,0,0,90,0,0,0,0,0,0,2,25,11,0,0,2,0,0,0,0,78,0,0
0,0,78,0,0,0,90,0,0,90,0,0,0,0,90,90,2,2,2,2,2,2,0,0,0,0,78,0,0
0,0,2,90,0,90,90,0,0,90,0,0,0,0,0,0,90,0,0,0,0,90,0,0,0,0,2,0,0
0,0,78,0,0,0,0,0,0,90,0,0,0,0,0,0,90,0,0,0,0,14,0,0,0,0,78,0,0
0,0,78,0,0,0,0,0,0,14,0,0,0,0,0,0,90,0,0,0,0,14,0,0,0,0,78,0,0
0,0,2,0,0,0,0,0,0,14,0,0,0,0,0,0,90,0,0,0,0,0,0,0,0,0,2,0,0
0,0,78,0,0,0,0,0,0,14,0,0,0,0,0,0,90,0,0,0,0,0,0,0,0,0,78,0,0
0,0,78,0,0,0,0,0,0,0,0,0,0,0,0,0,90,0,0,0,0,0,0,0,0,0,78,0,0
0,0,2,0,0,0,0,0,0,0,0,0,0,0,0,0,90,0,0,0,0,0,0,0,0,0,2,0,0
0,0,2,2,78,78,2,78,78,2,78,78,2,78,78,78,2,78,78,2,78,78,2,78,78,2,2,0,0
0,0,0,0,0,0,0,0,0,0,0,0,0,0,0,0,0,0,0,0,0,0,0,0,0,0,0,0,0
0,0,0,0,0,0,0,0,0,0,0,0,0,0,0,0,0,0,0,0,0,0,0,0,0,0,0,0,0
endlayer

layer
0,0,0,0,0,0,0,0,0,0,0,0,0,0,0,0,0,0,0,0,0,0,0,0,0,0,0,0,0
0,0,0,0,0,0,0,0,0,0,0,0,0,0,0,0,0,0,0,0,0,0,0,0,0,0,0,0,0
0,0,50,2,78,78,2,78,78,2,78,78,2,78,78,78,2,78,78,2,78,78,2,78,78,2,50,0,0
0,0,2,0,0,0,0,0,0,90,0,0,0,0,0,0,0,0,0,90,0,0,0,0,0,0,2,0,0
0,0,78,0,0,0,0,0,0,90,0,0,0,0,0,0,0,0,0,14,0,0,0,0,0,0,78,0,0
0,0,78,0,0,0,0,0,0,90,0,0,0,0,0,0,0,0,0,14,0,0,0,0,0,0,78,0,0
0,0,2,0,0,0,0,0,0,90,0,0,0,0,0,0,0,0,0,14,0,0,0,0,0,0,2,0,0
0,0,78,0,0,0,0,0,0,90,0,0,0,0,0,0,0,0,0,90,0,0,0,0,0,0,78,0,0
0,0,78,0,0,0,0,0,0,90,0,0,0,0,0,90,0,0,0,90,0,0,0,0,0,0,78,0,0
0,0,2,90,90,90,90,0,0,90,0,0,0,0,0,90,0,7,0,90,0,0,0,0,0,0,2,0,0
0,0,78,0,0,0,90,0,0,90,0,0,0,2,2,2,2,2,2,2,2,2,0,0,0,0,78,0,0
0,0,78,0,0,0,90,0,0,90,0,0,0,2,0,0,0,2,0,0,0,2,64,0,0,0,78,0,0
0,0,2,0,0,0,90,0,0,90,0,0,0,2,17,0,0,2,0,0,8,2,0,0,0,0,2,0,0
0,0,2,0,0,0,90,0,0,90,0,0,0,2,0,0,0,2,0,0,0,2,0,0,0,0,2,0,0
0,0,78,0,0,90,90,5,90,90,90,5,90,2,0,0,0,2,0,0,0,2,90,90,0,0,78,0,0
0,0,78,0,7,90,0,0,0,0,0,0,0,0,0,0,0,0,0,0,0,0,0,5,0,0,78,0,0
0,0,2,90,90,90,0,0,0,0,0,0,0,0,0,0,0,0,0,0,0,0,0,90,90,90,2,0,0
0,0,78,0,41,90,0,0,0,0,0,0,0,0,0,0,0,0,0,0,0,0,0,5,0,0,78,0,0
0,0,78,0,0,90,90,5,90,90,90,5,90,90,90,90,90,90,90,2,2,2,90,90,0,0,78,0,0
0,0,2,0,0,0,90,0,0,90,0,0,0,0,0,0,2,2,2,2,2,2,0,0,0,0,2,0,0
0,0,2,0,0,0,90,0,0,90,0,0,0,0,0,0,2,2,0,0,0,2,0,0,0,0,2,0,0
0,0,78,0,0,0,90,0,0,90,0,0,0,0,0,91,2,11,0,0,0,2,64,0,0,0,78,0,0
0,0,78,0,0,0,90,0,0,90,0,0,0,0,90,90,2,2,2,2,2,2,0,0,0,0,78,0,0
0,0,2,90,90,90,90,0,0,90,0,0,0,0,0,0,90,0,0,0,0,90,0,0,0,0,2,0,0
0,0,78,0,0,0,0,0,0,90,0,0,0,0,0,0,90,0,0,0,0,14,0,0,0,0,78,0,0
0,0,78,0,0,0,0,0,0,90,0,0,0,0,0,0,90,0,0,0,0,14,0,0,0,0,78,0,0
0,0,2,0,0,0,0,0,0,90,0,0,0,0,0,0,90,0,0,0,0,0,0,0,0,0,2,0,0
0,0,78,0,0,0,0,0,0,90,0,0,0,0,0,0,90,0,0,0,0,0,0,0,0,0,78,0,0
0,0,78,0,0,0,0,0,0,90,0,0,0,0,0,0,90,0,0,0,0,0,0,0,0,0,78,0,0
0,0,2,0,0,0,0,0,0,0,0,0,0,0,0,0,90,0,0,0,0,0,0,0,0,0,2,0,0
0,0,50,2,78,78,2,78,78,2,78,78,2,78,78,78,2,78,78,2,78,78,2,78,78,2,50,0,0
0,0,0,0,0,0,0,0,0,0,0,0,0,0,0,0,0,0,0,0,0,0,0,0,0,0,0,0,0
0,0,0,0,0,0,0,0,0,0,0,0,0,0,0,0,0,0,0,0,0,0,0,0,0,0,0,0,0
endlayer

layer
0,0,0,0,0,0,0,0,0,0,0,0,0,0,0,0,0,0,0,0,0,0,0,0,0,0,0,0,0
0,0,0,0,0,0,0,0,0,0,0,0,0,0,0,0,0,0,0,0,0,0,0,0,0,0,0,0,0
0,0,2,2,78,78,2,78,78,2,78,78,2,78,78,78,2,78,78,2,78,78,2,78,78,2,2,0,0
0,0,2,0,0,0,0,0,0,90,0,0,0,0,0,0,0,0,0,90,0,0,0,0,0,0,2,0,0
0,0,78,0,0,0,0,0,0,90,0,0,0,0,0,0,0,0,0,90,0,0,0,0,0,0,78,0,0
0,0,78,0,0,0,0,0,0,90,0,0,0,0,0,0,0,0,0,90,0,0,0,0,0,0,78,0,0
0,0,2,0,0,0,0,0,0,90,0,0,0,0,0,0,0,0,0,90,0,0,0,0,0,0,2,0,0
0,0,78,0,0,0,0,0,0,90,0,0,0,0,0,0,0,0,0,90,0,0,0,0,0,0,78,0,0
0,0,78,0,0,0,0,0,0,90,0,0,0,0,0,90,0,0,0,90,0,0,0,0,0,0,78,0,0
0,0,2,90,90,90,90,0,0,90,0,0,0,0,0,90,0,0,0,90,0,0,0,0,0,0,2,0,0
0,0,78,0,0,0,90,0,0,90,0,0,0,2,2,2,2,2,2,2,2,2,0,0,0,0,78,0,0
0,0,78,0,0,0,90,0,0,90,0,0,0,2,0,0,0,2,0,0,0,2,0,0,0,0,78,0,0
0,0,2,0,0,0,90,0,0,90,0,0,0,2,17,0,0,2,0,0,8,2,0,0,0,0,2,0,0
0,0,2,0,0,0,90,0,0,90,0,0,0,2,0,0,0,2,0,0,0,2,0,0,0,0,2,0,0
0,0,78,0,0,90,90,90,90,90,90,90,90,2,86,86,86,2,86,86,86,2,90,90,0,0,78,0,0
0,0,78,0,0,90,0,0,0,0,0,0,0,0,0,0,0,0,0,0,0,0,0,90,0,0,78,0,0
0,0,2,90,90,90,0,0,0,0,0,0,0,0,0,0,0,0,0,0,0,0,0,90,90,90,2,0,0
0,0,78,0,0,90,0,0,0,0,0,0,0,0,0,0,0,0,0,0,0,0,0,90,0,0,78,0,0
0,0,78,0,0,90,90,90,90,90,90,90,90,90,90,90,90,90,90,2,2,2,90,90,0,0,78,0,0
0,0,2,0,0,0,90,0,0,90,0,0,0,0,0,0,2,2,2,2,2,2,0,0,0,0,2,0,0
0,0,2,0,0,0,90,0,0,90,0,0,0,0,0,0,2,32,31,0,0,2,0,0,0,0,2,0,0
0,0,78,0,0,0,90,0,0,90,0,0,0,0,0,0,2,0,0,0,0,2,0,0,0,0,78,0,0
0,0,78,0,0,0,90,0,0,90,0,0,0,0,90,90,2,2,2,2,2,2,0,0,0,0,78,0,0
0,0,2,90,90,90,90,0,0,90,0,0,0,0,0,0,90,0,0,0,0,90,0,0,0,0,2,0,0
0,0,78,0,0,0,0,0,0,90,0,0,0,0,0,0,90,0,0,0,0,90,0,0,0,0,78,0,0
0,0,78,0,0,0,0,0,0,90,0,0,0,0,0,0,90,0,0,0,0,90,0,0,0,0,78,0,0
0,0,2,0,0,0,0,0,0,90,0,0,0,0,0,0,90,0,0,0,0,0,0,0,0,0,2,0,0
0,0,78,0,0,0,0,0,0,90,0,0,0,0,0,0,90,0,0,0,0,0,0,0,0,0,78,0,0
0,0,78,0,0,0,0,0,0,90,0,0,0,0,0,0,90,0,0,0,0,0,0,0,0,0,78,0,0
0,0,2,0,0,0,0,0,0,90,0,0,0,0,0,0,90,0,0,0,0,0,0,0,0,0,2,0,0
0,0,2,2,78,78,2,78,78,2,78,78,2,78,78,78,2,78,78,2,78,78,2,78,78,2,2,0,0
0,0,0,0,0,0,0,0,0,0,0,0,0,0,0,0,0,0,0,0,0,0,0,0,0,0,0,0,0
0,0,0,0,0,0,0,0,0,0,0,0,0,0,0,0,0,0,0,0,0,0,0,0,0,0,0,0,0
endlayer

layer
0,0,0,0,0,0,0,0,0,0,0,0,0,0,0,0,0,0,0,0,0,0,0,0,0,0,0,0,0
0,0,0,0,0,0,0,0,0,0,0,0,0,0,0,0,0,0,0,0,0,0,0,0,0,0,0,0,0
0,0,50,2,36,36,2,36,36,2,36,36,2,36,36,36,2,36,36,2,36,36,2,36,36,2,50,0,0
0,0,2,60,60,60,60,60,60,90,60,60,60,60,60,60,60,60,60,90,60,60,60,60,60,60,2,0,0
0,0,36,60,60,60,60,60,60,90,60,60,60,60,60,60,60,60,60,90,60,60,60,60,60,60,36,0,0
0,0,36,60,60,60,60,60,60,90,60,60,60,60,60,60,60,60,60,90,60,60,60,60,60,60,36,0,0
0,0,2,60,60,60,60,60,60,90,60,60,60,60,60,60,60,60,60,90,60,60,60,60,60,60,2,0,0
0,0,36,60,60,60,60,60,60,90,60,60,60,60,60,60,60,60,60,90,60,60,60,60,60,60,36,0,0
0,0,36,60,60,60,60,60,60,90,60,60,60,60,60,90,60,60,60,90,60,60,60,60,60,60,36,0,0
0,0,2,90,90,90,90,60,60,90,60,60,60,60,60,90,60,60,60,90,60,60,60,60,60,60,2,0,0
0,0,36,60,60,60,90,60,60,90,60,60,60,2,2,2,2,2,2,2,2,2,60,60,60,60,36,0,0
0,0,36,60,60,60,90,60,60,90,60,60,60,2,0,0,0,2,0,0,0,2,60,60,60,60,36,0,0
0,0,2,60,60,60,90,60,60,90,60,60,60,2,17,0,0,2,0,0,8,2,60,60,60,60,2,0,0
0,0,2,60,60,60,90,60,60,90,60,60,60,2,0,0,0,2,0,0,0,2,60,60,60,60,2,0,0
0,0,36,60,60,90,90,90,90,90,90,90,90,2,2,2,2,2,2,2,2,2,90,90,60,60,36,0,0
0,0,36,60,60,90,60,60,60,60,60,60,60,60,60,60,60,60,60,60,60,60,60,90,60,60,36,0,0
0,0,85,90,90,90,0,60,60,60,60,60,60,60,60,60,60,60,60,60,60,60,60,90,90,90,2,0,0
0,0,39,0,0,90,0,60,60,60,60,60,60,60,60,60,60,60,60,60,60,60,60,90,60,60,36,0,0
0,0,39,0,0,90,90,90,90,90,90,90,90,90,90,90,90,90,90,2,2,2,90,90,60,60,36,0,0
0,0,85,0,0,0,90,60,60,90,60,60,60,60,60,60,2,2,2,2,2,2,60,60,60,60,2,0,0
0,0,85,0,0,0,90,60,60,90,60,60,60,60,60,60,2,0,37,31,0,2,60,60,60,60,2,0,0
0,0,39,0,0,0,90,60,60,90,60,60,60,60,60,60,2,0,0,0,0,2,60,60,60,60,36,0,0
0,0,39,0,0,0,90,60,60,90,60,60,60,60,90,90,2,2,2,2,2,2,60,60,60,60,36,0,0
0,0,85,90,90,90,90,60,60,90,60,60,60,60,60,60,90,60,60,60,60,90,60,60,60,60,2,0,0
0,0,36,0,0,0,0,60,60,90,60,60,60,60,60,60,90,60,60,60,60,90,60,60,60,60,36,0,0
0,0,36,60,60,60,60,60,60,90,60,60,60,60,60,60,90,60,60,60,60,90,60,60,60,60,36,0,0
0,0,2,60,60,60,60,60,60,90,60,60,60,60,60,60,90,60,60,60,60,60,60,60,60,60,2,0,0
0,0,36,60,60,60,60,60,60,90,60,60,60,60,60,60,90,60,60,60,60,60,60,60,60,60,36,0,0
0,0,36,60,60,60,60,60,60,90,60,60,60,60,60,60,90,60,60,0,0,0,0,0,0,60,36,0,0
0,0,2,60,60,60,60,60,60,90,60,60,60,60,60,60,90,60,60,0,0,0,0,0,0,60,2,0,0
0,0,50,2,36,36,2,36,36,2,36,36,2,36,36,36,2,36,36,2,36,36,2,36,36,2,50,0,0
0,0,0,0,0,0,0,0,0,0,0,0,0,0,0,0,0,0,0,0,0,0,0,0,0,0,0,0,0
0,0,0,0,0,0,0,0,0,0,0,0,0,0,0,0,0,0,0,0,0,0,0,0,0,0,0,0,0
endlayer

layer
0,0,0,0,0,0,0,0,0,0,0,0,0,0,0,0,0,0,0,0,0,0,0,0,0,0,0,0,0
0,0,0,0,0,0,0,0,0,0,0,0,0,0,0,0,0,0,0,0,0,0,0,0,0,0,0,0,0
0,0,2,2,2,2,2,2,2,2,2,2,2,2,2,2,2,2,2,2,2,2,2,2,2,2,2,0,0
0,0,2,73,73,73,73,73,73,73,73,73,73,73,73,73,73,73,73,73,73,73,73,73,73,73,2,0,0
0,0,2,73,73,73,73,73,73,73,73,73,73,73,73,73,73,73,73,73,73,73,73,73,73,73,2,0,0
0,0,2,73,73,73,73,73,73,73,73,73,73,73,73,73,73,73,73,73,73,73,73,73,73,73,2,0,0
0,0,2,73,73,73,73,73,73,73,73,73,73,73,73,73,73,73,73,73,73,73,73,73,73,73,2,0,0
0,0,2,73,73,73,73,73,73,73,73,73,73,73,73,74,74,74,74,73,73,73,73,73,73,73,2,0,0
0,0,2,73,73,73,73,73,73,73,73,73,73,73,73,73,74,74,74,73,73,73,73,73,73,73,2,0,0
0,0,2,73,73,73,73,73,73,73,73,73,73,73,73,73,73,73,73,73,73,73,73,73,73,73,2,0,0
0,0,2,73,73,73,73,73,73,73,73,73,73,2,2,2,2,2,2,2,2,2,73,74,73,73,2,0,0
0,0,2,73,73,73,73,73,73,73,73,73,73,2,2,2,2,2,2,2,2,2,73,74,73,73,2,0,0
0,0,2,73,73,73,73,73,73,73,73,73,73,2,17,0,0,2,0,0,8,2,73,74,73,73,2,0,0
0,0,2,73,73,73,73,73,73,73,73,73,73,2,0,0,0,2,0,0,0,2,73,74,73,73,2,0,0
0,0,2,74,74,73,73,73,73,73,73,73,73,2,2,2,2,2,2,2,2,2,73,73,73,73,2,0,0
0,0,2,73,73,73,73,73,73,73,73,73,73,73,73,73,73,73,73,73,73,73,73,73,73,73,2,0,0
0,0,85,83,83,83,83,73,73,73,73,73,73,73,73,73,73,73,73,73,73,73,73,73,73,73,2,0,0
0,0,85,83,83,83,83,73,73,73,73,73,73,73,73,73,73,73,73,73,73,73,73,73,73,73,2,0,0
0,0,85,83,83,83,83,73,73,73,73,73,73,73,73,73,2,2,2,2,2,2,73,73,73,73,2,0,0
0,0,85,83,83,83,83,73,73,73,73,73,73,74,74,73,2,2,2,2,2,2,73,74,73,73,2,0,0
0,0,85,83,83,83,83,73,73,73,73,73,73,74,74,73,2,0,0,0,37,2,73,74,73,73,2,0,0
0,0,85,83,83,83,83,73,73,73,73,73,73,74,74,73,2,0,0,25,2,2,73,74,73,73,2,0,0
0,0,85,83,83,83,83,73,73,73,73,73,73,74,73,73,2,2,2,2,2,2,73,74,73,73,2,0,0
0,0,85,83,83,83,83,73,73,73,73,73,73,73,73,73,73,73,73,73,73,73,73,73,73,73,2,0,0
0,0,2,83,83,83,83,73,73,73,73,73,73,73,73,73,73,73,73,73,73,73,73,73,73,73,2,0,0
0,0,2,73,73,73,73,73,73,73,73,73,73,73,73,73,73,73,73,73,73,73,73,73,73,73,2,0,0
0,0,2,73,73,73,73,73,73,73,73,73,73,73,73,73,73,73,73,73,73,73,73,73,73,73,2,0,0
0,0,2,73,73,73,73,73,73,73,73,73,73,73,73,73,73,73,73,73,73,73,73,73,73,73,2,0,0
0,0,2,73,73,73,73,73,73,73,73,73,73,73,73,73,73,73,73,83,83,83,83,83,83,73,2,0,0
0,0,2,73,73,73,73,73,73,73,73,73,73,73,73,73,73,73,73,83,83,83,83,83,83,73,2,0,0
0,0,2,2,2,2,2,2,2,2,2,2,2,2,2,2,2,2,2,2,2,2,2,2,2,2,2,0,0
0,0,0,0,0,0,0,0,0,0,0,0,0,0,0,0,0,0,0,0,0,0,0,0,0,0,0,0,0
0,0,0,0,0,0,0,0,0,0,0,0,0,0,0,0,0,0,0,0,0,0,0,0,0,0,0,0,0
endlayer

layer
0,0,0,0,0,0,0,0,0,0,0,0,0,0,0,0,0,0,0,0,0,0,0,0,0,0,0,0,0
0,0,0,0,0,0,0,0,0,0,0,0,0,0,0,0,0,0,0,0,0,0,0,0,0,0,0,0,0
0,0,50,2,36,36,2,36,36,2,36,36,2,36,36,36,2,36,36,2,36,36,2,36,36,2,50,0,0
0,0,2,15,15,15,15,15,15,86,15,15,15,15,15,15,15,15,15,86,15,15,15,15,15,15,2,0,0
0,0,36,15,15,15,15,15,15,86,15,15,15,15,15,15,15,15,15,86,15,15,15,15,15,15,36,0,0
0,0,36,15,15,15,15,15,15,86,15,15,15,15,15,15,15,15,15,86,15,15,15,15,15,15,36,0,0
0,0,2,15,15,15,15,15,15,86,15,15,15,15,15,15,15,15,15,86,15,15,15,15,15,15,2,0,0
0,0,36,0,0,0,0,0,0,86,15,15,15,15,0,0,0,0,0,86,58,0,15,15,15,15,36,0,0
0,0,36,0,0,62,62,0,0,86,15,15,0,0,0,86,0,0,0,86,58,0,15,15,15,15,36,0,0
0,0,2,86,0,86,86,0,0,86,15,15,0,62,62,86,60,88,60,86,15,15,15,15,15,15,2,0,0
0,0,36,0,0,15,86,0,0,86,0,0,0,2,2,2,2,2,2,2,2,2,60,0,0,0,36,0,0
0,0,36,0,0,15,86,0,0,86,0,0,0,2,0,0,0,2,0,0,0,2,87,0,0,0,36,0,0
0,0,2,0,0,15,86,0,0,86,0,0,0,2,17,0,0,2,0,0,8,2,60,0,0,0,2,0,0
0,0,2,0,0,15,86,0,0,86,0,0,0,2,0,0,0,2,0,0,0,2,60,0,0,0,2,0,0
0,0,36,0,0,86,86,55,86,86,86,55,86,2,0,0,0,2,0,0,0,2,86,86,0,0,36,0,0
0,0,36,60,88,86,0,0,0,0,0,0,0,0,0,0,0,0,0,0,0,0,0,63,0,0,36,0,0
0,0,85,0,0,0,0,0,0,0,0,0,0,0,0,0,0,0,0,0,0,0,0,86,86,86,2,0,0
0,0,39,0,0,0,0,0,0,0,0,0,0,0,0,0,0,0,0,0,0,0,0,63,0,0,36,0,0
0,0,39,0,0,0,0,0,86,86,86,56,86,86,86,86,86,86,86,2,9,2,86,86,0,0,36,0,0
0,0,85,0,0,0,0,0,0,86,0,0,0,0,0,60,2,2,2,0,10,2,60,0,0,0,2,0,0
0,0,85,0,0,0,0,0,0,86,0,0,0,0,0,60,2,42,0,0,0,2,60,0,0,0,2,0,0
0,0,39,0,0,0,0,0,0,86,0,0,0,0,0,89,2,0,25,11,0,2,87,0,0,0,36,0,0
0,0,39,0,0,0,0,0,0,86,0,0,0,0,86,86,2,2,2,2,2,2,60,0,0,0,36,0,0
0,0,85,0,0,0,0,0,0,86,15,15,15,15,15,15,86,15,15,15,15,86,15,15,15,15,2,0,0
0,0,36,0,0,0,0,15,15,86,15,15,15,15,15,15,86,15,15,15,15,86,15,15,15,15,36,0,0
0,0,36,15,15,15,15,15,15,86,15,15,15,15,15,15,86,15,15,15,15,86,15,15,15,15,36,0,0
0,0,2,15,15,15,15,15,15,86,15,15,15,15,15,15,86,15,15,15,15,15,15,15,15,15,2,0,0
0,0,36,15,15,15,15,0,51,86,15,15,15,15,0,51,86,58,0,15,15,15,15,15,15,15,36,0,0
0,0,36,15,15,15,15,0,51,86,15,15,15,15,0,51,86,58,0,0,0,0,0,0,0,15,36,0,0
0,0,2,15,15,15,15,15,15,86,15,15,15,15,15,15,86,15,15,0,0,0,0,0,0,15,2,0,0
0,0,50,2,36,36,2,36,36,2,36,36,2,36,36,36,2,36,36,85,39,39,85,39,39,2,50,0,0
0,0,0,0,0,0,0,0,0,0,0,0,0,0,0,0,0,0,0,0,0,0,0,0,0,0,0,0,0
0,0,0,0,0,0,0,0,0,0,0,0,0,0,0,0,0,0,0,0,0,0,0,0,0,0,0,0,0
endlayer

layer
0,0,0,0,0,0,0,0,0,0,0,0,0,0,0,0,0,0,0,0,0,0,0,0,0,0,0,0,0
0,0,0,0,0,0,0,0,0,0,0,0,0,0,0,0,0,0,0,0,0,0,0,0,0,0,0,0,0
0,0,2,2,78,78,2,78,78,2,78,78,2,78,78,78,2,78,78,2,78,78,2,78,78,2,2,0,0
0,0,2,0,0,0,0,0,0,90,0,0,0,0,0,0,0,0,0,90,0,0,0,0,0,0,2,0,0
0,0,78,0,0,0,0,0,0,14,0,0,0,0,0,0,0,0,0,14,0,0,0,0,0,0,78,0,0
0,0,78,0,0,0,0,0,0,14,0,0,0,0,0,0,0,0,0,14,0,0,0,0,0,0,78,0,0
0,0,2,0,0,0,0,0,0,90,0,0,0,0,0,0,0,0,0,14,0,0,0,0,0,0,2,0,0
0,0,78,0,0,0,0,0,0,90,0,0,0,0,0,0,0,0,0,90,0,0,0,0,0,0,78,0,0
0,0,78,0,0,0,0,0,0,90,0,0,0,0,0,90,0,0,0,90,0,0,0,0,0,0,78,0,0
0,0,2,90,0,90,90,0,0,90,0,0,0,0,0,90,0,0,0,90,0,0,0,0,0,0,2,0,0
0,0,78,0,0,0,90,0,0,90,0,0,0,2,2,2,2,2,2,2,2,2,0,0,0,0,78,0,0
0,0,78,0,0,0,90,0,0,90,0,0,0,2,0,0,0,2,0,0,0,2,0,0,0,0,78,0,0
0,0,2,0,0,0,90,0,0,90,0,0,0,2,17,0,0,2,0,0,8,2,0,0,0,0,2,0,0
0,0,2,0,0,0,90,0,0,90,0,0,0,2,0,0,0,2,0,0,0,2,0,0,0,0,2,0,0
0,0,78,0,0,90,90,69,90,90,90,69,90,2,0,0,0,2,0,0,0,2,90,90,0,0,78,0,0
0,0,78,0,0,90,0,0,0,0,0,0,0,0,0,0,0,0,0,0,0,0,0,69,0,0,78,0,0
0,0,85,0,0,0,0,0,0,0,0,0,0,0,0,0,0,0,0,0,0,0,0,90,90,90,2,0,0
0,0,27,0,0,0,0,0,0,0,0,0,0,0,0,0,0,0,0,22,0,0,0,69,0,0,78,0,0
0,0,27,0,0,0,0,0,90,90,90,69,90,90,90,90,90,90,90,2,21,2,90,90,0,0,78,0,0
0,0,85,0,0,0,0,0,0,90,0,0,0,0,0,0,2,2,2,0,0,2,0,0,0,0,2,0,0
0,0,85,0,0,0,0,0,0,90,0,0,0,0,0,0,2,0,0,0,0,2,0,0,0,0,2,0,0
0,0,27,0,0,0,0,0,0,90,0,0,0,0,0,0,2,25,11,0,0,2,0,0,0,0,78,0,0
0,0,27,0,0,0,0,0,0,90,0,0,0,0,90,90,2,2,2,2,2,2,0,0,0,0,78,0,0
0,0,85,0,0,0,0,0,0,90,0,0,0,0,0,0,90,0,0,0,0,90,0,0,0,0,2,0,0
0,0,78,0,0,0,0,0,0,90,0,0,0,0,0,0,90,0,0,0,0,14,0,0,0,0,78,0,0
0,0,78,0,0,0,0,0,0,14,0,0,0,0,0,0,90,0,0,0,0,14,0,0,0,0,78,0,0
0,0,2,0,0,0,0,0,0,14,0,0,0,0,0,0,90,0,0,0,0,0,0,0,0,0,2,0,0
0,0,78,0,0,0,0,0,0,14,0,0,0,0,0,0,90,0,0,0,0,0,0,0,0,0,78,0,0
0,0,78,0,0,0,0,0,0,90,0,0,0,0,0,0,90,0,0,0,0,0,0,0,0,0,78,0,0
0,0,2,0,0,0,0,0,0,90,0,0,0,0,0,0,90,0,0,0,0,0,0,0,0,0,2,0,0
0,0,2,2,78,78,2,78,78,2,78,78,2,78,78,78,2,78,78,85,27,27,85,27,27,2,2,0,0
0,0,0,0,0,0,0,0,0,0,0,0,0,0,0,0,0,0,0,0,0,0,0,0,0,0,0,0,0
0,0,0,0,0,0,0,0,0,0,0,0,0,0,0,0,0,0,0,0,0,0,0,0,0,0,0,0,0
endlayer

layer
0,0,0,0,0,0,0,0,0,0,0,0,0,0,0,0,0,0,0,0,0,0,0,0,0,0,0,0,0
0,0,0,0,0,0,0,0,0,0,0,0,0,0,0,0,0,0,0,0,0,0,0,0,0,0,0,0,0
0,0,50,2,78,78,2,78,78,2,78,78,2,78,78,78,2,78,78,2,78,78,2,78,78,2,50,0,0
0,0,2,0,0,0,0,0,0,90,0,0,0,0,0,0,0,0,0,90,0,0,0,0,0,0,2,0,0
0,0,78,0,0,0,0,0,0,90,0,0,0,0,0,0,0,0,0,14,0,0,0,0,0,0,78,0,0
0,0,78,0,0,0,0,0,0,90,0,0,0,0,0,0,0,0,0,14,0,0,0,0,0,0,78,0,0
0,0,2,0,0,0,0,0,0,90,0,0,0,0,0,0,0,0,0,14,0,0,0,0,0,0,2,0,0
0,0,78,0,0,0,0,0,0,90,0,0,0,0,0,0,0,0,0,90,0,0,0,0,0,0,78,0,0
0,0,78,0,0,0,0,0,0,90,0,0,0,0,0,90,0,0,0,90,0,0,0,0,0,0,78,0,0
0,0,2,90,90,90,90,0,0,90,0,0,0,0,0,90,0,7,0,90,0,0,0,0,0,0,2,0,0
0,0,78,0,0,0,90,0,0,90,0,0,0,2,2,2,2,2,2,2,2,2,0,0,0,0,78,0,0
0,0,78,0,0,0,90,0,0,90,0,0,0,2,0,0,0,2,0,0,0,2,64,0,0,0,78,0,0
0,0,2,0,0,0,90,0,0,90,0,0,0,2,17,0,0,2,0,0,8,2,0,0,0,0,2,0,0
0,0,2,0,0,0,90,0,0,90,0,0,0,2,0,0,0,2,0,0,0,2,0,0,0,0,2,0,0
0,0,78,0,0,90,90,5,90,90,90,5,90,2,0,0,0,2,0,0,0,2,90,90,0,0,78,0,0
0,0,78,0,0,90,0,0,0,0,0,0,0,0,0,0,0,0,0,0,0,0,0,5,0,0,78,0,0
0,0,85,0,0,0,0,0,0,0,0,0,0,0,0,0,0,0,0,0,0,0,0,90,90,90,2,0,0
0,0,27,0,0,0,0,0,0,0,0,0,0,0,0,0,0,0,0,0,0,0,0,5,0,0,78,0,0
0,0,27,0,0,0,0,5,90,90,90,5,90,90,90,90,90,90,90,2,2,2,90,90,0,0,78,0,0
0,0,85,0,0,0,0,0,0,90,0,0,0,0,0,0,2,2,2,2,2,2,0,0,0,0,2,0,0
0,0,85,0,0,0,0,0,0,90,0,0,0,0,0,0,2,2,0,0,0,2,0,0,0,0,2,0,0
0,0,27,0,0,0,0,0,0,90,0,0,0,0,0,91,2,11,0,0,0,2,64,0,0,0,78,0,0
0,0,27,0,0,0,0,0,0,90,0,0,0,0,90,90,2,2,2,2,2,2,0,0,0,0,78,0,0
0,0,85,0,0,0,0,0,0,90,0,0,0,0,0,0,90,0,0,0,0,90,0,0,0,0,2,0,0
0,0,78,0,0,0,0,0,0,90,0,0,0,0,0,0,90,0,0,0,0,14,0,0,0,0,78,0,0
0,0,78,0,0,0,0,0,0,90,0,0,0,0,0,0,90,0,0,0,0,14,0,0,0,0,78,0,0
0,0,2,0,0,0,0,0,0,90,0,0,0,0,0,0,90,0,0,0,0,0,0,0,0,0,2,0,0
0,0,78,0,0,0,0,0,0,90,0,0,0,0,0,0,90,0,0,0,0,0,0,0,0,0,78,0,0
0,0,78,0,0,0,0,0,0,90,0,0,0,0,0,0,90,0,0,0,0,0,0,0,0,0,78,0,0
0,0,2,0,0,0,0,0,0,90,0,0,0,0,0,0,90,0,0,0,0,0,0,0,0,0,2,0,0
0,0,50,2,78,78,2,78,78,2,78,78,2,78,78,78,2,78,78,85,27,27,85,27,27,2,50,0,0
0,0,0,0,0,0,0,0,0,0,0,0,0,0,0,0,0,0,0,0,0,0,0,0,0,0,0,0,0
0,0,0,0,0,0,0,0,0,0,0,0,0,0,0,0,0,0,0,0,0,0,0,0,0,0,0,0,0
endlayer

layer
0,0,0,0,0,0,0,0,0,0,0,0,0,0,0,0,0,0,0,0,0,0,0,0,0,0,0,0,0
0,0,0,0,0,0,0,0,0,0,0,0,0,0,0,0,0,0,0,0,0,0,0,0,0,0,0,0,0
0,0,2,2,78,78,2,78,78,2,78,78,2,78,78,78,2,78,78,2,78,78,2,78,78,2,2,0,0
0,0,2,0,0,0,0,0,0,90,0,0,0,0,0,0,0,0,0,90,0,0,0,0,0,0,2,0,0
0,0,78,0,0,0,0,0,0,90,0,0,0,0,0,0,0,0,0,90,0,0,0,0,0,0,78,0,0
0,0,78,0,0,0,0,0,0,90,0,0,0,0,0,0,0,0,0,90,0,0,0,0,0,0,78,0,0
0,0,2,0,0,0,0,0,0,90,0,0,0,0,0,0,0,0,0,90,0,0,0,0,0,0,2,0,0
0,0,78,0,0,0,0,0,0,90,0,0,0,0,0,0,0,0,0,90,0,0,0,0,0,0,78,0,0
0,0,78,0,0,0,0,0,0,90,0,0,0,0,0,90,0,0,0,90,0,0,0,0,0,0,78,0,0
0,0,2,90,90,90,90,0,0,90,0,0,0,0,0,90,0,0,0,90,0,0,0,0,0,0,2,0,0
0,0,78,0,0,0,90,0,0,90,0,0,0,2,2,2,2,2,2,2,2,2,0,0,0,0,78,0,0
0,0,78,0,0,0,90,0,0,90,0,0,0,2,0,0,0,2,0,0,0,2,0,0,0,0,78,0,0
0,0,2,0,0,0,90,0,0,90,0,0,0,2,17,0,0,2,0,0,8,2,0,0,0,0,2,0,0
0,0,2,0,0,0,90,0,0,90,0,0,0,2,0,0,0,2,0,0,0,2,0,0,0,0,2,0,0
0,0,78,0,0,90,90,90,90,90,90,90,90,2,86,86,86,2,86,86,86,2,90,90,0,0,78,0,0
0,0,78,0,0,90,0,0,0,0,0,0,0,0,0,0,0,0,0,0,0,0,0,90,0,0,78,0,0
0,0,85,0,0,0,0,0,0,0,0,0,0,0,0,0,0,0,0,0,0,0,0,90,90,90,2,0,0
0,0,27,0,0,0,0,0,0,0,0,0,0,0,0,0,0,0,0,0,0,0,0,90,0,0,78,0,0
0,0,27,0,0,0,0,90,90,90,90,90,90,90,90,90,90,90,90,2,2,2,90,90,0,0,78,0,0
0,0,85,0,0,0,0,0,0,90,0,0,0,0,0,0,2,2,2,2,2,2,0,0,0,0,2,0,0
0,0,85,0,0,0,0,0,0,90,0,0,0,0,0,0,2,32,31,0,0,2,0,0,0,0,2,0,0
0,0,27,0,0,0,0,0,0,90,0,0,0,0,0,0,2,0,0,0,0,2,0,0,0,0,78,0,0
0,0,27,0,0,0,0,0,0,90,0,0,0,0,90,90,2,2,2,2,2,2,0,0,0,0,78,0,0
0,0,85,0,0,0,0,0,0,90,0,0,0,0,0,0,90,0,0,0,0,90,0,0,0,0,2,0,0
0,0,78,0,0,0,0,0,0,90,0,0,0,0,0,0,90,0,0,0,0,90,0,0,0,0,78,0,0
0,0,78,0,0,0,0,0,0,90,0,0,0,0,0,0,90,0,0,0,0,90,0,0,0,0,78,0,0
0,0,2,0,0,0,0,0,0,90,0,0,0,0,0,0,90,0,0,0,0,0,0,0,0,0,2,0,0
0,0,78,0,0,0,0,0,0,90,0,0,0,0,0,0,90,0,0,0,0,0,0,0,0,0,78,0,0
0,0,78,0,0,0,0,0,0,90,0,0,0,0,0,0,90,0,0,0,0,0,0,0,0,0,78,0,0
0,0,2,0,0,0,0,0,0,90,0,0,0,0,0,0,90,0,0,0,0,0,0,0,0,0,2,0,0
0,0,2,2,78,78,2,78,78,2,78,78,2,78,78,78,2,78,78,85,27,27,85,27,27,2,2,0,0
0,0,0,0,0,0,0,0,0,0,0,0,0,0,0,0,0,0,0,0,0,0,0,0,0,0,0,0,0
0,0,0,0,0,0,0,0,0,0,0,0,0,0,0,0,0,0,0,0,0,0,0,0,0,0,0,0,0
endlayer

layer
0,0,0,0,0,0,0,0,0,0,0,0,0,0,0,0,0,0,0,0,0,0,0,0,0,0,0,0,0
0,0,0,0,0,0,0,0,0,0,0,0,0,0,0,0,0,0,0,0,0,0,0,0,0,0,0,0,0
0,0,50,2,36,36,2,36,36,2,36,36,2,36,36,36,2,36,36,2,36,36,2,36,36,2,50,0,0
0,0,2,60,60,60,60,60,60,90,60,60,60,60,60,60,60,60,60,90,60,60,60,60,60,60,2,0,0
0,0,36,60,60,60,60,60,60,90,60,60,60,60,60,60,60,60,60,90,60,60,60,60,60,60,36,0,0
0,0,36,60,60,60,60,60,60,90,60,60,60,60,60,60,60,60,60,90,60,60,60,60,60,60,36,0,0
0,0,2,60,60,60,60,60,60,90,60,60,60,60,60,60,60,60,60,90,60,60,60,60,60,60,2,0,0
0,0,36,0,0,0,0,60,60,90,60,60,60,60,60,60,60,60,60,90,60,60,60,60,60,60,36,0,0
