# Haunted Graveyard
# Author: Mozai
# based on a design by Mantonization (http://redd.it/lolso)
# formivore fixed stairs to the new metas
# Adapted to The End is Extremely Nigh by cavechunk

weight=10
acceptable_target_blocks=1,2,3,12,13,162,163,164,165,166,167,168,169,170,171,172,254,255
embed_into_distance=1
dimensions=5,21,26
max_leveling=4
max_cut_in=5
preserve_plants=1

# wall brick
rule1=0,100,45
# paths
rule2=0,100,48,48,48,2
# grass
rule3=0,100,2
# coffins (duplicate)
rule4=0,100,99-14,0,0,0,3,3,140,35-12,46,103,54,54,54,HardMobSpawn,EasyChest
# haunted coffins (duplicate)
rule5=0,100,99-14,0,0,0,3,3,140,35-12,46,103,54,54,54,HardMobSpawn,EasyChest
# overgrowth (60% nothing, 20% grass, 20% other)
rule6=0,40,31-1,31-1,31-1,31-1,37,38,31-0,31-0
# headstone 
rule7=0,100,24,24,24-1,35-9,48
# half-slab gravecover
rule8=0,100,44-1
# treetrunk (nixed)
rule9=0,0,17
# brick for vaults
rule10=0,95,45
# iron fence
rule11=0,100,101
# tree leaves (nixed)
rule12=0,0,18
# gargoyle
rule13=0,50,35-8
# slope roof westside (ascending north?)
rule14=0,100,108-3
# slope roof backside
rule15=0,100,44-4
# slope roof eastside (ascending south?)
rule16=0,100,108-2


layer
1,1,1,1,1,1,1,1,1,1,1,1,2,2,1,1,1,1,1,1,1,1,1,1,1,1
1,3,3,3,3,3,3,3,3,3,3,3,2,2,3,3,3,3,3,3,3,3,3,3,3,1
1,3,3,3,3,3,3,3,3,3,3,3,2,2,3,3,3,3,3,3,3,3,3,3,3,1
1,3,4,3,4,3,4,3,4,3,4,3,2,2,3,4,3,4,3,4,3,4,3,4,3,1
1,3,3,3,3,3,3,3,3,3,3,3,2,2,3,3,3,3,3,3,3,3,3,3,3,1
1,3,2,2,2,2,2,2,2,2,2,2,2,2,2,2,2,2,2,2,2,2,2,2,3,1
1,3,2,2,2,2,2,2,2,2,2,2,2,2,2,2,2,2,2,2,2,2,2,2,3,1
1,3,3,3,3,3,3,3,3,3,3,3,2,2,3,3,3,3,3,3,3,3,3,3,3,1
1,3,3,3,3,3,4,3,5,3,5,3,2,2,3,5,3,5,3,4,3,3,3,3,3,1
1,3,3,3,3,3,3,3,3,3,3,3,2,2,3,3,3,3,3,3,3,3,4,3,3,1
1,3,3,3,3,3,3,3,3,3,3,3,2,2,3,3,3,3,3,3,3,3,3,3,3,1
1,3,3,4,3,3,3,3,3,3,3,3,2,2,3,3,3,3,3,3,3,3,3,3,3,1
1,3,3,3,3,3,4,3,5,3,5,3,2,2,3,5,3,5,3,4,3,3,3,3,3,1
1,3,3,3,3,3,3,3,3,3,3,3,2,2,3,3,3,3,3,3,3,3,3,3,3,1
1,3,2,2,2,2,2,2,2,2,2,2,2,2,2,2,2,2,2,2,2,2,2,2,3,1
1,3,2,2,2,2,2,2,2,2,2,2,2,2,2,2,2,2,2,2,2,2,2,2,3,1
1,3,3,3,3,3,3,3,3,3,3,3,2,2,3,3,3,3,3,3,3,3,3,3,3,1
1,3,4,3,4,3,4,3,4,3,4,3,2,2,3,4,3,4,3,4,3,4,3,4,3,1
1,3,3,3,3,3,3,3,3,3,3,3,2,2,3,3,3,3,3,3,3,3,3,3,3,1
1,3,3,3,3,3,3,3,3,3,3,3,2,2,3,3,3,3,3,3,3,3,3,3,3,1
1,1,1,1,1,1,1,1,1,1,1,1,2,2,1,1,1,1,1,1,1,1,1,1,1,1
endlayer

layer
1,1,1,1,1,1,1,1,1,1,1,1,0,0,1,1,1,1,1,1,1,1,1,1,1,1
1,6,6,6,6,6,6,6,6,6,6,6,0,0,6,6,6,6,6,6,6,6,6,6,6,1
1,6,7,6,7,6,7,6,7,6,7,6,0,0,6,7,6,7,6,7,6,7,6,7,6,1
1,6,8,6,8,6,8,6,8,6,8,6,0,0,6,8,6,8,6,8,6,8,6,8,6,1
1,6,6,6,6,6,6,6,6,6,6,6,0,0,6,6,6,6,6,6,6,6,6,6,6,1
1,6,0,0,0,0,0,0,0,0,0,0,0,0,0,0,0,0,0,0,0,0,0,0,6,1
1,6,0,0,0,0,0,0,0,0,0,0,0,0,0,0,0,0,0,0,0,0,0,0,6,1
1,6,6,6,6,6,6,6,6,6,6,6,0,0,6,6,6,6,6,6,6,6,6,6,6,1
1,6,6,9,6,6,8,6,8,6,8,6,0,0,6,8,6,8,6,8,6,10,6,10,6,1
1,6,6,6,6,6,7,6,7,6,7,6,0,0,6,7,6,7,6,7,6,10,7,10,6,1
1,6,10,10,10,6,6,6,6,6,6,6,0,0,6,6,6,6,6,6,6,10,10,10,6,1
1,6,10,7,10,6,7,6,7,6,7,6,0,0,6,7,6,7,6,7,6,6,6,6,6,1
1,6,10,6,10,6,8,6,8,6,8,6,0,0,6,8,6,8,6,8,6,6,9,6,6,1
1,6,6,6,6,6,6,6,6,6,6,6,0,0,6,6,6,6,6,6,6,6,6,6,6,1
1,6,0,0,0,0,0,0,0,0,0,0,0,0,0,0,0,0,0,0,0,0,0,0,6,1
1,6,0,0,0,0,0,0,0,0,0,0,0,0,0,0,0,0,0,0,0,0,0,0,6,1
1,6,6,6,6,6,6,6,6,6,6,6,0,0,6,6,6,6,6,6,6,6,6,6,6,1
1,6,8,6,8,6,8,6,8,6,8,6,0,0,6,8,6,8,6,8,6,8,6,8,6,1
1,6,7,6,7,6,7,6,7,6,7,6,0,0,6,7,6,7,6,7,6,7,6,7,6,1
1,6,6,6,6,6,6,6,6,6,6,6,0,0,6,6,6,6,6,6,6,6,6,6,6,1
1,1,1,1,1,1,1,1,1,1,1,1,0,0,1,1,1,1,1,1,1,1,1,1,1,1
endlayer

layer
11,11,11,11,11,11,11,11,11,11,11,1,0,0,1,11,11,11,11,11,11,11,11,11,11,11
11,0,0,0,0,0,0,0,0,0,0,0,0,0,0,0,0,0,0,0,0,0,0,0,0,11
11,0,0,0,0,0,0,0,0,0,0,0,0,0,0,0,0,0,0,0,0,0,0,0,0,11
11,0,0,0,0,0,0,0,0,0,0,0,0,0,0,0,0,0,0,0,0,0,0,0,0,11
11,0,0,0,0,0,0,0,0,0,0,0,0,0,0,0,0,0,0,0,0,0,0,0,0,11
11,0,0,0,0,0,0,0,0,0,0,0,0,0,0,0,0,0,0,0,0,0,0,0,0,11
11,0,0,0,0,0,0,0,0,0,0,0,0,0,0,0,0,0,0,0,0,0,0,0,0,11
11,0,0,12,0,0,0,0,0,0,0,0,0,0,0,0,0,0,0,0,0,0,0,0,0,11
11,0,12,9,12,0,0,0,0,0,0,0,0,0,0,0,0,0,0,0,0,10,0,10,0,11
11,0,0,12,0,0,0,0,0,0,0,0,0,0,0,0,0,0,0,0,0,10,13,10,0,11
11,0,10,10,10,0,0,0,0,0,0,0,0,0,0,0,0,0,0,0,0,10,10,10,0,11
11,0,10,13,10,0,0,0,0,0,0,0,0,0,0,0,0,0,0,0,0,0,12,0,0,11
11,0,10,0,10,0,0,0,0,0,0,0,0,0,0,0,0,0,0,0,0,12,9,12,0,11
11,0,0,0,0,0,0,0,0,0,0,0,0,0,0,0,0,0,0,0,0,0,12,0,0,11
11,0,0,0,0,0,0,0,0,0,0,0,0,0,0,0,0,0,0,0,0,0,0,0,0,11
11,0,0,0,0,0,0,0,0,0,0,0,0,0,0,0,0,0,0,0,0,0,0,0,0,11
11,0,0,0,0,0,0,0,0,0,0,0,0,0,0,0,0,0,0,0,0,0,0,0,0,11
11,0,0,0,0,0,0,0,0,0,0,0,0,0,0,0,0,0,0,0,0,0,0,0,0,11
11,0,0,0,0,0,0,0,0,0,0,0,0,0,0,0,0,0,0,0,0,0,0,0,0,11
11,0,0,0,0,0,0,0,0,0,0,0,0,0,0,0,0,0,0,0,0,0,0,0,0,11
11,11,11,11,11,11,11,11,11,11,11,1,0,0,1,11,11,11,11,11,11,11,11,11,11,11
endlayer

layer
11,11,11,11,11,11,11,11,11,11,11,1,0,0,1,11,11,11,11,11,11,11,11,11,11,11
11,0,0,0,0,0,0,0,0,0,0,0,0,0,0,0,0,0,0,0,0,0,0,0,0,11
11,0,0,0,0,0,0,0,0,0,0,0,0,0,0,0,0,0,0,0,0,0,0,0,0,11
11,0,0,0,0,0,0,0,0,0,0,0,0,0,0,0,0,0,0,0,0,0,0,0,0,11
11,0,0,0,0,0,0,0,0,0,0,0,0,0,0,0,0,0,0,0,0,0,0,0,0,11
11,0,0,0,0,0,0,0,0,0,0,0,0,0,0,0,0,0,0,0,0,0,0,0,0,11
11,0,0,0,0,0,0,0,0,0,0,0,0,0,0,0,0,0,0,0,0,0,0,0,0,11
11,0,12,12,12,0,0,0,0,0,0,0,0,0,0,0,0,0,0,0,0,0,0,0,0,11
11,0,12,9,12,0,0,0,0,0,0,0,0,0,0,0,0,0,0,0,0,14,10,16,0,11
11,0,12,12,12,0,0,0,0,0,0,0,0,0,0,0,0,0,0,0,0,14,10,16,0,11
11,0,15,15,15,0,0,0,0,0,0,0,0,0,0,0,0,0,0,0,0,15,15,15,0,11
11,0,14,10,16,0,0,0,0,0,0,0,0,0,0,0,0,0,0,0,0,12,12,12,0,11
11,0,14,10,16,0,0,0,0,0,0,0,0,0,0,0,0,0,0,0,0,12,9,12,0,11
11,0,0,0,0,0,0,0,0,0,0,0,0,0,0,0,0,0,0,0,0,12,12,12,0,11
11,0,0,0,0,0,0,0,0,0,0,0,0,0,0,0,0,0,0,0,0,0,0,0,0,11
11,0,0,0,0,0,0,0,0,0,0,0,0,0,0,0,0,0,0,0,0,0,0,0,0,11
11,0,0,0,0,0,0,0,0,0,0,0,0,0,0,0,0,0,0,0,0,0,0,0,0,11
11,0,0,0,0,0,0,0,0,0,0,0,0,0,0,0,0,0,0,0,0,0,0,0,0,11
11,0,0,0,0,0,0,0,0,0,0,0,0,0,0,0,0,0,0,0,0,0,0,0,0,11
11,0,0,0,0,0,0,0,0,0,0,0,0,0,0,0,0,0,0,0,0,0,0,0,0,11
11,11,11,11,11,11,11,11,11,11,11,1,0,0,1,11,11,11,11,11,11,11,11,11,11,11
endlayer

layer
0,0,0,0,0,0,0,0,0,0,0,14,1,1,16,0,0,0,0,0,0,0,0,0,0,0
0,0,0,0,0,0,0,0,0,0,0,0,0,0,0,0,0,0,0,0,0,0,0,0,0,0
0,0,0,0,0,0,0,0,0,0,0,0,0,0,0,0,0,0,0,0,0,0,0,0,0,0
0,0,0,0,0,0,0,0,0,0,0,0,0,0,0,0,0,0,0,0,0,0,0,0,0,0
0,0,0,0,0,0,0,0,0,0,0,0,0,0,0,0,0,0,0,0,0,0,0,0,0,0
0,0,0,0,0,0,0,0,0,0,0,0,0,0,0,0,0,0,0,0,0,0,0,0,0,0
0,0,0,0,0,0,0,0,0,0,0,0,0,0,0,0,0,0,0,0,0,0,0,0,0,0
0,0,0,12,0,0,0,0,0,0,0,0,0,0,0,0,0,0,0,0,0,0,0,0,0,0
0,0,12,12,12,0,0,0,0,0,0,0,0,0,0,0,0,0,0,0,0,0,0,0,0,0
0,0,0,12,0,0,0,0,0,0,0,0,0,0,0,0,0,0,0,0,0,0,0,0,0,0
0,0,0,0,0,0,0,0,0,0,0,0,0,0,0,0,0,0,0,0,0,0,0,0,0,0
0,0,0,0,0,0,0,0,0,0,0,0,0,0,0,0,0,0,0,0,0,0,12,0,0,0
0,0,0,0,0,0,0,0,0,0,0,0,0,0,0,0,0,0,0,0,0,12,12,12,0,0
0,0,0,0,0,0,0,0,0,0,0,0,0,0,0,0,0,0,0,0,0,0,12,0,0,0
0,0,0,0,0,0,0,0,0,0,0,0,0,0,0,0,0,0,0,0,0,0,0,0,0,0
0,0,0,0,0,0,0,0,0,0,0,0,0,0,0,0,0,0,0,0,0,0,0,0,0,0
0,0,0,0,0,0,0,0,0,0,0,0,0,0,0,0,0,0,0,0,0,0,0,0,0,0
0,0,0,0,0,0,0,0,0,0,0,0,0,0,0,0,0,0,0,0,0,0,0,0,0,0
0,0,0,0,0,0,0,0,0,0,0,0,0,0,0,0,0,0,0,0,0,0,0,0,0,0
0,0,0,0,0,0,0,0,0,0,0,0,0,0,0,0,0,0,0,0,0,0,0,0,0,0
0,0,0,0,0,0,0,0,0,0,0,14,1,1,16,0,0,0,0,0,0,0,0,0,0,0
endlayer

