# Converted from schematic
# THIS TEMPLATE USES DEFAULTS!  Please edit for corrections.
# If you need help, consult template_rules.txt

weight=10
embed_into_distance=1
acceptable_target_blocks=1,2,3,12,13,162,163,164,165,166,167,168,169,170,171,172,254,255
dimensions=6,9,9
allowable_overhang=0
max_cut_in=2
cut_in_buffer=1
max_leveling=2
leveling_buffer=1
preserve_water=0
preserve_lava=0
preserve_plants=0


rule1=0,100,98-1
rule2=0,100,3
rule3=0,100,17
rule4=0,100,5
rule5=0,100,44-3
rule6=0,100,4


layer
1,1,1,1,1,1,1,1,1
1,1,2,2,2,1,2,1,1
1,1,3,3,3,3,0,2,1
1,1,0,0,0,3,0,2,1
1,3,3,4,0,0,3,2,1
1,1,0,3,3,0,3,2,1
1,1,3,3,3,0,3,2,1
1,1,1,1,1,1,2,1,1
1,1,1,1,1,1,1,1,1
endlayer

layer
0,0,0,0,0,0,0,0,0
0,0,4,4,4,0,4,0,0
0,4,0,0,0,0,0,4,0
0,0,0,0,0,0,0,4,0
0,0,0,0,0,0,0,4,0
0,4,0,0,0,0,0,4,0
0,4,0,0,0,0,0,4,0
0,0,4,0,0,4,4,0,0
0,0,0,0,0,0,0,0,0
endlayer

layer
0,0,0,0,0,0,0,0,0
0,0,0,0,0,0,4,0,0
0,0,0,0,0,0,0,0,0
0,0,0,0,0,0,0,0,0
0,0,0,0,0,0,0,0,0
0,0,0,0,0,0,0,0,0
0,0,0,0,0,0,0,4,0
0,0,0,0,0,0,4,0,0
0,0,0,0,0,0,0,0,0
endlayer

layer
0,0,0,0,0,0,0,0,0
0,0,0,0,0,0,4,0,0
0,0,0,0,0,0,0,0,0
0,0,0,0,0,0,0,0,0
0,0,0,0,0,0,0,0,0
0,0,0,0,0,0,0,0,0
0,0,0,0,0,0,0,4,0
0,0,4,0,0,0,4,0,0
0,0,0,0,0,0,0,0,0
endlayer

layer
0,0,5,5,5,5,5,0,0
0,0,0,0,6,6,6,5,0
0,0,0,0,0,0,6,6,5
0,0,0,0,0,0,0,6,5
0,0,0,0,0,0,0,6,5
0,0,0,0,0,0,6,6,5
0,0,0,0,0,0,6,6,5
0,5,6,0,6,6,6,0,0
0,0,5,5,5,5,5,0,0
endlayer

layer
0,0,0,0,0,0,0,0,0
0,0,0,0,0,0,0,0,0
0,0,0,0,0,5,5,0,0
0,0,0,0,0,6,5,0,0
0,0,0,0,0,6,5,0,0
0,0,0,0,0,6,5,0,0
0,0,0,0,5,5,5,0,0
0,0,0,0,0,0,0,0,0
0,0,0,0,0,0,0,0,0
endlayer

