# Author: d00dv4d3r
# From: Default Template

weight=5
embed_into_distance=1
acceptable_target_blocks=1,2,3,12,13,162,163,164,165,166,167,168,169,170,171,172,254,255
dimensions=8,7,7
allowable_overhang=2
max_cut_in=2
cut_in_buffer=1
max_leveling=2
leveling_buffer=1
preserve_water=0
preserve_lava=0
preserve_plants=1

rule1=0,100,0,4,44-3
rule2=0,100,4,98,98-1,98-2
rule3=1,75,4,98,98-1,98-2
rule4=1,50,4,98,98-1,98-2
rule5=2,100,0,4,44-3
rule6=0,100,0,67,67,67

layer
2,2,2,2,2,2,2
2,1,1,1,1,1,2
2,1,1,1,1,1,2
2,1,1,1,1,1,2
2,1,1,1,1,1,2
2,1,1,1,1,1,2
2,2,2,2,2,2,2
endlayer

layer
3,3,3,3,3,3,3
3,0,0,0,0,0,3
3,0,0,0,0,6,3
3,0,0,0,0,0,3
3,0,0,0,0,0,3
3,0,0,0,0,0,3
3,3,3,3,3,3,3
endlayer

layer
3,3,3,3,3,3,3
3,0,0,0,0,0,3
3,0,0,0,0,0,3
3,0,0,0,0,6,3
3,0,0,0,0,0,3
3,0,0,0,0,0,3
3,3,3,3,3,3,3
endlayer

layer
3,3,3,3,3,3,3
3,0,0,0,0,0,3
3,0,0,0,0,0,3
3,0,0,0,0,0,3
3,0,0,0,0,6,3
3,0,0,0,0,0,3
3,3,3,3,3,3,3
endlayer

layer
3,3,3,3,3,3,3
3,5,5,5,5,5,3
3,5,5,5,5,0,3
3,5,5,5,5,0,3
3,5,5,5,5,0,3
3,5,5,5,5,6,3
3,3,3,3,3,3,3
endlayer

layer
4,4,4,4,4,4,4
4,0,0,0,0,0,4
4,0,0,0,0,0,4
4,0,0,0,0,0,4
4,0,0,0,0,0,4
4,0,0,0,0,0,4
4,4,4,4,4,4,4
endlayer

layer
4,4,4,4,4,4,4
4,0,0,0,0,0,4
4,0,0,0,0,0,4
4,0,0,0,0,0,4
4,0,0,0,0,0,4
4,0,0,0,0,0,4
4,4,4,4,4,4,4
endlayer

layer
4,4,4,4,4,4,4
4,0,0,0,0,0,4
4,0,0,0,0,0,4
4,0,0,0,0,0,4
4,0,0,0,0,0,4
4,0,0,0,0,0,4
4,4,4,4,4,4,4
endlayer
