weight=5
acceptable_target_blocks=1,2,3,12,13,24,162,163,164,165,166,167,168,169,170,171,172,254,255
embed_into_distance=1
dimensions=4,18,30
allowable_overhang=0
max_leveling=1
preserve_plants=1


rule1=1,70,45
rule2=1,40,5-1,45,45,45,45,98-3
rule3=1,100,43,45
rule4=1,65,24-1
rule5=0,0,35-14
rule6=0,50,44
rule7=2,50,102


layer
1,1,1,1,1,1,1,1,1,1,1,1,1,1,1,1,1,1,1,1,1,1,1,1,1,1,1,1,1,1
1,2,2,2,2,2,2,2,1,2,2,2,2,2,2,2,1,2,2,2,2,2,2,2,2,2,2,2,2,1
1,2,2,2,2,2,2,2,1,2,2,2,2,2,2,2,1,2,2,2,2,2,2,2,2,2,2,2,2,1
1,2,2,2,2,2,2,2,1,2,2,2,2,2,2,2,1,2,2,2,2,2,2,2,2,2,2,2,2,1
1,2,2,2,2,2,2,2,1,2,2,2,2,2,2,2,1,2,2,2,2,2,2,2,2,2,2,2,2,1
1,2,2,2,2,2,2,2,1,2,2,2,2,2,2,2,1,2,2,2,2,2,2,2,2,2,2,2,2,1
1,2,2,2,2,2,2,2,1,2,2,2,2,2,2,2,1,2,2,2,2,2,2,2,2,2,2,2,2,1
1,1,1,1,1,1,1,1,1,1,1,1,1,1,1,1,1,1,1,1,1,1,1,1,1,1,1,1,1,1
1,2,2,2,2,2,2,2,2,2,2,2,2,2,2,2,2,2,2,2,2,2,2,2,2,2,2,2,2,1
1,2,2,2,2,2,2,2,2,2,2,2,2,2,2,2,2,2,2,2,2,2,2,2,2,2,2,2,2,1
1,1,1,1,1,1,1,1,1,1,1,1,1,1,1,1,1,1,1,1,1,1,1,1,1,1,2,2,1,1
1,2,2,2,2,2,2,2,2,2,2,2,1,2,2,2,2,2,2,2,2,1,1,1,1,1,2,2,2,1
1,2,2,2,2,2,2,2,2,2,2,2,1,2,2,2,2,2,2,2,2,1,1,1,1,2,2,2,2,1
1,2,2,2,2,2,2,2,2,2,2,2,1,2,2,2,2,2,2,2,2,1,2,2,2,2,2,2,2,1
1,2,2,2,2,2,2,2,2,2,2,2,1,2,2,2,2,2,2,2,2,1,2,2,2,2,2,2,2,1
1,2,2,2,2,2,2,2,2,2,2,2,1,2,2,2,2,2,2,2,2,1,2,2,2,2,2,2,2,1
1,2,2,2,2,2,2,2,2,2,2,2,1,2,2,2,2,2,2,2,2,1,2,2,2,2,2,2,2,1
1,1,1,1,1,1,1,1,1,1,1,1,1,1,1,1,1,1,1,1,1,1,1,1,1,1,1,1,1,1
endlayer

layer
3,1,4,4,1,1,4,4,1,1,4,4,1,1,4,4,1,1,4,4,1,1,4,4,1,1,4,4,1,3
1,5,5,5,5,5,5,5,1,5,5,5,5,5,5,5,1,5,5,5,5,5,5,5,5,5,5,5,5,1
1,5,5,5,5,5,5,5,1,5,5,5,5,5,5,5,1,5,5,5,5,5,5,5,5,5,5,5,5,4
1,5,5,5,5,5,5,5,1,5,5,5,5,5,5,5,1,5,5,5,5,5,5,5,5,5,5,5,5,4
1,5,5,5,5,5,5,5,1,5,5,5,5,5,5,5,1,5,5,5,5,5,5,5,5,5,5,5,5,1
1,5,5,5,5,5,5,5,1,5,5,5,5,5,5,5,1,5,5,5,5,5,5,5,5,5,5,5,5,4
1,5,5,5,5,5,5,5,1,5,5,5,5,5,5,5,1,5,5,5,5,5,5,5,5,5,5,5,5,4
1,1,1,5,1,1,1,1,1,1,1,1,5,5,1,1,1,1,1,1,1,1,1,1,5,5,1,1,1,1
5,5,5,5,5,5,5,5,5,5,5,5,5,5,5,5,5,5,5,5,5,5,5,5,5,5,5,5,5,5
1,5,5,5,5,5,5,5,5,5,5,5,5,5,5,5,5,5,5,5,5,5,5,5,5,5,5,5,5,5
1,1,1,1,1,1,1,5,5,1,1,1,1,1,1,1,1,1,5,1,1,1,3,3,3,6,5,5,1,1
1,5,5,5,5,5,5,5,5,5,5,5,1,5,5,5,5,5,5,5,5,1,3,3,3,6,5,5,5,4
1,5,5,5,5,5,5,5,5,5,5,5,1,5,5,5,5,5,5,5,5,1,3,3,3,5,5,5,5,4
1,5,5,5,5,5,5,5,5,5,5,5,1,5,5,5,5,5,5,5,5,1,5,5,5,5,5,5,5,1
1,5,5,5,5,5,5,5,5,5,5,5,1,5,5,5,5,5,5,5,5,1,5,5,5,5,5,5,5,4
1,5,5,5,5,5,5,5,5,5,5,5,1,5,5,5,5,5,5,5,5,1,5,5,5,5,5,5,5,4
1,5,5,5,5,5,5,5,5,5,5,5,1,5,5,5,5,5,5,5,5,1,5,5,5,5,5,5,5,1
3,1,4,4,1,1,4,4,1,1,4,4,1,1,4,4,1,1,4,4,1,1,4,4,1,1,4,4,1,3
endlayer

layer
1,1,7,7,1,1,7,7,1,1,7,7,1,1,7,7,1,1,7,7,1,1,7,7,1,1,7,7,1,1
1,5,5,5,5,5,5,5,1,5,5,5,5,5,5,5,1,5,5,5,5,5,5,5,5,5,5,5,5,1
1,5,5,5,5,5,5,5,1,5,5,5,5,5,5,5,1,5,5,5,5,5,5,5,5,5,5,5,5,7
1,5,5,5,5,5,5,5,1,5,5,5,5,5,5,5,1,5,5,5,5,5,5,5,5,5,5,5,5,7
1,5,5,5,5,5,5,5,1,5,5,5,5,5,5,5,1,5,5,5,5,5,5,5,5,5,5,5,5,1
1,5,5,5,5,5,5,5,1,5,5,5,5,5,5,5,1,5,5,5,5,5,5,5,5,5,5,5,5,7
1,5,5,5,5,5,5,5,1,5,5,5,5,5,5,5,1,5,5,5,5,5,5,5,5,5,5,5,5,7
1,1,1,5,1,1,1,1,1,1,1,1,5,5,1,1,1,1,1,1,1,1,1,1,5,5,1,1,1,1
5,5,5,5,5,5,5,5,5,5,5,5,5,5,5,5,5,5,5,5,5,5,5,5,5,5,5,5,5,5
1,5,5,5,5,5,5,5,5,5,5,5,5,5,5,5,5,5,5,5,5,5,5,5,5,5,5,5,5,5
1,1,1,1,1,1,1,5,5,1,1,1,1,1,1,1,1,1,5,1,1,1,5,5,5,5,5,5,1,1
1,5,5,5,5,5,5,5,5,5,5,5,1,5,5,5,5,5,5,5,5,1,5,5,5,5,5,5,5,7
1,5,5,5,5,5,5,5,5,5,5,5,1,5,5,5,5,5,5,5,5,1,5,5,5,5,5,5,5,7
1,5,5,5,5,5,5,5,5,5,5,5,1,5,5,5,5,5,5,5,5,1,5,5,5,5,5,5,5,1
1,5,5,5,5,5,5,5,5,5,5,5,1,5,5,5,5,5,5,5,5,1,5,5,5,5,5,5,5,7
1,5,5,5,5,5,5,5,5,5,5,5,1,5,5,5,5,5,5,5,5,1,5,5,5,5,5,5,5,7
1,5,5,5,5,5,5,5,5,5,5,5,1,5,5,5,5,5,5,5,5,1,5,5,5,5,5,5,5,1
1,1,7,7,1,1,7,7,1,1,7,7,1,1,7,7,1,1,7,7,1,1,7,7,1,1,7,7,1,1
endlayer

layer
1,1,7,7,1,1,7,7,1,1,7,7,1,1,7,7,1,1,7,7,1,1,7,7,1,1,7,7,1,1
1,5,5,5,5,5,5,5,5,5,5,5,5,5,5,5,5,5,5,5,5,5,5,5,5,5,5,5,5,1
1,5,5,5,5,5,5,5,5,5,5,5,5,5,5,5,5,5,5,5,5,5,5,5,5,5,5,5,5,7
1,5,5,5,5,5,5,5,5,5,5,5,5,5,5,5,5,5,5,5,5,5,5,5,5,5,5,5,5,7
1,5,5,5,5,5,5,5,5,5,5,5,5,5,5,5,5,5,5,5,5,5,5,5,5,5,5,5,5,1
1,5,5,5,5,5,5,5,5,5,5,5,5,5,5,5,5,5,5,5,5,5,5,5,5,5,5,5,5,7
1,5,5,5,5,5,5,5,5,5,5,5,5,5,5,5,5,5,5,5,5,5,5,5,5,5,5,5,5,7
1,5,5,5,5,5,5,5,5,5,5,5,5,5,5,5,5,5,5,5,5,5,5,5,5,5,1,1,1,1
1,5,5,5,5,5,5,5,5,5,5,5,5,5,5,5,5,5,5,5,5,5,5,5,5,5,5,5,5,5
1,5,5,5,5,5,5,5,5,5,5,5,5,5,5,5,5,5,5,5,5,5,5,5,5,5,5,5,5,5
1,5,5,5,5,5,5,5,5,5,5,5,5,5,5,5,5,5,5,5,5,5,5,5,5,5,5,5,1,1
1,5,5,5,5,5,5,5,5,5,5,5,5,5,5,5,5,5,5,5,5,5,5,5,5,5,5,5,5,7
1,5,5,5,5,5,5,5,5,5,5,5,5,5,5,5,5,5,5,5,5,5,5,5,5,5,5,5,5,7
1,5,5,5,5,5,5,5,5,5,5,5,5,5,5,5,5,5,5,5,5,5,5,5,5,5,5,5,5,1
1,5,5,5,5,5,5,5,5,5,5,5,5,5,5,5,5,5,5,5,5,5,5,5,5,5,5,5,5,7
1,5,5,5,5,5,5,5,5,5,5,5,5,5,5,5,5,5,5,5,5,5,5,5,5,5,5,5,5,7
1,5,5,5,5,5,5,5,5,5,5,5,5,5,5,5,5,5,5,5,5,5,5,5,5,5,5,5,5,1
1,1,7,7,1,1,7,7,1,1,7,7,1,1,7,7,1,1,7,7,1,1,7,7,1,1,7,7,1,1
endlayer

