# Converted from schematic
# THIS TEMPLATE USES DEFAULTS!  Please edit for corrections.
# If you need help, consult template_rules.txt

weight=5
embed_into_distance=10
acceptable_target_blocks=1,2,3,12,13,162,163,164,165,166,167,168,169,170,171,172,254,255
dimensions=12,17,14
allowable_overhang=0
max_cut_in=0
cut_in_buffer=0
max_leveling=0
leveling_buffer=0
preserve_water=0
preserve_lava=0
preserve_plants=0


rule1=0,100,3
rule2=0,100,1
rule3=0,100,11
rule4=0,100,2
rule5=0,100,98-1
rule6=0,100,55
rule7=0,100,76-5
rule8=0,100,98-2
rule9=0,100,55-15
rule10=0,100,20
rule11=0,100,MobSpawner:Creeper
rule12=0,100,55-14
rule13=0,100,29-11
rule14=0,100,106-4
rule15=0,100,34-11
rule16=0,100,35-15
rule17=0,100,44-5
rule18=0,100,70
rule19=0,100,34-10
rule20=0,100,106-1
rule21=0,100,106-8
rule22=0,100,29-10
rule23=0,100,106-11
rule24=0,100,MediumChest
rule25=0,100,106-2
rule26=0,100,106-3
rule27=0,100,55-13
rule28=0,100,preserveBlock


layer
1,1,1,1,1,1,1,1,1,1,1,1,1,1
1,1,1,1,1,1,1,1,1,1,1,1,1,1
1,1,1,1,1,1,1,1,1,1,1,1,1,1
1,1,1,3,1,1,1,1,1,1,3,1,1,1
1,1,1,1,1,1,1,1,1,1,1,1,1,1
1,1,1,1,1,1,1,1,1,1,1,1,1,1
1,1,1,1,1,1,1,1,1,1,1,1,1,1
1,1,1,1,1,1,1,1,1,1,1,1,1,1
1,1,1,1,1,1,1,1,1,1,1,1,1,1
1,1,1,1,1,1,1,1,1,1,1,1,1,1
1,1,1,1,1,1,1,1,1,1,1,1,1,1
2,2,2,2,2,2,2,2,2,2,2,2,2,2
2,2,2,2,2,2,2,2,2,2,2,2,2,2
2,2,2,2,2,2,2,2,2,2,2,2,2,2
2,2,2,2,2,2,2,2,2,2,2,2,2,2
2,2,2,2,2,2,2,2,2,2,2,2,2,2
2,2,2,2,2,2,2,2,2,2,2,2,2,2
endlayer

layer
1,1,1,1,1,1,1,1,1,1,1,1,1,1
1,1,1,1,1,1,1,1,1,1,1,1,1,1
1,1,1,5,1,1,1,1,1,1,5,1,1,1
1,1,5,0,5,1,1,1,1,5,0,5,1,1
1,1,1,5,1,1,1,1,1,1,5,1,1,1
1,1,1,1,1,1,1,1,1,1,1,1,1,1
1,1,1,1,1,1,1,1,1,1,1,1,1,1
1,1,1,1,1,1,1,1,1,1,1,1,1,1
1,4,4,4,4,4,4,4,4,4,4,4,4,1
1,4,4,4,4,4,4,4,4,4,4,4,4,1
1,1,1,1,1,1,1,1,1,1,1,1,1,1
2,2,2,2,2,2,2,2,2,2,2,2,2,2
2,2,2,2,2,2,2,2,2,2,2,2,2,2
2,2,2,2,2,2,2,2,2,2,2,2,2,2
2,2,2,2,2,2,2,2,2,2,2,2,2,2
2,2,2,2,2,2,2,2,2,2,2,2,2,2
2,2,2,2,2,2,2,2,2,2,2,2,2,2
endlayer

layer
1,1,1,1,1,1,1,1,1,1,1,1,1,1
1,1,1,1,1,1,1,1,1,1,1,1,1,1
1,1,1,5,1,1,1,1,1,1,5,1,1,1
1,1,5,0,5,1,1,1,1,5,0,5,1,1
1,1,1,5,1,1,1,1,1,1,5,1,1,1
1,1,1,1,1,1,1,1,1,1,1,1,1,1
1,1,1,1,1,1,1,1,1,1,1,1,1,1
1,4,4,1,1,1,1,1,1,1,1,4,4,1
1,6,0,0,0,0,6,6,0,0,0,0,6,1
1,6,6,6,6,6,6,6,6,6,6,6,6,1
1,1,1,1,1,1,1,1,1,1,1,1,1,1
2,1,1,1,1,2,2,2,2,2,2,2,2,2
2,2,2,1,1,2,2,2,2,2,2,2,2,2
2,2,2,2,2,2,2,2,2,2,2,2,2,2
2,2,2,2,2,2,2,2,2,2,2,2,2,2
2,2,2,2,2,2,2,2,2,2,2,2,2,2
2,2,2,2,2,2,2,2,2,2,2,2,2,2
endlayer

layer
1,1,1,1,1,1,1,1,1,1,1,1,1,1
1,1,8,5,5,5,5,5,5,5,5,5,1,1
1,8,8,8,8,5,5,8,5,5,5,5,5,1
1,8,8,10,11,8,5,5,8,11,10,8,5,1
1,8,8,8,5,8,5,5,5,8,5,5,5,1
1,1,5,5,5,8,5,5,5,5,5,5,1,1
1,1,1,1,1,1,5,8,1,1,1,1,1,1
1,7,9,4,4,4,2,2,4,4,4,9,7,1
1,1,1,1,1,1,2,2,1,1,1,1,1,1
1,1,1,1,1,5,5,5,5,1,1,1,1,1
1,1,1,1,5,5,5,5,5,5,1,1,1,1
2,1,1,1,1,1,2,2,2,2,2,2,2,2
2,2,1,1,5,1,2,2,2,2,2,2,2,2
2,2,2,2,1,1,2,2,2,2,2,2,2,2
2,2,2,2,2,2,2,2,2,2,2,2,2,2
2,2,2,2,2,2,2,2,2,2,2,2,2,2
2,2,2,2,2,2,2,2,2,2,2,2,2,2
endlayer

layer
5,5,5,5,5,5,5,5,5,5,5,5,5,5
5,5,0,0,0,0,5,5,0,0,0,0,5,5
5,0,0,0,5,0,17,17,0,5,0,0,0,5
5,0,0,0,5,0,0,0,0,5,0,0,0,5
5,0,0,0,5,0,0,0,0,5,0,0,0,5
2,5,0,0,0,0,0,0,0,0,0,0,5,5
5,5,8,5,5,5,0,0,5,5,5,5,5,5
5,2,0,12,22,19,5,5,15,13,12,0,2,5
1,5,2,2,2,16,18,18,16,2,2,2,5,1
1,1,5,5,5,20,0,0,0,5,8,8,1,1
1,1,1,5,23,21,0,0,0,14,5,1,1,1
2,1,1,1,5,5,5,5,5,5,2,2,2,2
2,2,1,1,5,1,2,2,2,2,2,2,2,2
2,1,1,2,1,1,2,2,2,2,2,2,2,2
2,1,1,1,2,2,2,2,2,2,2,2,2,2
2,2,1,1,1,1,2,2,2,2,2,2,2,2
2,2,2,1,1,1,2,2,2,2,2,2,2,2
endlayer

layer
5,5,5,5,5,5,5,5,5,5,5,5,5,5
5,5,0,0,0,0,24,24,0,0,0,0,5,5
5,0,0,0,0,0,0,0,0,0,0,0,0,5
5,0,0,0,0,0,0,0,0,0,0,0,0,5
5,0,0,0,0,0,0,0,0,0,0,0,0,5
2,5,0,0,0,0,0,0,0,0,0,0,5,5
5,5,5,5,8,8,0,0,5,5,8,5,5,5
5,9,2,2,22,19,16,16,15,13,2,2,9,8
1,5,2,2,2,16,0,0,16,2,2,2,8,1
1,1,5,5,5,0,0,0,0,5,5,8,1,1
1,1,1,5,26,0,25,0,0,14,5,1,1,1
1,1,1,1,5,20,0,0,0,5,1,1,1,1
1,1,1,1,5,5,5,5,5,1,1,1,1,1
1,1,1,1,5,1,1,1,1,1,1,1,1,1
1,1,1,1,1,1,1,1,1,1,1,1,1,1
1,1,1,1,1,1,1,1,1,1,1,1,1,1
1,1,1,1,1,1,1,1,1,1,1,1,1,1
endlayer

layer
5,5,5,5,5,5,5,5,5,5,5,5,5,5
5,5,0,0,0,0,0,0,0,0,0,0,5,5
5,0,0,0,0,0,0,0,0,0,0,0,0,5
5,0,0,0,0,0,0,0,0,0,0,0,0,5
5,0,0,0,0,0,0,0,0,0,0,0,0,5
2,5,0,0,0,0,0,0,0,0,0,0,5,5
5,5,8,5,8,8,0,0,5,8,8,5,8,5
5,0,12,27,22,19,16,16,15,13,27,12,0,8
1,5,2,2,2,16,0,0,16,2,2,2,5,1
1,1,5,5,5,0,0,0,0,5,8,5,1,1
1,1,1,5,26,25,25,0,25,14,5,1,1,1
1,1,1,5,5,20,0,0,0,5,1,1,1,1
1,1,1,1,5,21,0,0,21,5,1,1,1,1
1,1,1,1,5,5,5,5,5,5,1,1,1,1
1,1,1,1,1,1,1,1,1,1,1,1,1,1
1,1,1,1,1,1,1,1,1,1,1,1,1,1
1,1,1,1,1,1,1,1,1,1,1,1,1,1
endlayer

layer
5,5,5,5,5,5,5,5,5,5,5,5,5,5
5,5,5,5,5,5,5,5,5,5,5,5,5,5
5,5,5,5,5,5,5,5,5,5,5,5,5,5
5,5,5,5,5,5,5,5,5,5,5,5,5,5
5,5,5,5,5,5,5,5,5,5,5,5,5,5
5,5,5,5,5,5,5,5,5,5,5,5,5,5
5,5,5,5,8,8,5,5,8,5,5,8,8,5
5,2,2,2,2,2,2,2,2,2,2,2,2,8
1,5,2,2,2,16,16,16,16,2,2,2,5,1
1,1,5,8,5,0,0,0,0,5,5,5,1,1
1,1,1,5,25,25,25,0,25,14,5,1,1,1
1,1,1,5,20,0,0,0,0,14,5,1,1,1
1,1,1,5,5,21,0,0,21,5,5,1,1,1
1,1,1,5,5,5,0,0,5,5,5,1,1,1
1,1,1,1,1,5,5,5,1,1,1,1,1,1
1,1,1,1,1,1,1,1,1,1,1,1,1,1
1,1,1,1,1,1,1,1,1,1,1,1,1,1
endlayer

layer
28,28,28,28,28,28,28,28,28,28,28,28,28,28
28,28,28,28,28,28,28,28,28,28,28,28,28,28
28,28,28,28,28,28,28,28,28,28,28,28,28,28
28,28,28,28,28,28,28,28,28,28,28,28,28,28
28,28,28,28,28,28,28,28,28,28,28,28,28,28
28,28,28,28,28,28,28,28,28,28,28,28,28,28
28,28,28,28,28,28,28,28,28,28,28,28,28,28
28,28,5,5,8,5,8,5,5,5,5,5,28,28
28,28,2,2,2,2,16,16,2,2,2,2,28,28
28,28,5,8,5,5,0,0,8,5,5,5,28,28
28,28,5,0,25,25,25,0,25,25,25,5,28,28
28,28,5,0,0,0,0,0,0,0,0,5,28,28
28,28,5,0,0,0,0,0,0,0,0,5,28,28
28,28,5,5,0,0,0,0,0,5,0,5,28,28
28,28,5,5,5,5,0,0,5,5,5,5,28,28
28,28,5,5,5,5,5,5,5,5,5,5,28,28
1,1,1,1,1,1,1,1,1,1,1,1,1,1
endlayer

layer
28,28,28,28,28,28,28,28,28,28,28,28,28,28
28,28,28,28,28,28,28,28,28,28,28,28,28,28
28,28,28,28,28,28,28,28,28,28,28,28,28,28
28,28,28,28,28,28,28,28,28,28,28,28,28,28
28,28,28,28,28,28,28,28,28,28,28,28,28,28
28,28,28,28,28,28,28,28,28,28,28,28,28,28
28,28,28,28,28,28,28,28,28,28,28,28,28,28
28,28,5,5,8,8,8,5,5,5,5,5,28,28
28,28,5,5,16,16,0,0,16,16,5,5,28,28
28,28,8,5,0,0,5,5,0,0,8,5,28,28
28,28,5,25,0,0,25,25,25,25,25,5,28,28
28,28,5,0,0,0,0,0,0,0,0,5,28,28
28,28,5,0,0,0,0,0,0,0,0,5,28,28
28,28,5,0,0,0,0,0,0,0,0,5,28,28
28,28,5,5,0,0,0,0,0,0,5,5,28,28
28,28,5,5,5,5,0,0,5,5,5,5,28,28
28,28,5,5,5,5,5,5,5,5,5,5,28,28
endlayer

layer
28,28,28,28,28,28,28,28,28,28,28,28,28,28
28,28,28,28,28,28,28,28,28,28,28,28,28,28
28,28,28,28,28,28,28,28,28,28,28,28,28,28
28,28,28,28,28,28,28,28,28,28,28,28,28,28
28,28,28,28,28,28,28,28,28,28,28,28,28,28
28,28,28,28,28,28,28,28,28,28,28,28,28,28
28,28,28,28,28,28,28,28,28,28,28,28,28,28
28,28,5,5,5,5,5,5,5,5,5,5,28,28
28,28,5,0,16,16,0,0,16,16,5,5,28,28
28,28,5,8,0,0,8,5,0,0,5,8,28,28
0,0,25,25,0,0,25,25,25,25,25,25,0,0
0,0,0,0,0,0,0,0,0,0,0,0,0,0
0,0,0,0,0,0,0,0,0,0,0,0,0,0
0,0,0,0,0,0,0,0,0,0,0,0,0,0
0,0,0,0,0,0,0,0,0,0,0,0,0,0
0,0,0,0,0,0,0,0,0,0,0,0,0,0
0,0,0,0,0,0,0,0,0,0,0,0,0,0
endlayer

layer
0,0,0,0,0,0,0,0,0,0,0,0,0,0
0,0,0,0,0,0,0,0,0,0,0,0,0,0
0,0,0,0,0,0,0,0,0,0,0,0,0,0
0,0,0,0,0,0,0,0,0,0,0,0,0,0
0,0,0,0,0,0,0,0,0,0,0,0,0,0
0,0,0,0,0,0,0,0,0,0,0,0,0,0
0,0,0,0,21,0,0,0,0,0,21,0,0,0
0,0,5,5,5,5,5,5,5,5,5,5,0,0
0,14,5,5,5,5,5,5,5,5,5,5,20,0
0,14,5,5,5,5,5,5,5,5,5,8,20,0
0,0,25,25,25,25,25,25,25,25,25,0,0,0
0,0,0,0,0,0,0,0,0,0,0,0,0,0
0,0,0,0,0,0,0,0,0,0,0,0,0,0
0,0,0,0,0,0,0,0,0,0,0,0,0,0
0,0,0,0,0,0,0,0,0,0,0,0,0,0
0,0,0,0,0,0,0,0,0,0,0,0,0,0
0,0,0,0,0,0,0,0,0,0,0,0,0,0
endlayer

