weight=80
acceptable_target_blocks=1,2,3,12,13,24,162,163,164,165,166,167,168,169,170,171,172,254,255
embed_into_distance=1
dimensions=70,16,16
max_leveling=4
leveling_buffer=0
max_cut_in=25
preserve_plants=1

#outer column
rule1=1,90,48,48,48,48,48,48,48,48,48,48,48,48,48,48,48,48,48,48,48,48,48,48,48,48,48,48,48,48,48,48,48,48,48,48,48,48,48,48,48,48,48,48,48,48,48,48,48,48,48,48,48,48,48,48,48,48,48,48,48,48,48,48,48,48,48,48,48,48,48,48,48,48,48,48,48,48,48,48,48,48,48,48,48,48,48,48,1,1,1,1,1,1,1,1,1,1,1,1,1,1,1,1,1,1,1,1,1,15
#floors
rule2=2,68,48,48,48,48,48,48,48,48,48,48,48,48,48,48,48,48,48,48,48,48,48,48,48,48,48,48,48,48,48,48,48,48,48,48,48,48,48,48,48,48,48,48,48,48,48,48,48,48,48,48,48,48,48,48,48,48,48,48,48,48,48,48,48,48,48,48,48,48,48,48,48,48,48,1,1,1,1,1,1,1,1,1,1,1,1,1,1,1,1,1,1,15
#inner structure
rule3=1,96,48,48,48,48,48,48,48,48,48,48,48,48,48,48,48,48,48,48,48,48,48,48,48,48,48,48,48,48,48,48,48,48,48,48,48,48,48,48,48,48,48,48,48,48,48,48,48,48,48,48,48,48,48,48,48,48,48,48,48,48,48,48,48,48,48,48,48,48,48,48,48,48,48,48,48,48,48,48,48,48,48,48,48,48,48,1,1,1,1,1,1,1,1,1,1,1,1,1,1,1,1,1,1,1,1,1,1,15,73
#optional fill up to 3rd story
rule4=0,0,35-14
#ladder
rule5=2,50,65-4


layer
1,2,2,2,2,1,2,2,2,2,1,2,2,2,2,1
2,2,2,2,2,2,2,2,2,2,2,2,2,2,2,2
2,2,2,2,2,2,2,2,2,2,2,2,2,2,2,2
2,2,2,3,2,2,2,2,2,2,2,2,3,2,2,2
2,2,2,2,2,2,2,2,2,2,2,2,2,2,2,2
1,2,2,2,2,2,2,2,2,2,2,2,2,2,2,1
2,2,2,2,2,2,3,3,3,3,2,2,2,2,2,2
2,2,2,2,2,2,2,0,0,2,2,2,2,2,2,2
2,2,2,2,2,2,2,0,0,2,2,2,2,2,2,2
2,2,2,2,2,2,3,3,3,3,2,2,2,2,2,2
1,2,2,2,2,2,2,2,2,2,2,2,2,2,2,1
2,2,2,2,2,2,2,2,2,2,2,2,2,2,2,2
2,2,2,3,2,2,2,2,2,2,2,2,3,2,2,2
2,2,2,2,2,2,2,2,2,2,2,2,2,2,2,2
2,2,2,2,2,2,2,2,2,2,2,2,2,2,2,2
1,2,2,2,2,1,2,2,2,2,1,2,2,2,2,1
endlayer

layer
1,4,4,4,4,1,4,4,4,4,1,4,4,4,4,1
4,4,4,4,4,4,4,4,4,4,4,4,4,4,4,4
4,4,4,4,4,4,4,4,4,4,4,4,4,4,4,4
4,4,4,3,4,4,4,4,4,4,4,4,3,4,4,4
4,4,4,4,4,4,4,4,4,4,4,4,4,4,4,4
1,4,4,4,4,4,4,4,4,4,4,4,4,4,4,1
4,4,4,4,4,4,3,3,3,3,4,4,4,4,4,4
4,4,4,4,4,4,4,0,0,4,4,4,4,4,4,4
4,4,4,4,4,4,4,5,0,4,4,4,4,4,4,4
4,4,4,4,4,4,3,3,3,3,4,4,4,4,4,4
1,4,4,4,4,4,4,4,4,4,4,4,4,4,4,1
4,4,4,4,4,4,4,4,4,4,4,4,4,4,4,4
4,4,4,3,4,4,4,4,4,4,4,4,3,4,4,4
4,4,4,4,4,4,4,4,4,4,4,4,4,4,4,4
4,4,4,4,4,4,4,4,4,4,4,4,4,4,4,4
1,4,4,4,4,1,4,4,4,4,1,4,4,4,4,1
endlayer

layer
1,4,4,4,4,1,4,4,4,4,1,4,4,4,4,1
4,4,4,4,4,4,4,4,4,4,4,4,4,4,4,4
4,4,4,4,4,4,4,4,4,4,4,4,4,4,4,4
4,4,4,3,4,4,4,4,4,4,4,4,3,4,4,4
4,4,4,4,4,4,4,4,4,4,4,4,4,4,4,4
1,4,4,4,4,4,4,4,4,4,4,4,4,4,4,1
4,4,4,4,4,4,3,3,3,3,4,4,4,4,4,4
4,4,4,4,4,4,4,0,0,4,4,4,4,4,4,4
4,4,4,4,4,4,4,5,0,4,4,4,4,4,4,4
4,4,4,4,4,4,3,3,3,3,4,4,4,4,4,4
1,4,4,4,4,4,4,4,4,4,4,4,4,4,4,1
4,4,4,4,4,4,4,4,4,4,4,4,4,4,4,4
4,4,4,3,4,4,4,4,4,4,4,4,3,4,4,4
4,4,4,4,4,4,4,4,4,4,4,4,4,4,4,4
4,4,4,4,4,4,4,4,4,4,4,4,4,4,4,4
1,4,4,4,4,1,4,4,4,4,1,4,4,4,4,1
endlayer

layer
1,4,4,4,4,1,4,4,4,4,1,4,4,4,4,1
4,4,4,4,4,4,4,4,4,4,4,4,4,4,4,4
4,4,4,4,4,4,4,4,4,4,4,4,4,4,4,4
4,4,4,3,4,4,4,4,4,4,4,4,3,4,4,4
4,4,4,4,4,4,4,4,4,4,4,4,4,4,4,4
1,4,4,4,4,4,4,4,4,4,4,4,4,4,4,1
4,4,4,4,4,4,3,3,3,3,4,4,4,4,4,4
4,4,4,4,4,4,4,0,0,4,4,4,4,4,4,4
4,4,4,4,4,4,4,5,0,4,4,4,4,4,4,4
4,4,4,4,4,4,3,3,3,3,4,4,4,4,4,4
1,4,4,4,4,4,4,4,4,4,4,4,4,4,4,1
4,4,4,4,4,4,4,4,4,4,4,4,4,4,4,4
4,4,4,3,4,4,4,4,4,4,4,4,3,4,4,4
4,4,4,4,4,4,4,4,4,4,4,4,4,4,4,4
4,4,4,4,4,4,4,4,4,4,4,4,4,4,4,4
1,4,4,4,4,1,4,4,4,4,1,4,4,4,4,1
endlayer

layer
1,2,2,2,2,1,2,2,2,2,1,2,2,2,2,1
2,2,2,2,2,2,2,2,2,2,2,2,2,2,2,2
2,2,2,2,2,2,2,2,2,2,2,2,2,2,2,2
2,2,2,3,2,2,2,2,2,2,2,2,3,2,2,2
2,2,2,2,2,2,2,2,2,2,2,2,2,2,2,2
1,2,2,2,2,2,2,2,2,2,2,2,2,2,2,1
2,2,2,2,2,2,3,3,3,3,2,2,2,2,2,2
2,2,2,2,2,2,2,0,0,2,2,2,2,2,2,2
2,2,2,2,2,2,2,5,0,2,2,2,2,2,2,2
2,2,2,2,2,2,3,3,3,3,2,2,2,2,2,2
1,2,2,2,2,2,2,2,2,2,2,2,2,2,2,1
2,2,2,2,2,2,2,2,2,2,2,2,2,2,2,2
2,2,2,3,2,2,2,2,2,2,2,2,3,2,2,2
2,2,2,2,2,2,2,2,2,2,2,2,2,2,2,2
2,2,2,2,2,2,2,2,2,2,2,2,2,2,2,2
1,2,2,2,2,1,2,2,2,2,1,2,2,2,2,1
endlayer

layer
1,4,4,4,4,1,4,4,4,4,1,4,4,4,4,1
4,4,4,4,4,4,4,4,4,4,4,4,4,4,4,4
4,4,4,4,4,4,4,4,4,4,4,4,4,4,4,4
4,4,4,3,4,4,4,4,4,4,4,4,3,4,4,4
4,4,4,4,4,4,4,4,4,4,4,4,4,4,4,4
1,4,4,4,4,4,4,4,4,4,4,4,4,4,4,1
4,4,4,4,4,4,3,3,3,3,4,4,4,4,4,4
4,4,4,4,4,4,4,0,0,4,4,4,4,4,4,4
4,4,4,4,4,4,4,5,0,4,4,4,4,4,4,4
4,4,4,4,4,4,3,3,3,3,4,4,4,4,4,4
1,4,4,4,4,4,4,4,4,4,4,4,4,4,4,1
4,4,4,4,4,4,4,4,4,4,4,4,4,4,4,4
4,4,4,3,4,4,4,4,4,4,4,4,3,4,4,4
4,4,4,4,4,4,4,4,4,4,4,4,4,4,4,4
4,4,4,4,4,4,4,4,4,4,4,4,4,4,4,4
1,4,4,4,4,1,4,4,4,4,1,4,4,4,4,1
endlayer

layer
1,4,4,4,4,1,4,4,4,4,1,4,4,4,4,1
4,4,4,4,4,4,4,4,4,4,4,4,4,4,4,4
4,4,4,4,4,4,4,4,4,4,4,4,4,4,4,4
4,4,4,3,4,4,4,4,4,4,4,4,3,4,4,4
4,4,4,4,4,4,4,4,4,4,4,4,4,4,4,4
1,4,4,4,4,4,4,4,4,4,4,4,4,4,4,1
4,4,4,4,4,4,3,3,3,3,4,4,4,4,4,4
4,4,4,4,4,4,4,0,0,4,4,4,4,4,4,4
4,4,4,4,4,4,4,5,0,4,4,4,4,4,4,4
4,4,4,4,4,4,3,3,3,3,4,4,4,4,4,4
1,4,4,4,4,4,4,4,4,4,4,4,4,4,4,1
4,4,4,4,4,4,4,4,4,4,4,4,4,4,4,4
4,4,4,3,4,4,4,4,4,4,4,4,3,4,4,4
4,4,4,4,4,4,4,4,4,4,4,4,4,4,4,4
4,4,4,4,4,4,4,4,4,4,4,4,4,4,4,4
1,4,4,4,4,1,4,4,4,4,1,4,4,4,4,1
endlayer

layer
1,4,4,4,4,1,4,4,4,4,1,4,4,4,4,1
4,4,4,4,4,4,4,4,4,4,4,4,4,4,4,4
4,4,4,4,4,4,4,4,4,4,4,4,4,4,4,4
4,4,4,3,4,4,4,4,4,4,4,4,3,4,4,4
4,4,4,4,4,4,4,4,4,4,4,4,4,4,4,4
1,4,4,4,4,4,4,4,4,4,4,4,4,4,4,1
4,4,4,4,4,4,3,3,3,3,4,4,4,4,4,4
4,4,4,4,4,4,4,0,0,4,4,4,4,4,4,4
4,4,4,4,4,4,4,5,0,4,4,4,4,4,4,4
4,4,4,4,4,4,3,3,3,3,4,4,4,4,4,4
1,4,4,4,4,4,4,4,4,4,4,4,4,4,4,1
4,4,4,4,4,4,4,4,4,4,4,4,4,4,4,4
4,4,4,3,4,4,4,4,4,4,4,4,3,4,4,4
4,4,4,4,4,4,4,4,4,4,4,4,4,4,4,4
4,4,4,4,4,4,4,4,4,4,4,4,4,4,4,4
1,4,4,4,4,1,4,4,4,4,1,4,4,4,4,1
endlayer

layer
1,2,2,2,2,1,2,2,2,2,1,2,2,2,2,1
2,2,2,2,2,2,2,2,2,2,2,2,2,2,2,2
2,2,2,2,2,2,2,2,2,2,2,2,2,2,2,2
2,2,2,3,2,2,2,2,2,2,2,2,3,2,2,2
2,2,2,2,2,2,2,2,2,2,2,2,2,2,2,2
1,2,2,2,2,2,2,2,2,2,2,2,2,2,2,1
2,2,2,2,2,2,3,3,3,3,2,2,2,2,2,2
2,2,2,2,2,2,2,0,0,2,2,2,2,2,2,2
2,2,2,2,2,2,2,5,0,2,2,2,2,2,2,2
2,2,2,2,2,2,3,3,3,3,2,2,2,2,2,2
1,2,2,2,2,2,2,2,2,2,2,2,2,2,2,1
2,2,2,2,2,2,2,2,2,2,2,2,2,2,2,2
2,2,2,3,2,2,2,2,2,2,2,2,3,2,2,2
2,2,2,2,2,2,2,2,2,2,2,2,2,2,2,2
2,2,2,2,2,2,2,2,2,2,2,2,2,2,2,2
1,2,2,2,2,1,2,2,2,2,1,2,2,2,2,1
endlayer

layer
1,4,4,4,4,1,4,4,4,4,1,4,4,4,4,1
4,4,4,4,4,4,4,4,4,4,4,4,4,4,4,4
4,4,4,4,4,4,4,4,4,4,4,4,4,4,4,4
4,4,4,3,4,4,4,4,4,4,4,4,3,4,4,4
4,4,4,4,4,4,4,4,4,4,4,4,4,4,4,4
1,4,4,4,4,4,4,4,4,4,4,4,4,4,4,1
4,4,4,4,4,4,3,3,3,3,4,4,4,4,4,4
4,4,4,4,4,4,4,0,0,4,4,4,4,4,4,4
4,4,4,4,4,4,4,5,0,4,4,4,4,4,4,4
4,4,4,4,4,4,3,3,3,3,4,4,4,4,4,4
1,4,4,4,4,4,4,4,4,4,4,4,4,4,4,1
4,4,4,4,4,4,4,4,4,4,4,4,4,4,4,4
4,4,4,3,4,4,4,4,4,4,4,4,3,4,4,4
4,4,4,4,4,4,4,4,4,4,4,4,4,4,4,4
4,4,4,4,4,4,4,4,4,4,4,4,4,4,4,4
1,4,4,4,4,1,4,4,4,4,1,4,4,4,4,1
endlayer

layer
1,4,4,4,4,1,4,4,4,4,1,4,4,4,4,1
4,4,4,4,4,4,4,4,4,4,4,4,4,4,4,4
4,4,4,4,4,4,4,4,4,4,4,4,4,4,4,4
4,4,4,3,4,4,4,4,4,4,4,4,3,4,4,4
4,4,4,4,4,4,4,4,4,4,4,4,4,4,4,4
1,4,4,4,4,4,4,4,4,4,4,4,4,4,4,1
4,4,4,4,4,4,3,3,3,3,4,4,4,4,4,4
4,4,4,4,4,4,4,0,0,4,4,4,4,4,4,4
4,4,4,4,4,4,4,5,0,4,4,4,4,4,4,4
4,4,4,4,4,4,3,3,3,3,4,4,4,4,4,4
1,4,4,4,4,4,4,4,4,4,4,4,4,4,4,1
4,4,4,4,4,4,4,4,4,4,4,4,4,4,4,4
4,4,4,3,4,4,4,4,4,4,4,4,3,4,4,4
4,4,4,4,4,4,4,4,4,4,4,4,4,4,4,4
4,4,4,4,4,4,4,4,4,4,4,4,4,4,4,4
1,4,4,4,4,1,4,4,4,4,1,4,4,4,4,1
endlayer

layer
1,4,4,4,4,1,4,4,4,4,1,4,4,4,4,1
4,4,4,4,4,4,4,4,4,4,4,4,4,4,4,4
4,4,4,4,4,4,4,4,4,4,4,4,4,4,4,4
4,4,4,3,4,4,4,4,4,4,4,4,3,4,4,4
4,4,4,4,4,4,4,4,4,4,4,4,4,4,4,4
1,4,4,4,4,4,4,4,4,4,4,4,4,4,4,1
4,4,4,4,4,4,3,3,3,3,4,4,4,4,4,4
4,4,4,4,4,4,4,0,0,4,4,4,4,4,4,4
4,4,4,4,4,4,4,5,0,4,4,4,4,4,4,4
4,4,4,4,4,4,3,3,3,3,4,4,4,4,4,4
1,4,4,4,4,4,4,4,4,4,4,4,4,4,4,1
4,4,4,4,4,4,4,4,4,4,4,4,4,4,4,4
4,4,4,3,4,4,4,4,4,4,4,4,3,4,4,4
4,4,4,4,4,4,4,4,4,4,4,4,4,4,4,4
4,4,4,4,4,4,4,4,4,4,4,4,4,4,4,4
1,4,4,4,4,1,4,4,4,4,1,4,4,4,4,1
endlayer

layer
1,2,2,2,2,1,2,2,2,2,1,2,2,2,2,1
2,2,2,2,2,2,2,2,2,2,2,2,2,2,2,2
2,2,2,2,2,2,2,2,2,2,2,2,2,2,2,2
2,2,2,3,2,2,2,2,2,2,2,2,3,2,2,2
2,2,2,2,2,2,2,2,2,2,2,2,2,2,2,2
1,2,2,2,2,2,2,2,2,2,2,2,2,2,2,1
2,2,2,2,2,2,3,3,3,3,2,2,2,2,2,2
2,2,2,2,2,2,2,0,0,2,2,2,2,2,2,2
2,2,2,2,2,2,2,5,0,2,2,2,2,2,2,2
2,2,2,2,2,2,3,3,3,3,2,2,2,2,2,2
1,2,2,2,2,2,2,2,2,2,2,2,2,2,2,1
2,2,2,2,2,2,2,2,2,2,2,2,2,2,2,2
2,2,2,3,2,2,2,2,2,2,2,2,3,2,2,2
2,2,2,2,2,2,2,2,2,2,2,2,2,2,2,2
2,2,2,2,2,2,2,2,2,2,2,2,2,2,2,2
1,2,2,2,2,1,2,2,2,2,1,2,2,2,2,1
endlayer

layer
1,0,0,0,0,1,0,0,0,0,1,0,0,0,0,1
0,0,0,0,0,0,0,0,0,0,0,0,0,0,0,0
0,0,0,0,0,0,0,0,0,0,0,0,0,0,0,0
0,0,0,3,0,0,0,0,0,0,0,0,3,0,0,0
0,0,0,0,0,0,0,0,0,0,0,0,0,0,0,0
1,0,0,0,0,0,0,0,0,0,0,0,0,0,0,1
0,0,0,0,0,0,3,3,3,3,0,0,0,0,0,0
0,0,0,0,0,0,0,0,0,0,0,0,0,0,0,0
0,0,0,0,0,0,0,5,0,0,0,0,0,0,0,0
0,0,0,0,0,0,3,3,3,3,0,0,0,0,0,0
1,0,0,0,0,0,0,0,0,0,0,0,0,0,0,1
0,0,0,0,0,0,0,0,0,0,0,0,0,0,0,0
0,0,0,3,0,0,0,0,0,0,0,0,3,0,0,0
0,0,0,0,0,0,0,0,0,0,0,0,0,0,0,0
0,0,0,0,0,0,0,0,0,0,0,0,0,0,0,0
1,0,0,0,0,1,0,0,0,0,1,0,0,0,0,1
endlayer

layer
1,0,0,0,0,1,0,0,0,0,1,0,0,0,0,1
0,0,0,0,0,0,0,0,0,0,0,0,0,0,0,0
0,0,0,0,0,0,0,0,0,0,0,0,0,0,0,0
0,0,0,3,0,0,0,0,0,0,0,0,3,0,0,0
0,0,0,0,0,0,0,0,0,0,0,0,0,0,0,0
1,0,0,0,0,0,0,0,0,0,0,0,0,0,0,1
0,0,0,0,0,0,3,3,3,3,0,0,0,0,0,0
0,0,0,0,0,0,0,0,0,0,0,0,0,0,0,0
0,0,0,0,0,0,0,5,0,0,0,0,0,0,0,0
0,0,0,0,0,0,3,3,3,3,0,0,0,0,0,0
1,0,0,0,0,0,0,0,0,0,0,0,0,0,0,1
0,0,0,0,0,0,0,0,0,0,0,0,0,0,0,0
0,0,0,3,0,0,0,0,0,0,0,0,3,0,0,0
0,0,0,0,0,0,0,0,0,0,0,0,0,0,0,0
0,0,0,0,0,0,0,0,0,0,0,0,0,0,0,0
1,0,0,0,0,1,0,0,0,0,1,0,0,0,0,1
endlayer

layer
1,0,0,0,0,1,0,0,0,0,1,0,0,0,0,1
0,0,0,0,0,0,0,0,0,0,0,0,0,0,0,0
0,0,0,0,0,0,0,0,0,0,0,0,0,0,0,0
0,0,0,3,0,0,0,0,0,0,0,0,3,0,0,0
0,0,0,0,0,0,0,0,0,0,0,0,0,0,0,0
1,0,0,0,0,0,0,0,0,0,0,0,0,0,0,1
0,0,0,0,0,0,3,3,3,3,0,0,0,0,0,0
0,0,0,0,0,0,0,0,0,0,0,0,0,0,0,0
0,0,0,0,0,0,0,5,0,0,0,0,0,0,0,0
0,0,0,0,0,0,3,3,3,3,0,0,0,0,0,0
1,0,0,0,0,0,0,0,0,0,0,0,0,0,0,1
0,0,0,0,0,0,0,0,0,0,0,0,0,0,0,0
0,0,0,3,0,0,0,0,0,0,0,0,3,0,0,0
0,0,0,0,0,0,0,0,0,0,0,0,0,0,0,0
0,0,0,0,0,0,0,0,0,0,0,0,0,0,0,0
1,0,0,0,0,1,0,0,0,0,1,0,0,0,0,1
endlayer

layer
1,2,2,2,2,1,2,2,2,2,1,2,2,2,2,1
2,2,2,2,2,2,2,2,2,2,2,2,2,2,2,2
2,2,2,2,2,2,2,2,2,2,2,2,2,2,2,2
2,2,2,3,2,2,2,2,2,2,2,2,3,2,2,2
2,2,2,2,2,2,2,2,2,2,2,2,2,2,2,2
1,2,2,2,2,2,2,2,2,2,2,2,2,2,2,1
2,2,2,2,2,2,3,3,3,3,2,2,2,2,2,2
2,2,2,2,2,2,2,0,0,2,2,2,2,2,2,2
2,2,2,2,2,2,2,5,0,2,2,2,2,2,2,2
2,2,2,2,2,2,3,3,3,3,2,2,2,2,2,2
1,2,2,2,2,2,2,2,2,2,2,2,2,2,2,1
2,2,2,2,2,2,2,2,2,2,2,2,2,2,2,2
2,2,2,3,2,2,2,2,2,2,2,2,3,2,2,2
2,2,2,2,2,2,2,2,2,2,2,2,2,2,2,2
2,2,2,2,2,2,2,2,2,2,2,2,2,2,2,2
1,2,2,2,2,1,2,2,2,2,1,2,2,2,2,1
endlayer

layer
1,0,0,0,0,1,0,0,0,0,1,0,0,0,0,1
0,0,0,0,0,0,0,0,0,0,0,0,0,0,0,0
0,0,0,0,0,0,0,0,0,0,0,0,0,0,0,0
0,0,0,3,0,0,0,0,0,0,0,0,3,0,0,0
0,0,0,0,0,0,0,0,0,0,0,0,0,0,0,0
1,0,0,0,0,0,0,0,0,0,0,0,0,0,0,1
0,0,0,0,0,0,3,3,3,3,0,0,0,0,0,0
0,0,0,0,0,0,0,0,0,0,0,0,0,0,0,0
0,0,0,0,0,0,0,5,0,0,0,0,0,0,0,0
0,0,0,0,0,0,3,3,3,3,0,0,0,0,0,0
1,0,0,0,0,0,0,0,0,0,0,0,0,0,0,1
0,0,0,0,0,0,0,0,0,0,0,0,0,0,0,0
0,0,0,3,0,0,0,0,0,0,0,0,3,0,0,0
0,0,0,0,0,0,0,0,0,0,0,0,0,0,0,0
0,0,0,0,0,0,0,0,0,0,0,0,0,0,0,0
1,0,0,0,0,1,0,0,0,0,1,0,0,0,0,1
endlayer

layer
1,0,0,0,0,1,0,0,0,0,1,0,0,0,0,1
0,0,0,0,0,0,0,0,0,0,0,0,0,0,0,0
0,0,0,0,0,0,0,0,0,0,0,0,0,0,0,0
0,0,0,3,0,0,0,0,0,0,0,0,3,0,0,0
0,0,0,0,0,0,0,0,0,0,0,0,0,0,0,0
1,0,0,0,0,0,0,0,0,0,0,0,0,0,0,1
0,0,0,0,0,0,3,3,3,3,0,0,0,0,0,0
0,0,0,0,0,0,0,0,0,0,0,0,0,0,0,0
0,0,0,0,0,0,0,5,0,0,0,0,0,0,0,0
0,0,0,0,0,0,3,3,3,3,0,0,0,0,0,0
1,0,0,0,0,0,0,0,0,0,0,0,0,0,0,1
0,0,0,0,0,0,0,0,0,0,0,0,0,0,0,0
0,0,0,3,0,0,0,0,0,0,0,0,3,0,0,0
0,0,0,0,0,0,0,0,0,0,0,0,0,0,0,0
0,0,0,0,0,0,0,0,0,0,0,0,0,0,0,0
1,0,0,0,0,1,0,0,0,0,1,0,0,0,0,1
endlayer

layer
1,0,0,0,0,1,0,0,0,0,1,0,0,0,0,1
0,0,0,0,0,0,0,0,0,0,0,0,0,0,0,0
0,0,0,0,0,0,0,0,0,0,0,0,0,0,0,0
0,0,0,3,0,0,0,0,0,0,0,0,3,0,0,0
0,0,0,0,0,0,0,0,0,0,0,0,0,0,0,0
1,0,0,0,0,0,0,0,0,0,0,0,0,0,0,1
0,0,0,0,0,0,3,3,3,3,0,0,0,0,0,0
0,0,0,0,0,0,0,0,0,0,0,0,0,0,0,0
0,0,0,0,0,0,0,5,0,0,0,0,0,0,0,0
0,0,0,0,0,0,3,3,3,3,0,0,0,0,0,0
1,0,0,0,0,0,0,0,0,0,0,0,0,0,0,1
0,0,0,0,0,0,0,0,0,0,0,0,0,0,0,0
0,0,0,3,0,0,0,0,0,0,0,0,3,0,0,0
0,0,0,0,0,0,0,0,0,0,0,0,0,0,0,0
0,0,0,0,0,0,0,0,0,0,0,0,0,0,0,0
1,0,0,0,0,1,0,0,0,0,1,0,0,0,0,1
endlayer

layer
1,2,2,2,2,1,2,2,2,2,1,2,2,2,2,1
2,2,2,2,2,2,2,2,2,2,2,2,2,2,2,2
2,2,2,2,2,2,2,2,2,2,2,2,2,2,2,2
2,2,2,3,2,2,2,2,2,2,2,2,3,2,2,2
2,2,2,2,2,2,2,2,2,2,2,2,2,2,2,2
1,2,2,2,2,2,2,2,2,2,2,2,2,2,2,1
2,2,2,2,2,2,3,3,3,3,2,2,2,2,2,2
2,2,2,2,2,2,2,0,0,2,2,2,2,2,2,2
2,2,2,2,2,2,2,5,0,2,2,2,2,2,2,2
2,2,2,2,2,2,3,3,3,3,2,2,2,2,2,2
1,2,2,2,2,2,2,2,2,2,2,2,2,2,2,1
2,2,2,2,2,2,2,2,2,2,2,2,2,2,2,2
2,2,2,3,2,2,2,2,2,2,2,2,3,2,2,2
2,2,2,2,2,2,2,2,2,2,2,2,2,2,2,2
2,2,2,2,2,2,2,2,2,2,2,2,2,2,2,2
1,2,2,2,2,1,2,2,2,2,1,2,2,2,2,1
endlayer

layer
1,0,0,0,0,1,0,0,0,0,1,0,0,0,0,1
0,0,0,0,0,0,0,0,0,0,0,0,0,0,0,0
0,0,0,0,0,0,0,0,0,0,0,0,0,0,0,0
0,0,0,3,0,0,0,0,0,0,0,0,3,0,0,0
0,0,0,0,0,0,0,0,0,0,0,0,0,0,0,0
1,0,0,0,0,0,0,0,0,0,0,0,0,0,0,1
0,0,0,0,0,0,3,3,3,3,0,0,0,0,0,0
0,0,0,0,0,0,0,0,0,0,0,0,0,0,0,0
0,0,0,0,0,0,0,5,0,0,0,0,0,0,0,0
0,0,0,0,0,0,3,3,3,3,0,0,0,0,0,0
1,0,0,0,0,0,0,0,0,0,0,0,0,0,0,1
0,0,0,0,0,0,0,0,0,0,0,0,0,0,0,0
0,0,0,3,0,0,0,0,0,0,0,0,3,0,0,0
0,0,0,0,0,0,0,0,0,0,0,0,0,0,0,0
0,0,0,0,0,0,0,0,0,0,0,0,0,0,0,0
1,0,0,0,0,1,0,0,0,0,1,0,0,0,0,1
endlayer

layer
1,0,0,0,0,1,0,0,0,0,1,0,0,0,0,1
0,0,0,0,0,0,0,0,0,0,0,0,0,0,0,0
0,0,0,0,0,0,0,0,0,0,0,0,0,0,0,0
0,0,0,3,0,0,0,0,0,0,0,0,3,0,0,0
0,0,0,0,0,0,0,0,0,0,0,0,0,0,0,0
1,0,0,0,0,0,0,0,0,0,0,0,0,0,0,1
0,0,0,0,0,0,3,3,3,3,0,0,0,0,0,0
0,0,0,0,0,0,0,0,0,0,0,0,0,0,0,0
0,0,0,0,0,0,0,5,0,0,0,0,0,0,0,0
0,0,0,0,0,0,3,3,3,3,0,0,0,0,0,0
1,0,0,0,0,0,0,0,0,0,0,0,0,0,0,1
0,0,0,0,0,0,0,0,0,0,0,0,0,0,0,0
0,0,0,3,0,0,0,0,0,0,0,0,3,0,0,0
0,0,0,0,0,0,0,0,0,0,0,0,0,0,0,0
0,0,0,0,0,0,0,0,0,0,0,0,0,0,0,0
1,0,0,0,0,1,0,0,0,0,1,0,0,0,0,1
endlayer

layer
1,0,0,0,0,1,0,0,0,0,1,0,0,0,0,1
0,0,0,0,0,0,0,0,0,0,0,0,0,0,0,0
0,0,0,0,0,0,0,0,0,0,0,0,0,0,0,0
0,0,0,3,0,0,0,0,0,0,0,0,3,0,0,0
0,0,0,0,0,0,0,0,0,0,0,0,0,0,0,0
1,0,0,0,0,0,0,0,0,0,0,0,0,0,0,1
0,0,0,0,0,0,3,3,3,3,0,0,0,0,0,0
0,0,0,0,0,0,0,0,0,0,0,0,0,0,0,0
0,0,0,0,0,0,0,5,0,0,0,0,0,0,0,0
0,0,0,0,0,0,3,3,3,3,0,0,0,0,0,0
1,0,0,0,0,0,0,0,0,0,0,0,0,0,0,1
0,0,0,0,0,0,0,0,0,0,0,0,0,0,0,0
0,0,0,3,0,0,0,0,0,0,0,0,3,0,0,0
0,0,0,0,0,0,0,0,0,0,0,0,0,0,0,0
0,0,0,0,0,0,0,0,0,0,0,0,0,0,0,0
1,0,0,0,0,1,0,0,0,0,1,0,0,0,0,1
endlayer

layer
1,2,2,2,2,1,2,2,2,2,1,2,2,2,2,1
2,2,2,2,2,2,2,2,2,2,2,2,2,2,2,2
2,2,2,2,2,2,2,2,2,2,2,2,2,2,2,2
2,2,2,3,2,2,2,2,2,2,2,2,3,2,2,2
2,2,2,2,2,2,2,2,2,2,2,2,2,2,2,2
1,2,2,2,2,2,2,2,2,2,2,2,2,2,2,1
2,2,2,2,2,2,3,3,3,3,2,2,2,2,2,2
2,2,2,2,2,2,2,0,0,2,2,2,2,2,2,2
2,2,2,2,2,2,2,5,0,2,2,2,2,2,2,2
2,2,2,2,2,2,3,3,3,3,2,2,2,2,2,2
1,2,2,2,2,2,2,2,2,2,2,2,2,2,2,1
2,2,2,2,2,2,2,2,2,2,2,2,2,2,2,2
2,2,2,3,2,2,2,2,2,2,2,2,3,2,2,2
2,2,2,2,2,2,2,2,2,2,2,2,2,2,2,2
2,2,2,2,2,2,2,2,2,2,2,2,2,2,2,2
1,2,2,2,2,1,2,2,2,2,1,2,2,2,2,1
endlayer

layer
1,0,0,0,0,1,0,0,0,0,1,0,0,0,0,1
0,0,0,0,0,0,0,0,0,0,0,0,0,0,0,0
0,0,0,0,0,0,0,0,0,0,0,0,0,0,0,0
0,0,0,3,0,0,0,0,0,0,0,0,3,0,0,0
0,0,0,0,0,0,0,0,0,0,0,0,0,0,0,0
1,0,0,0,0,0,0,0,0,0,0,0,0,0,0,1
0,0,0,0,0,0,3,3,3,3,0,0,0,0,0,0
0,0,0,0,0,0,0,0,0,0,0,0,0,0,0,0
0,0,0,0,0,0,0,5,0,0,0,0,0,0,0,0
0,0,0,0,0,0,3,3,3,3,0,0,0,0,0,0
1,0,0,0,0,0,0,0,0,0,0,0,0,0,0,1
0,0,0,0,0,0,0,0,0,0,0,0,0,0,0,0
0,0,0,3,0,0,0,0,0,0,0,0,3,0,0,0
0,0,0,0,0,0,0,0,0,0,0,0,0,0,0,0
0,0,0,0,0,0,0,0,0,0,0,0,0,0,0,0
1,0,0,0,0,1,0,0,0,0,1,0,0,0,0,1
endlayer

layer
1,0,0,0,0,1,0,0,0,0,1,0,0,0,0,1
0,0,0,0,0,0,0,0,0,0,0,0,0,0,0,0
0,0,0,0,0,0,0,0,0,0,0,0,0,0,0,0
0,0,0,3,0,0,0,0,0,0,0,0,3,0,0,0
0,0,0,0,0,0,0,0,0,0,0,0,0,0,0,0
1,0,0,0,0,0,0,0,0,0,0,0,0,0,0,1
0,0,0,0,0,0,3,3,3,3,0,0,0,0,0,0
0,0,0,0,0,0,0,0,0,0,0,0,0,0,0,0
0,0,0,0,0,0,0,5,0,0,0,0,0,0,0,0
0,0,0,0,0,0,3,3,3,3,0,0,0,0,0,0
1,0,0,0,0,0,0,0,0,0,0,0,0,0,0,1
0,0,0,0,0,0,0,0,0,0,0,0,0,0,0,0
0,0,0,3,0,0,0,0,0,0,0,0,3,0,0,0
0,0,0,0,0,0,0,0,0,0,0,0,0,0,0,0
0,0,0,0,0,0,0,0,0,0,0,0,0,0,0,0
1,0,0,0,0,1,0,0,0,0,1,0,0,0,0,1
endlayer

layer
1,0,0,0,0,1,0,0,0,0,1,0,0,0,0,1
0,0,0,0,0,0,0,0,0,0,0,0,0,0,0,0
0,0,0,0,0,0,0,0,0,0,0,0,0,0,0,0
0,0,0,3,0,0,0,0,0,0,0,0,3,0,0,0
0,0,0,0,0,0,0,0,0,0,0,0,0,0,0,0
1,0,0,0,0,0,0,0,0,0,0,0,0,0,0,1
0,0,0,0,0,0,3,3,3,3,0,0,0,0,0,0
0,0,0,0,0,0,0,0,0,0,0,0,0,0,0,0
0,0,0,0,0,0,0,5,0,0,0,0,0,0,0,0
0,0,0,0,0,0,3,3,3,3,0,0,0,0,0,0
1,0,0,0,0,0,0,0,0,0,0,0,0,0,0,1
0,0,0,0,0,0,0,0,0,0,0,0,0,0,0,0
0,0,0,3,0,0,0,0,0,0,0,0,3,0,0,0
0,0,0,0,0,0,0,0,0,0,0,0,0,0,0,0
0,0,0,0,0,0,0,0,0,0,0,0,0,0,0,0
1,0,0,0,0,1,0,0,0,0,1,0,0,0,0,1
endlayer

layer
1,2,2,2,2,1,2,2,2,2,1,2,2,2,2,1
2,2,2,2,2,2,2,2,2,2,2,2,2,2,2,2
2,2,2,2,2,2,2,2,2,2,2,2,2,2,2,2
2,2,2,3,2,2,2,2,2,2,2,2,3,2,2,2
2,2,2,2,2,2,2,2,2,2,2,2,2,2,2,2
1,2,2,2,2,2,2,2,2,2,2,2,2,2,2,1
2,2,2,2,2,2,3,3,3,3,2,2,2,2,2,2
2,2,2,2,2,2,2,0,0,2,2,2,2,2,2,2
2,2,2,2,2,2,2,5,0,2,2,2,2,2,2,2
2,2,2,2,2,2,3,3,3,3,2,2,2,2,2,2
1,2,2,2,2,2,2,2,2,2,2,2,2,2,2,1
2,2,2,2,2,2,2,2,2,2,2,2,2,2,2,2
2,2,2,3,2,2,2,2,2,2,2,2,3,2,2,2
2,2,2,2,2,2,2,2,2,2,2,2,2,2,2,2
2,2,2,2,2,2,2,2,2,2,2,2,2,2,2,2
1,2,2,2,2,1,2,2,2,2,1,2,2,2,2,1
endlayer

layer
1,0,0,0,0,1,0,0,0,0,1,0,0,0,0,1
0,0,0,0,0,0,0,0,0,0,0,0,0,0,0,0
0,0,0,0,0,0,0,0,0,0,0,0,0,0,0,0
0,0,0,3,0,0,0,0,0,0,0,0,3,0,0,0
0,0,0,0,0,0,0,0,0,0,0,0,0,0,0,0
1,0,0,0,0,0,0,0,0,0,0,0,0,0,0,1
0,0,0,0,0,0,3,3,3,3,0,0,0,0,0,0
0,0,0,0,0,0,0,0,0,0,0,0,0,0,0,0
0,0,0,0,0,0,0,5,0,0,0,0,0,0,0,0
0,0,0,0,0,0,3,3,3,3,0,0,0,0,0,0
1,0,0,0,0,0,0,0,0,0,0,0,0,0,0,1
0,0,0,0,0,0,0,0,0,0,0,0,0,0,0,0
0,0,0,3,0,0,0,0,0,0,0,0,3,0,0,0
0,0,0,0,0,0,0,0,0,0,0,0,0,0,0,0
0,0,0,0,0,0,0,0,0,0,0,0,0,0,0,0
1,0,0,0,0,1,0,0,0,0,1,0,0,0,0,1
endlayer

layer
1,0,0,0,0,1,0,0,0,0,1,0,0,0,0,1
0,0,0,0,0,0,0,0,0,0,0,0,0,0,0,0
0,0,0,0,0,0,0,0,0,0,0,0,0,0,0,0
0,0,0,3,0,0,0,0,0,0,0,0,3,0,0,0
0,0,0,0,0,0,0,0,0,0,0,0,0,0,0,0
1,0,0,0,0,0,0,0,0,0,0,0,0,0,0,1
0,0,0,0,0,0,3,3,3,3,0,0,0,0,0,0
0,0,0,0,0,0,0,0,0,0,0,0,0,0,0,0
0,0,0,0,0,0,0,5,0,0,0,0,0,0,0,0
0,0,0,0,0,0,3,3,3,3,0,0,0,0,0,0
1,0,0,0,0,0,0,0,0,0,0,0,0,0,0,1
0,0,0,0,0,0,0,0,0,0,0,0,0,0,0,0
0,0,0,3,0,0,0,0,0,0,0,0,3,0,0,0
0,0,0,0,0,0,0,0,0,0,0,0,0,0,0,0
0,0,0,0,0,0,0,0,0,0,0,0,0,0,0,0
1,0,0,0,0,1,0,0,0,0,1,0,0,0,0,1
endlayer

layer
1,0,0,0,0,1,0,0,0,0,1,0,0,0,0,1
0,0,0,0,0,0,0,0,0,0,0,0,0,0,0,0
0,0,0,0,0,0,0,0,0,0,0,0,0,0,0,0
0,0,0,3,0,0,0,0,0,0,0,0,3,0,0,0
0,0,0,0,0,0,0,0,0,0,0,0,0,0,0,0
1,0,0,0,0,0,0,0,0,0,0,0,0,0,0,1
0,0,0,0,0,0,3,3,3,3,0,0,0,0,0,0
0,0,0,0,0,0,0,0,0,0,0,0,0,0,0,0
0,0,0,0,0,0,0,5,0,0,0,0,0,0,0,0
0,0,0,0,0,0,3,3,3,3,0,0,0,0,0,0
1,0,0,0,0,0,0,0,0,0,0,0,0,0,0,1
0,0,0,0,0,0,0,0,0,0,0,0,0,0,0,0
0,0,0,3,0,0,0,0,0,0,0,0,3,0,0,0
0,0,0,0,0,0,0,0,0,0,0,0,0,0,0,0
0,0,0,0,0,0,0,0,0,0,0,0,0,0,0,0
1,0,0,0,0,1,0,0,0,0,1,0,0,0,0,1
endlayer

layer
1,2,2,2,2,1,2,2,2,2,1,2,2,2,2,1
2,2,2,2,2,2,2,2,2,2,2,2,2,2,2,2
2,2,2,2,2,2,2,2,2,2,2,2,2,2,2,2
2,2,2,3,2,2,2,2,2,2,2,2,3,2,2,2
2,2,2,2,2,2,2,2,2,2,2,2,2,2,2,2
1,2,2,2,2,2,2,2,2,2,2,2,2,2,2,1
2,2,2,2,2,2,3,3,3,3,2,2,2,2,2,2
2,2,2,2,2,2,2,0,0,2,2,2,2,2,2,2
2,2,2,2,2,2,2,5,0,2,2,2,2,2,2,2
2,2,2,2,2,2,3,3,3,3,2,2,2,2,2,2
1,2,2,2,2,2,2,2,2,2,2,2,2,2,2,1
2,2,2,2,2,2,2,2,2,2,2,2,2,2,2,2
2,2,2,3,2,2,2,2,2,2,2,2,3,2,2,2
2,2,2,2,2,2,2,2,2,2,2,2,2,2,2,2
2,2,2,2,2,2,2,2,2,2,2,2,2,2,2,2
1,2,2,2,2,1,2,2,2,2,1,2,2,2,2,1
endlayer

layer
1,0,0,0,0,1,0,0,0,0,1,0,0,0,0,1
0,0,0,0,0,0,0,0,0,0,0,0,0,0,0,0
0,0,0,0,0,0,0,0,0,0,0,0,0,0,0,0
0,0,0,3,0,0,0,0,0,0,0,0,3,0,0,0
0,0,0,0,0,0,0,0,0,0,0,0,0,0,0,0
1,0,0,0,0,0,0,0,0,0,0,0,0,0,0,1
0,0,0,0,0,0,3,3,3,3,0,0,0,0,0,0
0,0,0,0,0,0,0,0,0,0,0,0,0,0,0,0
0,0,0,0,0,0,0,5,0,0,0,0,0,0,0,0
0,0,0,0,0,0,3,3,3,3,0,0,0,0,0,0
1,0,0,0,0,0,0,0,0,0,0,0,0,0,0,1
0,0,0,0,0,0,0,0,0,0,0,0,0,0,0,0
0,0,0,3,0,0,0,0,0,0,0,0,3,0,0,0
0,0,0,0,0,0,0,0,0,0,0,0,0,0,0,0
0,0,0,0,0,0,0,0,0,0,0,0,0,0,0,0
1,0,0,0,0,1,0,0,0,0,1,0,0,0,0,1
endlayer

layer
1,0,0,0,0,1,0,0,0,0,1,0,0,0,0,1
0,0,0,0,0,0,0,0,0,0,0,0,0,0,0,0
0,0,0,0,0,0,0,0,0,0,0,0,0,0,0,0
0,0,0,3,0,0,0,0,0,0,0,0,3,0,0,0
0,0,0,0,0,0,0,0,0,0,0,0,0,0,0,0
1,0,0,0,0,0,0,0,0,0,0,0,0,0,0,1
0,0,0,0,0,0,3,3,3,3,0,0,0,0,0,0
0,0,0,0,0,0,0,0,0,0,0,0,0,0,0,0
0,0,0,0,0,0,0,5,0,0,0,0,0,0,0,0
0,0,0,0,0,0,3,3,3,3,0,0,0,0,0,0
1,0,0,0,0,0,0,0,0,0,0,0,0,0,0,1
0,0,0,0,0,0,0,0,0,0,0,0,0,0,0,0
0,0,0,3,0,0,0,0,0,0,0,0,3,0,0,0
0,0,0,0,0,0,0,0,0,0,0,0,0,0,0,0
0,0,0,0,0,0,0,0,0,0,0,0,0,0,0,0
1,0,0,0,0,1,0,0,0,0,1,0,0,0,0,1
endlayer

layer
1,0,0,0,0,1,0,0,0,0,1,0,0,0,0,1
0,0,0,0,0,0,0,0,0,0,0,0,0,0,0,0
0,0,0,0,0,0,0,0,0,0,0,0,0,0,0,0
0,0,0,3,0,0,0,0,0,0,0,0,3,0,0,0
0,0,0,0,0,0,0,0,0,0,0,0,0,0,0,0
1,0,0,0,0,0,0,0,0,0,0,0,0,0,0,1
0,0,0,0,0,0,3,3,3,3,0,0,0,0,0,0
0,0,0,0,0,0,0,0,0,0,0,0,0,0,0,0
0,0,0,0,0,0,0,5,0,0,0,0,0,0,0,0
0,0,0,0,0,0,3,3,3,3,0,0,0,0,0,0
1,0,0,0,0,0,0,0,0,0,0,0,0,0,0,1
0,0,0,0,0,0,0,0,0,0,0,0,0,0,0,0
0,0,0,3,0,0,0,0,0,0,0,0,3,0,0,0
0,0,0,0,0,0,0,0,0,0,0,0,0,0,0,0
0,0,0,0,0,0,0,0,0,0,0,0,0,0,0,0
1,0,0,0,0,1,0,0,0,0,1,0,0,0,0,1
endlayer

layer
1,2,2,2,2,1,2,2,2,2,1,2,2,2,2,1
2,2,2,2,2,2,2,2,2,2,2,2,2,2,2,2
2,2,2,2,2,2,2,2,2,2,2,2,2,2,2,2
2,2,2,3,2,2,2,2,2,2,2,2,3,2,2,2
2,2,2,2,2,2,2,2,2,2,2,2,2,2,2,2
1,2,2,2,2,2,2,2,2,2,2,2,2,2,2,1
2,2,2,2,2,2,3,3,3,3,2,2,2,2,2,2
2,2,2,2,2,2,2,0,0,2,2,2,2,2,2,2
2,2,2,2,2,2,2,5,0,2,2,2,2,2,2,2
2,2,2,2,2,2,3,3,3,3,2,2,2,2,2,2
1,2,2,2,2,2,2,2,2,2,2,2,2,2,2,1
2,2,2,2,2,2,2,2,2,2,2,2,2,2,2,2
2,2,2,3,2,2,2,2,2,2,2,2,3,2,2,2
2,2,2,2,2,2,2,2,2,2,2,2,2,2,2,2
2,2,2,2,2,2,2,2,2,2,2,2,2,2,2,2
1,2,2,2,2,1,2,2,2,2,1,2,2,2,2,1
endlayer

layer
1,0,0,0,0,1,0,0,0,0,1,0,0,0,0,1
0,0,0,0,0,0,0,0,0,0,0,0,0,0,0,0
0,0,0,0,0,0,0,0,0,0,0,0,0,0,0,0
0,0,0,3,0,0,0,0,0,0,0,0,3,0,0,0
0,0,0,0,0,0,0,0,0,0,0,0,0,0,0,0
1,0,0,0,0,0,0,0,0,0,0,0,0,0,0,1
0,0,0,0,0,0,3,3,3,3,0,0,0,0,0,0
0,0,0,0,0,0,0,0,0,0,0,0,0,0,0,0
0,0,0,0,0,0,0,5,0,0,0,0,0,0,0,0
0,0,0,0,0,0,3,3,3,3,0,0,0,0,0,0
1,0,0,0,0,0,0,0,0,0,0,0,0,0,0,1
0,0,0,0,0,0,0,0,0,0,0,0,0,0,0,0
0,0,0,3,0,0,0,0,0,0,0,0,3,0,0,0
0,0,0,0,0,0,0,0,0,0,0,0,0,0,0,0
0,0,0,0,0,0,0,0,0,0,0,0,0,0,0,0
1,0,0,0,0,1,0,0,0,0,1,0,0,0,0,1
endlayer

layer
1,0,0,0,0,1,0,0,0,0,1,0,0,0,0,1
0,0,0,0,0,0,0,0,0,0,0,0,0,0,0,0
0,0,0,0,0,0,0,0,0,0,0,0,0,0,0,0
0,0,0,3,0,0,0,0,0,0,0,0,3,0,0,0
0,0,0,0,0,0,0,0,0,0,0,0,0,0,0,0
1,0,0,0,0,0,0,0,0,0,0,0,0,0,0,1
0,0,0,0,0,0,3,3,3,3,0,0,0,0,0,0
0,0,0,0,0,0,0,0,0,0,0,0,0,0,0,0
0,0,0,0,0,0,0,5,0,0,0,0,0,0,0,0
0,0,0,0,0,0,3,3,3,3,0,0,0,0,0,0
1,0,0,0,0,0,0,0,0,0,0,0,0,0,0,1
0,0,0,0,0,0,0,0,0,0,0,0,0,0,0,0
0,0,0,3,0,0,0,0,0,0,0,0,3,0,0,0
0,0,0,0,0,0,0,0,0,0,0,0,0,0,0,0
0,0,0,0,0,0,0,0,0,0,0,0,0,0,0,0
1,0,0,0,0,1,0,0,0,0,1,0,0,0,0,1
endlayer

layer
1,0,0,0,0,1,0,0,0,0,1,0,0,0,0,1
0,0,0,0,0,0,0,0,0,0,0,0,0,0,0,0
0,0,0,0,0,0,0,0,0,0,0,0,0,0,0,0
0,0,0,3,0,0,0,0,0,0,0,0,3,0,0,0
0,0,0,0,0,0,0,0,0,0,0,0,0,0,0,0
1,0,0,0,0,0,0,0,0,0,0,0,0,0,0,1
0,0,0,0,0,0,3,3,3,3,0,0,0,0,0,0
0,0,0,0,0,0,0,0,0,0,0,0,0,0,0,0
0,0,0,0,0,0,0,5,0,0,0,0,0,0,0,0
0,0,0,0,0,0,3,3,3,3,0,0,0,0,0,0
1,0,0,0,0,0,0,0,0,0,0,0,0,0,0,1
0,0,0,0,0,0,0,0,0,0,0,0,0,0,0,0
0,0,0,3,0,0,0,0,0,0,0,0,3,0,0,0
0,0,0,0,0,0,0,0,0,0,0,0,0,0,0,0
0,0,0,0,0,0,0,0,0,0,0,0,0,0,0,0
1,0,0,0,0,1,0,0,0,0,1,0,0,0,0,1
endlayer

layer
1,2,2,2,2,1,2,2,2,2,1,2,2,2,2,1
2,2,2,2,2,2,2,2,2,2,2,2,2,2,2,2
2,2,2,2,2,2,2,2,2,2,2,2,2,2,2,2
2,2,2,3,2,2,2,2,2,2,2,2,3,2,2,2
2,2,2,2,2,2,2,2,2,2,2,2,2,2,2,2
1,2,2,2,2,2,2,2,2,2,2,2,2,2,2,1
2,2,2,2,2,2,3,3,3,3,2,2,2,2,2,2
2,2,2,2,2,2,2,0,0,2,2,2,2,2,2,2
2,2,2,2,2,2,2,5,0,2,2,2,2,2,2,2
2,2,2,2,2,2,3,3,3,3,2,2,2,2,2,2
1,2,2,2,2,2,2,2,2,2,2,2,2,2,2,1
2,2,2,2,2,2,2,2,2,2,2,2,2,2,2,2
2,2,2,3,2,2,2,2,2,2,2,2,3,2,2,2
2,2,2,2,2,2,2,2,2,2,2,2,2,2,2,2
2,2,2,2,2,2,2,2,2,2,2,2,2,2,2,2
1,2,2,2,2,1,2,2,2,2,1,2,2,2,2,1
endlayer

layer
1,0,0,0,0,1,0,0,0,0,1,0,0,0,0,1
0,0,0,0,0,0,0,0,0,0,0,0,0,0,0,0
0,0,0,0,0,0,0,0,0,0,0,0,0,0,0,0
0,0,0,3,0,0,0,0,0,0,0,0,3,0,0,0
0,0,0,0,0,0,0,0,0,0,0,0,0,0,0,0
1,0,0,0,0,0,0,0,0,0,0,0,0,0,0,1
0,0,0,0,0,0,3,3,3,3,0,0,0,0,0,0
0,0,0,0,0,0,0,0,0,0,0,0,0,0,0,0
0,0,0,0,0,0,0,5,0,0,0,0,0,0,0,0
0,0,0,0,0,0,3,3,3,3,0,0,0,0,0,0
1,0,0,0,0,0,0,0,0,0,0,0,0,0,0,1
0,0,0,0,0,0,0,0,0,0,0,0,0,0,0,0
0,0,0,3,0,0,0,0,0,0,0,0,3,0,0,0
0,0,0,0,0,0,0,0,0,0,0,0,0,0,0,0
0,0,0,0,0,0,0,0,0,0,0,0,0,0,0,0
1,0,0,0,0,1,0,0,0,0,1,0,0,0,0,1
endlayer

layer
1,0,0,0,0,1,0,0,0,0,1,0,0,0,0,1
0,0,0,0,0,0,0,0,0,0,0,0,0,0,0,0
0,0,0,0,0,0,0,0,0,0,0,0,0,0,0,0
0,0,0,3,0,0,0,0,0,0,0,0,3,0,0,0
0,0,0,0,0,0,0,0,0,0,0,0,0,0,0,0
1,0,0,0,0,0,0,0,0,0,0,0,0,0,0,1
0,0,0,0,0,0,3,3,3,3,0,0,0,0,0,0
0,0,0,0,0,0,0,0,0,0,0,0,0,0,0,0
0,0,0,0,0,0,0,5,0,0,0,0,0,0,0,0
0,0,0,0,0,0,3,3,3,3,0,0,0,0,0,0
1,0,0,0,0,0,0,0,0,0,0,0,0,0,0,1
0,0,0,0,0,0,0,0,0,0,0,0,0,0,0,0
0,0,0,3,0,0,0,0,0,0,0,0,3,0,0,0
0,0,0,0,0,0,0,0,0,0,0,0,0,0,0,0
0,0,0,0,0,0,0,0,0,0,0,0,0,0,0,0
1,0,0,0,0,1,0,0,0,0,1,0,0,0,0,1
endlayer

layer
1,0,0,0,0,1,0,0,0,0,1,0,0,0,0,1
0,0,0,0,0,0,0,0,0,0,0,0,0,0,0,0
0,0,0,0,0,0,0,0,0,0,0,0,0,0,0,0
0,0,0,3,0,0,0,0,0,0,0,0,3,0,0,0
0,0,0,0,0,0,0,0,0,0,0,0,0,0,0,0
1,0,0,0,0,0,0,0,0,0,0,0,0,0,0,1
0,0,0,0,0,0,3,3,3,3,0,0,0,0,0,0
0,0,0,0,0,0,0,0,0,0,0,0,0,0,0,0
0,0,0,0,0,0,0,5,0,0,0,0,0,0,0,0
0,0,0,0,0,0,3,3,3,3,0,0,0,0,0,0
1,0,0,0,0,0,0,0,0,0,0,0,0,0,0,1
0,0,0,0,0,0,0,0,0,0,0,0,0,0,0,0
0,0,0,3,0,0,0,0,0,0,0,0,3,0,0,0
0,0,0,0,0,0,0,0,0,0,0,0,0,0,0,0
0,0,0,0,0,0,0,0,0,0,0,0,0,0,0,0
1,0,0,0,0,1,0,0,0,0,1,0,0,0,0,1
endlayer

layer
1,2,2,2,2,1,2,2,2,2,1,2,2,2,2,1
2,2,2,2,2,2,2,2,2,2,2,2,2,2,2,2
2,2,2,2,2,2,2,2,2,2,2,2,2,2,2,2
2,2,2,3,2,2,2,2,2,2,2,2,3,2,2,2
2,2,2,2,2,2,2,2,2,2,2,2,2,2,2,2
1,2,2,2,2,2,2,2,2,2,2,2,2,2,2,1
2,2,2,2,2,2,3,3,3,3,2,2,2,2,2,2
2,2,2,2,2,2,2,0,0,2,2,2,2,2,2,2
2,2,2,2,2,2,2,5,0,2,2,2,2,2,2,2
2,2,2,2,2,2,3,3,3,3,2,2,2,2,2,2
1,2,2,2,2,2,2,2,2,2,2,2,2,2,2,1
2,2,2,2,2,2,2,2,2,2,2,2,2,2,2,2
2,2,2,3,2,2,2,2,2,2,2,2,3,2,2,2
2,2,2,2,2,2,2,2,2,2,2,2,2,2,2,2
2,2,2,2,2,2,2,2,2,2,2,2,2,2,2,2
1,2,2,2,2,1,2,2,2,2,1,2,2,2,2,1
endlayer

layer
1,0,0,0,0,1,0,0,0,0,1,0,0,0,0,1
0,0,0,0,0,0,0,0,0,0,0,0,0,0,0,0
0,0,0,0,0,0,0,0,0,0,0,0,0,0,0,0
0,0,0,3,0,0,0,0,0,0,0,0,3,0,0,0
0,0,0,0,0,0,0,0,0,0,0,0,0,0,0,0
1,0,0,0,0,0,0,0,0,0,0,0,0,0,0,1
0,0,0,0,0,0,3,3,3,3,0,0,0,0,0,0
0,0,0,0,0,0,0,0,0,0,0,0,0,0,0,0
0,0,0,0,0,0,0,5,0,0,0,0,0,0,0,0
0,0,0,0,0,0,3,3,3,3,0,0,0,0,0,0
1,0,0,0,0,0,0,0,0,0,0,0,0,0,0,1
0,0,0,0,0,0,0,0,0,0,0,0,0,0,0,0
0,0,0,3,0,0,0,0,0,0,0,0,3,0,0,0
0,0,0,0,0,0,0,0,0,0,0,0,0,0,0,0
0,0,0,0,0,0,0,0,0,0,0,0,0,0,0,0
1,0,0,0,0,1,0,0,0,0,1,0,0,0,0,1
endlayer

layer
1,0,0,0,0,1,0,0,0,0,1,0,0,0,0,1
0,0,0,0,0,0,0,0,0,0,0,0,0,0,0,0
0,0,0,0,0,0,0,0,0,0,0,0,0,0,0,0
0,0,0,3,0,0,0,0,0,0,0,0,3,0,0,0
0,0,0,0,0,0,0,0,0,0,0,0,0,0,0,0
1,0,0,0,0,0,0,0,0,0,0,0,0,0,0,1
0,0,0,0,0,0,3,3,3,3,0,0,0,0,0,0
0,0,0,0,0,0,0,0,0,0,0,0,0,0,0,0
0,0,0,0,0,0,0,5,0,0,0,0,0,0,0,0
0,0,0,0,0,0,3,3,3,3,0,0,0,0,0,0
1,0,0,0,0,0,0,0,0,0,0,0,0,0,0,1
0,0,0,0,0,0,0,0,0,0,0,0,0,0,0,0
0,0,0,3,0,0,0,0,0,0,0,0,3,0,0,0
0,0,0,0,0,0,0,0,0,0,0,0,0,0,0,0
0,0,0,0,0,0,0,0,0,0,0,0,0,0,0,0
1,0,0,0,0,1,0,0,0,0,1,0,0,0,0,1
endlayer

layer
1,0,0,0,0,1,0,0,0,0,1,0,0,0,0,1
0,0,0,0,0,0,0,0,0,0,0,0,0,0,0,0
0,0,0,0,0,0,0,0,0,0,0,0,0,0,0,0
0,0,0,3,0,0,0,0,0,0,0,0,3,0,0,0
0,0,0,0,0,0,0,0,0,0,0,0,0,0,0,0
1,0,0,0,0,0,0,0,0,0,0,0,0,0,0,1
0,0,0,0,0,0,3,3,3,3,0,0,0,0,0,0
0,0,0,0,0,0,0,0,0,0,0,0,0,0,0,0
0,0,0,0,0,0,0,5,0,0,0,0,0,0,0,0
0,0,0,0,0,0,3,3,3,3,0,0,0,0,0,0
1,0,0,0,0,0,0,0,0,0,0,0,0,0,0,1
0,0,0,0,0,0,0,0,0,0,0,0,0,0,0,0
0,0,0,3,0,0,0,0,0,0,0,0,3,0,0,0
0,0,0,0,0,0,0,0,0,0,0,0,0,0,0,0
0,0,0,0,0,0,0,0,0,0,0,0,0,0,0,0
1,0,0,0,0,1,0,0,0,0,1,0,0,0,0,1
endlayer

layer
1,2,2,2,2,1,2,2,2,2,1,2,2,2,2,1
2,2,2,2,2,2,2,2,2,2,2,2,2,2,2,2
2,2,2,2,2,2,2,2,2,2,2,2,2,2,2,2
2,2,2,3,2,2,2,2,2,2,2,2,3,2,2,2
2,2,2,2,2,2,2,2,2,2,2,2,2,2,2,2
1,2,2,2,2,2,2,2,2,2,2,2,2,2,2,1
2,2,2,2,2,2,3,3,3,3,2,2,2,2,2,2
2,2,2,2,2,2,2,0,0,2,2,2,2,2,2,2
2,2,2,2,2,2,2,5,0,2,2,2,2,2,2,2
2,2,2,2,2,2,3,3,3,3,2,2,2,2,2,2
1,2,2,2,2,2,2,2,2,2,2,2,2,2,2,1
2,2,2,2,2,2,2,2,2,2,2,2,2,2,2,2
2,2,2,3,2,2,2,2,2,2,2,2,3,2,2,2
2,2,2,2,2,2,2,2,2,2,2,2,2,2,2,2
2,2,2,2,2,2,2,2,2,2,2,2,2,2,2,2
1,2,2,2,2,1,2,2,2,2,1,2,2,2,2,1
endlayer

layer
1,0,0,0,0,1,0,0,0,0,1,0,0,0,0,1
0,0,0,0,0,0,0,0,0,0,0,0,0,0,0,0
0,0,0,0,0,0,0,0,0,0,0,0,0,0,0,0
0,0,0,3,0,0,0,0,0,0,0,0,3,0,0,0
0,0,0,0,0,0,0,0,0,0,0,0,0,0,0,0
1,0,0,0,0,0,0,0,0,0,0,0,0,0,0,1
0,0,0,0,0,0,3,3,3,3,0,0,0,0,0,0
0,0,0,0,0,0,0,0,0,0,0,0,0,0,0,0
0,0,0,0,0,0,0,5,0,0,0,0,0,0,0,0
0,0,0,0,0,0,3,3,3,3,0,0,0,0,0,0
1,0,0,0,0,0,0,0,0,0,0,0,0,0,0,1
0,0,0,0,0,0,0,0,0,0,0,0,0,0,0,0
0,0,0,3,0,0,0,0,0,0,0,0,3,0,0,0
0,0,0,0,0,0,0,0,0,0,0,0,0,0,0,0
0,0,0,0,0,0,0,0,0,0,0,0,0,0,0,0
1,0,0,0,0,1,0,0,0,0,1,0,0,0,0,1
endlayer

layer
1,0,0,0,0,1,0,0,0,0,1,0,0,0,0,1
0,0,0,0,0,0,0,0,0,0,0,0,0,0,0,0
0,0,0,0,0,0,0,0,0,0,0,0,0,0,0,0
0,0,0,3,0,0,0,0,0,0,0,0,3,0,0,0
0,0,0,0,0,0,0,0,0,0,0,0,0,0,0,0
1,0,0,0,0,0,0,0,0,0,0,0,0,0,0,1
0,0,0,0,0,0,3,3,3,3,0,0,0,0,0,0
0,0,0,0,0,0,0,0,0,0,0,0,0,0,0,0
0,0,0,0,0,0,0,5,0,0,0,0,0,0,0,0
0,0,0,0,0,0,3,3,3,3,0,0,0,0,0,0
1,0,0,0,0,0,0,0,0,0,0,0,0,0,0,1
0,0,0,0,0,0,0,0,0,0,0,0,0,0,0,0
0,0,0,3,0,0,0,0,0,0,0,0,3,0,0,0
0,0,0,0,0,0,0,0,0,0,0,0,0,0,0,0
0,0,0,0,0,0,0,0,0,0,0,0,0,0,0,0
1,0,0,0,0,1,0,0,0,0,1,0,0,0,0,1
endlayer

layer
1,0,0,0,0,1,0,0,0,0,1,0,0,0,0,1
0,0,0,0,0,0,0,0,0,0,0,0,0,0,0,0
0,0,0,0,0,0,0,0,0,0,0,0,0,0,0,0
0,0,0,3,0,0,0,0,0,0,0,0,3,0,0,0
0,0,0,0,0,0,0,0,0,0,0,0,0,0,0,0
1,0,0,0,0,0,0,0,0,0,0,0,0,0,0,1
0,0,0,0,0,0,3,3,3,3,0,0,0,0,0,0
0,0,0,0,0,0,0,0,0,0,0,0,0,0,0,0
0,0,0,0,0,0,0,5,0,0,0,0,0,0,0,0
0,0,0,0,0,0,3,3,3,3,0,0,0,0,0,0
1,0,0,0,0,0,0,0,0,0,0,0,0,0,0,1
0,0,0,0,0,0,0,0,0,0,0,0,0,0,0,0
0,0,0,3,0,0,0,0,0,0,0,0,3,0,0,0
0,0,0,0,0,0,0,0,0,0,0,0,0,0,0,0
0,0,0,0,0,0,0,0,0,0,0,0,0,0,0,0
1,0,0,0,0,1,0,0,0,0,1,0,0,0,0,1
endlayer

layer
1,2,2,2,2,1,2,2,2,2,1,2,2,2,2,1
2,2,2,2,2,2,2,2,2,2,2,2,2,2,2,2
2,2,2,2,2,2,2,2,2,2,2,2,2,2,2,2
2,2,2,3,2,2,2,2,2,2,2,2,3,2,2,2
2,2,2,2,2,2,2,2,2,2,2,2,2,2,2,2
1,2,2,2,2,2,2,2,2,2,2,2,2,2,2,1
2,2,2,2,2,2,3,3,3,3,2,2,2,2,2,2
2,2,2,2,2,2,2,0,0,2,2,2,2,2,2,2
2,2,2,2,2,2,2,5,0,2,2,2,2,2,2,2
2,2,2,2,2,2,3,3,3,3,2,2,2,2,2,2
1,2,2,2,2,2,2,2,2,2,2,2,2,2,2,1
2,2,2,2,2,2,2,2,2,2,2,2,2,2,2,2
2,2,2,3,2,2,2,2,2,2,2,2,3,2,2,2
2,2,2,2,2,2,2,2,2,2,2,2,2,2,2,2
2,2,2,2,2,2,2,2,2,2,2,2,2,2,2,2
1,2,2,2,2,1,2,2,2,2,1,2,2,2,2,1
endlayer

layer
1,0,0,0,0,1,0,0,0,0,1,0,0,0,0,1
0,0,0,0,0,0,0,0,0,0,0,0,0,0,0,0
0,0,0,0,0,0,0,0,0,0,0,0,0,0,0,0
0,0,0,3,0,0,0,0,0,0,0,0,3,0,0,0
0,0,0,0,0,0,0,0,0,0,0,0,0,0,0,0
1,0,0,0,0,0,0,0,0,0,0,0,0,0,0,1
0,0,0,0,0,0,3,3,3,3,0,0,0,0,0,0
0,0,0,0,0,0,0,0,0,0,0,0,0,0,0,0
0,0,0,0,0,0,0,5,0,0,0,0,0,0,0,0
0,0,0,0,0,0,3,3,3,3,0,0,0,0,0,0
1,0,0,0,0,0,0,0,0,0,0,0,0,0,0,1
0,0,0,0,0,0,0,0,0,0,0,0,0,0,0,0
0,0,0,3,0,0,0,0,0,0,0,0,3,0,0,0
0,0,0,0,0,0,0,0,0,0,0,0,0,0,0,0
0,0,0,0,0,0,0,0,0,0,0,0,0,0,0,0
1,0,0,0,0,1,0,0,0,0,1,0,0,0,0,1
endlayer

layer
1,0,0,0,0,1,0,0,0,0,1,0,0,0,0,1
0,0,0,0,0,0,0,0,0,0,0,0,0,0,0,0
0,0,0,0,0,0,0,0,0,0,0,0,0,0,0,0
0,0,0,3,0,0,0,0,0,0,0,0,3,0,0,0
0,0,0,0,0,0,0,0,0,0,0,0,0,0,0,0
1,0,0,0,0,0,0,0,0,0,0,0,0,0,0,1
0,0,0,0,0,0,3,3,3,3,0,0,0,0,0,0
0,0,0,0,0,0,0,0,0,0,0,0,0,0,0,0
0,0,0,0,0,0,0,5,0,0,0,0,0,0,0,0
0,0,0,0,0,0,3,3,3,3,0,0,0,0,0,0
1,0,0,0,0,0,0,0,0,0,0,0,0,0,0,1
0,0,0,0,0,0,0,0,0,0,0,0,0,0,0,0
0,0,0,3,0,0,0,0,0,0,0,0,3,0,0,0
0,0,0,0,0,0,0,0,0,0,0,0,0,0,0,0
0,0,0,0,0,0,0,0,0,0,0,0,0,0,0,0
1,0,0,0,0,1,0,0,0,0,1,0,0,0,0,1
endlayer

layer
1,0,0,0,0,1,0,0,0,0,1,0,0,0,0,1
0,0,0,0,0,0,0,0,0,0,0,0,0,0,0,0
0,0,0,0,0,0,0,0,0,0,0,0,0,0,0,0
0,0,0,3,0,0,0,0,0,0,0,0,3,0,0,0
0,0,0,0,0,0,0,0,0,0,0,0,0,0,0,0
1,0,0,0,0,0,0,0,0,0,0,0,0,0,0,1
0,0,0,0,0,0,3,3,3,3,0,0,0,0,0,0
0,0,0,0,0,0,0,0,0,0,0,0,0,0,0,0
0,0,0,0,0,0,0,5,0,0,0,0,0,0,0,0
0,0,0,0,0,0,3,3,3,3,0,0,0,0,0,0
1,0,0,0,0,0,0,0,0,0,0,0,0,0,0,1
0,0,0,0,0,0,0,0,0,0,0,0,0,0,0,0
0,0,0,3,0,0,0,0,0,0,0,0,3,0,0,0
0,0,0,0,0,0,0,0,0,0,0,0,0,0,0,0
0,0,0,0,0,0,0,0,0,0,0,0,0,0,0,0
1,0,0,0,0,1,0,0,0,0,1,0,0,0,0,1
endlayer

layer
1,2,2,2,2,1,2,2,2,2,1,2,2,2,2,1
2,2,2,2,2,2,2,2,2,2,2,2,2,2,2,2
2,2,2,2,2,2,2,2,2,2,2,2,2,2,2,2
2,2,2,3,2,2,2,2,2,2,2,2,3,2,2,2
2,2,2,2,2,2,2,2,2,2,2,2,2,2,2,2
1,2,2,2,2,2,2,2,2,2,2,2,2,2,2,1
2,2,2,2,2,2,3,3,3,3,2,2,2,2,2,2
2,2,2,2,2,2,2,0,0,2,2,2,2,2,2,2
2,2,2,2,2,2,2,5,0,2,2,2,2,2,2,2
2,2,2,2,2,2,3,3,3,3,2,2,2,2,2,2
1,2,2,2,2,2,2,2,2,2,2,2,2,2,2,1
2,2,2,2,2,2,2,2,2,2,2,2,2,2,2,2
2,2,2,3,2,2,2,2,2,2,2,2,3,2,2,2
2,2,2,2,2,2,2,2,2,2,2,2,2,2,2,2
2,2,2,2,2,2,2,2,2,2,2,2,2,2,2,2
1,2,2,2,2,1,2,2,2,2,1,2,2,2,2,1
endlayer

layer
1,0,0,0,0,1,0,0,0,0,1,0,0,0,0,1
0,0,0,0,0,0,0,0,0,0,0,0,0,0,0,0
0,0,0,0,0,0,0,0,0,0,0,0,0,0,0,0
0,0,0,3,0,0,0,0,0,0,0,0,3,0,0,0
0,0,0,0,0,0,0,0,0,0,0,0,0,0,0,0
1,0,0,0,0,0,0,0,0,0,0,0,0,0,0,1
0,0,0,0,0,0,3,3,3,3,0,0,0,0,0,0
0,0,0,0,0,0,0,0,0,0,0,0,0,0,0,0
0,0,0,0,0,0,0,5,0,0,0,0,0,0,0,0
0,0,0,0,0,0,3,3,3,3,0,0,0,0,0,0
1,0,0,0,0,0,0,0,0,0,0,0,0,0,0,1
0,0,0,0,0,0,0,0,0,0,0,0,0,0,0,0
0,0,0,3,0,0,0,0,0,0,0,0,3,0,0,0
0,0,0,0,0,0,0,0,0,0,0,0,0,0,0,0
0,0,0,0,0,0,0,0,0,0,0,0,0,0,0,0
1,0,0,0,0,1,0,0,0,0,1,0,0,0,0,1
endlayer

layer
1,0,0,0,0,1,0,0,0,0,1,0,0,0,0,1
0,0,0,0,0,0,0,0,0,0,0,0,0,0,0,0
0,0,0,0,0,0,0,0,0,0,0,0,0,0,0,0
0,0,0,3,0,0,0,0,0,0,0,0,3,0,0,0
0,0,0,0,0,0,0,0,0,0,0,0,0,0,0,0
1,0,0,0,0,0,0,0,0,0,0,0,0,0,0,1
0,0,0,0,0,0,3,3,3,3,0,0,0,0,0,0
0,0,0,0,0,0,0,0,0,0,0,0,0,0,0,0
0,0,0,0,0,0,0,5,0,0,0,0,0,0,0,0
0,0,0,0,0,0,3,3,3,3,0,0,0,0,0,0
1,0,0,0,0,0,0,0,0,0,0,0,0,0,0,1
0,0,0,0,0,0,0,0,0,0,0,0,0,0,0,0
0,0,0,3,0,0,0,0,0,0,0,0,3,0,0,0
0,0,0,0,0,0,0,0,0,0,0,0,0,0,0,0
0,0,0,0,0,0,0,0,0,0,0,0,0,0,0,0
1,0,0,0,0,1,0,0,0,0,1,0,0,0,0,1
endlayer

layer
1,0,0,0,0,1,0,0,0,0,1,0,0,0,0,1
0,0,0,0,0,0,0,0,0,0,0,0,0,0,0,0
0,0,0,0,0,0,0,0,0,0,0,0,0,0,0,0
0,0,0,3,0,0,0,0,0,0,0,0,3,0,0,0
0,0,0,0,0,0,0,0,0,0,0,0,0,0,0,0
1,0,0,0,0,0,0,0,0,0,0,0,0,0,0,1
0,0,0,0,0,0,3,3,3,3,0,0,0,0,0,0
0,0,0,0,0,0,0,0,0,0,0,0,0,0,0,0
0,0,0,0,0,0,0,5,0,0,0,0,0,0,0,0
0,0,0,0,0,0,3,3,3,3,0,0,0,0,0,0
1,0,0,0,0,0,0,0,0,0,0,0,0,0,0,1
0,0,0,0,0,0,0,0,0,0,0,0,0,0,0,0
0,0,0,3,0,0,0,0,0,0,0,0,3,0,0,0
0,0,0,0,0,0,0,0,0,0,0,0,0,0,0,0
0,0,0,0,0,0,0,0,0,0,0,0,0,0,0,0
1,0,0,0,0,1,0,0,0,0,1,0,0,0,0,1
endlayer

layer
1,2,2,2,2,1,2,2,2,2,1,2,2,2,2,1
2,2,2,2,2,2,2,2,2,2,2,2,2,2,2,2
2,2,2,2,2,2,2,2,2,2,2,2,2,2,2,2
2,2,2,3,2,2,2,2,2,2,2,2,3,2,2,2
2,2,2,2,2,2,2,2,2,2,2,2,2,2,2,2
1,2,2,2,2,2,2,2,2,2,2,2,2,2,2,1
2,2,2,2,2,2,3,3,3,3,2,2,2,2,2,2
2,2,2,2,2,2,2,0,0,2,2,2,2,2,2,2
2,2,2,2,2,2,2,5,0,2,2,2,2,2,2,2
2,2,2,2,2,2,3,3,3,3,2,2,2,2,2,2
1,2,2,2,2,2,2,2,2,2,2,2,2,2,2,1
2,2,2,2,2,2,2,2,2,2,2,2,2,2,2,2
2,2,2,3,2,2,2,2,2,2,2,2,3,2,2,2
2,2,2,2,2,2,2,2,2,2,2,2,2,2,2,2
2,2,2,2,2,2,2,2,2,2,2,2,2,2,2,2
1,2,2,2,2,1,2,2,2,2,1,2,2,2,2,1
endlayer

layer
1,0,0,0,0,1,0,0,0,0,1,0,0,0,0,1
0,0,0,0,0,0,0,0,0,0,0,0,0,0,0,0
0,0,0,0,0,0,0,0,0,0,0,0,0,0,0,0
0,0,0,3,0,0,0,0,0,0,0,0,3,0,0,0
0,0,0,0,0,0,0,0,0,0,0,0,0,0,0,0
1,0,0,0,0,0,0,0,0,0,0,0,0,0,0,1
0,0,0,0,0,0,3,3,3,3,0,0,0,0,0,0
0,0,0,0,0,0,0,0,0,0,0,0,0,0,0,0
0,0,0,0,0,0,0,5,0,0,0,0,0,0,0,0
0,0,0,0,0,0,3,3,3,3,0,0,0,0,0,0
1,0,0,0,0,0,0,0,0,0,0,0,0,0,0,1
0,0,0,0,0,0,0,0,0,0,0,0,0,0,0,0
0,0,0,3,0,0,0,0,0,0,0,0,3,0,0,0
0,0,0,0,0,0,0,0,0,0,0,0,0,0,0,0
0,0,0,0,0,0,0,0,0,0,0,0,0,0,0,0
1,0,0,0,0,1,0,0,0,0,1,0,0,0,0,1
endlayer

layer
1,0,0,0,0,1,0,0,0,0,1,0,0,0,0,1
0,0,0,0,0,0,0,0,0,0,0,0,0,0,0,0
0,0,0,0,0,0,0,0,0,0,0,0,0,0,0,0
0,0,0,3,0,0,0,0,0,0,0,0,3,0,0,0
0,0,0,0,0,0,0,0,0,0,0,0,0,0,0,0
1,0,0,0,0,0,0,0,0,0,0,0,0,0,0,1
0,0,0,0,0,0,3,3,3,3,0,0,0,0,0,0
0,0,0,0,0,0,0,0,0,0,0,0,0,0,0,0
0,0,0,0,0,0,0,5,0,0,0,0,0,0,0,0
0,0,0,0,0,0,3,3,3,3,0,0,0,0,0,0
1,0,0,0,0,0,0,0,0,0,0,0,0,0,0,1
0,0,0,0,0,0,0,0,0,0,0,0,0,0,0,0
0,0,0,3,0,0,0,0,0,0,0,0,3,0,0,0
0,0,0,0,0,0,0,0,0,0,0,0,0,0,0,0
0,0,0,0,0,0,0,0,0,0,0,0,0,0,0,0
1,0,0,0,0,1,0,0,0,0,1,0,0,0,0,1
endlayer

layer
1,0,0,0,0,1,0,0,0,0,1,0,0,0,0,1
0,0,0,0,0,0,0,0,0,0,0,0,0,0,0,0
0,0,0,0,0,0,0,0,0,0,0,0,0,0,0,0
0,0,0,3,0,0,0,0,0,0,0,0,3,0,0,0
0,0,0,0,0,0,0,0,0,0,0,0,0,0,0,0
1,0,0,0,0,0,0,0,0,0,0,0,0,0,0,1
0,0,0,0,0,0,3,3,3,3,0,0,0,0,0,0
0,0,0,0,0,0,0,0,0,0,0,0,0,0,0,0
0,0,0,0,0,0,0,5,0,0,0,0,0,0,0,0
0,0,0,0,0,0,3,3,3,3,0,0,0,0,0,0
1,0,0,0,0,0,0,0,0,0,0,0,0,0,0,1
0,0,0,0,0,0,0,0,0,0,0,0,0,0,0,0
0,0,0,3,0,0,0,0,0,0,0,0,3,0,0,0
0,0,0,0,0,0,0,0,0,0,0,0,0,0,0,0
0,0,0,0,0,0,0,0,0,0,0,0,0,0,0,0
1,0,0,0,0,1,0,0,0,0,1,0,0,0,0,1
endlayer

layer
1,2,2,2,2,1,2,2,2,2,1,2,2,2,2,1
2,2,2,2,2,2,2,2,2,2,2,2,2,2,2,2
2,2,2,2,2,2,2,2,2,2,2,2,2,2,2,2
2,2,2,3,2,2,2,2,2,2,2,2,3,2,2,2
2,2,2,2,2,2,2,2,2,2,2,2,2,2,2,2
1,2,2,2,2,2,2,2,2,2,2,2,2,2,2,1
2,2,2,2,2,2,3,3,3,3,2,2,2,2,2,2
2,2,2,2,2,2,2,0,0,2,2,2,2,2,2,2
2,2,2,2,2,2,2,5,0,2,2,2,2,2,2,2
2,2,2,2,2,2,3,3,3,3,2,2,2,2,2,2
1,2,2,2,2,2,2,2,2,2,2,2,2,2,2,1
2,2,2,2,2,2,2,2,2,2,2,2,2,2,2,2
2,2,2,3,2,2,2,2,2,2,2,2,3,2,2,2
2,2,2,2,2,2,2,2,2,2,2,2,2,2,2,2
2,2,2,2,2,2,2,2,2,2,2,2,2,2,2,2
1,2,2,2,2,1,2,2,2,2,1,2,2,2,2,1
endlayer

layer
1,0,0,0,0,1,0,0,0,0,1,0,0,0,0,1
0,0,0,0,0,0,0,0,0,0,0,0,0,0,0,0
0,0,0,0,0,0,0,0,0,0,0,0,0,0,0,0
0,0,0,3,0,0,0,0,0,0,0,0,3,0,0,0
0,0,0,0,0,0,0,0,0,0,0,0,0,0,0,0
1,0,0,0,0,0,0,0,0,0,0,0,0,0,0,1
0,0,0,0,0,0,3,3,3,3,0,0,0,0,0,0
0,0,0,0,0,0,0,0,0,0,0,0,0,0,0,0
0,0,0,0,0,0,0,5,0,0,0,0,0,0,0,0
0,0,0,0,0,0,3,3,3,3,0,0,0,0,0,0
1,0,0,0,0,0,0,0,0,0,0,0,0,0,0,1
0,0,0,0,0,0,0,0,0,0,0,0,0,0,0,0
0,0,0,3,0,0,0,0,0,0,0,0,3,0,0,0
0,0,0,0,0,0,0,0,0,0,0,0,0,0,0,0
0,0,0,0,0,0,0,0,0,0,0,0,0,0,0,0
1,0,0,0,0,1,0,0,0,0,1,0,0,0,0,1
endlayer

layer
1,0,0,0,0,1,0,0,0,0,1,0,0,0,0,1
0,0,0,0,0,0,0,0,0,0,0,0,0,0,0,0
0,0,0,0,0,0,0,0,0,0,0,0,0,0,0,0
0,0,0,3,0,0,0,0,0,0,0,0,3,0,0,0
0,0,0,0,0,0,0,0,0,0,0,0,0,0,0,0
1,0,0,0,0,0,0,0,0,0,0,0,0,0,0,1
0,0,0,0,0,0,3,3,3,3,0,0,0,0,0,0
0,0,0,0,0,0,0,0,0,0,0,0,0,0,0,0
0,0,0,0,0,0,0,5,0,0,0,0,0,0,0,0
0,0,0,0,0,0,3,3,3,3,0,0,0,0,0,0
1,0,0,0,0,0,0,0,0,0,0,0,0,0,0,1
0,0,0,0,0,0,0,0,0,0,0,0,0,0,0,0
0,0,0,3,0,0,0,0,0,0,0,0,3,0,0,0
0,0,0,0,0,0,0,0,0,0,0,0,0,0,0,0
0,0,0,0,0,0,0,0,0,0,0,0,0,0,0,0
1,0,0,0,0,1,0,0,0,0,1,0,0,0,0,1
endlayer

layer
1,0,0,0,0,1,0,0,0,0,1,0,0,0,0,1
0,0,0,0,0,0,0,0,0,0,0,0,0,0,0,0
0,0,0,0,0,0,0,0,0,0,0,0,0,0,0,0
0,0,0,3,0,0,0,0,0,0,0,0,3,0,0,0
0,0,0,0,0,0,0,0,0,0,0,0,0,0,0,0
1,0,0,0,0,0,0,0,0,0,0,0,0,0,0,1
0,0,0,0,0,0,3,3,3,3,0,0,0,0,0,0
0,0,0,0,0,0,0,0,0,0,0,0,0,0,0,0
0,0,0,0,0,0,0,5,0,0,0,0,0,0,0,0
0,0,0,0,0,0,3,3,3,3,0,0,0,0,0,0
1,0,0,0,0,0,0,0,0,0,0,0,0,0,0,1
0,0,0,0,0,0,0,0,0,0,0,0,0,0,0,0
0,0,0,3,0,0,0,0,0,0,0,0,3,0,0,0
0,0,0,0,0,0,0,0,0,0,0,0,0,0,0,0
0,0,0,0,0,0,0,0,0,0,0,0,0,0,0,0
1,0,0,0,0,1,0,0,0,0,1,0,0,0,0,1
endlayer

layer
1,2,2,2,2,1,2,2,2,2,1,2,2,2,2,1
2,2,2,2,2,2,2,2,2,2,2,2,2,2,2,2
2,2,2,2,2,2,2,2,2,2,2,2,2,2,2,2
2,2,2,3,2,2,2,2,2,2,2,2,3,2,2,2
2,2,2,2,2,2,2,2,2,2,2,2,2,2,2,2
1,2,2,2,2,2,2,2,2,2,2,2,2,2,2,1
2,2,2,2,2,2,3,3,3,3,2,2,2,2,2,2
2,2,2,2,2,2,2,3,3,2,2,2,2,2,2,2
2,2,2,2,2,2,2,3,3,2,2,2,2,2,2,2
2,2,2,2,2,2,3,3,3,3,2,2,2,2,2,2
1,2,2,2,2,2,2,2,2,2,2,2,2,2,2,1
2,2,2,2,2,2,2,2,2,2,2,2,2,2,2,2
2,2,2,3,2,2,2,2,2,2,2,2,3,2,2,2
2,2,2,2,2,2,2,2,2,2,2,2,2,2,2,2
2,2,2,2,2,2,2,2,2,2,2,2,2,2,2,2
1,2,2,2,2,1,2,2,2,2,1,2,2,2,2,1
endlayer

layer
1,0,0,0,0,1,0,0,0,0,1,0,0,0,0,1
0,0,0,0,0,0,0,0,0,0,0,0,0,0,0,0
0,0,0,0,0,0,0,0,0,0,0,0,0,0,0,0
0,0,0,0,0,0,0,0,0,0,0,0,0,0,0,0
0,0,0,0,0,0,0,0,0,0,0,0,0,0,0,0
1,0,0,0,0,0,0,0,0,0,0,0,0,0,0,1
0,0,0,0,0,0,0,0,0,0,0,0,0,0,0,0
0,0,0,0,0,0,0,0,0,0,0,0,0,0,0,0
0,0,0,0,0,0,0,0,0,0,0,0,0,0,0,0
0,0,0,0,0,0,0,0,0,0,0,0,0,0,0,0
1,0,0,0,0,0,0,0,0,0,0,0,0,0,0,1
0,0,0,0,0,0,0,0,0,0,0,0,0,0,0,0
0,0,0,0,0,0,0,0,0,0,0,0,0,0,0,0
0,0,0,0,0,0,0,0,0,0,0,0,0,0,0,0
0,0,0,0,0,0,0,0,0,0,0,0,0,0,0,0
1,0,0,0,0,1,0,0,0,0,1,0,0,0,0,1
endlayer

