acceptable_target_blocks=1,2,3,12,13,24,162,163,164,165,166,167,168,169,170,171,172,254,255
weight=80
embed_into_distance=1
dimensions=72,25,25
max_leveling=4
leveling_buffer=0
max_cut_in=25
preserve_plants=1

#outer column
rule1=0,95,48,48,48,48,48,48,48,48,48,48,48,48,48,48,48,48,48,48,48,48,48,48,48,48,48,48,48,48,48,48,48,48,48,48,48,48,48,48,48,48,48,48,48,48,48,48,48,48,48,48,48,48,48,48,48,48,48,48,48,48,48,48,48,48,48,48,48,48,48,48,48,48,48,48,48,48,48,48,48,48,48,48,48,48,48,48,48,48,48,48,48,48,48,48,1,1,13,13,13,1,1,1,1,1,1,1,15
#cement interior
rule2=0,90,48,48,48,48,48,48,48,48,48,48,48,48,48,48,48,48,48,48,48,48,48,48,48,48,48,48,48,48,48,48,48,48,48,48,48,48,48,48,48,48,48,48,48,48,48,48,48,48,48,48,48,48,48,48,48,48,48,48,48,48,48,48,48,48,48,48,48,48,48,48,48,48,48,48,48,48,48,48,48,48,48,48,48,48,48,48,48,48,48,48,48,48,48,48,48,48,48,48,48,48,48,48,48,48,48,1,1,13,13,13,13,1,1,1,1,1,1,1,73,15
#inner column
rule3=0,98,48,48,48,48,48,48,48,48,48,48,48,48,48,48,48,48,48,48,48,48,48,48,48,48,48,48,48,48,48,48,48,48,48,48,48,48,48,48,48,48,48,48,48,48,48,48,48,48,48,48,48,48,48,48,48,48,48,48,48,48,48,48,48,48,48,48,48,48,48,48,48,48,48,48,48,48,48,48,48,48,48,48,48,48,48,48,48,48,48,48,48,48,48,48,48,1,1,13,13,13,1,1,1,1,1,1,1,15
#ladders
rule4=0,50,65-3
rule5=0,50,65-2
#1st floor walls
rule6=0,98,24
#glass
rule7=0,50,20
rule8=0,100,102
#ceiling
rule9=0,80,48,48,48,48,48,48,48,48,48,48,48,48,48,48,48,48,48,48,48,48,48,48,48,48,48,48,48,48,48,48,48,48,48,48,48,48,48,48,48,48,48,48,48,48,48,48,48,48,48,48,48,48,48,48,48,48,48,48,48,48,48,48,48,48,48,48,48,48,48,48,48,48,48,48,48,48,48,48,48,48,48,48,48,48,48,48,48,48,48,48,48,48,48,48,48,1,1,13,13,13,1,1,1,1,1,1,1,15
#floor
rule10=1,100,48
#windowsill
rule11=2,95,24-1
#wrecked outer column base
rule12=0,75,48,48,48,48,48,48,48,48,48,48,48,48,48,48,48,48,48,48,48,48,48,48,48,48,48,48,48,48,48,48,48,48,48,48,48,48,48,48,48,48,48,48,48,48,48,48,48,48,48,48,48,48,48,48,48,48,48,48,48,48,48,48,48,48,48,48,48,48,48,48,48,48,48,48,48,48,48,48,48,48,48,48,48,48,48,48,48,48,48,48,48,48,48,1,1,13,13,13,13,1,1,1,1,1,1,1,15
#wrecked outer column
rule13=1,95,48,48,48,48,48,48,48,48,48,48,48,48,48,48,48,48,48,48,48,48,48,48,48,48,48,48,48,48,48,48,48,48,48,48,48,48,48,48,48,48,48,48,48,48,48,48,48,48,48,48,48,48,48,48,48,48,48,48,48,48,48,48,48,48,48,48,48,48,48,48,48,48,48,48,48,48,48,48,48,48,48,48,48,48,48,48,48,48,48,48,48,48,48,1,1,13,13,13,13,1,1,1,1,1,1,1,15
#wrecked floor
rule14=2,70,48,48,48,48,48,48,48,48,48,48,48,48,48,48,48,48,48,48,48,48,48,48,48,48,48,48,48,48,48,48,48,48,48,48,48,48,48,48,48,48,48,48,48,48,48,48,48,48,48,48,48,48,48,48,48,48,48,48,48,48,48,48,48,48,48,48,48,48,48,48,48,48,48,48,48,48,48,48,48,48,48,48,48,48,48,1,1,13,13,13,1,1,1,1,1,1,1,15
rule15=0,0,50-4
#roof edge
rule16=2,100,48
rule17=0,100,67-2
rule18=0,95,4
rule19=0,100,35-11
rule20=0,100,67-3
rule21=0,100,96-3


layer
1,2,2,2,1,2,2,2,1,2,2,2,1,2,2,2,1,2,2,2,1,2,2,2,1
2,2,2,2,2,2,2,2,2,2,2,2,2,2,2,2,2,2,2,2,2,2,2,2,2
2,2,2,2,2,2,2,2,2,2,2,2,2,2,2,2,2,2,2,2,2,2,2,2,2
2,2,2,2,2,2,2,2,2,2,2,2,2,2,2,2,2,2,2,2,2,2,2,2,2
1,2,2,2,3,2,2,2,2,2,2,2,2,2,2,2,2,2,2,2,3,2,2,2,1
2,2,2,2,2,2,2,2,2,2,2,2,2,2,2,2,2,2,2,2,2,2,2,2,2
2,2,2,2,2,2,2,2,2,2,2,2,2,2,2,2,2,2,2,2,2,2,2,2,2
2,2,2,2,2,2,2,2,2,2,2,2,2,2,2,2,2,2,2,2,2,2,2,2,2
1,2,2,2,3,2,2,2,2,2,2,2,2,2,2,2,2,2,2,2,3,2,2,2,1
2,2,2,2,2,2,2,2,2,2,2,2,2,2,2,2,2,2,2,2,2,2,2,2,2
2,2,2,2,2,2,2,2,2,5,0,2,2,2,0,0,2,2,2,2,2,2,2,2,2
2,2,2,2,2,2,2,2,2,0,0,2,2,2,0,0,2,2,2,2,2,2,2,2,2
1,2,2,2,3,2,2,2,2,2,2,2,2,2,2,2,2,2,2,2,3,2,2,2,1
2,2,2,2,2,2,2,2,2,5,0,2,2,2,0,0,2,2,2,2,2,2,2,2,2
2,2,2,2,2,2,2,2,2,0,0,2,2,2,0,4,2,2,2,2,2,2,2,2,2
2,2,2,2,2,2,2,2,2,2,2,2,2,2,2,2,2,2,2,2,2,2,2,2,2
1,2,2,2,3,2,2,2,2,2,2,2,2,2,2,2,2,2,2,2,3,2,2,2,1
2,2,2,2,2,2,2,2,2,2,2,2,2,2,2,2,2,2,2,2,2,2,2,2,2
2,2,2,2,2,2,2,2,2,2,2,2,2,2,2,2,2,2,2,2,2,2,2,2,2
2,2,2,2,2,2,2,2,2,2,2,2,2,2,2,2,2,2,2,2,2,2,2,2,2
1,2,2,2,3,2,2,2,2,2,2,2,2,2,2,2,2,2,2,2,3,2,2,2,1
2,2,2,2,2,2,2,2,2,2,2,2,2,2,2,2,2,2,2,2,2,2,2,2,2
2,2,2,2,2,2,2,2,2,2,2,2,2,2,2,2,2,2,2,2,2,2,2,2,2
2,2,2,2,2,2,2,2,2,2,2,2,2,2,2,2,2,2,2,2,2,2,2,2,2
1,2,2,2,1,2,2,2,1,2,2,2,1,2,2,2,1,2,2,2,1,2,2,2,1
endlayer

layer
1,6,6,6,1,7,7,7,1,0,8,0,1,0,8,0,1,7,7,7,1,6,6,6,1
6,0,0,0,0,0,0,0,0,0,0,0,0,0,0,0,0,0,0,0,0,0,0,0,6
6,0,0,0,0,0,0,0,0,0,0,0,0,0,0,0,0,0,0,0,0,0,0,0,6
6,0,0,0,0,0,0,0,0,0,0,0,0,0,0,0,0,0,0,0,0,0,0,0,6
1,0,0,0,3,0,0,0,0,0,0,0,0,0,0,0,0,0,0,0,3,0,0,0,1
6,0,0,0,0,0,0,0,0,0,0,0,0,0,0,0,0,0,0,0,0,0,0,0,6
6,0,0,0,0,0,0,0,0,0,0,0,0,0,0,0,0,0,0,0,0,0,0,0,6
6,0,0,0,0,0,0,0,0,0,0,0,0,0,0,0,0,0,0,0,0,0,0,0,6
1,0,0,0,3,0,0,0,0,0,0,0,0,0,0,0,0,0,0,0,3,0,0,0,1
6,0,0,0,0,0,0,0,2,2,2,0,0,0,2,2,2,0,0,0,0,0,0,0,6
6,0,0,0,0,0,0,0,2,5,0,0,0,0,0,0,2,0,0,0,0,0,0,0,6
6,0,0,0,0,0,0,0,2,0,0,0,0,0,0,4,2,0,0,0,0,0,0,0,6
1,0,0,0,3,0,0,0,2,2,2,0,0,0,2,2,2,0,0,0,3,0,0,0,1
6,0,0,0,0,0,0,0,2,5,0,0,0,0,0,0,2,0,0,0,0,0,0,0,6
6,0,0,0,0,0,0,0,2,0,0,0,0,0,0,4,2,0,0,0,0,0,0,0,6
6,0,0,0,0,0,0,0,2,2,2,0,0,0,2,2,2,0,0,0,0,0,0,0,6
1,0,0,0,3,0,0,0,0,0,0,0,0,0,0,0,0,0,0,0,3,0,0,0,1
6,0,0,0,0,0,0,0,0,0,0,0,0,0,0,0,0,0,0,0,0,0,0,0,6
6,0,0,0,0,0,0,0,0,0,0,0,0,0,0,0,0,0,0,0,0,0,0,0,6
6,0,0,0,0,0,0,0,0,0,0,0,0,0,0,0,0,0,0,0,0,0,0,0,6
1,0,0,0,3,0,0,0,0,0,0,0,0,0,0,0,0,0,0,0,3,0,0,0,1
6,0,0,0,0,0,0,0,0,0,0,0,0,0,0,0,0,0,0,0,0,0,0,0,6
6,0,0,0,0,0,0,0,0,0,0,0,0,0,0,0,0,0,0,0,0,0,0,0,6
6,0,0,0,0,0,0,0,0,0,0,0,0,0,0,0,0,0,0,0,0,0,0,0,6
1,6,6,6,1,7,7,7,1,0,8,0,1,0,8,0,1,7,7,7,1,6,6,6,1
endlayer

layer
1,6,6,6,1,7,7,7,1,0,8,0,1,0,8,0,1,7,7,7,1,6,6,6,1
6,0,0,0,0,0,0,0,0,0,0,0,0,0,0,0,0,0,0,0,0,0,0,0,6
6,0,0,0,0,0,0,0,0,0,0,0,0,0,0,0,0,0,0,0,0,0,0,0,6
6,0,0,0,0,0,0,0,0,0,0,0,0,0,0,0,0,0,0,0,0,0,0,0,6
1,0,0,0,3,0,0,0,0,0,0,0,0,0,0,0,0,0,0,0,3,0,0,0,1
6,0,0,0,0,0,0,0,0,0,0,0,0,0,0,0,0,0,0,0,0,0,0,0,6
6,0,0,0,0,0,0,0,0,0,0,0,0,0,0,0,0,0,0,0,0,0,0,0,6
6,0,0,0,0,0,0,0,0,0,0,0,0,0,0,0,0,0,0,0,0,0,0,0,6
1,0,0,0,3,0,0,0,0,0,0,0,0,0,0,0,0,0,0,0,3,0,0,0,1
6,0,0,0,0,0,0,0,2,2,2,0,0,0,2,2,2,0,0,0,0,0,0,0,6
6,0,0,0,0,0,0,0,2,5,0,0,0,0,0,0,2,0,0,0,0,0,0,0,6
6,0,0,0,0,0,0,0,2,0,0,0,0,0,0,4,2,0,0,0,0,0,0,0,6
1,0,0,0,3,0,0,0,2,2,2,0,0,0,2,2,2,0,0,0,3,0,0,0,1
6,0,0,0,0,0,0,0,2,5,0,0,0,0,0,0,2,0,0,0,0,0,0,0,6
6,0,0,0,0,0,0,0,2,0,0,0,0,0,0,4,2,0,0,0,0,0,0,0,6
6,0,0,0,0,0,0,0,2,2,2,0,0,0,2,2,2,0,0,0,0,0,0,0,6
1,0,0,0,3,0,0,0,0,0,0,0,0,0,0,0,0,0,0,0,3,0,0,0,1
6,0,0,0,0,0,0,0,0,0,0,0,0,0,0,0,0,0,0,0,0,0,0,0,6
6,0,0,0,0,0,0,0,0,0,0,0,0,0,0,0,0,0,0,0,0,0,0,0,6
6,0,0,0,0,0,0,0,0,0,0,0,0,0,0,0,0,0,0,0,0,0,0,0,6
1,0,0,0,3,0,0,0,0,0,0,0,0,0,0,0,0,0,0,0,3,0,0,0,1
6,0,0,0,0,0,0,0,0,0,0,0,0,0,0,0,0,0,0,0,0,0,0,0,6
6,0,0,0,0,0,0,0,0,0,0,0,0,0,0,0,0,0,0,0,0,0,0,0,6
6,0,0,0,0,0,0,0,0,0,0,0,0,0,0,0,0,0,0,0,0,0,0,0,6
1,6,6,6,1,7,7,7,1,0,8,0,1,0,8,0,1,7,7,7,1,6,6,6,1
endlayer

layer
1,6,6,6,1,7,7,7,1,7,7,7,1,7,7,7,1,7,7,7,1,6,6,6,1
6,0,0,0,0,0,0,0,0,0,0,0,0,0,0,0,0,0,0,0,0,0,0,0,6
6,0,0,0,0,0,0,0,0,0,0,0,0,0,0,0,0,0,0,0,0,0,0,0,6
6,0,0,0,0,0,0,0,0,0,0,0,0,0,0,0,0,0,0,0,0,0,0,0,6
1,0,0,0,3,0,0,0,0,0,0,0,0,0,0,0,0,0,0,0,3,0,0,0,1
6,0,0,0,0,0,0,0,0,0,0,0,0,0,0,0,0,0,0,0,0,0,0,0,6
6,0,0,0,0,0,0,0,0,0,0,0,0,0,0,0,0,0,0,0,0,0,0,0,6
6,0,0,0,0,0,0,0,0,0,0,0,0,0,0,0,0,0,0,0,0,0,0,0,6
1,0,0,0,3,0,0,0,0,0,0,0,0,0,0,0,0,0,0,0,3,0,0,0,1
6,0,0,0,0,0,0,0,2,2,2,0,0,0,2,2,2,0,0,0,0,0,0,0,6
6,0,0,0,0,0,0,0,2,5,0,0,0,0,0,0,2,0,0,0,0,0,0,0,6
6,0,0,0,0,0,0,0,2,0,0,0,0,0,0,4,2,0,0,0,0,0,0,0,6
1,0,0,0,3,0,0,0,2,2,2,0,0,0,2,2,2,0,0,0,3,0,0,0,1
6,0,0,0,0,0,0,0,2,5,0,0,0,0,0,0,2,0,0,0,0,0,0,0,6
6,0,0,0,0,0,0,0,2,0,0,0,0,0,0,4,2,0,0,0,0,0,0,0,6
6,0,0,0,0,0,0,0,2,2,2,0,0,0,2,2,2,0,0,0,0,0,0,0,6
1,0,0,0,3,0,0,0,0,0,0,0,0,0,0,0,0,0,0,0,3,0,0,0,1
6,0,0,0,0,0,0,0,0,0,0,0,0,0,0,0,0,0,0,0,0,0,0,0,6
6,0,0,0,0,0,0,0,0,0,0,0,0,0,0,0,0,0,0,0,0,0,0,0,6
6,0,0,0,0,0,0,0,0,0,0,0,0,0,0,0,0,0,0,0,0,0,0,0,6
1,0,0,0,3,0,0,0,0,0,0,0,0,0,0,0,0,0,0,0,3,0,0,0,1
6,0,0,0,0,0,0,0,0,0,0,0,0,0,0,0,0,0,0,0,0,0,0,0,6
6,0,0,0,0,0,0,0,0,0,0,0,0,0,0,0,0,0,0,0,0,0,0,0,6
6,0,0,0,0,0,0,0,0,0,0,0,0,0,0,0,0,0,0,0,0,0,0,0,6
1,6,6,6,1,7,7,7,1,7,7,7,1,7,7,7,1,7,7,7,1,6,6,6,1
endlayer

layer
1,9,9,9,1,9,9,9,1,9,9,9,1,9,9,9,1,9,9,9,1,9,9,9,1
9,9,9,9,9,9,9,9,9,9,9,9,9,9,9,9,9,9,9,9,9,9,9,9,9
9,9,9,9,9,9,9,9,9,9,9,9,9,9,9,9,9,9,9,9,9,9,9,9,9
9,9,9,9,9,9,9,9,9,9,9,9,9,9,9,9,9,9,9,9,9,9,9,9,9
1,9,9,9,3,9,9,9,3,2,2,9,9,9,2,2,3,9,9,9,3,9,9,9,1
9,9,9,9,9,9,9,9,9,9,2,9,9,9,2,9,9,9,9,9,9,9,9,9,9
9,9,9,9,9,9,9,9,9,9,2,9,9,9,2,9,9,9,9,9,9,9,9,9,9
9,9,9,9,9,9,9,9,9,9,2,9,9,9,2,9,9,9,9,9,9,9,9,9,9
1,9,9,9,3,9,9,9,9,9,2,9,9,9,2,9,9,9,9,9,3,9,9,9,1
9,9,9,9,9,9,9,9,2,2,2,9,9,9,2,2,2,9,9,9,9,9,9,9,9
9,9,9,9,9,9,9,9,2,5,0,9,9,9,0,0,2,9,9,9,9,9,9,9,9
9,9,9,9,9,9,9,9,2,0,0,9,9,9,0,4,2,9,9,9,9,9,9,9,9
1,9,9,9,3,9,9,9,2,2,2,9,9,9,2,2,2,9,9,9,3,9,9,9,1
9,9,9,9,9,9,9,9,2,5,0,9,9,9,0,0,2,9,9,9,9,9,9,9,9
9,9,9,9,9,9,9,9,2,0,0,9,9,9,0,4,2,9,9,9,9,9,9,9,9
9,9,9,9,9,9,9,9,2,2,2,9,9,9,2,2,2,9,9,9,9,9,9,9,9
1,9,9,9,3,9,9,9,9,9,2,9,9,9,2,9,9,9,9,9,3,9,9,9,1
9,9,9,9,9,9,9,9,9,9,2,9,9,9,2,9,9,9,9,9,9,9,9,9,9
9,9,9,9,9,9,9,9,9,9,2,9,9,9,2,9,9,9,9,9,9,9,9,9,9
9,9,9,9,9,9,9,9,9,9,2,9,9,9,2,9,9,9,9,9,9,9,9,9,9
1,9,9,9,3,9,9,9,3,2,2,9,9,9,2,2,3,9,9,9,3,9,9,9,1
9,9,9,9,9,9,9,9,9,9,9,9,9,9,9,9,9,9,9,9,9,9,9,9,9
9,9,9,9,9,9,9,9,9,9,9,9,9,9,9,9,9,9,9,9,9,9,9,9,9
9,9,9,9,9,9,9,9,9,9,9,9,9,9,9,9,9,9,9,9,9,9,9,9,9
1,9,9,9,1,9,9,9,1,9,9,9,1,9,9,9,1,9,9,9,1,9,9,9,1
endlayer

layer
1,10,10,10,1,10,10,10,1,10,10,10,1,10,10,10,1,10,10,10,1,10,10,10,1
10,10,10,10,10,10,10,10,10,10,10,10,10,10,10,10,10,10,10,10,10,10,10,10,10
10,10,10,10,10,10,10,10,10,10,10,10,10,10,10,10,10,10,10,10,10,10,10,10,10
10,10,10,10,10,10,10,10,10,10,10,10,10,10,10,10,10,10,10,10,10,10,10,10,10
1,10,10,10,3,10,10,10,3,10,10,10,10,10,2,2,3,10,10,10,3,10,10,10,1
10,10,10,10,10,10,10,10,10,10,10,10,10,10,2,10,10,10,10,10,10,10,10,10,10
10,10,10,10,10,10,10,10,10,10,10,10,10,10,2,10,10,10,10,10,10,10,10,10,10
10,10,10,10,10,10,10,10,10,10,10,10,10,10,2,10,10,10,10,10,10,10,10,10,10
1,10,10,10,3,10,10,10,10,10,10,10,10,10,2,10,10,10,10,10,3,10,10,10,1
10,10,10,10,10,10,10,10,2,2,2,10,10,10,2,2,2,10,10,10,10,10,10,10,10
10,10,10,10,10,10,10,10,2,5,0,10,10,10,0,0,2,10,10,10,10,10,10,10,10
10,10,10,10,10,10,10,10,2,0,0,10,10,10,0,0,2,10,10,10,10,10,10,10,10
1,10,10,10,3,10,10,10,2,2,2,10,10,10,2,2,2,10,10,10,3,10,10,10,1
10,10,10,10,10,10,10,10,2,5,0,10,10,10,0,0,2,10,10,10,10,10,10,10,10
10,10,10,10,10,10,10,10,2,0,0,10,10,10,0,4,2,10,10,10,10,10,10,10,10
10,10,10,10,10,10,10,10,2,2,2,10,10,10,2,2,2,10,10,10,10,10,10,10,10
1,10,10,10,3,10,10,10,10,10,2,10,10,10,2,10,10,10,10,10,3,10,10,10,1
10,10,10,10,10,10,10,10,10,10,2,10,10,10,2,10,10,10,10,10,10,10,10,10,10
10,10,10,10,10,10,10,10,10,10,2,10,10,10,2,10,10,10,10,10,10,10,10,10,10
10,10,10,10,10,10,10,10,10,10,2,10,10,10,2,10,10,10,10,10,10,10,10,10,10
1,10,10,10,3,10,10,10,3,2,2,10,10,10,2,2,3,10,10,10,3,10,10,10,1
10,10,10,10,10,10,10,10,10,10,10,10,10,10,10,10,10,10,10,10,10,10,10,10,10
10,10,10,10,10,10,10,10,10,10,10,10,10,10,10,10,10,10,10,10,10,10,10,10,10
10,10,10,10,10,10,10,10,10,10,10,10,10,10,10,10,10,10,10,10,10,10,10,10,10
1,10,10,10,1,10,10,10,1,10,10,10,1,10,10,10,1,10,10,10,1,10,10,10,1
endlayer

layer
1,11,11,11,1,11,11,11,1,11,11,11,1,11,11,11,1,11,11,11,1,11,11,11,1
11,0,0,0,0,0,0,0,0,0,0,0,0,0,0,0,0,0,0,0,0,0,0,0,11
11,0,0,0,0,0,0,0,0,0,0,0,0,0,0,0,0,0,0,0,0,0,0,0,11
11,0,0,0,0,0,0,0,0,0,0,0,0,0,0,0,0,0,0,0,0,0,0,0,11
1,0,0,0,3,0,0,0,3,2,2,0,0,0,2,2,3,0,0,0,3,0,0,0,1
11,0,0,0,0,0,0,0,0,0,2,0,0,0,2,0,0,0,0,0,0,0,0,0,11
11,0,0,0,0,0,0,0,0,0,2,0,0,0,2,0,0,0,0,0,0,0,0,0,11
11,0,0,0,0,0,0,0,0,0,2,0,0,0,2,0,0,0,0,0,0,0,0,0,11
1,0,0,0,3,0,0,0,0,0,2,0,0,0,2,0,0,0,0,0,3,0,0,0,1
11,0,0,0,0,0,0,0,2,2,2,0,0,0,2,2,2,0,0,0,0,0,0,0,11
11,0,0,0,0,0,0,0,2,5,0,0,0,0,0,0,2,0,0,0,0,0,0,0,11
11,0,0,0,0,0,0,0,2,0,0,0,0,0,0,4,2,0,0,0,0,0,0,0,11
1,0,0,0,3,0,0,0,2,2,2,0,0,0,2,2,2,0,0,0,3,0,0,0,1
11,0,0,0,0,0,0,0,2,5,0,0,0,0,0,0,2,0,0,0,0,0,0,0,11
11,0,0,0,0,0,0,0,2,0,0,0,0,0,0,4,2,0,0,0,0,0,0,0,11
11,0,0,0,0,0,0,0,2,2,2,0,0,0,2,2,2,0,0,0,0,0,0,0,11
1,0,0,0,3,0,0,0,0,0,2,0,0,0,2,0,0,0,0,0,3,0,0,0,1
11,0,0,0,0,0,0,0,0,0,2,0,0,0,2,0,0,0,0,0,0,0,0,0,11
11,0,0,0,0,0,0,0,0,0,2,0,0,0,2,0,0,0,0,0,0,0,0,0,11
11,0,0,0,0,0,0,0,0,0,2,0,0,0,2,0,0,0,0,0,0,0,0,0,11
1,0,0,0,3,0,0,0,3,2,2,0,0,0,2,2,3,0,0,0,3,0,0,0,1
11,0,0,0,0,0,0,0,0,0,0,0,0,0,0,0,0,0,0,0,0,0,0,0,11
11,0,0,0,0,0,0,0,0,0,0,0,0,0,0,0,0,0,0,0,0,0,0,0,11
11,0,0,0,0,0,0,0,0,0,0,0,0,0,0,0,0,0,0,0,0,0,0,0,11
1,11,11,11,1,11,11,11,1,11,11,11,1,11,11,11,1,11,11,11,1,11,11,11,1
endlayer

layer
1,7,7,7,1,7,7,7,1,7,7,7,1,7,7,7,1,7,7,7,1,7,7,7,1
7,0,0,0,0,0,0,0,0,0,0,0,0,0,0,0,0,0,0,0,0,0,0,0,7
7,0,0,0,0,0,0,0,0,0,0,0,0,0,0,0,0,0,0,0,0,0,0,0,7
7,0,0,0,0,0,0,0,0,0,0,0,0,0,0,0,0,0,0,0,0,0,0,0,7
1,0,0,0,3,0,0,0,3,2,2,0,0,0,2,2,3,0,0,0,3,0,0,0,1
7,0,0,0,0,0,0,0,0,0,2,0,0,0,2,0,0,0,0,0,0,0,0,0,7
7,0,0,0,0,0,0,0,0,0,2,0,0,0,2,0,0,0,0,0,0,0,0,0,7
7,0,0,0,0,0,0,0,0,0,2,0,0,0,2,0,0,0,0,0,0,0,0,0,7
1,0,0,0,3,0,0,0,0,0,2,0,0,0,2,0,0,0,0,0,3,0,0,0,1
7,0,0,0,0,0,0,0,2,2,2,0,0,0,2,2,2,0,0,0,0,0,0,0,7
7,0,0,0,0,0,0,0,2,5,0,0,0,0,0,0,2,0,0,0,0,0,0,0,7
7,0,0,0,0,0,0,0,2,0,0,0,0,0,0,4,2,0,0,0,0,0,0,0,7
1,0,0,0,3,0,0,0,2,2,2,0,0,0,2,2,2,0,0,0,3,0,0,0,1
7,0,0,0,0,0,0,0,2,5,0,0,0,0,0,0,2,0,0,0,0,0,0,0,7
7,0,0,0,0,0,0,0,2,0,0,0,0,0,0,4,2,0,0,0,0,0,0,0,7
7,0,0,0,0,0,0,0,2,2,2,0,0,0,2,2,2,0,0,0,0,0,0,0,7
1,0,0,0,3,0,0,0,0,0,2,0,0,0,2,0,0,0,0,0,3,0,0,0,1
7,0,0,0,0,0,0,0,0,0,2,0,0,0,2,0,0,0,0,0,0,0,0,0,7
7,0,0,0,0,0,0,0,0,0,2,0,0,0,2,0,0,0,0,0,0,0,0,0,7
7,0,0,0,0,0,0,0,0,0,2,0,0,0,2,0,0,0,0,0,0,0,0,0,7
1,0,0,0,3,0,0,0,3,2,2,0,0,0,2,2,3,0,0,0,3,0,0,0,1
7,0,0,0,0,0,0,0,0,0,0,0,0,0,0,0,0,0,0,0,0,0,0,0,7
7,0,0,0,0,0,0,0,0,0,0,0,0,0,0,0,0,0,0,0,0,0,0,0,7
7,0,0,0,0,0,0,0,0,0,0,0,0,0,0,0,0,0,0,0,0,0,0,0,7
1,7,7,7,1,7,7,7,1,7,7,7,1,7,7,7,1,7,7,7,1,7,7,7,1
endlayer

layer
1,7,7,7,1,7,7,7,1,7,7,7,1,7,7,7,1,7,7,7,1,7,7,7,1
7,0,0,0,0,0,0,0,0,0,0,0,0,0,0,0,0,0,0,0,0,0,0,0,7
7,0,0,0,0,0,0,0,0,0,0,0,0,0,0,0,0,0,0,0,0,0,0,0,7
7,0,0,0,0,0,0,0,0,0,0,0,0,0,0,0,0,0,0,0,0,0,0,0,7
1,0,0,0,3,0,0,0,3,2,2,0,0,0,2,2,3,0,0,0,3,0,0,0,1
7,0,0,0,0,0,0,0,0,0,2,0,0,0,2,0,0,0,0,0,0,0,0,0,7
7,0,0,0,0,0,0,0,0,0,2,0,0,0,2,0,0,0,0,0,0,0,0,0,7
7,0,0,0,0,0,0,0,0,0,2,0,0,0,2,0,0,0,0,0,0,0,0,0,7
1,0,0,0,3,0,0,0,0,0,2,0,0,0,2,0,0,0,0,0,3,0,0,0,1
7,0,0,0,0,0,0,0,2,2,2,0,0,0,2,2,2,0,0,0,0,0,0,0,7
7,0,0,0,0,0,0,0,2,5,0,0,0,0,0,0,2,0,0,0,0,0,0,0,7
7,0,0,0,0,0,0,0,2,0,0,0,0,0,0,4,2,0,0,0,0,0,0,0,7
1,0,0,0,3,0,0,0,2,2,2,0,0,0,2,2,2,0,0,0,3,0,0,0,1
7,0,0,0,0,0,0,0,2,5,0,0,0,0,0,0,2,0,0,0,0,0,0,0,7
7,0,0,0,0,0,0,0,2,0,0,0,0,0,0,4,2,0,0,0,0,0,0,0,7
7,0,0,0,0,0,0,0,2,2,2,0,0,0,2,2,2,0,0,0,0,0,0,0,7
1,0,0,0,3,0,0,0,0,0,2,0,0,0,2,0,0,0,0,0,3,0,0,0,1
7,0,0,0,0,0,0,0,0,0,2,0,0,0,2,0,0,0,0,0,0,0,0,0,7
7,0,0,0,0,0,0,0,0,0,2,0,0,0,2,0,0,0,0,0,0,0,0,0,7
7,0,0,0,0,0,0,0,0,0,2,0,0,0,2,0,0,0,0,0,0,0,0,0,7
1,0,0,0,3,0,0,0,3,2,2,0,0,0,2,2,3,0,0,0,3,0,0,0,1
7,0,0,0,0,0,0,0,0,0,0,0,0,0,0,0,0,0,0,0,0,0,0,0,7
7,0,0,0,0,0,0,0,0,0,0,0,0,0,0,0,0,0,0,0,0,0,0,0,7
7,0,0,0,0,0,0,0,0,0,0,0,0,0,0,0,0,0,0,0,0,0,0,0,7
1,7,7,7,1,7,7,7,1,7,7,7,1,7,7,7,1,7,7,7,1,7,7,7,1
endlayer

layer
1,9,9,9,1,9,9,9,1,9,9,9,1,9,9,9,1,9,9,9,1,9,9,9,1
9,9,9,9,9,9,9,9,9,9,9,9,9,9,9,9,9,9,9,9,9,9,9,9,9
9,9,9,9,9,9,9,9,9,9,9,9,9,9,9,9,9,9,9,9,9,9,9,9,9
9,9,9,9,9,9,9,9,9,9,9,9,9,9,9,9,9,9,9,9,9,9,9,9,9
1,9,9,9,3,9,9,9,3,2,2,9,9,9,2,2,3,9,9,9,3,9,9,9,1
9,9,9,9,9,9,9,9,9,9,2,9,9,9,2,9,9,9,9,9,9,9,9,9,9
9,9,9,9,9,9,9,9,9,9,2,9,9,9,2,9,9,9,9,9,9,9,9,9,9
9,9,9,9,9,9,9,9,9,9,2,9,9,9,2,9,9,9,9,9,9,9,9,9,9
1,9,9,9,3,9,9,9,9,9,2,9,9,9,2,9,9,9,9,9,3,9,9,9,1
9,9,9,9,9,9,9,9,2,2,2,9,9,9,2,2,2,9,9,9,9,9,9,9,9
9,9,9,9,9,9,9,9,2,5,0,9,9,9,0,0,2,9,9,9,9,9,9,9,9
9,9,9,9,9,9,9,9,2,0,0,9,9,9,0,4,2,9,9,9,9,9,9,9,9
1,9,9,9,3,9,9,9,2,2,2,9,9,9,2,2,2,9,9,9,3,9,9,9,1
9,9,9,9,9,9,9,9,2,5,0,9,9,9,0,0,2,9,9,9,9,9,9,9,9
9,9,9,9,9,9,9,9,2,0,0,9,9,9,0,4,2,9,9,9,9,9,9,9,9
9,9,9,9,9,9,9,9,2,2,2,9,9,9,2,2,2,9,9,9,9,9,9,9,9
1,9,9,9,3,9,9,9,9,9,2,9,9,9,2,9,9,9,9,9,3,9,9,9,1
9,9,9,9,9,9,9,9,9,9,2,9,9,9,2,9,9,9,9,9,9,9,9,9,9
9,9,9,9,9,9,9,9,9,9,2,9,9,9,2,9,9,9,9,9,9,9,9,9,9
9,9,9,9,9,9,9,9,9,9,2,9,9,9,2,9,9,9,9,9,9,9,9,9,9
1,9,9,9,3,9,9,9,3,2,2,9,9,9,2,2,3,9,9,9,3,9,9,9,1
9,9,9,9,9,9,9,9,9,9,9,9,9,9,9,9,9,9,9,9,9,9,9,9,9
9,9,9,9,9,9,9,9,9,9,9,9,9,9,9,9,9,9,9,9,9,9,9,9,9
9,9,9,9,9,9,9,9,9,9,9,9,9,9,9,9,9,9,9,9,9,9,9,9,9
1,9,9,9,1,9,9,9,1,9,9,9,1,9,9,9,1,9,9,9,1,9,9,9,1
endlayer

layer
1,10,10,10,1,10,10,10,1,10,10,10,1,10,10,10,1,10,10,10,1,10,10,10,1
10,10,10,10,10,10,10,10,10,10,10,10,10,10,10,10,10,10,10,10,10,10,10,10,10
10,10,10,10,10,10,10,10,10,10,10,10,10,10,10,10,10,10,10,10,10,10,10,10,10
10,10,10,10,10,10,10,10,10,10,10,10,10,10,10,10,10,10,10,10,10,10,10,10,10
1,10,10,10,3,10,10,10,3,10,10,10,10,10,2,2,3,10,10,10,3,10,10,10,1
10,10,10,10,10,10,10,10,10,10,10,10,10,10,2,10,10,10,10,10,10,10,10,10,10
10,10,10,10,10,10,10,10,10,10,10,10,10,10,2,10,10,10,10,10,10,10,10,10,10
10,10,10,10,10,10,10,10,10,10,10,10,10,10,2,10,10,10,10,10,10,10,10,10,10
1,10,10,10,3,10,10,10,10,10,10,10,10,10,2,10,10,10,10,10,3,10,10,10,1
10,10,10,10,10,10,10,10,2,2,2,10,10,10,2,2,2,10,10,10,10,10,10,10,10
10,10,10,10,10,10,10,10,2,5,0,10,10,10,0,0,2,10,10,10,10,10,10,10,10
10,10,10,10,10,10,10,10,2,0,0,10,10,10,0,0,2,10,10,10,10,10,10,10,10
1,10,10,10,3,10,10,10,2,2,2,10,10,10,2,2,2,10,10,10,3,10,10,10,1
10,10,10,10,10,10,10,10,2,5,0,10,10,10,0,0,2,10,10,10,10,10,10,10,10
10,10,10,10,10,10,10,10,2,0,0,10,10,10,0,4,2,10,10,10,10,10,10,10,10
10,10,10,10,10,10,10,10,2,2,2,10,10,10,2,2,2,10,10,10,10,10,10,10,10
1,10,10,10,3,10,10,10,10,10,2,10,10,10,2,10,10,10,10,10,3,10,10,10,1
10,10,10,10,10,10,10,10,10,10,2,10,10,10,2,10,10,10,10,10,10,10,10,10,10
10,10,10,10,10,10,10,10,10,10,2,10,10,10,2,10,10,10,10,10,10,10,10,10,10
10,10,10,10,10,10,10,10,10,10,2,10,10,10,2,10,10,10,10,10,10,10,10,10,10
1,10,10,10,3,10,10,10,3,2,2,10,10,10,2,2,3,10,10,10,3,10,10,10,1
10,10,10,10,10,10,10,10,10,10,10,10,10,10,10,10,10,10,10,10,10,10,10,10,10
10,10,10,10,10,10,10,10,10,10,10,10,10,10,10,10,10,10,10,10,10,10,10,10,10
10,10,10,10,10,10,10,10,10,10,10,10,10,10,10,10,10,10,10,10,10,10,10,10,10
1,10,10,10,1,10,10,10,1,10,10,10,1,10,10,10,1,10,10,10,1,10,10,10,1
endlayer

layer
1,11,11,11,1,11,11,11,1,11,11,11,1,11,11,11,1,11,11,11,1,11,11,11,1
11,0,0,0,0,0,0,0,0,0,0,0,0,0,0,0,0,0,0,0,0,0,0,0,11
11,0,0,0,0,0,0,0,0,0,0,0,0,0,0,0,0,0,0,0,0,0,0,0,11
11,0,0,0,0,0,0,0,0,0,0,0,0,0,0,0,0,0,0,0,0,0,0,0,11
1,0,0,0,3,0,0,0,3,2,2,0,0,0,2,2,3,0,0,0,3,0,0,0,1
11,0,0,0,0,0,0,0,0,0,2,0,0,0,2,0,0,0,0,0,0,0,0,0,11
11,0,0,0,0,0,0,0,0,0,2,0,0,0,2,0,0,0,0,0,0,0,0,0,11
11,0,0,0,0,0,0,0,0,0,2,0,0,0,2,0,0,0,0,0,0,0,0,0,11
1,0,0,0,3,0,0,0,0,0,2,0,0,0,2,0,0,0,0,0,3,0,0,0,1
11,0,0,0,0,0,0,0,2,2,2,0,0,0,2,2,2,0,0,0,0,0,0,0,11
11,0,0,0,0,0,0,0,2,5,0,0,0,0,0,0,2,0,0,0,0,0,0,0,11
11,0,0,0,0,0,0,0,2,0,0,0,0,0,0,4,2,0,0,0,0,0,0,0,11
1,0,0,0,3,0,0,0,2,2,2,0,0,0,2,2,2,0,0,0,3,0,0,0,1
11,0,0,0,0,0,0,0,2,5,0,0,0,0,0,0,2,0,0,0,0,0,0,0,11
11,0,0,0,0,0,0,0,2,0,0,0,0,0,0,4,2,0,0,0,0,0,0,0,11
11,0,0,0,0,0,0,0,2,2,2,0,0,0,2,2,2,0,0,0,0,0,0,0,11
1,0,0,0,3,0,0,0,0,0,2,0,0,0,2,0,0,0,0,0,3,0,0,0,1
11,0,0,0,0,0,0,0,0,0,2,0,0,0,2,0,0,0,0,0,0,0,0,0,11
11,0,0,0,0,0,0,0,0,0,2,0,0,0,2,0,0,0,0,0,0,0,0,0,11
11,0,0,0,0,0,0,0,0,0,2,0,0,0,2,0,0,0,0,0,0,0,0,0,11
1,0,0,0,3,0,0,0,3,2,2,0,0,0,2,2,3,0,0,0,3,0,0,0,1
11,0,0,0,0,0,0,0,0,0,0,0,0,0,0,0,0,0,0,0,0,0,0,0,11
11,0,0,0,0,0,0,0,0,0,0,0,0,0,0,0,0,0,0,0,0,0,0,0,11
11,0,0,0,0,0,0,0,0,0,0,0,0,0,0,0,0,0,0,0,0,0,0,0,11
1,11,11,11,1,11,11,11,1,11,11,11,1,11,11,11,1,11,11,11,1,11,11,11,1
endlayer

layer
1,7,7,7,1,7,7,7,1,7,7,7,1,7,7,7,1,7,7,7,1,7,7,7,1
7,0,0,0,0,0,0,0,0,0,0,0,0,0,0,0,0,0,0,0,0,0,0,0,7
7,0,0,0,0,0,0,0,0,0,0,0,0,0,0,0,0,0,0,0,0,0,0,0,7
7,0,0,0,0,0,0,0,0,0,0,0,0,0,0,0,0,0,0,0,0,0,0,0,7
1,0,0,0,3,0,0,0,3,2,2,0,0,0,2,2,3,0,0,0,3,0,0,0,1
7,0,0,0,0,0,0,0,0,0,2,0,0,0,2,0,0,0,0,0,0,0,0,0,7
7,0,0,0,0,0,0,0,0,0,2,0,0,0,2,0,0,0,0,0,0,0,0,0,7
7,0,0,0,0,0,0,0,0,0,2,0,0,0,2,0,0,0,0,0,0,0,0,0,7
1,0,0,0,3,0,0,0,0,0,2,0,0,0,2,0,0,0,0,0,3,0,0,0,1
7,0,0,0,0,0,0,0,2,2,2,0,0,0,2,2,2,0,0,0,0,0,0,0,7
7,0,0,0,0,0,0,0,2,5,0,0,0,0,0,0,2,0,0,0,0,0,0,0,7
7,0,0,0,0,0,0,0,2,0,0,0,0,0,0,4,2,0,0,0,0,0,0,0,7
1,0,0,0,3,0,0,0,2,2,2,0,0,0,2,2,2,0,0,0,3,0,0,0,1
7,0,0,0,0,0,0,0,2,5,0,0,0,0,0,0,2,0,0,0,0,0,0,0,7
7,0,0,0,0,0,0,0,2,0,0,0,0,0,0,4,2,0,0,0,0,0,0,0,7
7,0,0,0,0,0,0,0,2,2,2,0,0,0,2,2,2,0,0,0,0,0,0,0,7
1,0,0,0,3,0,0,0,0,0,2,0,0,0,2,0,0,0,0,0,3,0,0,0,1
7,0,0,0,0,0,0,0,0,0,2,0,0,0,2,0,0,0,0,0,0,0,0,0,7
7,0,0,0,0,0,0,0,0,0,2,0,0,0,2,0,0,0,0,0,0,0,0,0,7
7,0,0,0,0,0,0,0,0,0,2,0,0,0,2,0,0,0,0,0,0,0,0,0,7
1,0,0,0,3,0,0,0,3,2,2,0,0,0,2,2,3,0,0,0,3,0,0,0,1
7,0,0,0,0,0,0,0,0,0,0,0,0,0,0,0,0,0,0,0,0,0,0,0,7
7,0,0,0,0,0,0,0,0,0,0,0,0,0,0,0,0,0,0,0,0,0,0,0,7
7,0,0,0,0,0,0,0,0,0,0,0,0,0,0,0,0,0,0,0,0,0,0,0,7
1,7,7,7,1,7,7,7,1,7,7,7,1,7,7,7,1,7,7,7,1,7,7,7,1
endlayer

layer
1,7,7,7,1,7,7,7,1,7,7,7,1,7,7,7,1,7,7,7,1,7,7,7,1
7,0,0,0,0,0,0,0,0,0,0,0,0,0,0,0,0,0,0,0,0,0,0,0,7
7,0,0,0,0,0,0,0,0,0,0,0,0,0,0,0,0,0,0,0,0,0,0,0,7
7,0,0,0,0,0,0,0,0,0,0,0,0,0,0,0,0,0,0,0,0,0,0,0,7
1,0,0,0,3,0,0,0,3,2,2,0,0,0,2,2,3,0,0,0,3,0,0,0,1
7,0,0,0,0,0,0,0,0,0,2,0,0,0,2,0,0,0,0,0,0,0,0,0,7
7,0,0,0,0,0,0,0,0,0,2,0,0,0,2,0,0,0,0,0,0,0,0,0,7
7,0,0,0,0,0,0,0,0,0,2,0,0,0,2,0,0,0,0,0,0,0,0,0,7
1,0,0,0,3,0,0,0,0,0,2,0,0,0,2,0,0,0,0,0,3,0,0,0,1
7,0,0,0,0,0,0,0,2,2,2,0,0,0,2,2,2,0,0,0,0,0,0,0,7
7,0,0,0,0,0,0,0,2,5,0,0,0,0,0,0,2,0,0,0,0,0,0,0,7
7,0,0,0,0,0,0,0,2,0,0,0,0,0,0,4,2,0,0,0,0,0,0,0,7
1,0,0,0,3,0,0,0,2,2,2,0,0,0,2,2,2,0,0,0,3,0,0,0,1
7,0,0,0,0,0,0,0,2,5,0,0,0,0,0,0,2,0,0,0,0,0,0,0,7
7,0,0,0,0,0,0,0,2,0,0,0,0,0,0,4,2,0,0,0,0,0,0,0,7
7,0,0,0,0,0,0,0,2,2,2,0,0,0,2,2,2,0,0,0,0,0,0,0,7
1,0,0,0,3,0,0,0,0,0,2,0,0,0,2,0,0,0,0,0,3,0,0,0,1
7,0,0,0,0,0,0,0,0,0,2,0,0,0,2,0,0,0,0,0,0,0,0,0,7
7,0,0,0,0,0,0,0,0,0,2,0,0,0,2,0,0,0,0,0,0,0,0,0,7
7,0,0,0,0,0,0,0,0,0,2,0,0,0,2,0,0,0,0,0,0,0,0,0,7
1,0,0,0,3,0,0,0,3,2,2,0,0,0,2,2,3,0,0,0,3,0,0,0,1
7,0,0,0,0,0,0,0,0,0,0,0,0,0,0,0,0,0,0,0,0,0,0,0,7
7,0,0,0,0,0,0,0,0,0,0,0,0,0,0,0,0,0,0,0,0,0,0,0,7
7,0,0,0,0,0,0,0,0,0,0,0,0,0,0,0,0,0,0,0,0,0,0,0,7
1,7,7,7,1,7,7,7,1,7,7,7,1,7,7,7,1,7,7,7,1,7,7,7,1
endlayer

layer
1,9,9,9,1,9,9,9,1,9,9,9,1,9,9,9,1,9,9,9,1,9,9,9,1
9,9,9,9,9,9,9,9,9,9,9,9,9,9,9,9,9,9,9,9,9,9,9,9,9
9,9,9,9,9,9,9,9,9,9,9,9,9,9,9,9,9,9,9,9,9,9,9,9,9
9,9,9,9,9,9,9,9,9,9,9,9,9,9,9,9,9,9,9,9,9,9,9,9,9
1,9,9,9,3,9,9,9,3,2,2,9,9,9,2,2,3,9,9,9,3,9,9,9,1
9,9,9,9,9,9,9,9,9,9,2,9,9,9,2,9,9,9,9,9,9,9,9,9,9
9,9,9,9,9,9,9,9,9,9,2,9,9,9,2,9,9,9,9,9,9,9,9,9,9
9,9,9,9,9,9,9,9,9,9,2,9,9,9,2,9,9,9,9,9,9,9,9,9,9
1,9,9,9,3,9,9,9,9,9,2,9,9,9,2,9,9,9,9,9,3,9,9,9,1
9,9,9,9,9,9,9,9,2,2,2,9,9,9,2,2,2,9,9,9,9,9,9,9,9
9,9,9,9,9,9,9,9,2,5,0,9,9,9,0,0,2,9,9,9,9,9,9,9,9
9,9,9,9,9,9,9,9,2,0,0,9,9,9,0,4,2,9,9,9,9,9,9,9,9
1,9,9,9,3,9,9,9,2,2,2,9,9,9,2,2,2,9,9,9,3,9,9,9,1
9,9,9,9,9,9,9,9,2,5,0,9,9,9,0,0,2,9,9,9,9,9,9,9,9
9,9,9,9,9,9,9,9,2,0,0,9,9,9,0,4,2,9,9,9,9,9,9,9,9
9,9,9,9,9,9,9,9,2,2,2,9,9,9,2,2,2,9,9,9,9,9,9,9,9
1,9,9,9,3,9,9,9,9,9,2,9,9,9,2,9,9,9,9,9,3,9,9,9,1
9,9,9,9,9,9,9,9,9,9,2,9,9,9,2,9,9,9,9,9,9,9,9,9,9
9,9,9,9,9,9,9,9,9,9,2,9,9,9,2,9,9,9,9,9,9,9,9,9,9
9,9,9,9,9,9,9,9,9,9,2,9,9,9,2,9,9,9,9,9,9,9,9,9,9
1,9,9,9,3,9,9,9,3,2,2,9,9,9,2,2,3,9,9,9,3,9,9,9,1
9,9,9,9,9,9,9,9,9,9,9,9,9,9,9,9,9,9,9,9,9,9,9,9,9
9,9,9,9,9,9,9,9,9,9,9,9,9,9,9,9,9,9,9,9,9,9,9,9,9
9,9,9,9,9,9,9,9,9,9,9,9,9,9,9,9,9,9,9,9,9,9,9,9,9
1,9,9,9,1,9,9,9,1,9,9,9,1,9,9,9,1,9,9,9,1,9,9,9,1
endlayer

layer
1,10,10,10,1,10,10,10,1,10,10,10,1,10,10,10,1,10,10,10,1,10,10,10,1
10,10,10,10,10,10,10,10,10,10,10,10,10,10,10,10,10,10,10,10,10,10,10,10,10
10,10,10,10,10,10,10,10,10,10,10,10,10,10,10,10,10,10,10,10,10,10,10,10,10
10,10,10,10,10,10,10,10,10,10,10,10,10,10,10,10,10,10,10,10,10,10,10,10,10
1,10,10,10,3,10,10,10,3,10,10,10,10,10,2,2,3,10,10,10,3,10,10,10,1
10,10,10,10,10,10,10,10,10,10,10,10,10,10,2,10,10,10,10,10,10,10,10,10,10
10,10,10,10,10,10,10,10,10,10,10,10,10,10,2,10,10,10,10,10,10,10,10,10,10
10,10,10,10,10,10,10,10,10,10,10,10,10,10,2,10,10,10,10,10,10,10,10,10,10
1,10,10,10,3,10,10,10,10,10,10,10,10,10,2,10,10,10,10,10,3,10,10,10,1
10,10,10,10,10,10,10,10,2,2,2,10,10,10,2,2,2,10,10,10,10,10,10,10,10
10,10,10,10,10,10,10,10,2,5,0,10,10,10,0,0,2,10,10,10,10,10,10,10,10
10,10,10,10,10,10,10,10,2,0,0,10,10,10,0,0,2,10,10,10,10,10,10,10,10
1,10,10,10,3,10,10,10,2,2,2,10,10,10,2,2,2,10,10,10,3,10,10,10,1
10,10,10,10,10,10,10,10,2,5,0,10,10,10,0,0,2,10,10,10,10,10,10,10,10
10,10,10,10,10,10,10,10,2,0,0,10,10,10,0,4,2,10,10,10,10,10,10,10,10
10,10,10,10,10,10,10,10,2,2,2,10,10,10,2,2,2,10,10,10,10,10,10,10,10
1,10,10,10,3,10,10,10,10,10,2,10,10,10,2,10,10,10,10,10,3,10,10,10,1
10,10,10,10,10,10,10,10,10,10,2,10,10,10,2,10,10,10,10,10,10,10,10,10,10
10,10,10,10,10,10,10,10,10,10,2,10,10,10,2,10,10,10,10,10,10,10,10,10,10
10,10,10,10,10,10,10,10,10,10,2,10,10,10,2,10,10,10,10,10,10,10,10,10,10
1,10,10,10,3,10,10,10,3,2,2,10,10,10,2,2,3,10,10,10,3,10,10,10,1
10,10,10,10,10,10,10,10,10,10,10,10,10,10,10,10,10,10,10,10,10,10,10,10,10
10,10,10,10,10,10,10,10,10,10,10,10,10,10,10,10,10,10,10,10,10,10,10,10,10
10,10,10,10,10,10,10,10,10,10,10,10,10,10,10,10,10,10,10,10,10,10,10,10,10
1,10,10,10,1,10,10,10,1,10,10,10,1,10,10,10,1,10,10,10,1,10,10,10,1
endlayer

layer
1,11,11,11,1,11,11,11,1,11,11,11,1,11,11,11,1,11,11,11,1,11,11,11,1
11,0,0,0,0,0,0,0,0,0,0,0,0,0,0,0,0,0,0,0,0,0,0,0,11
11,0,0,0,0,0,0,0,0,0,0,0,0,0,0,0,0,0,0,0,0,0,0,0,11
11,0,0,0,0,0,0,0,0,0,0,0,0,0,0,0,0,0,0,0,0,0,0,0,11
1,0,0,0,3,0,0,0,3,2,2,0,0,0,2,2,3,0,0,0,3,0,0,0,1
11,0,0,0,0,0,0,0,0,0,2,0,0,0,2,0,0,0,0,0,0,0,0,0,11
11,0,0,0,0,0,0,0,0,0,2,0,0,0,2,0,0,0,0,0,0,0,0,0,11
11,0,0,0,0,0,0,0,0,0,2,0,0,0,2,0,0,0,0,0,0,0,0,0,11
1,0,0,0,3,0,0,0,0,0,2,0,0,0,2,0,0,0,0,0,3,0,0,0,1
11,0,0,0,0,0,0,0,2,2,2,0,0,0,2,2,2,0,0,0,0,0,0,0,11
11,0,0,0,0,0,0,0,2,5,0,0,0,0,0,0,2,0,0,0,0,0,0,0,11
11,0,0,0,0,0,0,0,2,0,0,0,0,0,0,4,2,0,0,0,0,0,0,0,11
1,0,0,0,3,0,0,0,2,2,2,0,0,0,2,2,2,0,0,0,3,0,0,0,1
11,0,0,0,0,0,0,0,2,5,0,0,0,0,0,0,2,0,0,0,0,0,0,0,11
11,0,0,0,0,0,0,0,2,0,0,0,0,0,0,4,2,0,0,0,0,0,0,0,11
11,0,0,0,0,0,0,0,2,2,2,0,0,0,2,2,2,0,0,0,0,0,0,0,11
1,0,0,0,3,0,0,0,0,0,2,0,0,0,2,0,0,0,0,0,3,0,0,0,1
11,0,0,0,0,0,0,0,0,0,2,0,0,0,2,0,0,0,0,0,0,0,0,0,11
11,0,0,0,0,0,0,0,0,0,2,0,0,0,2,0,0,0,0,0,0,0,0,0,11
11,0,0,0,0,0,0,0,0,0,2,0,0,0,2,0,0,0,0,0,0,0,0,0,11
1,0,0,0,3,0,0,0,3,2,2,0,0,0,2,2,3,0,0,0,3,0,0,0,1
11,0,0,0,0,0,0,0,0,0,0,0,0,0,0,0,0,0,0,0,0,0,0,0,11
11,0,0,0,0,0,0,0,0,0,0,0,0,0,0,0,0,0,0,0,0,0,0,0,11
11,0,0,0,0,0,0,0,0,0,0,0,0,0,0,0,0,0,0,0,0,0,0,0,11
1,11,11,11,1,11,11,11,1,11,11,11,1,11,11,11,1,11,11,11,1,11,11,11,1
endlayer

layer
1,7,7,7,1,7,7,7,1,7,7,7,1,7,7,7,1,7,7,7,1,7,7,7,1
7,0,0,0,0,0,0,0,0,0,0,0,0,0,0,0,0,0,0,0,0,0,0,0,7
7,0,0,0,0,0,0,0,0,0,0,0,0,0,0,0,0,0,0,0,0,0,0,0,7
7,0,0,0,0,0,0,0,0,0,0,0,0,0,0,0,0,0,0,0,0,0,0,0,7
1,0,0,0,3,0,0,0,3,2,2,0,0,0,2,2,3,0,0,0,3,0,0,0,1
7,0,0,0,0,0,0,0,0,0,2,0,0,0,2,0,0,0,0,0,0,0,0,0,7
7,0,0,0,0,0,0,0,0,0,2,0,0,0,2,0,0,0,0,0,0,0,0,0,7
7,0,0,0,0,0,0,0,0,0,2,0,0,0,2,0,0,0,0,0,0,0,0,0,7
1,0,0,0,3,0,0,0,0,0,2,0,0,0,2,0,0,0,0,0,3,0,0,0,1
7,0,0,0,0,0,0,0,2,2,2,0,0,0,2,2,2,0,0,0,0,0,0,0,7
7,0,0,0,0,0,0,0,2,5,0,0,0,0,0,0,2,0,0,0,0,0,0,0,7
7,0,0,0,0,0,0,0,2,0,0,0,0,0,0,4,2,0,0,0,0,0,0,0,7
1,0,0,0,3,0,0,0,2,2,2,0,0,0,2,2,2,0,0,0,3,0,0,0,1
7,0,0,0,0,0,0,0,2,5,0,0,0,0,0,0,2,0,0,0,0,0,0,0,7
7,0,0,0,0,0,0,0,2,0,0,0,0,0,0,4,2,0,0,0,0,0,0,0,7
7,0,0,0,0,0,0,0,2,2,2,0,0,0,2,2,2,0,0,0,0,0,0,0,7
1,0,0,0,3,0,0,0,0,0,2,0,0,0,2,0,0,0,0,0,3,0,0,0,1
7,0,0,0,0,0,0,0,0,0,2,0,0,0,2,0,0,0,0,0,0,0,0,0,7
7,0,0,0,0,0,0,0,0,0,2,0,0,0,2,0,0,0,0,0,0,0,0,0,7
7,0,0,0,0,0,0,0,0,0,2,0,0,0,2,0,0,0,0,0,0,0,0,0,7
1,0,0,0,3,0,0,0,3,2,2,0,0,0,2,2,3,0,0,0,3,0,0,0,1
7,0,0,0,0,0,0,0,0,0,0,0,0,0,0,0,0,0,0,0,0,0,0,0,7
7,0,0,0,0,0,0,0,0,0,0,0,0,0,0,0,0,0,0,0,0,0,0,0,7
7,0,0,0,0,0,0,0,0,0,0,0,0,0,0,0,0,0,0,0,0,0,0,0,7
1,7,7,7,1,7,7,7,1,7,7,7,1,7,7,7,1,7,7,7,1,7,7,7,1
endlayer

layer
1,7,7,7,1,7,7,7,1,7,7,7,1,7,7,7,1,7,7,7,1,7,7,7,1
7,0,0,0,0,0,0,0,0,0,0,0,0,0,0,0,0,0,0,0,0,0,0,0,7
7,0,0,0,0,0,0,0,0,0,0,0,0,0,0,0,0,0,0,0,0,0,0,0,7
7,0,0,0,0,0,0,0,0,0,0,0,0,0,0,0,0,0,0,0,0,0,0,0,7
1,0,0,0,3,0,0,0,3,2,2,0,0,0,2,2,3,0,0,0,3,0,0,0,1
7,0,0,0,0,0,0,0,0,0,2,0,0,0,2,0,0,0,0,0,0,0,0,0,7
7,0,0,0,0,0,0,0,0,0,2,0,0,0,2,0,0,0,0,0,0,0,0,0,7
7,0,0,0,0,0,0,0,0,0,2,0,0,0,2,0,0,0,0,0,0,0,0,0,7
1,0,0,0,3,0,0,0,0,0,2,0,0,0,2,0,0,0,0,0,3,0,0,0,1
7,0,0,0,0,0,0,0,2,2,2,0,0,0,2,2,2,0,0,0,0,0,0,0,7
7,0,0,0,0,0,0,0,2,5,0,0,0,0,0,0,2,0,0,0,0,0,0,0,7
7,0,0,0,0,0,0,0,2,0,0,0,0,0,0,4,2,0,0,0,0,0,0,0,7
1,0,0,0,3,0,0,0,2,2,2,0,0,0,2,2,2,0,0,0,3,0,0,0,1
7,0,0,0,0,0,0,0,2,5,0,0,0,0,0,0,2,0,0,0,0,0,0,0,7
7,0,0,0,0,0,0,0,2,0,0,0,0,0,0,4,2,0,0,0,0,0,0,0,7
7,0,0,0,0,0,0,0,2,2,2,0,0,0,2,2,2,0,0,0,0,0,0,0,7
1,0,0,0,3,0,0,0,0,0,2,0,0,0,2,0,0,0,0,0,3,0,0,0,1
7,0,0,0,0,0,0,0,0,0,2,0,0,0,2,0,0,0,0,0,0,0,0,0,7
7,0,0,0,0,0,0,0,0,0,2,0,0,0,2,0,0,0,0,0,0,0,0,0,7
7,0,0,0,0,0,0,0,0,0,2,0,0,0,2,0,0,0,0,0,0,0,0,0,7
1,0,0,0,3,0,0,0,3,2,2,0,0,0,2,2,3,0,0,0,3,0,0,0,1
7,0,0,0,0,0,0,0,0,0,0,0,0,0,0,0,0,0,0,0,0,0,0,0,7
7,0,0,0,0,0,0,0,0,0,0,0,0,0,0,0,0,0,0,0,0,0,0,0,7
7,0,0,0,0,0,0,0,0,0,0,0,0,0,0,0,0,0,0,0,0,0,0,0,7
1,7,7,7,1,7,7,7,1,7,7,7,1,7,7,7,1,7,7,7,1,7,7,7,1
endlayer

layer
12,9,9,9,12,9,9,9,12,9,9,9,12,9,9,9,12,9,9,9,12,9,9,9,12
9,9,9,9,9,9,9,9,9,9,9,9,9,9,9,9,9,9,9,9,9,9,9,9,9
9,9,9,9,9,9,9,9,9,9,9,9,9,9,9,9,9,9,9,9,9,9,9,9,9
9,9,9,9,9,9,9,9,9,9,9,9,9,9,9,9,9,9,9,9,9,9,9,9,9
12,9,9,9,3,9,9,9,3,2,2,9,9,9,2,2,3,9,9,9,3,9,9,9,12
9,9,9,9,9,9,9,9,9,9,2,9,9,9,2,9,9,9,9,9,9,9,9,9,9
9,9,9,9,9,9,9,9,9,9,2,9,9,9,2,9,9,9,9,9,9,9,9,9,9
9,9,9,9,9,9,9,9,9,9,2,9,9,9,2,9,9,9,9,9,9,9,9,9,9
12,9,9,9,3,9,9,9,9,9,2,9,9,9,2,9,9,9,9,9,3,9,9,9,12
9,9,9,9,9,9,9,9,2,2,2,9,9,9,2,2,2,9,9,9,9,9,9,9,9
9,9,9,9,9,9,9,9,2,5,0,9,9,9,0,0,2,9,9,9,9,9,9,9,9
9,9,9,9,9,9,9,9,2,0,0,9,9,9,0,4,2,9,9,9,9,9,9,9,9
12,9,9,9,3,9,9,9,2,2,2,9,9,9,2,2,2,9,9,9,3,9,9,9,12
9,9,9,9,9,9,9,9,2,5,0,9,9,9,0,0,2,9,9,9,9,9,9,9,9
9,9,9,9,9,9,9,9,2,0,0,9,9,9,0,4,2,9,9,9,9,9,9,9,9
9,9,9,9,9,9,9,9,2,2,2,9,9,9,2,2,2,9,9,9,9,9,9,9,9
12,9,9,9,3,9,9,9,9,9,2,9,9,9,2,9,9,9,9,9,3,9,9,9,12
9,9,9,9,9,9,9,9,9,9,2,9,9,9,2,9,9,9,9,9,9,9,9,9,9
9,9,9,9,9,9,9,9,9,9,2,9,9,9,2,9,9,9,9,9,9,9,9,9,9
9,9,9,9,9,9,9,9,9,9,2,9,9,9,2,9,9,9,9,9,9,9,9,9,9
12,9,9,9,3,9,9,9,3,2,2,9,9,9,2,2,3,9,9,9,3,9,9,9,12
9,9,9,9,9,9,9,9,9,9,9,9,9,9,9,9,9,9,9,9,9,9,9,9,9
9,9,9,9,9,9,9,9,9,9,9,9,9,9,9,9,9,9,9,9,9,9,9,9,9
9,9,9,9,9,9,9,9,9,9,9,9,9,9,9,9,9,9,9,9,9,9,9,9,9
12,9,9,9,12,9,9,9,12,9,9,9,12,9,9,9,12,9,9,9,12,9,9,9,12
endlayer

layer
13,14,14,14,13,14,14,14,13,14,14,14,13,14,14,14,13,14,14,14,13,14,14,14,13
14,14,14,14,14,14,14,14,14,14,14,14,14,14,14,14,14,14,14,14,14,14,14,14,14
14,14,14,14,14,14,14,14,14,14,14,14,14,14,14,14,14,14,14,14,14,14,14,14,14
14,14,14,14,14,14,14,14,14,14,14,14,14,14,14,14,14,14,14,14,14,14,14,14,14
13,14,14,14,3,14,14,14,3,2,2,14,14,14,2,2,3,14,14,14,3,14,14,14,13
14,14,14,14,14,10,10,10,10,10,2,10,10,10,2,10,10,10,10,10,14,14,14,14,14
14,14,14,14,14,10,10,10,10,10,2,10,10,10,2,10,10,10,10,10,14,14,14,14,14
14,14,14,14,14,10,10,10,10,10,2,10,10,10,2,10,10,10,10,10,14,14,14,14,14
13,14,14,14,3,10,10,10,10,10,2,10,10,10,2,10,10,10,10,10,3,14,14,14,13
14,14,14,14,14,10,10,10,2,2,2,10,10,10,2,2,2,10,10,10,14,14,14,14,14
14,14,14,14,14,10,10,10,2,5,0,10,10,10,0,0,2,10,10,10,14,14,14,14,14
14,14,14,14,14,10,10,10,2,0,0,10,10,10,0,0,2,10,10,10,14,14,14,14,14
13,14,14,14,3,10,10,10,2,2,2,10,10,10,2,2,2,10,10,10,3,14,14,14,13
14,14,14,14,14,10,10,10,2,5,0,10,10,10,0,0,2,10,10,10,14,14,14,14,14
14,14,14,14,14,10,10,10,2,0,0,10,10,10,0,4,2,10,10,10,14,14,14,14,14
14,14,14,14,14,10,10,10,2,2,2,10,10,10,2,2,2,10,10,10,14,14,14,14,14
13,14,14,14,3,10,10,10,10,10,2,10,10,10,2,10,10,10,10,10,3,14,14,14,13
14,14,14,14,14,10,10,10,10,10,2,10,10,10,2,10,10,10,10,10,14,14,14,14,14
14,14,14,14,14,10,10,10,10,10,2,10,10,10,2,10,10,10,10,10,14,14,14,14,14
14,14,14,14,14,10,10,10,10,10,2,10,10,10,2,10,10,10,10,10,14,14,14,14,14
13,14,14,14,3,14,14,14,3,2,2,14,14,14,2,2,3,14,14,14,3,14,14,14,13
14,14,14,14,14,14,14,14,14,14,14,14,14,14,14,14,14,14,14,14,14,14,14,14,14
14,14,14,14,14,14,14,14,14,14,14,14,14,14,14,14,14,14,14,14,14,14,14,14,14
14,14,14,14,14,14,14,14,14,14,14,14,14,14,14,14,14,14,14,14,14,14,14,14,14
13,14,14,14,13,14,14,14,13,14,14,14,13,14,14,14,13,14,14,14,13,14,14,14,13
endlayer

layer
13,11,11,11,13,11,11,11,13,11,11,11,13,11,11,11,13,11,11,11,13,11,11,11,13
11,0,0,0,0,0,0,0,0,0,0,0,0,0,0,0,0,0,0,0,0,0,0,0,11
11,0,0,0,0,0,0,0,0,0,0,0,0,0,0,0,0,0,0,0,0,0,0,0,11
11,0,0,0,0,0,0,0,0,0,0,0,0,0,0,0,0,0,0,0,0,0,0,0,11
13,0,0,0,3,0,0,0,3,2,2,0,0,0,2,2,3,0,0,0,3,0,0,0,13
11,0,0,0,0,0,0,0,0,0,2,0,0,0,2,0,0,0,0,0,0,0,0,0,11
11,0,0,0,0,0,0,0,0,0,2,0,0,0,2,0,0,0,0,0,0,0,0,0,11
11,0,0,0,0,0,0,0,0,0,2,0,0,0,2,0,0,0,0,0,0,0,0,0,11
13,0,0,0,3,0,0,0,0,0,2,0,0,0,2,0,0,0,0,0,3,0,0,0,13
11,0,0,0,0,0,0,0,2,2,2,0,0,0,2,2,2,0,0,0,0,0,0,0,11
11,0,0,0,0,0,0,0,2,5,0,0,0,0,0,0,2,0,0,0,0,0,0,0,11
11,0,0,0,0,0,0,0,2,0,0,0,0,0,0,4,2,0,0,0,0,0,0,0,11
13,0,0,0,3,0,0,0,2,2,2,0,0,0,2,2,2,0,0,0,3,0,0,0,13
11,0,0,0,0,0,0,0,2,5,0,0,0,0,0,0,2,0,0,0,0,0,0,0,11
11,0,0,0,0,0,0,0,2,0,0,0,0,0,0,4,2,0,0,0,0,0,0,0,11
11,0,0,0,0,0,0,0,2,2,2,0,0,0,2,2,2,0,0,0,0,0,0,0,11
13,0,0,0,3,0,0,0,0,0,2,0,0,0,2,0,0,0,0,0,3,0,0,0,13
11,0,0,0,0,0,0,0,0,0,2,0,0,0,2,0,0,0,0,0,0,0,0,0,11
11,0,0,0,0,0,0,0,0,0,2,0,0,0,2,0,0,0,0,0,0,0,0,0,11
11,0,0,0,0,0,0,0,0,0,2,0,0,0,2,0,0,0,0,0,0,0,0,0,11
13,0,0,0,3,0,0,0,3,2,2,0,0,0,2,2,3,0,0,0,3,0,0,0,13
11,0,0,0,0,0,0,0,0,0,0,0,0,0,0,0,0,0,0,0,0,0,0,0,11
11,0,0,0,0,0,0,0,0,0,0,0,0,0,0,0,0,0,0,0,0,0,0,0,11
11,0,0,0,0,0,0,0,0,0,0,0,0,0,0,0,0,0,0,0,0,0,0,0,11
13,11,11,11,13,11,11,11,13,11,11,11,13,11,11,11,13,11,11,11,13,11,11,11,13
endlayer

layer
13,0,0,0,13,0,0,0,13,0,0,0,13,0,0,0,13,0,0,0,13,0,0,0,13
0,0,0,0,0,0,0,0,0,0,0,0,0,0,0,0,0,0,0,0,0,0,0,0,0
0,0,0,0,0,0,0,0,0,0,0,0,0,0,0,0,0,0,0,0,0,0,0,0,0
0,0,0,0,0,0,0,0,0,0,0,0,0,0,0,0,0,0,0,0,0,0,0,0,0
13,0,0,0,3,0,0,0,3,2,2,0,0,0,2,2,3,0,0,0,3,0,0,0,13
0,0,0,0,0,0,0,0,0,0,2,0,0,0,2,0,0,0,0,0,0,0,0,0,0
0,0,0,0,0,0,0,0,0,0,2,0,0,0,2,0,0,0,0,0,0,0,0,0,0
0,0,0,0,0,0,0,0,0,0,2,0,0,0,2,0,0,0,0,0,0,0,0,0,0
13,0,0,0,3,0,0,0,0,0,2,0,0,0,2,0,0,0,0,0,3,0,0,0,13
0,0,0,0,0,0,0,0,2,2,2,0,0,0,2,2,2,0,0,0,0,0,0,0,0
0,0,0,0,0,0,0,0,2,5,0,0,0,0,0,0,2,0,0,0,0,0,0,0,0
0,0,0,0,0,0,0,0,2,0,0,0,0,0,0,4,2,0,0,0,0,0,0,0,0
13,0,0,0,3,0,0,0,2,2,2,0,0,0,2,2,2,0,0,0,3,0,0,0,13
0,0,0,0,0,0,0,0,2,5,0,0,0,0,0,0,2,0,0,0,0,0,0,0,0
0,0,0,0,0,0,0,0,2,0,0,0,0,0,0,4,2,0,0,0,0,0,0,0,0
0,0,0,0,0,0,0,0,2,2,2,0,0,0,2,2,2,0,0,0,0,0,0,0,0
13,0,0,0,3,0,0,0,0,0,2,0,0,0,2,0,0,0,0,0,3,0,0,0,13
0,0,0,0,0,0,0,0,0,0,2,0,0,0,2,0,0,0,0,0,0,0,0,0,0
0,0,0,0,0,0,0,0,0,0,2,0,0,0,2,0,0,0,0,0,0,0,0,0,0
0,0,0,0,0,0,0,0,0,0,2,0,0,0,2,0,0,0,0,0,0,0,0,0,0
13,0,0,0,3,0,0,0,3,2,2,0,0,0,2,2,3,0,0,0,3,0,0,0,13
0,0,0,0,0,0,0,0,0,0,0,0,0,0,0,0,0,0,0,0,0,0,0,0,0
0,0,0,0,0,0,0,0,0,0,0,0,0,0,0,0,0,0,0,0,0,0,0,0,0
0,0,0,0,0,0,0,0,0,0,0,0,0,0,0,0,0,0,0,0,0,0,0,0,0
13,0,0,0,13,0,0,0,13,0,0,0,13,0,0,0,13,0,0,0,13,0,0,0,13
endlayer

layer
13,0,0,0,13,0,0,0,13,0,0,0,13,0,0,0,13,0,0,0,13,0,0,0,13
0,0,0,0,0,0,0,0,0,0,0,0,0,0,0,0,0,0,0,0,0,0,0,0,0
0,0,0,0,0,0,0,0,0,0,0,0,0,0,0,0,0,0,0,0,0,0,0,0,0
0,0,0,0,0,0,0,0,0,0,0,0,0,0,0,0,0,0,0,0,0,0,0,0,0
13,0,0,0,3,0,0,0,3,2,2,0,0,0,2,2,3,0,0,0,3,0,0,0,13
0,0,0,0,0,0,0,0,0,0,2,0,0,0,2,0,0,0,0,0,0,0,0,0,0
0,0,0,0,0,0,0,0,0,0,2,0,0,0,2,0,0,0,0,0,0,0,0,0,0
0,0,0,0,0,0,0,0,0,0,2,0,0,0,2,0,0,0,0,0,0,0,0,0,0
13,0,0,0,3,0,0,0,0,0,2,0,0,0,2,0,0,0,0,0,3,0,0,0,13
0,0,0,0,0,0,0,0,2,2,2,0,0,0,2,2,2,0,0,0,0,0,0,0,0
0,0,0,0,0,0,0,0,2,5,0,0,0,0,0,0,2,0,0,0,0,0,0,0,0
0,0,0,0,0,0,0,0,2,0,0,0,0,0,0,4,2,0,0,0,0,0,0,0,0
13,0,0,0,3,0,0,0,2,2,2,0,0,0,2,2,2,0,0,0,3,0,0,0,13
0,0,0,0,0,0,0,0,2,5,0,0,0,0,0,0,2,0,0,0,0,0,0,0,0
0,0,0,0,0,0,0,0,2,0,0,0,0,0,0,4,2,0,0,0,0,0,0,0,0
0,0,0,0,0,0,0,0,2,2,2,0,0,0,2,2,2,0,0,0,0,0,0,0,0
13,0,0,0,3,0,0,0,0,0,2,0,0,0,2,0,0,0,0,0,3,0,0,0,13
0,0,0,0,0,0,0,0,0,0,2,0,0,0,2,0,0,0,0,0,0,0,0,0,0
0,0,0,0,0,0,0,0,0,0,2,0,0,0,2,0,0,0,0,0,0,0,0,0,0
0,0,0,0,0,0,0,0,0,0,2,0,0,0,2,0,0,0,0,0,0,0,0,0,0
13,0,0,0,3,0,0,0,3,2,2,0,0,0,2,2,3,0,0,0,3,0,0,0,13
0,0,0,0,0,0,0,0,0,0,0,0,0,0,0,0,0,0,0,0,0,0,0,0,0
0,0,0,0,0,0,0,0,0,0,0,0,0,0,0,0,0,0,0,0,0,0,0,0,0
0,0,0,0,0,0,0,0,0,0,0,0,0,0,0,0,0,0,0,0,0,0,0,0,0
13,0,0,0,13,0,0,0,13,0,0,0,13,0,0,0,13,0,0,0,13,0,0,0,13
endlayer

layer
13,14,14,14,13,14,14,14,13,14,14,14,13,14,14,14,13,14,14,14,13,14,14,14,13
14,0,0,0,0,0,0,0,0,0,0,0,0,0,0,0,0,0,0,0,0,0,0,0,14
14,0,0,0,0,0,0,0,0,0,0,0,0,0,0,0,0,0,0,0,0,0,0,0,14
14,0,0,0,0,0,0,0,0,0,0,0,0,0,0,0,0,0,0,0,0,0,0,0,14
13,0,0,0,3,0,0,0,3,2,2,0,0,0,2,2,3,0,0,0,3,0,0,0,13
14,0,0,0,0,9,9,9,9,9,2,9,9,9,2,9,9,9,9,9,0,0,0,0,14
14,0,0,0,0,9,9,9,9,9,2,9,9,9,2,9,9,9,9,9,0,0,0,0,14
14,0,0,0,0,9,9,9,9,9,2,9,9,9,2,9,9,9,9,9,0,0,0,0,14
13,0,0,0,3,9,9,9,9,9,2,9,9,9,2,9,9,9,9,9,3,0,0,0,13
14,0,0,0,0,9,9,9,2,2,2,9,9,9,2,2,2,9,9,9,0,0,0,0,14
14,0,0,0,0,9,9,9,2,5,0,9,9,9,0,0,2,9,9,9,0,0,0,0,14
14,0,0,0,0,9,9,9,2,0,0,9,9,9,0,4,2,9,9,9,0,0,0,0,14
13,0,0,0,3,9,9,9,2,2,2,9,9,9,2,2,2,9,9,9,3,0,0,0,13
14,0,0,0,0,9,9,9,2,5,0,9,9,9,0,0,2,9,9,9,0,0,0,0,14
14,0,0,0,0,9,9,9,2,0,0,9,9,9,0,4,2,9,9,9,0,0,0,0,14
14,0,0,0,0,9,9,9,2,2,2,9,9,9,2,2,2,9,9,9,0,0,0,0,14
13,0,0,0,3,9,9,9,9,9,2,9,9,9,2,9,9,9,9,9,3,0,0,0,13
14,0,0,0,0,9,9,9,9,9,2,9,9,9,2,9,9,9,9,9,0,0,0,0,14
14,0,0,0,0,9,9,9,9,9,2,9,9,9,2,9,9,9,9,9,0,0,0,0,14
14,0,0,0,0,9,9,9,9,9,2,9,9,9,2,9,9,9,9,9,0,0,0,0,14
13,0,0,0,3,0,0,0,3,2,2,0,0,0,2,2,3,0,0,0,3,0,0,0,13
14,0,0,0,0,0,0,0,0,0,0,0,0,0,0,0,0,0,0,0,0,0,0,0,14
14,0,0,0,0,0,0,0,0,0,0,0,0,0,0,0,0,0,0,0,0,0,0,0,14
14,0,0,0,0,0,0,0,0,0,0,0,0,0,0,0,0,0,0,0,0,0,0,0,14
13,14,14,14,13,14,14,14,13,14,14,14,13,14,14,14,13,14,14,14,13,14,14,14,13
endlayer

layer
13,14,14,14,13,14,14,14,13,14,14,14,13,14,14,14,13,14,14,14,13,14,14,14,13
14,14,14,14,14,14,14,14,14,14,14,14,14,14,14,14,14,14,14,14,14,14,14,14,14
14,14,14,14,14,14,14,14,14,14,14,14,14,14,14,14,14,14,14,14,14,14,14,14,14
14,14,14,14,14,14,14,14,14,14,14,14,14,14,14,14,14,14,14,14,14,14,14,14,14
13,14,14,14,3,14,14,14,3,2,2,14,14,14,2,2,3,14,14,14,3,14,14,14,13
14,14,14,14,14,10,10,10,10,10,2,10,10,10,2,10,10,10,10,10,14,14,14,14,14
14,14,14,14,14,10,10,10,10,10,2,10,10,10,2,10,10,10,10,10,14,14,14,14,14
14,14,14,14,14,10,10,10,10,10,2,10,10,10,2,10,10,10,10,10,14,14,14,14,14
13,14,14,14,3,10,10,10,10,10,2,10,10,10,2,10,10,10,10,10,3,14,14,14,13
14,14,14,14,14,10,10,10,2,2,2,10,10,10,2,2,2,10,10,10,14,14,14,14,14
14,14,14,14,14,10,10,10,2,5,0,10,10,10,0,0,2,10,10,10,14,14,14,14,14
14,14,14,14,14,10,10,10,2,0,0,10,10,10,0,0,2,10,10,10,14,14,14,14,14
13,14,14,14,3,10,10,10,2,2,2,10,10,10,2,2,2,10,10,10,3,14,14,14,13
14,14,14,14,14,10,10,10,2,5,0,10,10,10,0,0,2,10,10,10,14,14,14,14,14
14,14,14,14,14,10,10,10,2,0,0,10,10,10,0,4,2,10,10,10,14,14,14,14,14
14,14,14,14,14,10,10,10,2,2,2,10,10,10,2,2,2,10,10,10,14,14,14,14,14
13,14,14,14,3,10,10,10,10,10,2,10,10,10,2,10,10,10,10,10,3,14,14,14,13
14,14,14,14,14,10,10,10,10,10,2,10,10,10,2,10,10,10,10,10,14,14,14,14,14
14,14,14,14,14,10,10,10,10,10,2,10,10,10,2,10,10,10,10,10,14,14,14,14,14
14,14,14,14,14,10,10,10,10,10,2,10,10,10,2,10,10,10,10,10,14,14,14,14,14
13,14,14,14,3,14,14,14,3,2,2,14,14,14,2,2,3,14,14,14,3,14,14,14,13
14,14,14,14,14,14,14,14,14,14,14,14,14,14,14,14,14,14,14,14,14,14,14,14,14
14,14,14,14,14,14,14,14,14,14,14,14,14,14,14,14,14,14,14,14,14,14,14,14,14
14,14,14,14,14,14,14,14,14,14,14,14,14,14,14,14,14,14,14,14,14,14,14,14,14
13,14,14,14,13,14,14,14,13,14,14,14,13,14,14,14,13,14,14,14,13,14,14,14,13
endlayer

layer
13,11,11,11,13,11,11,11,13,11,11,11,13,11,11,11,13,11,11,11,13,11,11,11,13
11,0,0,0,0,0,0,0,0,0,0,0,0,0,0,0,0,0,0,0,0,0,0,0,11
11,0,0,0,0,0,0,0,0,0,0,0,0,0,0,0,0,0,0,0,0,0,0,0,11
11,0,0,0,0,0,0,0,0,0,0,0,0,0,0,0,0,0,0,0,0,0,0,0,11
13,0,0,0,3,0,0,0,3,2,2,0,0,0,2,2,3,0,0,0,3,0,0,0,13
11,0,0,0,0,0,0,0,0,0,2,0,0,0,2,0,0,0,0,0,0,0,0,0,11
11,0,0,0,0,0,0,0,0,0,2,0,0,0,2,0,0,0,0,0,0,0,0,0,11
11,0,0,0,0,0,0,0,0,0,2,0,0,0,2,0,0,0,0,0,0,0,0,0,11
13,0,0,0,3,0,0,0,0,0,2,0,0,0,2,0,0,0,0,0,3,0,0,0,13
11,0,0,0,0,0,0,0,2,2,2,0,0,0,2,2,2,0,0,0,0,0,0,0,11
11,0,0,0,0,0,0,0,2,5,0,0,0,0,0,0,2,0,0,0,0,0,0,0,11
11,0,0,0,0,0,0,0,2,0,0,0,0,0,0,4,2,0,0,0,0,0,0,0,11
13,0,0,0,3,0,0,0,2,2,2,0,0,0,2,2,2,0,0,0,3,0,0,0,13
11,0,0,0,0,0,0,0,2,5,0,0,0,0,0,0,2,0,0,0,0,0,0,0,11
11,0,0,0,0,0,0,0,2,0,0,0,0,0,0,4,2,0,0,0,0,0,0,0,11
11,0,0,0,0,0,0,0,2,2,2,0,0,0,2,2,2,0,0,0,0,0,0,0,11
13,0,0,0,3,0,0,0,0,0,2,0,0,0,2,0,0,0,0,0,3,0,0,0,13
11,0,0,0,0,0,0,0,0,0,2,0,0,0,2,0,0,0,0,0,0,0,0,0,11
11,0,0,0,0,0,0,0,0,0,2,0,0,0,2,0,0,0,0,0,0,0,0,0,11
11,0,0,0,0,0,0,0,0,0,2,0,0,0,2,0,0,0,0,0,0,0,0,0,11
13,0,0,0,3,0,0,0,3,2,2,0,0,0,2,2,3,0,0,0,3,0,0,0,13
11,0,0,0,0,0,0,0,0,0,0,0,0,0,0,0,0,0,0,0,0,0,0,0,11
11,0,0,0,0,0,0,0,0,0,0,0,0,0,0,0,0,0,0,0,0,0,0,0,11
11,0,0,0,0,0,0,0,0,0,0,0,0,0,0,0,0,0,0,0,0,0,0,0,11
13,11,11,11,13,11,11,11,13,11,11,11,13,11,11,11,13,11,11,11,13,11,11,11,13
endlayer

layer
13,0,0,0,13,0,0,0,13,0,0,0,13,0,0,0,13,0,0,0,13,0,0,0,13
0,0,0,0,0,0,0,0,0,0,0,0,0,0,0,0,0,0,0,0,0,0,0,0,0
0,0,0,0,0,0,0,0,0,0,0,0,0,0,0,0,0,0,0,0,0,0,0,0,0
0,0,0,0,0,0,0,0,0,0,0,0,0,0,0,0,0,0,0,0,0,0,0,0,0
13,0,0,0,3,0,0,0,3,2,2,0,0,0,2,2,3,0,0,0,3,0,0,0,13
0,0,0,0,0,0,0,0,0,0,2,0,0,0,2,0,0,0,0,0,0,0,0,0,0
0,0,0,0,0,0,0,0,0,0,2,0,0,0,2,0,0,0,0,0,0,0,0,0,0
0,0,0,0,0,0,0,0,0,0,2,0,0,0,2,0,0,0,0,0,0,0,0,0,0
13,0,0,0,3,0,0,0,0,0,2,0,0,0,2,0,0,0,0,0,3,0,0,0,13
0,0,0,0,0,0,0,0,2,2,2,0,0,0,2,2,2,0,0,0,0,0,0,0,0
0,0,0,0,0,0,0,0,2,5,0,0,0,0,0,0,2,0,0,0,0,0,0,0,0
0,0,0,0,0,0,0,0,2,0,0,0,0,0,0,4,2,0,0,0,0,0,0,0,0
13,0,0,0,3,0,0,0,2,2,2,0,0,0,2,2,2,0,0,0,3,0,0,0,13
0,0,0,0,0,0,0,0,2,5,0,0,0,0,0,0,2,0,0,0,0,0,0,0,0
0,0,0,0,0,0,0,0,2,0,0,0,0,0,0,4,2,0,0,0,0,0,0,0,0
0,0,0,0,0,0,0,0,2,2,2,0,0,0,2,2,2,0,0,0,0,0,0,0,0
13,0,0,0,3,0,0,0,0,0,2,0,0,0,2,0,0,0,0,0,3,0,0,0,13
0,0,0,0,0,0,0,0,0,0,2,0,0,0,2,0,0,0,0,0,0,0,0,0,0
0,0,0,0,0,0,0,0,0,0,2,0,0,0,2,0,0,0,0,0,0,0,0,0,0
0,0,0,0,0,0,0,0,0,0,2,0,0,0,2,0,0,0,0,0,0,0,0,0,0
13,0,0,0,3,0,0,0,3,2,2,0,0,0,2,2,3,0,0,0,3,0,0,0,13
0,0,0,0,0,0,0,0,0,0,0,0,0,0,0,0,0,0,0,0,0,0,0,0,0
0,0,0,0,0,0,0,0,0,0,0,0,0,0,0,0,0,0,0,0,0,0,0,0,0
0,0,0,0,0,0,0,0,0,0,0,0,0,0,0,0,0,0,0,0,0,0,0,0,0
13,0,0,0,13,0,0,0,13,0,0,0,13,0,0,0,13,0,0,0,13,0,0,0,13
endlayer

layer
13,0,0,0,13,0,0,0,13,0,0,0,13,0,0,0,13,0,0,0,13,0,0,0,13
0,0,0,0,0,0,0,0,0,0,0,0,0,0,0,0,0,0,0,0,0,0,0,0,0
0,0,0,0,0,0,0,0,0,0,0,0,0,0,0,0,0,0,0,0,0,0,0,0,0
0,0,0,0,0,0,0,0,0,0,0,0,0,0,0,0,0,0,0,0,0,0,0,0,0
13,0,0,0,3,0,0,0,3,2,2,0,0,0,2,2,3,0,0,0,3,0,0,0,13
0,0,0,0,0,0,0,0,0,0,2,0,0,0,2,0,0,0,0,0,0,0,0,0,0
0,0,0,0,0,0,0,0,0,0,2,0,0,0,2,0,0,0,0,0,0,0,0,0,0
0,0,0,0,0,0,0,0,0,0,2,0,0,0,2,0,0,0,0,0,0,0,0,0,0
13,0,0,0,3,0,0,0,0,0,2,0,0,0,2,0,0,0,0,0,3,0,0,0,13
0,0,0,0,0,0,0,0,2,2,2,0,0,0,2,2,2,0,0,0,0,0,0,0,0
0,0,0,0,0,0,0,0,2,5,0,0,0,0,0,0,2,0,0,0,0,0,0,0,0
0,0,0,0,0,0,0,0,2,0,0,0,0,0,0,4,2,0,0,0,0,0,0,0,0
13,0,0,0,3,0,0,0,2,2,2,0,0,0,2,2,2,0,0,0,3,0,0,0,13
0,0,0,0,0,0,0,0,2,5,0,0,0,0,0,0,2,0,0,0,0,0,0,0,0
0,0,0,0,0,0,0,0,2,0,0,0,0,0,0,4,2,0,0,0,0,0,0,0,0
0,0,0,0,0,0,0,0,2,2,2,0,0,0,2,2,2,0,0,0,0,0,0,0,0
13,0,0,0,3,0,0,0,0,0,2,0,0,0,2,0,0,0,0,0,3,0,0,0,13
0,0,0,0,0,0,0,0,0,0,2,0,0,0,2,0,0,0,0,0,0,0,0,0,0
0,0,0,0,0,0,0,0,0,0,2,0,0,0,2,0,0,0,0,0,0,0,0,0,0
0,0,0,0,0,0,0,0,0,0,2,0,0,0,2,0,0,0,0,0,0,0,0,0,0
13,0,0,0,3,0,0,0,3,2,2,0,0,0,2,2,3,0,0,0,3,0,0,0,13
0,0,0,0,0,0,0,0,0,0,0,0,0,0,0,0,0,0,0,0,0,0,0,0,0
0,0,0,0,0,0,0,0,0,0,0,0,0,0,0,0,0,0,0,0,0,0,0,0,0
0,0,0,0,0,0,0,0,0,0,0,0,0,0,0,0,0,0,0,0,0,0,0,0,0
13,0,0,0,13,0,0,0,13,0,0,0,13,0,0,0,13,0,0,0,13,0,0,0,13
endlayer

layer
13,14,14,14,13,14,14,14,13,14,14,14,13,14,14,14,13,14,14,14,13,14,14,14,13
14,0,0,0,0,0,0,0,0,0,0,0,0,0,0,0,0,0,0,0,0,0,0,0,14
14,0,0,0,0,0,0,0,0,0,0,0,0,0,0,0,0,0,0,0,0,0,0,0,14
14,0,0,0,0,0,0,0,0,0,0,0,0,0,0,0,0,0,0,0,0,0,0,0,14
13,0,0,0,3,0,0,0,3,2,2,0,0,0,2,2,3,0,0,0,3,0,0,0,13
14,0,0,0,0,9,9,9,9,9,2,9,9,9,2,9,9,9,9,9,0,0,0,0,14
14,0,0,0,0,9,9,9,9,9,2,9,9,9,2,9,9,9,9,9,0,0,0,0,14
14,0,0,0,0,9,9,9,9,9,2,9,9,9,2,9,9,9,9,9,0,0,0,0,14
13,0,0,0,3,9,9,9,9,9,2,9,9,9,2,9,9,9,9,9,3,0,0,0,13
14,0,0,0,0,9,9,9,2,2,2,9,9,9,2,2,2,9,9,9,0,0,0,0,14
14,0,0,0,0,9,9,9,2,5,0,9,9,9,0,0,2,9,9,9,0,0,0,0,14
14,0,0,0,0,9,9,9,2,0,0,9,9,9,0,4,2,9,9,9,0,0,0,0,14
13,0,0,0,3,9,9,9,2,2,2,9,9,9,2,2,2,9,9,9,3,0,0,0,13
14,0,0,0,0,9,9,9,2,5,0,9,9,9,0,0,2,9,9,9,0,0,0,0,14
14,0,0,0,0,9,9,9,2,0,0,9,9,9,0,4,2,9,9,9,0,0,0,0,14
14,0,0,0,0,9,9,9,2,2,2,9,9,9,2,2,2,9,9,9,0,0,0,0,14
13,0,0,0,3,9,9,9,9,9,2,9,9,9,2,9,9,9,9,9,3,0,0,0,13
14,0,0,0,0,9,9,9,9,9,2,9,9,9,2,9,9,9,9,9,0,0,0,0,14
14,0,0,0,0,9,9,9,9,9,2,9,9,9,2,9,9,9,9,9,0,0,0,0,14
14,0,0,0,0,9,9,9,9,9,2,9,9,9,2,9,9,9,9,9,0,0,0,0,14
13,0,0,0,3,0,0,0,3,2,2,0,0,0,2,2,3,0,0,0,3,0,0,0,13
14,0,0,0,0,0,0,0,0,0,0,0,0,0,0,0,0,0,0,0,0,0,0,0,14
14,0,0,0,0,0,0,0,0,0,0,0,0,0,0,0,0,0,0,0,0,0,0,0,14
14,0,0,0,0,0,0,0,0,0,0,0,0,0,0,0,0,0,0,0,0,0,0,0,14
13,14,14,14,13,14,14,14,13,14,14,14,13,14,14,14,13,14,14,14,13,14,14,14,13
endlayer

layer
13,14,14,14,13,14,14,14,13,14,14,14,13,14,14,14,13,14,14,14,13,14,14,14,13
14,14,14,14,14,14,14,14,14,14,14,14,14,14,14,14,14,14,14,14,14,14,14,14,14
14,14,14,14,14,14,14,14,14,14,14,14,14,14,14,14,14,14,14,14,14,14,14,14,14
14,14,14,14,14,14,14,14,14,14,14,14,14,14,14,14,14,14,14,14,14,14,14,14,14
13,14,14,14,3,14,14,14,3,2,2,14,14,14,2,2,3,14,14,14,3,14,14,14,13
14,14,14,14,14,10,10,10,10,10,2,10,10,10,2,10,10,10,10,10,14,14,14,14,14
14,14,14,14,14,10,10,10,10,10,2,10,10,10,2,10,10,10,10,10,14,14,14,14,14
14,14,14,14,14,10,10,10,10,10,2,10,10,10,2,10,10,10,10,10,14,14,14,14,14
13,14,14,14,3,10,10,10,10,10,2,10,10,10,2,10,10,10,10,10,3,14,14,14,13
14,14,14,14,14,10,10,10,2,2,2,10,10,10,2,2,2,10,10,10,14,14,14,14,14
14,14,14,14,14,10,10,10,2,5,0,10,10,10,0,0,2,10,10,10,14,14,14,14,14
14,14,14,14,14,10,10,10,2,0,0,10,10,10,0,0,2,10,10,10,14,14,14,14,14
13,14,14,14,3,10,10,10,2,2,2,10,10,10,2,2,2,10,10,10,3,14,14,14,13
14,14,14,14,14,10,10,10,2,5,0,10,10,10,0,0,2,10,10,10,14,14,14,14,14
14,14,14,14,14,10,10,10,2,0,0,10,10,10,0,4,2,10,10,10,14,14,14,14,14
14,14,14,14,14,10,10,10,2,2,2,10,10,10,2,2,2,10,10,10,14,14,14,14,14
13,14,14,14,3,10,10,10,10,10,2,10,10,10,2,10,10,10,10,10,3,14,14,14,13
14,14,14,14,14,10,10,10,10,10,2,10,10,10,2,10,10,10,10,10,14,14,14,14,14
14,14,14,14,14,10,10,10,10,10,2,10,10,10,2,10,10,10,10,10,14,14,14,14,14
14,14,14,14,14,10,10,10,10,10,2,10,10,10,2,10,10,10,10,10,14,14,14,14,14
13,14,14,14,3,14,14,14,3,2,2,14,14,14,2,2,3,14,14,14,3,14,14,14,13
14,14,14,14,14,14,14,14,14,14,14,14,14,14,14,14,14,14,14,14,14,14,14,14,14
14,14,14,14,14,14,14,14,14,14,14,14,14,14,14,14,14,14,14,14,14,14,14,14,14
14,14,14,14,14,14,14,14,14,14,14,14,14,14,14,14,14,14,14,14,14,14,14,14,14
13,14,14,14,13,14,14,14,13,14,14,14,13,14,14,14,13,14,14,14,13,14,14,14,13
endlayer

layer
13,11,11,11,13,11,11,11,13,11,11,11,13,11,11,11,13,11,11,11,13,11,11,11,13
11,0,0,0,0,0,0,0,0,0,0,0,0,0,0,0,0,0,0,0,0,0,0,0,11
11,0,0,0,0,0,0,0,0,0,0,0,0,0,0,0,0,0,0,0,0,0,0,0,11
11,0,0,0,0,0,0,0,0,0,0,0,0,0,0,0,0,0,0,0,0,0,0,0,11
13,0,0,0,3,0,0,0,3,2,2,0,0,0,2,2,3,0,0,0,3,0,0,0,13
11,0,0,0,0,0,0,0,0,0,2,0,0,0,2,0,0,0,0,0,0,0,0,0,11
11,0,0,0,0,0,0,0,0,0,2,0,0,0,2,0,0,0,0,0,0,0,0,0,11
11,0,0,0,0,0,0,0,0,0,2,0,0,0,2,0,0,0,0,0,0,0,0,0,11
13,0,0,0,3,0,0,0,0,0,2,0,0,0,2,0,0,0,0,0,3,0,0,0,13
11,0,0,0,0,0,0,0,2,2,2,0,0,0,2,2,2,0,0,0,0,0,0,0,11
11,0,0,0,0,0,0,0,2,5,0,0,0,0,0,0,2,0,0,0,0,0,0,0,11
11,0,0,0,0,0,0,0,2,0,0,0,0,0,0,4,2,0,0,0,0,0,0,0,11
13,0,0,0,3,0,0,0,2,2,2,0,0,0,2,2,2,0,0,0,3,0,0,0,13
11,0,0,0,0,0,0,0,2,5,0,0,0,0,0,0,2,0,0,0,0,0,0,0,11
11,0,0,0,0,0,0,0,2,0,0,0,0,0,0,4,2,0,0,0,0,0,0,0,11
11,0,0,0,0,0,0,0,2,2,2,0,0,0,2,2,2,0,0,0,0,0,0,0,11
13,0,0,0,3,0,0,0,0,0,2,0,0,0,2,0,0,0,0,0,3,0,0,0,13
11,0,0,0,0,0,0,0,0,0,2,0,0,0,2,0,0,0,0,0,0,0,0,0,11
11,0,0,0,0,0,0,0,0,0,2,0,0,0,2,0,0,0,0,0,0,0,0,0,11
11,0,0,0,0,0,0,0,0,0,2,0,0,0,2,0,0,0,0,0,0,0,0,0,11
13,0,0,0,3,0,0,0,3,2,2,0,0,0,2,2,3,0,0,0,3,0,0,0,13
11,0,0,0,0,0,0,0,0,0,0,0,0,0,0,0,0,0,0,0,0,0,0,0,11
11,0,0,0,0,0,0,0,0,0,0,0,0,0,0,0,0,0,0,0,0,0,0,0,11
11,0,0,0,0,0,0,0,0,0,0,0,0,0,0,0,0,0,0,0,0,0,0,0,11
13,11,11,11,13,11,11,11,13,11,11,11,13,11,11,11,13,11,11,11,13,11,11,11,13
endlayer

layer
13,0,0,0,13,0,0,0,13,0,0,0,13,0,0,0,13,0,0,0,13,0,0,0,13
0,0,0,0,0,0,0,0,0,0,0,0,0,0,0,0,0,0,0,0,0,0,0,0,0
0,0,0,0,0,0,0,0,0,0,0,0,0,0,0,0,0,0,0,0,0,0,0,0,0
0,0,0,0,0,0,0,0,0,0,0,0,0,0,0,0,0,0,0,0,0,0,0,0,0
13,0,0,0,3,0,0,0,3,2,2,0,0,0,2,2,3,0,0,0,3,0,0,0,13
0,0,0,0,0,0,0,0,0,0,2,0,0,0,2,0,0,0,0,0,0,0,0,0,0
0,0,0,0,0,0,0,0,0,0,2,0,0,0,2,0,0,0,0,0,0,0,0,0,0
0,0,0,0,0,0,0,0,0,0,2,0,0,0,2,0,0,0,0,0,0,0,0,0,0
13,0,0,0,3,0,0,0,0,0,2,0,0,0,2,0,0,0,0,0,3,0,0,0,13
0,0,0,0,0,0,0,0,2,2,2,0,0,0,2,2,2,0,0,0,0,0,0,0,0
0,0,0,0,0,0,0,0,2,5,0,0,0,0,0,0,2,0,0,0,0,0,0,0,0
0,0,0,0,0,0,0,0,2,0,0,0,0,0,0,4,2,0,0,0,0,0,0,0,0
13,0,0,0,3,0,0,0,2,2,2,0,0,0,2,2,2,0,0,0,3,0,0,0,13
0,0,0,0,0,0,0,0,2,5,0,0,0,0,0,0,2,0,0,0,0,0,0,0,0
0,0,0,0,0,0,0,0,2,0,0,0,0,0,0,4,2,0,0,0,0,0,0,0,0
0,0,0,0,0,0,0,0,2,2,2,0,0,0,2,2,2,0,0,0,0,0,0,0,0
13,0,0,0,3,0,0,0,0,0,2,0,0,0,2,0,0,0,0,0,3,0,0,0,13
0,0,0,0,0,0,0,0,0,0,2,0,0,0,2,0,0,0,0,0,0,0,0,0,0
0,0,0,0,0,0,0,0,0,0,2,0,0,0,2,0,0,0,0,0,0,0,0,0,0
0,0,0,0,0,0,0,0,0,0,2,0,0,0,2,0,0,0,0,0,0,0,0,0,0
13,0,0,0,3,0,0,0,3,2,2,0,0,0,2,2,3,0,0,0,3,0,0,0,13
0,0,0,0,0,0,0,0,0,0,0,0,0,0,0,0,0,0,0,0,0,0,0,0,0
0,0,0,0,0,0,0,0,0,0,0,0,0,0,0,0,0,0,0,0,0,0,0,0,0
0,0,0,0,0,0,0,0,0,0,0,0,0,0,0,0,0,0,0,0,0,0,0,0,0
13,0,0,0,13,0,0,0,13,0,0,0,13,0,0,0,13,0,0,0,13,0,0,0,13
endlayer

layer
13,0,0,0,13,0,0,0,13,0,0,0,13,0,0,0,13,0,0,0,13,0,0,0,13
0,0,0,0,0,0,0,0,0,0,0,0,0,0,0,0,0,0,0,0,0,0,0,0,0
0,0,0,0,0,0,0,0,0,0,0,0,0,0,0,0,0,0,0,0,0,0,0,0,0
0,0,0,0,0,0,0,0,0,0,0,0,0,0,0,0,0,0,0,0,0,0,0,0,0
13,0,0,0,3,0,0,0,3,2,2,0,0,0,2,2,3,0,0,0,3,0,0,0,13
0,0,0,0,0,0,0,0,0,0,2,0,0,0,2,0,0,0,0,0,0,0,0,0,0
0,0,0,0,0,0,0,0,0,0,2,0,0,0,2,0,0,0,0,0,0,0,0,0,0
0,0,0,0,0,0,0,0,0,0,2,0,0,0,2,0,0,0,0,0,0,0,0,0,0
13,0,0,0,3,0,0,0,0,0,2,0,0,0,2,0,0,0,0,0,3,0,0,0,13
0,0,0,0,0,0,0,0,2,2,2,0,0,0,2,2,2,0,0,0,0,0,0,0,0
0,0,0,0,0,0,0,0,2,5,0,0,0,0,0,0,2,0,0,0,0,0,0,0,0
0,0,0,0,0,0,0,0,2,0,0,0,0,0,0,4,2,0,0,0,0,0,0,0,0
13,0,0,0,3,0,0,0,2,2,2,0,0,0,2,2,2,0,0,0,3,0,0,0,13
0,0,0,0,0,0,0,0,2,5,0,0,0,0,0,0,2,0,0,0,0,0,0,0,0
0,0,0,0,0,0,0,0,2,0,0,0,0,0,0,4,2,0,0,0,0,0,0,0,0
0,0,0,0,0,0,0,0,2,2,2,0,0,0,2,2,2,0,0,0,0,0,0,0,0
13,0,0,0,3,0,0,0,0,0,2,0,0,0,2,0,0,0,0,0,3,0,0,0,13
0,0,0,0,0,0,0,0,0,0,2,0,0,0,2,0,0,0,0,0,0,0,0,0,0
0,0,0,0,0,0,0,0,0,0,2,0,0,0,2,0,0,0,0,0,0,0,0,0,0
0,0,0,0,0,0,0,0,0,0,2,0,0,0,2,0,0,0,0,0,0,0,0,0,0
13,0,0,0,3,0,0,0,3,2,2,0,0,0,2,2,3,0,0,0,3,0,0,0,13
0,0,0,0,0,0,0,0,0,0,0,0,0,0,0,0,0,0,0,0,0,0,0,0,0
0,0,0,0,0,0,0,0,0,0,0,0,0,0,0,0,0,0,0,0,0,0,0,0,0
0,0,0,0,0,0,0,0,0,0,0,0,0,0,0,0,0,0,0,0,0,0,0,0,0
13,0,0,0,13,0,0,0,13,0,0,0,13,0,0,0,13,0,0,0,13,0,0,0,13
endlayer

layer
13,14,14,14,13,14,14,14,13,14,14,14,13,14,14,14,13,14,14,14,13,14,14,14,13
14,0,0,0,0,0,0,0,0,0,0,0,0,0,0,0,0,0,0,0,0,0,0,0,14
14,0,0,0,0,0,0,0,0,0,0,0,0,0,0,0,0,0,0,0,0,0,0,0,14
14,0,0,0,0,0,0,0,0,0,0,0,0,0,0,0,0,0,0,0,0,0,0,0,14
13,0,0,0,3,0,0,0,3,2,2,0,0,0,2,2,3,0,0,0,3,0,0,0,13
14,0,0,0,0,9,9,9,9,9,2,9,9,9,2,9,9,9,9,9,0,0,0,0,14
14,0,0,0,0,9,9,9,9,9,2,9,9,9,2,9,9,9,9,9,0,0,0,0,14
14,0,0,0,0,9,9,9,9,9,2,9,9,9,2,9,9,9,9,9,0,0,0,0,14
13,0,0,0,3,9,9,9,9,9,2,9,9,9,2,9,9,9,9,9,3,0,0,0,13
14,0,0,0,0,9,9,9,2,2,2,9,9,9,2,2,2,9,9,9,0,0,0,0,14
14,0,0,0,0,9,9,9,2,5,0,9,9,9,0,0,2,9,9,9,0,0,0,0,14
14,0,0,0,0,9,9,9,2,0,0,9,9,9,0,4,2,9,9,9,0,0,0,0,14
13,0,0,0,3,9,9,9,2,2,2,9,9,9,2,2,2,9,9,9,3,0,0,0,13
14,0,0,0,0,9,9,9,2,5,0,9,9,9,0,0,2,9,9,9,0,0,0,0,14
14,0,0,0,0,9,9,9,2,0,0,9,9,9,0,4,2,9,9,9,0,0,0,0,14
14,0,0,0,0,9,9,9,2,2,2,9,9,9,2,2,2,9,9,9,0,0,0,0,14
13,0,0,0,3,9,9,9,9,9,2,9,9,9,2,9,9,9,9,9,3,0,0,0,13
14,0,0,0,0,9,9,9,9,9,2,9,9,9,2,9,9,9,9,9,0,0,0,0,14
14,0,0,0,0,9,9,9,9,9,2,9,9,9,2,9,9,9,9,9,0,0,0,0,14
14,0,0,0,0,9,9,9,9,9,2,9,9,9,2,9,9,9,9,9,0,0,0,0,14
13,0,0,0,3,0,0,0,3,2,2,0,0,0,2,2,3,0,0,0,3,0,0,0,13
14,0,0,0,0,0,0,0,0,0,0,0,0,0,0,0,0,0,0,0,0,0,0,0,14
14,0,0,0,0,0,0,0,0,0,0,0,0,0,0,0,0,0,0,0,0,0,0,0,14
14,0,0,0,0,0,0,0,0,0,0,0,0,0,0,0,0,0,0,0,0,0,0,0,14
13,14,14,14,13,14,14,14,13,14,14,14,13,14,14,14,13,14,14,14,13,14,14,14,13
endlayer

layer
13,14,14,14,13,14,14,14,13,14,14,14,13,14,14,14,13,14,14,14,13,14,14,14,13
14,14,14,14,14,14,14,14,14,14,14,14,14,14,14,14,14,14,14,14,14,14,14,14,14
14,14,14,14,14,14,14,14,14,14,14,14,14,14,14,14,14,14,14,14,14,14,14,14,14
14,14,14,14,14,14,14,14,14,14,14,14,14,14,14,14,14,14,14,14,14,14,14,14,14
13,14,14,14,3,14,14,14,3,2,2,14,14,14,2,2,3,14,14,14,3,14,14,14,13
14,14,14,14,14,10,10,10,10,10,2,10,10,10,2,10,10,10,10,10,14,14,14,14,14
14,14,14,14,14,10,10,10,10,10,2,10,10,10,2,10,10,10,10,10,14,14,14,14,14
14,14,14,14,14,10,10,10,10,10,2,10,10,10,2,10,10,10,10,10,14,14,14,14,14
13,14,14,14,3,10,10,10,10,10,2,10,10,10,2,10,10,10,10,10,3,14,14,14,13
14,14,14,14,14,10,10,10,2,2,2,10,10,10,2,2,2,10,10,10,14,14,14,14,14
14,14,14,14,14,10,10,10,2,5,0,10,10,10,0,0,2,10,10,10,14,14,14,14,14
14,14,14,14,14,10,10,10,2,0,0,10,10,10,0,0,2,10,10,10,14,14,14,14,14
13,14,14,14,3,10,10,10,2,2,2,10,10,10,2,2,2,10,10,10,3,14,14,14,13
14,14,14,14,14,10,10,10,2,5,0,10,10,10,0,0,2,10,10,10,14,14,14,14,14
14,14,14,14,14,10,10,10,2,0,0,10,10,10,0,4,2,10,10,10,14,14,14,14,14
14,14,14,14,14,10,10,10,2,2,2,10,10,10,2,2,2,10,10,10,14,14,14,14,14
13,14,14,14,3,10,10,10,10,10,2,10,10,10,2,10,10,10,10,10,3,14,14,14,13
14,14,14,14,14,10,10,10,10,10,2,10,10,10,2,10,10,10,10,10,14,14,14,14,14
14,14,14,14,14,10,10,10,10,10,2,10,10,10,2,10,10,10,10,10,14,14,14,14,14
14,14,14,14,14,10,10,10,10,10,2,10,10,10,2,10,10,10,10,10,14,14,14,14,14
13,14,14,14,3,14,14,14,3,2,2,14,14,14,2,2,3,14,14,14,3,14,14,14,13
14,14,14,14,14,14,14,14,14,14,14,14,14,14,14,14,14,14,14,14,14,14,14,14,14
14,14,14,14,14,14,14,14,14,14,14,14,14,14,14,14,14,14,14,14,14,14,14,14,14
14,14,14,14,14,14,14,14,14,14,14,14,14,14,14,14,14,14,14,14,14,14,14,14,14
13,14,14,14,13,14,14,14,13,14,14,14,13,14,14,14,13,14,14,14,13,14,14,14,13
endlayer

layer
13,11,11,11,13,11,11,11,13,11,11,11,13,11,11,11,13,11,11,11,13,11,11,11,13
11,0,0,0,0,0,0,0,0,0,0,0,0,0,0,0,0,0,0,0,0,0,0,0,11
11,0,0,0,0,0,0,0,0,0,0,0,0,0,0,0,0,0,0,0,0,0,0,0,11
11,0,0,0,0,0,0,0,0,0,0,0,0,0,0,0,0,0,0,0,0,0,0,0,11
13,0,0,0,3,0,0,0,3,2,2,0,0,0,2,2,3,0,0,0,3,0,0,0,13
11,0,0,0,0,0,0,0,0,0,2,0,0,0,2,0,0,0,0,0,0,0,0,0,11
11,0,0,0,0,0,0,0,0,0,2,0,0,0,2,0,0,0,0,0,0,0,0,0,11
11,0,0,0,0,0,0,0,0,0,2,0,0,0,2,0,0,0,0,0,0,0,0,0,11
13,0,0,0,3,0,0,0,0,0,2,0,0,0,2,0,0,0,0,0,3,0,0,0,13
11,0,0,0,0,0,0,0,2,2,2,0,0,0,2,2,2,0,0,0,0,0,0,0,11
11,0,0,0,0,0,0,0,2,5,0,0,0,0,0,0,2,0,0,0,0,0,0,0,11
11,0,0,0,0,0,0,0,2,0,0,0,0,0,0,4,2,0,0,0,0,0,0,0,11
13,0,0,0,3,0,0,0,2,2,2,0,0,0,2,2,2,0,0,0,3,0,0,0,13
11,0,0,0,0,0,0,0,2,5,0,0,0,0,0,0,2,0,0,0,0,0,0,0,11
11,0,0,0,0,0,0,0,2,0,0,0,0,0,0,4,2,0,0,0,0,0,0,0,11
11,0,0,0,0,0,0,0,2,2,2,0,0,0,2,2,2,0,0,0,0,0,0,0,11
13,0,0,0,3,0,0,0,0,0,2,0,0,0,2,0,0,0,0,0,3,0,0,0,13
11,0,0,0,0,0,0,0,0,0,2,0,0,0,2,0,0,0,0,0,0,0,0,0,11
11,0,0,0,0,0,0,0,0,0,2,0,0,0,2,0,0,0,0,0,0,0,0,0,11
11,0,0,0,0,0,0,0,0,0,2,0,0,0,2,0,0,0,0,0,0,0,0,0,11
13,0,0,0,3,0,0,0,3,2,2,0,0,0,2,2,3,0,0,0,3,0,0,0,13
11,0,0,0,0,0,0,0,0,0,0,0,0,0,0,0,0,0,0,0,0,0,0,0,11
11,0,0,0,0,0,0,0,0,0,0,0,0,0,0,0,0,0,0,0,0,0,0,0,11
11,0,0,0,0,0,0,0,0,0,0,0,0,0,0,0,0,0,0,0,0,0,0,0,11
13,11,11,11,13,11,11,11,13,11,11,11,13,11,11,11,13,11,11,11,13,11,11,11,13
endlayer

layer
13,0,0,0,13,0,0,0,13,0,0,0,13,0,0,0,13,0,0,0,13,0,0,0,13
0,0,0,0,0,0,0,0,0,0,0,0,0,0,0,0,0,0,0,0,0,0,0,0,0
0,0,0,0,0,0,0,0,0,0,0,0,0,0,0,0,0,0,0,0,0,0,0,0,0
0,0,0,0,0,0,0,0,0,0,0,0,0,0,0,0,0,0,0,0,0,0,0,0,0
13,0,0,0,3,0,0,0,3,2,2,0,0,0,2,2,3,0,0,0,3,0,0,0,13
0,0,0,0,0,0,0,0,0,0,2,0,0,0,2,0,0,0,0,0,0,0,0,0,0
0,0,0,0,0,0,0,0,0,0,2,0,0,0,2,0,0,0,0,0,0,0,0,0,0
0,0,0,0,0,0,0,0,0,0,2,0,0,0,2,0,0,0,0,0,0,0,0,0,0
13,0,0,0,3,0,0,0,0,0,2,0,0,0,2,0,0,0,0,0,3,0,0,0,13
0,0,0,0,0,0,0,0,2,2,2,0,0,0,2,2,2,0,0,0,0,0,0,0,0
0,0,0,0,0,0,0,0,2,5,0,0,0,0,0,0,2,0,0,0,0,0,0,0,0
0,0,0,0,0,0,0,0,2,0,0,0,0,0,0,4,2,0,0,0,0,0,0,0,0
13,0,0,0,3,0,0,0,2,2,2,0,0,0,2,2,2,0,0,0,3,0,0,0,13
0,0,0,0,0,0,0,0,2,5,0,0,0,0,0,0,2,0,0,0,0,0,0,0,0
0,0,0,0,0,0,0,0,2,0,0,0,0,0,0,4,2,0,0,0,0,0,0,0,0
0,0,0,0,0,0,0,0,2,2,2,0,0,0,2,2,2,0,0,0,0,0,0,0,0
13,0,0,0,3,0,0,0,0,0,2,0,0,0,2,0,0,0,0,0,3,0,0,0,13
0,0,0,0,0,0,0,0,0,0,2,0,0,0,2,0,0,0,0,0,0,0,0,0,0
0,0,0,0,0,0,0,0,0,0,2,0,0,0,2,0,0,0,0,0,0,0,0,0,0
0,0,0,0,0,0,0,0,0,0,2,0,0,0,2,0,0,0,0,0,0,0,0,0,0
13,0,0,0,3,0,0,0,3,2,2,0,0,0,2,2,3,0,0,0,3,0,0,0,13
0,0,0,0,0,0,0,0,0,0,0,0,0,0,0,0,0,0,0,0,0,0,0,0,0
0,0,0,0,0,0,0,0,0,0,0,0,0,0,0,0,0,0,0,0,0,0,0,0,0
0,0,0,0,0,0,0,0,0,0,0,0,0,0,0,0,0,0,0,0,0,0,0,0,0
13,0,0,0,13,0,0,0,13,0,0,0,13,0,0,0,13,0,0,0,13,0,0,0,13
endlayer

layer
13,0,0,0,13,0,0,0,13,0,0,0,13,0,0,0,13,0,0,0,13,0,0,0,13
0,0,0,0,0,0,0,0,0,0,0,0,0,0,0,0,0,0,0,0,0,0,0,0,0
0,0,0,0,0,0,0,0,0,0,0,0,0,0,0,0,0,0,0,0,0,0,0,0,0
0,0,0,0,0,0,0,0,0,0,0,0,0,0,0,0,0,0,0,0,0,0,0,0,0
13,0,0,0,3,0,0,0,3,2,2,0,0,0,2,2,3,0,0,0,3,0,0,0,13
0,0,0,0,0,0,0,0,0,0,2,0,0,0,2,0,0,0,0,0,0,0,0,0,0
0,0,0,0,0,0,0,0,0,0,2,0,0,0,2,0,0,0,0,0,0,0,0,0,0
0,0,0,0,0,0,0,0,0,0,2,0,0,0,2,0,0,0,0,0,0,0,0,0,0
13,0,0,0,3,0,0,0,0,0,2,0,0,0,2,0,0,0,0,0,3,0,0,0,13
0,0,0,0,0,0,0,0,2,2,2,0,0,0,2,2,2,0,0,0,0,0,0,0,0
0,0,0,0,0,0,0,0,2,5,0,0,0,0,0,0,2,0,0,0,0,0,0,0,0
0,0,0,0,0,0,0,0,2,0,0,0,0,0,0,4,2,0,0,0,0,0,0,0,0
13,0,0,0,3,0,0,0,2,2,2,0,0,0,2,2,2,0,0,0,3,0,0,0,13
0,0,0,0,0,0,0,0,2,5,0,0,0,0,0,0,2,0,0,0,0,0,0,0,0
0,0,0,0,0,0,0,0,2,0,0,0,0,0,0,4,2,0,0,0,0,0,0,0,0
0,0,0,0,0,0,0,0,2,2,2,0,0,0,2,2,2,0,0,0,0,0,0,0,0
13,0,0,0,3,0,0,0,0,0,2,0,0,0,2,0,0,0,0,0,3,0,0,0,13
0,0,0,0,0,0,0,0,0,0,2,0,0,0,2,0,0,0,0,0,0,0,0,0,0
0,0,0,0,0,0,0,0,0,0,2,0,0,0,2,0,0,0,0,0,0,0,0,0,0
0,0,0,0,0,0,0,0,0,0,2,0,0,0,2,0,0,0,0,0,0,0,0,0,0
13,0,0,0,3,0,0,0,3,2,2,0,0,0,2,2,3,0,0,0,3,0,0,0,13
0,0,0,0,0,0,0,0,0,0,0,0,0,0,0,0,0,0,0,0,0,0,0,0,0
0,0,0,0,0,0,0,0,0,0,0,0,0,0,0,0,0,0,0,0,0,0,0,0,0
0,0,0,0,0,0,0,0,0,0,0,0,0,0,0,0,0,0,0,0,0,0,0,0,0
13,0,0,0,13,0,0,0,13,0,0,0,13,0,0,0,13,0,0,0,13,0,0,0,13
endlayer

layer
13,14,14,14,13,14,14,14,13,14,14,14,13,14,14,14,13,14,14,14,13,14,14,14,13
14,0,0,0,0,0,0,0,0,0,0,0,0,0,0,0,0,0,0,0,0,0,0,0,14
14,0,0,0,0,0,0,0,0,0,0,0,0,0,0,0,0,0,0,0,0,0,0,0,14
14,0,0,0,0,0,0,0,0,0,0,0,0,0,0,0,0,0,0,0,0,0,0,0,14
13,0,0,0,3,0,0,0,3,2,2,0,0,0,2,2,3,0,0,0,3,0,0,0,13
14,0,0,0,0,9,9,9,9,9,2,9,9,9,2,9,9,9,9,9,0,0,0,0,14
14,0,0,0,0,9,9,9,9,9,2,9,9,9,2,9,9,9,9,9,0,0,0,0,14
14,0,0,0,0,9,9,9,9,9,2,9,9,9,2,9,9,9,9,9,0,0,0,0,14
13,0,0,0,3,9,9,9,9,9,2,9,9,9,2,9,9,9,9,9,3,0,0,0,13
14,0,0,0,0,9,9,9,2,2,2,9,9,9,2,2,2,9,9,9,0,0,0,0,14
14,0,0,0,0,9,9,9,2,5,0,9,9,9,0,0,2,9,9,9,0,0,0,0,14
14,0,0,0,0,9,9,9,2,0,0,9,9,9,0,4,2,9,9,9,0,0,0,0,14
13,0,0,0,3,9,9,9,2,2,2,9,9,9,2,2,2,9,9,9,3,0,0,0,13
14,0,0,0,0,9,9,9,2,5,0,9,9,9,0,0,2,9,9,9,0,0,0,0,14
14,0,0,0,0,9,9,9,2,0,0,9,9,9,0,4,2,9,9,9,0,0,0,0,14
14,0,0,0,0,9,9,9,2,2,2,9,9,9,2,2,2,9,9,9,0,0,0,0,14
13,0,0,0,3,9,9,9,9,9,2,9,9,9,2,9,9,9,9,9,3,0,0,0,13
14,0,0,0,0,9,9,9,9,9,2,9,9,9,2,9,9,9,9,9,0,0,0,0,14
14,0,0,0,0,9,9,9,9,9,2,9,9,9,2,9,9,9,9,9,0,0,0,0,14
14,0,0,0,0,9,9,9,9,9,2,9,9,9,2,9,9,9,9,9,0,0,0,0,14
13,0,0,0,3,0,0,0,3,2,2,0,0,0,2,2,3,0,0,0,3,0,0,0,13
14,0,0,0,0,0,0,0,0,0,0,0,0,0,0,0,0,0,0,0,0,0,0,0,14
14,0,0,0,0,0,0,0,0,0,0,0,0,0,0,0,0,0,0,0,0,0,0,0,14
14,0,0,0,0,0,0,0,0,0,0,0,0,0,0,0,0,0,0,0,0,0,0,0,14
13,14,14,14,13,14,14,14,13,14,14,14,13,14,14,14,13,14,14,14,13,14,14,14,13
endlayer

layer
13,14,14,14,13,14,14,14,13,14,14,14,13,14,14,14,13,14,14,14,13,14,14,14,13
14,14,14,14,14,14,14,14,14,14,14,14,14,14,14,14,14,14,14,14,14,14,14,14,14
14,14,14,14,14,14,14,14,14,14,14,14,14,14,14,14,14,14,14,14,14,14,14,14,14
14,14,14,14,14,14,14,14,14,14,14,14,14,14,14,14,14,14,14,14,14,14,14,14,14
13,14,14,14,3,14,14,14,3,2,2,14,14,14,2,2,3,14,14,14,3,14,14,14,13
14,14,14,14,14,10,10,10,10,10,2,10,10,10,2,10,10,10,10,10,14,14,14,14,14
14,14,14,14,14,10,10,10,10,10,2,10,10,10,2,10,10,10,10,10,14,14,14,14,14
14,14,14,14,14,10,10,10,10,10,2,10,10,10,2,10,10,10,10,10,14,14,14,14,14
13,14,14,14,3,10,10,10,10,10,2,10,10,10,2,10,10,10,10,10,3,14,14,14,13
14,14,14,14,14,10,10,10,2,2,2,10,10,10,2,2,2,10,10,10,14,14,14,14,14
14,14,14,14,14,10,10,10,2,5,0,10,10,10,0,0,2,10,10,10,14,14,14,14,14
14,14,14,14,14,10,10,10,2,0,0,10,10,10,0,0,2,10,10,10,14,14,14,14,14
13,14,14,14,3,10,10,10,2,2,2,10,10,10,2,2,2,10,10,10,3,14,14,14,13
14,14,14,14,14,10,10,10,2,5,0,10,10,10,0,0,2,10,10,10,14,14,14,14,14
14,14,14,14,14,10,10,10,2,0,0,10,10,10,0,4,2,10,10,10,14,14,14,14,14
14,14,14,14,14,10,10,10,2,2,2,10,10,10,2,2,2,10,10,10,14,14,14,14,14
13,14,14,14,3,10,10,10,10,10,2,10,10,10,2,10,10,10,10,10,3,14,14,14,13
14,14,14,14,14,10,10,10,10,10,2,10,10,10,2,10,10,10,10,10,14,14,14,14,14
14,14,14,14,14,10,10,10,10,10,2,10,10,10,2,10,10,10,10,10,14,14,14,14,14
14,14,14,14,14,10,10,10,10,10,2,10,10,10,2,10,10,10,10,10,14,14,14,14,14
13,14,14,14,3,14,14,14,3,2,2,14,14,14,2,2,3,14,14,14,3,14,14,14,13
14,14,14,14,14,14,14,14,14,14,14,14,14,14,14,14,14,14,14,14,14,14,14,14,14
14,14,14,14,14,14,14,14,14,14,14,14,14,14,14,14,14,14,14,14,14,14,14,14,14
14,14,14,14,14,14,14,14,14,14,14,14,14,14,14,14,14,14,14,14,14,14,14,14,14
13,14,14,14,13,14,14,14,13,14,14,14,13,14,14,14,13,14,14,14,13,14,14,14,13
endlayer

layer
13,11,11,11,13,11,11,11,13,11,11,11,13,11,11,11,13,11,11,11,13,11,11,11,13
11,0,0,0,0,0,0,0,0,0,0,0,0,0,0,0,0,0,0,0,0,0,0,0,11
11,0,0,0,0,0,0,0,0,0,0,0,0,0,0,0,0,0,0,0,0,0,0,0,11
11,0,0,0,0,0,0,0,0,0,0,0,0,0,0,0,0,0,0,0,0,0,0,0,11
13,0,0,0,3,0,0,0,3,2,2,0,0,0,2,2,3,0,0,0,3,0,0,0,13
11,0,0,0,0,0,0,0,0,0,2,0,0,0,2,0,0,0,0,0,0,0,0,0,11
11,0,0,0,0,0,0,0,0,0,2,0,0,0,2,0,0,0,0,0,0,0,0,0,11
11,0,0,0,0,0,0,0,0,0,2,0,0,0,2,0,0,0,0,0,0,0,0,0,11
13,0,0,0,3,0,0,0,0,0,2,0,0,0,2,0,0,0,0,0,3,0,0,0,13
11,0,0,0,0,0,0,0,2,2,2,0,0,0,2,2,2,0,0,0,0,0,0,0,11
11,0,0,0,0,0,0,0,2,5,0,0,0,0,0,0,2,0,0,0,0,0,0,0,11
11,0,0,0,0,0,0,0,2,0,0,0,0,0,0,4,2,0,0,0,0,0,0,0,11
13,0,0,0,3,0,0,0,2,2,2,0,0,0,2,2,2,0,0,0,3,0,0,0,13
11,0,0,0,0,0,0,0,2,5,0,0,0,0,0,0,2,0,0,0,0,0,0,0,11
11,0,0,0,0,0,0,0,2,0,0,0,0,0,0,4,2,0,0,0,0,0,0,0,11
11,0,0,0,0,0,0,0,2,2,2,0,0,0,2,2,2,0,0,0,0,0,0,0,11
13,0,0,0,3,0,0,0,0,0,2,0,0,0,2,0,0,0,0,0,3,0,0,0,13
11,0,0,0,0,0,0,0,0,0,2,0,0,0,2,0,0,0,0,0,0,0,0,0,11
11,0,0,0,0,0,0,0,0,0,2,0,0,0,2,0,0,0,0,0,0,0,0,0,11
11,0,0,0,0,0,0,0,0,0,2,0,0,0,2,0,0,0,0,0,0,0,0,0,11
13,0,0,0,3,0,0,0,3,2,2,0,0,0,2,2,3,0,0,0,3,0,0,0,13
11,0,0,0,0,0,0,0,0,0,0,0,0,0,0,0,0,0,0,0,0,0,0,0,11
11,0,0,0,0,0,0,0,0,0,0,0,0,0,0,0,0,0,0,0,0,0,0,0,11
11,0,0,0,0,0,0,0,0,0,0,0,0,0,0,0,0,0,0,0,0,0,0,0,11
13,11,11,11,13,11,11,11,13,11,11,11,13,11,11,11,13,11,11,11,13,11,11,11,13
endlayer

layer
13,0,0,0,13,0,0,0,13,0,0,0,13,0,0,0,13,0,0,0,13,0,0,0,13
0,0,0,0,0,0,0,0,0,0,0,0,0,0,0,0,0,0,0,0,0,0,0,0,0
0,0,0,0,0,0,0,0,0,0,0,0,0,0,0,0,0,0,0,0,0,0,0,0,0
0,0,0,0,0,0,0,0,0,0,0,0,0,0,0,0,0,0,0,0,0,0,0,0,0
13,0,0,0,3,0,0,0,3,2,2,0,0,0,2,2,3,0,0,0,3,0,0,0,13
0,0,0,0,0,0,0,0,0,0,2,0,0,0,2,0,0,0,0,0,0,0,0,0,0
0,0,0,0,0,0,0,0,0,0,2,0,0,0,2,0,0,0,0,0,0,0,0,0,0
0,0,0,0,0,0,0,0,0,0,2,0,0,0,2,0,0,0,0,0,0,0,0,0,0
13,0,0,0,3,0,0,0,0,0,2,0,0,0,2,0,0,0,0,0,3,0,0,0,13
0,0,0,0,0,0,0,0,2,2,2,0,0,0,2,2,2,0,0,0,0,0,0,0,0
0,0,0,0,0,0,0,0,2,5,0,0,0,0,0,0,2,0,0,0,0,0,0,0,0
0,0,0,0,0,0,0,0,2,0,0,0,0,0,0,4,2,0,0,0,0,0,0,0,0
13,0,0,0,3,0,0,0,2,2,2,0,0,0,2,2,2,0,0,0,3,0,0,0,13
0,0,0,0,0,0,0,0,2,5,0,0,0,0,0,0,2,0,0,0,0,0,0,0,0
0,0,0,0,0,0,0,0,2,0,0,0,0,0,0,4,2,0,0,0,0,0,0,0,0
0,0,0,0,0,0,0,0,2,2,2,0,0,0,2,2,2,0,0,0,0,0,0,0,0
13,0,0,0,3,0,0,0,0,0,2,0,0,0,2,0,0,0,0,0,3,0,0,0,13
0,0,0,0,0,0,0,0,0,0,2,0,0,0,2,0,0,0,0,0,0,0,0,0,0
0,0,0,0,0,0,0,0,0,0,2,0,0,0,2,0,0,0,0,0,0,0,0,0,0
0,0,0,0,0,0,0,0,0,0,2,0,0,0,2,0,0,0,0,0,0,0,0,0,0
13,0,0,0,3,0,0,0,3,2,2,0,0,0,2,2,3,0,0,0,3,0,0,0,13
0,0,0,0,0,0,0,0,0,0,0,0,0,0,0,0,0,0,0,0,0,0,0,0,0
0,0,0,0,0,0,0,0,0,0,0,0,0,0,0,0,0,0,0,0,0,0,0,0,0
0,0,0,0,0,0,0,0,0,0,0,0,0,0,0,0,0,0,0,0,0,0,0,0,0
13,0,0,0,13,0,0,0,13,0,0,0,13,0,0,0,13,0,0,0,13,0,0,0,13
endlayer

layer
13,0,0,0,13,0,0,0,13,0,0,0,13,0,0,0,13,0,0,0,13,0,0,0,13
0,0,0,0,0,0,0,0,0,0,0,0,0,0,0,0,0,0,0,0,0,0,0,0,0
0,0,0,0,0,0,0,0,0,0,0,0,0,0,0,0,0,0,0,0,0,0,0,0,0
0,0,0,0,0,0,0,0,0,0,0,0,0,0,0,0,0,0,0,0,0,0,0,0,0
13,0,0,0,3,0,0,0,3,2,2,0,0,0,2,2,3,0,0,0,3,0,0,0,13
0,0,0,0,0,0,0,0,0,0,2,0,0,0,2,0,0,0,0,0,0,0,0,0,0
0,0,0,0,0,0,0,0,0,0,2,0,0,0,2,0,0,0,0,0,0,0,0,0,0
0,0,0,0,0,0,0,0,0,0,2,0,0,0,2,0,0,0,0,0,0,0,0,0,0
13,0,0,0,3,0,0,0,0,0,2,0,0,0,2,0,0,0,0,0,3,0,0,0,13
0,0,0,0,0,0,0,0,2,2,2,0,0,0,2,2,2,0,0,0,0,0,0,0,0
0,0,0,0,0,0,0,0,2,5,0,0,0,0,0,0,2,0,0,0,0,0,0,0,0
0,0,0,0,0,0,0,0,2,0,0,0,0,0,0,4,2,0,0,0,0,0,0,0,0
13,0,0,0,3,0,0,0,2,2,2,0,0,0,2,2,2,0,0,0,3,0,0,0,13
0,0,0,0,0,0,0,0,2,5,0,0,0,0,0,0,2,0,0,0,0,0,0,0,0
0,0,0,0,0,0,0,0,2,0,0,0,0,0,0,4,2,0,0,0,0,0,0,0,0
0,0,0,0,0,0,0,0,2,2,2,0,0,0,2,2,2,0,0,0,0,0,0,0,0
13,0,0,0,3,0,0,0,0,0,2,0,0,0,2,0,0,0,0,0,3,0,0,0,13
0,0,0,0,0,0,0,0,0,0,2,0,0,0,2,0,0,0,0,0,0,0,0,0,0
0,0,0,0,0,0,0,0,0,0,2,0,0,0,2,0,0,0,0,0,0,0,0,0,0
0,0,0,0,0,0,0,0,0,0,2,0,0,0,2,0,0,0,0,0,0,0,0,0,0
13,0,0,0,3,0,0,0,3,2,2,0,0,0,2,2,3,0,0,0,3,0,0,0,13
0,0,0,0,0,0,0,0,0,0,0,0,0,0,0,0,0,0,0,0,0,0,0,0,0
0,0,0,0,0,0,0,0,0,0,0,0,0,0,0,0,0,0,0,0,0,0,0,0,0
0,0,0,0,0,0,0,0,0,0,0,0,0,0,0,0,0,0,0,0,0,0,0,0,0
13,0,0,0,13,0,0,0,13,0,0,0,13,0,0,0,13,0,0,0,13,0,0,0,13
endlayer

layer
13,14,14,14,13,14,14,14,13,14,14,14,13,14,14,14,13,14,14,14,13,14,14,14,13
14,0,0,0,0,0,0,0,0,0,0,0,0,0,0,0,0,0,0,0,0,0,0,0,14
14,0,0,0,0,0,0,0,0,0,0,0,0,0,0,0,0,0,0,0,0,0,0,0,14
14,0,0,0,0,0,0,0,0,0,0,0,0,0,0,0,0,0,0,0,0,0,0,0,14
13,0,0,0,3,0,0,0,3,2,2,0,0,0,2,2,3,0,0,0,3,0,0,0,13
14,0,0,0,0,9,9,9,9,9,2,9,9,9,2,9,9,9,9,9,0,0,0,0,14
14,0,0,0,0,9,9,9,9,9,2,9,9,9,2,9,9,9,9,9,0,0,0,0,14
14,0,0,0,0,9,9,9,9,9,2,9,9,9,2,9,9,9,9,9,0,0,0,0,14
13,0,0,0,3,9,9,9,9,9,2,9,9,9,2,9,9,9,9,9,3,0,0,0,13
14,0,0,0,0,9,9,9,2,2,2,9,9,9,2,2,2,9,9,9,0,0,0,0,14
14,0,0,0,0,9,9,9,2,5,0,9,9,9,0,0,2,9,9,9,0,0,0,0,14
14,0,0,0,0,9,9,9,2,0,0,9,9,9,0,4,2,9,9,9,0,0,0,0,14
13,0,0,0,3,9,9,9,2,2,2,9,9,9,2,2,2,9,9,9,3,0,0,0,13
14,0,0,0,0,9,9,9,2,5,0,9,9,9,0,0,2,9,9,9,0,0,0,0,14
14,0,0,0,0,9,9,9,2,0,0,9,9,9,0,4,2,9,9,9,0,0,0,0,14
14,0,0,0,0,9,9,9,2,2,2,9,9,9,2,2,2,9,9,9,0,0,0,0,14
13,0,0,0,3,9,9,9,9,9,2,9,9,9,2,9,9,9,9,9,3,0,0,0,13
14,0,0,0,0,9,9,9,9,9,2,9,9,9,2,9,9,9,9,9,0,0,0,0,14
14,0,0,0,0,9,9,9,9,9,2,9,9,9,2,9,9,9,9,9,0,0,0,0,14
14,0,0,0,0,9,9,9,9,9,2,9,9,9,2,9,9,9,9,9,0,0,0,0,14
13,0,0,0,3,0,0,0,3,2,2,0,0,0,2,2,3,0,0,0,3,0,0,0,13
14,0,0,0,0,0,0,0,0,0,0,0,0,0,0,0,0,0,0,0,0,0,0,0,14
14,0,0,0,0,0,0,0,0,0,0,0,0,0,0,0,0,0,0,0,0,0,0,0,14
14,0,0,0,0,0,0,0,0,0,0,0,0,0,0,0,0,0,0,0,0,0,0,0,14
13,14,14,14,13,14,14,14,13,14,14,14,13,14,14,14,13,14,14,14,13,14,14,14,13
endlayer

layer
13,14,14,14,13,14,14,14,13,14,14,14,13,14,14,14,13,14,14,14,13,14,14,14,13
14,14,14,14,14,14,14,14,14,14,14,14,14,14,14,14,14,14,14,14,14,14,14,14,14
14,14,14,14,14,14,14,14,14,14,14,14,14,14,14,14,14,14,14,14,14,14,14,14,14
14,14,14,14,14,14,14,14,14,14,14,14,14,14,14,14,14,14,14,14,14,14,14,14,14
13,14,14,14,3,14,14,14,3,2,2,14,14,14,2,2,3,14,14,14,3,14,14,14,13
14,14,14,14,14,10,10,10,10,10,2,10,10,10,2,10,10,10,10,10,14,14,14,14,14
14,14,14,14,14,10,10,10,10,10,2,10,10,10,2,10,10,10,10,10,14,14,14,14,14
14,14,14,14,14,10,10,10,10,10,2,10,10,10,2,10,10,10,10,10,14,14,14,14,14
13,14,14,14,3,10,10,10,10,10,2,10,10,10,2,10,10,10,10,10,3,14,14,14,13
14,14,14,14,14,10,10,10,2,2,2,10,10,10,2,2,2,10,10,10,14,14,14,14,14
14,14,14,14,14,10,10,10,2,5,0,10,10,10,0,0,2,10,10,10,14,14,14,14,14
14,14,14,14,14,10,10,10,2,0,0,10,10,10,0,0,2,10,10,10,14,14,14,14,14
13,14,14,14,3,10,10,10,2,2,2,10,10,10,2,2,2,10,10,10,3,14,14,14,13
14,14,14,14,14,10,10,10,2,5,0,10,10,10,0,0,2,10,10,10,14,14,14,14,14
14,14,14,14,14,10,10,10,2,0,0,10,10,10,0,4,2,10,10,10,14,14,14,14,14
14,14,14,14,14,10,10,10,2,2,2,10,10,10,2,2,2,10,10,10,14,14,14,14,14
13,14,14,14,3,10,10,10,10,10,2,10,10,10,2,10,10,10,10,10,3,14,14,14,13
14,14,14,14,14,10,10,10,10,10,2,10,10,10,2,10,10,10,10,10,14,14,14,14,14
14,14,14,14,14,10,10,10,10,10,2,10,10,10,2,10,10,10,10,10,14,14,14,14,14
14,14,14,14,14,10,10,10,10,10,2,10,10,10,2,10,10,10,10,10,14,14,14,14,14
13,14,14,14,3,14,14,14,3,2,2,14,14,14,2,2,3,14,14,14,3,14,14,14,13
14,14,14,14,14,14,14,14,14,14,14,14,14,14,14,14,14,14,14,14,14,14,14,14,14
14,14,14,14,14,14,14,14,14,14,14,14,14,14,14,14,14,14,14,14,14,14,14,14,14
14,14,14,14,14,14,14,14,14,14,14,14,14,14,14,14,14,14,14,14,14,14,14,14,14
13,14,14,14,13,14,14,14,13,14,14,14,13,14,14,14,13,14,14,14,13,14,14,14,13
endlayer

layer
13,11,11,11,13,11,11,11,13,11,11,11,13,11,11,11,13,11,11,11,13,11,11,11,13
11,0,0,0,0,0,0,0,0,0,0,0,0,0,0,0,0,0,0,0,0,0,0,0,11
11,0,0,0,0,0,0,0,0,0,0,0,0,0,0,0,0,0,0,0,0,0,0,0,11
11,0,0,0,0,0,0,0,0,0,0,0,0,0,0,0,0,0,0,0,0,0,0,0,11
13,0,0,0,3,0,0,0,3,2,2,0,0,0,2,2,3,0,0,0,3,0,0,0,13
11,0,0,0,0,0,0,0,0,0,2,0,0,0,2,0,0,0,0,0,0,0,0,0,11
11,0,0,0,0,0,0,0,0,0,2,0,0,0,2,0,0,0,0,0,0,0,0,0,11
11,0,0,0,0,0,0,0,0,0,2,0,0,0,2,0,0,0,0,0,0,0,0,0,11
13,0,0,0,3,0,0,0,0,0,2,0,0,0,2,0,0,0,0,0,3,0,0,0,13
11,0,0,0,0,0,0,0,2,2,2,0,0,0,2,2,2,0,0,0,0,0,0,0,11
11,0,0,0,0,0,0,0,2,5,0,0,0,0,0,0,2,0,0,0,0,0,0,0,11
11,0,0,0,0,0,0,0,2,0,0,0,0,0,0,4,2,0,0,0,0,0,0,0,11
13,0,0,0,3,0,0,0,2,2,2,0,0,0,2,2,2,0,0,0,3,0,0,0,13
11,0,0,0,0,0,0,0,2,5,0,0,0,0,0,0,2,0,0,0,0,0,0,0,11
11,0,0,0,0,0,0,0,2,0,0,0,0,0,0,4,2,0,0,0,0,0,0,0,11
11,0,0,0,0,0,0,0,2,2,2,0,0,0,2,2,2,0,0,0,0,0,0,0,11
13,0,0,0,3,0,0,0,0,0,2,0,0,0,2,0,0,0,0,0,3,0,0,0,13
11,0,0,0,0,0,0,0,0,0,2,0,0,0,2,0,0,0,0,0,0,0,0,0,11
11,0,0,0,0,0,0,0,0,0,2,0,0,0,2,0,0,0,0,0,0,0,0,0,11
11,0,0,0,0,0,0,0,0,0,2,0,0,0,2,0,0,0,0,0,0,0,0,0,11
13,0,0,0,3,0,0,0,3,2,2,0,0,0,2,2,3,0,0,0,3,0,0,0,13
11,0,0,0,0,0,0,0,0,0,0,0,0,0,0,0,0,0,0,0,0,0,0,0,11
11,0,0,0,0,0,0,0,0,0,0,0,0,0,0,0,0,0,0,0,0,0,0,0,11
11,0,0,0,0,0,0,0,0,0,0,0,0,0,0,0,0,0,0,0,0,0,0,0,11
13,11,11,11,13,11,11,11,13,11,11,11,13,11,11,11,13,11,11,11,13,11,11,11,13
endlayer

layer
13,0,0,0,13,0,0,0,13,0,0,0,13,0,0,0,13,0,0,0,13,0,0,0,13
0,0,0,0,0,0,0,0,0,0,0,0,0,0,0,0,0,0,0,0,0,0,0,0,0
0,0,0,0,0,0,0,0,0,0,0,0,0,0,0,0,0,0,0,0,0,0,0,0,0
0,0,0,0,0,0,0,0,0,0,0,0,0,0,0,0,0,0,0,0,0,0,0,0,0
13,0,0,0,3,0,0,0,3,2,2,0,0,0,2,2,3,0,0,0,3,0,0,0,13
0,0,0,0,0,0,0,0,0,0,2,0,0,0,2,0,0,0,0,0,0,0,0,0,0
0,0,0,0,0,0,0,0,0,0,2,0,0,0,2,0,0,0,0,0,0,0,0,0,0
0,0,0,0,0,0,0,0,0,0,2,0,0,0,2,0,0,0,0,0,0,0,0,0,0
13,0,0,0,3,0,0,0,0,0,2,0,0,0,2,0,0,0,0,0,3,0,0,0,13
0,0,0,0,0,0,0,0,2,2,2,0,0,0,2,2,2,0,0,0,0,0,0,0,0
0,0,0,0,0,0,0,0,2,5,0,0,0,0,0,0,2,0,0,0,0,0,0,0,0
0,0,0,0,0,0,0,0,2,0,0,0,0,0,0,4,2,0,0,0,0,0,0,0,0
13,0,0,0,3,0,0,0,2,2,2,0,0,0,2,2,2,0,0,0,3,0,0,0,13
0,0,0,0,0,0,0,0,2,5,0,0,0,0,0,0,2,0,0,0,0,0,0,0,0
0,0,0,0,0,0,0,0,2,0,0,0,0,0,0,4,2,0,0,0,0,0,0,0,0
0,0,0,0,0,0,0,0,2,2,2,0,0,0,2,2,2,0,0,0,0,0,0,0,0
13,0,0,0,3,0,0,0,0,0,2,0,0,0,2,0,0,0,0,0,3,0,0,0,13
0,0,0,0,0,0,0,0,0,0,2,0,0,0,2,0,0,0,0,0,0,0,0,0,0
0,0,0,0,0,0,0,0,0,0,2,0,0,0,2,0,0,0,0,0,0,0,0,0,0
0,0,0,0,0,0,0,0,0,0,2,0,0,0,2,0,0,0,0,0,0,0,0,0,0
13,0,0,0,3,0,0,0,3,2,2,0,0,0,2,2,3,0,0,0,3,0,0,0,13
0,0,0,0,0,0,0,0,0,0,0,0,0,0,0,0,0,0,0,0,0,0,0,0,0
0,0,0,0,0,0,0,0,0,0,0,0,0,0,0,0,0,0,0,0,0,0,0,0,0
0,0,0,0,0,0,0,0,0,0,0,0,0,0,0,0,0,0,0,0,0,0,0,0,0
13,0,0,0,13,0,0,0,13,0,0,0,13,0,0,0,13,0,0,0,13,0,0,0,13
endlayer

layer
13,0,0,0,13,0,0,0,13,0,0,0,13,0,0,0,13,0,0,0,13,0,0,0,13
0,0,0,0,0,0,0,0,0,0,0,0,0,0,0,0,0,0,0,0,0,0,0,0,0
0,0,0,0,0,0,0,0,0,0,0,0,0,0,0,0,0,0,0,0,0,0,0,0,0
0,0,0,0,0,0,0,0,0,0,0,0,0,0,0,0,0,0,0,0,0,0,0,0,0
13,0,0,0,3,0,0,0,3,2,2,0,0,0,2,2,3,0,0,0,3,0,0,0,13
0,0,0,0,0,0,0,0,0,0,2,0,0,0,2,0,0,0,0,0,0,0,0,0,0
0,0,0,0,0,0,0,0,0,0,2,0,0,0,2,0,0,0,0,0,0,0,0,0,0
0,0,0,0,0,0,0,0,0,0,2,0,0,0,2,0,0,0,0,0,0,0,0,0,0
13,0,0,0,3,0,0,0,0,0,2,0,0,0,2,0,0,0,0,0,3,0,0,0,13
0,0,0,0,0,0,0,0,2,2,2,0,0,0,2,2,2,0,0,0,0,0,0,0,0
0,0,0,0,0,0,0,0,2,5,0,0,0,0,0,0,2,0,0,0,0,0,0,0,0
0,0,0,0,0,0,0,0,2,0,0,0,0,0,0,4,2,0,0,0,0,0,0,0,0
13,0,0,0,3,0,0,0,2,2,2,0,0,0,2,2,2,0,0,0,3,0,0,0,13
0,0,0,0,0,0,0,0,2,5,0,0,0,0,0,0,2,0,0,0,0,0,0,0,0
0,0,0,0,0,0,0,0,2,0,0,0,0,0,0,4,2,0,0,0,0,0,0,0,0
0,0,0,0,0,0,0,0,2,2,2,0,0,0,2,2,2,0,0,0,0,0,0,0,0
13,0,0,0,3,0,0,0,0,0,2,0,0,0,2,0,0,0,0,0,3,0,0,0,13
0,0,0,0,0,0,0,0,0,0,2,0,0,0,2,0,0,0,0,0,0,0,0,0,0
0,0,0,0,0,0,0,0,0,0,2,0,0,0,2,0,0,0,0,0,0,0,0,0,0
0,0,0,0,0,0,0,0,0,0,2,0,0,0,2,0,0,0,0,0,0,0,0,0,0
13,0,0,0,3,0,0,0,3,2,2,0,0,0,2,2,3,0,0,0,3,0,0,0,13
0,0,0,0,0,0,0,0,0,0,0,0,0,0,0,0,0,0,0,0,0,0,0,0,0
0,0,0,0,0,0,0,0,0,0,0,0,0,0,0,0,0,0,0,0,0,0,0,0,0
0,0,0,0,0,0,0,0,0,0,0,0,0,0,0,0,0,0,0,0,0,0,0,0,0
13,0,0,0,13,0,0,0,13,0,0,0,13,0,0,0,13,0,0,0,13,0,0,0,13
endlayer

layer
13,14,14,14,13,14,14,14,13,14,14,14,13,14,14,14,13,14,14,14,13,14,14,14,13
14,0,0,0,0,0,0,0,0,0,0,0,0,0,0,0,0,0,0,0,0,0,0,0,14
14,0,0,0,0,0,0,0,0,0,0,0,0,0,0,0,0,0,0,0,0,0,0,0,14
14,0,0,0,0,0,0,0,0,0,0,0,0,0,0,0,0,0,0,0,0,0,0,0,14
13,0,0,0,3,0,0,0,3,2,2,0,0,0,2,2,3,0,0,0,3,0,0,0,13
14,0,0,0,0,9,9,9,9,9,2,9,9,9,2,9,9,9,9,9,0,0,0,0,14
14,0,0,0,0,9,9,9,9,9,2,9,9,9,2,9,9,9,9,9,0,0,0,0,14
14,0,0,0,0,9,9,9,9,9,2,9,9,9,2,9,9,9,9,9,0,0,0,0,14
13,0,0,0,3,9,9,9,9,9,2,9,9,9,2,9,9,9,9,9,3,0,0,0,13
14,0,0,0,0,9,9,9,2,2,2,9,9,9,2,2,2,9,9,9,0,0,0,0,14
14,0,0,0,0,9,9,9,2,5,0,9,9,9,0,0,2,9,9,9,0,0,0,0,14
14,0,0,0,0,9,9,9,2,0,0,9,9,9,0,4,2,9,9,9,0,0,0,0,14
13,0,0,0,3,9,9,9,2,2,2,9,9,9,2,2,2,9,9,9,3,0,0,0,13
14,0,0,0,0,9,9,9,2,5,0,9,9,9,0,0,2,9,9,9,0,0,0,0,14
14,0,0,0,0,9,9,9,2,0,0,9,9,9,0,4,2,9,9,9,0,0,0,0,14
14,0,0,0,0,9,9,9,2,2,2,9,9,9,2,2,2,9,9,9,0,0,0,0,14
13,0,0,0,3,9,9,9,9,9,2,9,9,9,2,9,9,9,9,9,3,0,0,0,13
14,0,0,0,0,9,9,9,9,9,2,9,9,9,2,9,9,9,9,9,0,0,0,0,14
14,0,0,0,0,9,9,9,9,9,2,9,9,9,2,9,9,9,9,9,0,0,0,0,14
14,0,0,0,0,9,9,9,9,9,2,9,9,9,2,9,9,9,9,9,0,0,0,0,14
13,0,0,0,3,0,0,0,3,2,2,0,0,0,2,2,3,0,0,0,3,0,0,0,13
14,0,0,0,0,0,0,0,0,0,0,0,0,0,0,0,0,0,0,0,0,0,0,0,14
14,0,0,0,0,0,0,0,0,0,0,0,0,0,0,0,0,0,0,0,0,0,0,0,14
14,0,0,0,0,0,0,0,0,0,0,0,0,0,0,0,0,0,0,0,0,0,0,0,14
13,14,14,14,13,14,14,14,13,14,14,14,13,14,14,14,13,14,14,14,13,14,14,14,13
endlayer

layer
13,14,14,14,13,14,14,14,13,14,14,14,13,14,14,14,13,14,14,14,13,14,14,14,13
14,14,14,14,14,14,14,14,14,14,14,14,14,14,14,14,14,14,14,14,14,14,14,14,14
14,14,14,14,14,14,14,14,14,14,14,14,14,14,14,14,14,14,14,14,14,14,14,14,14
14,14,14,14,14,14,14,14,14,14,14,14,14,14,14,14,14,14,14,14,14,14,14,14,14
13,14,14,14,3,14,14,14,3,2,2,14,14,14,2,2,3,14,14,14,3,14,14,14,13
14,14,14,14,14,10,10,10,10,10,2,10,10,10,2,10,10,10,10,10,14,14,14,14,14
14,14,14,14,14,10,10,10,10,10,2,10,10,10,2,10,10,10,10,10,14,14,14,14,14
14,14,14,14,14,10,10,10,10,10,2,10,10,10,2,10,10,10,10,10,14,14,14,14,14
13,14,14,14,3,10,10,10,10,10,2,10,10,10,2,10,10,10,10,10,3,14,14,14,13
14,14,14,14,14,10,10,10,2,2,2,10,10,10,2,2,2,10,10,10,14,14,14,14,14
14,14,14,14,14,10,10,10,2,5,0,10,10,10,0,0,2,10,10,10,14,14,14,14,14
14,14,14,14,14,10,10,10,2,0,0,10,10,10,0,0,2,10,10,10,14,14,14,14,14
13,14,14,14,3,10,10,10,2,2,2,10,10,10,2,2,2,10,10,10,3,14,14,14,13
14,14,14,14,14,10,10,10,2,5,0,10,10,10,0,0,2,10,10,10,14,14,14,14,14
14,14,14,14,14,10,10,10,2,0,0,10,10,10,0,4,2,10,10,10,14,14,14,14,14
14,14,14,14,14,10,10,10,2,2,2,10,10,10,2,2,2,10,10,10,14,14,14,14,14
13,14,14,14,3,10,10,10,10,10,2,10,10,10,2,10,10,10,10,10,3,14,14,14,13
14,14,14,14,14,10,10,10,10,10,2,10,10,10,2,10,10,10,10,10,14,14,14,14,14
14,14,14,14,14,10,10,10,10,10,2,10,10,10,2,10,10,10,10,10,14,14,14,14,14
14,14,14,14,14,10,10,10,10,10,2,10,10,10,2,10,10,10,10,10,14,14,14,14,14
13,14,14,14,3,14,14,14,3,2,2,14,14,14,2,2,3,14,14,14,3,14,14,14,13
14,14,14,14,14,14,14,14,14,14,14,14,14,14,14,14,14,14,14,14,14,14,14,14,14
14,14,14,14,14,14,14,14,14,14,14,14,14,14,14,14,14,14,14,14,14,14,14,14,14
14,14,14,14,14,14,14,14,14,14,14,14,14,14,14,14,14,14,14,14,14,14,14,14,14
13,14,14,14,13,14,14,14,13,14,14,14,13,14,14,14,13,14,14,14,13,14,14,14,13
endlayer

layer
13,11,11,11,13,11,11,11,13,11,11,11,13,11,11,11,13,11,11,11,13,11,11,11,13
11,0,0,0,0,0,0,0,0,0,0,0,0,0,0,0,0,0,0,0,0,0,0,0,11
11,0,0,0,0,0,0,0,0,0,0,0,0,0,0,0,0,0,0,0,0,0,0,0,11
11,0,0,0,0,0,0,0,0,0,0,0,0,0,0,0,0,0,0,0,0,0,0,0,11
13,0,0,0,3,0,0,0,3,2,2,0,0,0,2,2,3,0,0,0,3,0,0,0,13
11,0,0,0,0,0,0,0,0,0,2,0,0,0,2,0,0,0,0,0,0,0,0,0,11
11,0,0,0,0,0,0,0,0,0,2,0,0,0,2,0,0,0,0,0,0,0,0,0,11
11,0,0,0,0,0,0,0,0,0,2,0,0,0,2,0,0,0,0,0,0,0,0,0,11
13,0,0,0,3,0,0,0,0,0,2,0,0,0,2,0,0,0,0,0,3,0,0,0,13
11,0,0,0,0,0,0,0,2,2,2,0,0,0,2,2,2,0,0,0,0,0,0,0,11
11,0,0,0,0,0,0,0,2,5,0,0,0,0,0,0,2,0,0,0,0,0,0,0,11
11,0,0,0,0,0,0,0,2,0,0,0,0,0,0,4,2,0,0,0,0,0,0,0,11
13,0,0,0,3,0,0,0,2,2,2,0,0,0,2,2,2,0,0,0,3,0,0,0,13
11,0,0,0,0,0,0,0,2,5,0,0,0,0,0,0,2,0,0,0,0,0,0,0,11
11,0,0,0,0,0,0,0,2,0,0,0,0,0,0,4,2,0,0,0,0,0,0,0,11
11,0,0,0,0,0,0,0,2,2,2,0,0,0,2,2,2,0,0,0,0,0,0,0,11
13,0,0,0,3,0,0,0,0,0,2,0,0,0,2,0,0,0,0,0,3,0,0,0,13
11,0,0,0,0,0,0,0,0,0,2,0,0,0,2,0,0,0,0,0,0,0,0,0,11
11,0,0,0,0,0,0,0,0,0,2,0,0,0,2,0,0,0,0,0,0,0,0,0,11
11,0,0,0,0,0,0,0,0,0,2,0,0,0,2,0,0,0,0,0,0,0,0,0,11
13,0,0,0,3,0,0,0,3,2,2,0,0,0,2,2,3,0,0,0,3,0,0,0,13
11,0,0,0,0,0,0,0,0,0,0,0,0,0,0,0,0,0,0,0,0,0,0,0,11
11,0,0,0,0,0,0,0,0,0,0,0,0,0,0,0,0,0,0,0,0,0,0,0,11
11,0,0,0,0,0,0,0,0,0,0,0,0,0,0,0,0,0,0,0,0,0,0,0,11
13,11,11,11,13,11,11,11,13,11,11,11,13,11,11,11,13,11,11,11,13,11,11,11,13
endlayer

layer
13,0,0,0,13,0,0,0,13,0,0,0,13,0,0,0,13,0,0,0,13,0,0,0,13
0,0,0,0,0,0,0,0,0,0,0,0,0,0,0,0,0,0,0,0,0,0,0,0,0
0,0,0,0,0,0,0,0,0,0,0,0,0,0,0,0,0,0,0,0,0,0,0,0,0
0,0,0,0,0,0,0,0,0,0,0,0,0,0,0,0,0,0,0,0,0,0,0,0,0
13,0,0,0,3,0,0,0,3,2,2,0,0,0,2,2,3,0,0,0,3,0,0,0,13
0,0,0,0,0,0,0,0,0,0,2,0,0,0,2,0,0,0,0,0,0,0,0,0,0
0,0,0,0,0,0,0,0,0,0,2,0,0,0,2,0,0,0,0,0,0,0,0,0,0
0,0,0,0,0,0,0,0,0,0,2,0,0,0,2,0,0,0,0,0,0,0,0,0,0
13,0,0,0,3,0,0,0,0,0,2,0,0,0,2,0,0,0,0,0,3,0,0,0,13
0,0,0,0,0,0,0,0,2,2,2,0,0,0,2,2,2,0,0,0,0,0,0,0,0
0,0,0,0,0,0,0,0,2,5,0,0,0,0,0,0,2,0,0,0,0,0,0,0,0
0,0,0,0,0,0,0,0,2,0,0,0,0,0,0,4,2,0,0,0,0,0,0,0,0
13,0,0,0,3,0,0,0,2,2,2,0,0,0,2,2,2,0,0,0,3,0,0,0,13
0,0,0,0,0,0,0,0,2,5,0,0,0,0,0,0,2,0,0,0,0,0,0,0,0
0,0,0,0,0,0,0,0,2,0,0,0,0,0,0,4,2,0,0,0,0,0,0,0,0
0,0,0,0,0,0,0,0,2,2,2,0,0,0,2,2,2,0,0,0,0,0,0,0,0
13,0,0,0,3,0,0,0,0,0,2,0,0,0,2,0,0,0,0,0,3,0,0,0,13
0,0,0,0,0,0,0,0,0,0,2,0,0,0,2,0,0,0,0,0,0,0,0,0,0
0,0,0,0,0,0,0,0,0,0,2,0,0,0,2,0,0,0,0,0,0,0,0,0,0
0,0,0,0,0,0,0,0,0,0,2,0,0,0,2,0,0,0,0,0,0,0,0,0,0
13,0,0,0,3,0,0,0,3,2,2,0,0,0,2,2,3,0,0,0,3,0,0,0,13
0,0,0,0,0,0,0,0,0,0,0,0,0,0,0,0,0,0,0,0,0,0,0,0,0
0,0,0,0,0,0,0,0,0,0,0,0,0,0,0,0,0,0,0,0,0,0,0,0,0
0,0,0,0,0,0,0,0,0,0,0,0,0,0,0,0,0,0,0,0,0,0,0,0,0
13,0,0,0,13,0,0,0,13,0,0,0,13,0,0,0,13,0,0,0,13,0,0,0,13
endlayer

layer
13,0,0,0,13,0,0,0,13,0,0,0,13,0,0,0,13,0,0,0,13,0,0,0,13
0,0,0,0,0,0,0,0,0,0,0,0,0,0,0,0,0,0,0,0,0,0,0,0,0
0,0,0,0,0,0,0,0,0,0,0,0,0,0,0,0,0,0,0,0,0,0,0,0,0
0,0,0,0,0,0,0,0,0,0,0,0,0,0,0,0,0,0,0,0,0,0,0,0,0
13,0,0,0,3,0,0,0,3,2,2,0,0,0,2,2,3,0,0,0,3,0,0,0,13
0,0,0,0,0,0,0,0,0,0,2,0,0,0,2,0,0,0,0,0,0,0,0,0,0
0,0,0,0,0,0,0,0,0,0,2,0,0,0,2,0,0,0,0,0,0,0,0,0,0
0,0,0,0,0,0,0,0,0,0,2,0,0,0,2,0,0,0,0,0,0,0,0,0,0
13,0,0,0,3,0,0,0,0,0,2,0,0,0,2,0,0,0,0,0,3,0,0,0,13
0,0,0,0,0,0,0,0,2,2,2,0,0,0,2,2,2,0,0,0,0,0,0,0,0
0,0,0,0,0,0,0,0,2,5,0,0,0,0,0,0,2,0,0,0,0,0,0,0,0
0,0,0,0,0,0,0,0,2,0,0,0,0,0,0,4,2,0,0,0,0,0,0,0,0
13,0,0,0,3,0,0,0,2,2,2,0,0,0,2,2,2,0,0,0,3,0,0,0,13
0,0,0,0,0,0,0,0,2,5,0,0,0,0,0,0,2,0,0,0,0,0,0,0,0
0,0,0,0,0,0,0,0,2,0,0,0,0,0,0,4,2,0,0,0,0,0,0,0,0
0,0,0,0,0,0,0,0,2,2,2,0,0,0,2,2,2,0,0,0,0,0,0,0,0
13,0,0,0,3,0,0,0,0,0,2,0,0,0,2,0,0,0,0,0,3,0,0,0,13
0,0,0,0,0,0,0,0,0,0,2,0,0,0,2,0,0,0,0,0,0,0,0,0,0
0,0,0,0,0,0,0,0,0,0,2,0,0,0,2,0,0,0,0,0,0,0,0,0,0
0,0,0,0,0,0,0,0,0,0,2,0,0,0,2,0,0,0,0,0,0,0,0,0,0
13,0,0,0,3,0,0,0,3,2,2,0,0,0,2,2,3,0,0,0,3,0,0,0,13
0,0,0,0,0,0,0,0,0,0,0,0,0,0,0,0,0,0,0,0,0,0,0,0,0
0,0,0,0,0,0,0,0,0,0,0,0,0,0,0,0,0,0,0,0,0,0,0,0,0
0,0,0,0,0,0,0,0,0,0,0,0,0,0,0,0,0,0,0,0,0,0,0,0,0
13,0,0,0,13,0,0,0,13,0,0,0,13,0,0,0,13,0,0,0,13,0,0,0,13
endlayer

layer
13,14,14,14,13,14,14,14,13,14,14,14,13,14,14,14,13,14,14,14,13,14,14,14,13
14,0,0,0,0,0,0,0,0,0,0,0,0,0,0,0,0,0,0,0,0,0,0,0,14
14,0,0,0,0,0,0,0,0,0,0,0,0,0,0,0,0,0,0,0,0,0,0,0,14
14,0,0,0,0,0,0,0,0,0,0,0,0,0,0,0,0,0,0,0,0,0,0,0,14
13,0,0,0,3,0,0,0,3,2,2,0,0,0,2,2,3,0,0,0,3,0,0,0,13
14,0,0,0,0,9,9,9,9,9,2,9,9,9,2,9,9,9,9,9,0,0,0,0,14
14,0,0,0,0,9,9,9,9,9,2,9,9,9,2,9,9,9,9,9,0,0,0,0,14
14,0,0,0,0,9,9,9,9,9,2,9,9,9,2,9,9,9,9,9,0,0,0,0,14
13,0,0,0,3,9,9,9,9,9,2,9,9,9,2,9,9,9,9,9,3,0,0,0,13
14,0,0,0,0,9,9,9,2,2,2,9,9,9,2,2,2,9,9,9,0,0,0,0,14
14,0,0,0,0,9,9,9,2,5,0,9,9,9,0,0,2,9,9,9,0,0,0,0,14
14,0,0,0,0,9,9,9,2,0,0,9,9,9,0,4,2,9,9,9,0,0,0,0,14
13,0,0,0,3,9,9,9,2,2,2,9,9,9,2,2,2,9,9,9,3,0,0,0,13
14,0,0,0,0,9,9,9,2,5,0,9,9,9,0,0,2,9,9,9,0,0,0,0,14
14,0,0,0,0,9,9,9,2,0,0,9,9,9,0,4,2,9,9,9,0,0,0,0,14
14,0,0,0,0,9,9,9,2,2,2,9,9,9,2,2,2,9,9,9,0,0,0,0,14
13,0,0,0,3,9,9,9,9,9,2,9,9,9,2,9,9,9,9,9,3,0,0,0,13
14,0,0,0,0,9,9,9,9,9,2,9,9,9,2,9,9,9,9,9,0,0,0,0,14
14,0,0,0,0,9,9,9,9,9,2,9,9,9,2,9,9,9,9,9,0,0,0,0,14
14,0,0,0,0,9,9,9,9,9,2,9,9,9,2,9,9,9,9,9,0,0,0,0,14
13,0,0,0,3,0,0,0,3,2,2,0,0,0,2,2,3,0,0,0,3,0,0,0,13
14,0,0,0,0,0,0,0,0,0,0,0,0,0,0,0,0,0,0,0,0,0,0,0,14
14,0,0,0,0,0,0,0,0,0,0,0,0,0,0,0,0,0,0,0,0,0,0,0,14
14,0,0,0,0,0,0,0,0,0,0,0,0,0,0,0,0,0,0,0,0,0,0,0,14
13,14,14,14,13,14,14,14,13,14,14,14,13,14,14,14,13,14,14,14,13,14,14,14,13
endlayer

layer
13,14,14,14,13,14,14,14,13,14,14,14,13,14,14,14,13,14,14,14,13,14,14,14,13
14,14,14,14,14,14,14,14,14,14,14,14,14,14,14,14,14,14,14,14,14,14,14,14,14
14,14,14,14,14,14,14,14,14,14,14,14,14,14,14,14,14,14,14,14,14,14,14,14,14
14,14,14,14,14,14,14,14,14,14,14,14,14,14,14,14,14,14,14,14,14,14,14,14,14
13,14,14,14,3,14,14,14,3,2,2,14,14,14,2,2,3,14,14,14,3,14,14,14,13
14,14,14,14,14,10,10,10,10,10,2,10,10,10,2,10,10,10,10,10,14,14,14,14,14
14,14,14,14,14,10,10,10,10,10,2,10,10,10,2,10,10,10,10,10,14,14,14,14,14
14,14,14,14,14,10,10,10,10,10,2,10,10,10,2,10,10,10,10,10,14,14,14,14,14
13,14,14,14,3,10,10,10,10,10,2,10,10,10,2,10,10,10,10,10,3,14,14,14,13
14,14,14,14,14,10,10,10,2,2,2,10,10,10,2,2,2,10,10,10,14,14,14,14,14
14,14,14,14,14,10,10,10,2,5,0,10,10,10,0,0,2,10,10,10,14,14,14,14,14
14,14,14,14,14,10,10,10,2,0,0,10,10,10,0,0,2,10,10,10,14,14,14,14,14
13,14,14,14,3,10,10,10,2,2,2,10,10,10,2,2,2,10,10,10,3,14,14,14,13
14,14,14,14,14,10,10,10,2,5,0,10,10,10,0,0,2,10,10,10,14,14,14,14,14
14,14,14,14,14,10,10,10,2,0,0,10,10,10,0,4,2,10,10,10,14,14,14,14,14
14,14,14,14,14,10,10,10,2,2,2,10,10,10,2,2,2,10,10,10,14,14,14,14,14
13,14,14,14,3,10,10,10,10,10,2,10,10,10,2,10,10,10,10,10,3,14,14,14,13
14,14,14,14,14,10,10,10,10,10,2,10,10,10,2,10,10,10,10,10,14,14,14,14,14
14,14,14,14,14,10,10,10,10,10,2,10,10,10,2,10,10,10,10,10,14,14,14,14,14
14,14,14,14,14,10,10,10,10,10,2,10,10,10,2,10,10,10,10,10,14,14,14,14,14
13,14,14,14,3,14,14,14,3,2,2,14,14,14,2,2,3,14,14,14,3,14,14,14,13
14,14,14,14,14,14,14,14,14,14,14,14,14,14,14,14,14,14,14,14,14,14,14,14,14
14,14,14,14,14,14,14,14,14,14,14,14,14,14,14,14,14,14,14,14,14,14,14,14,14
14,14,14,14,14,14,14,14,14,14,14,14,14,14,14,14,14,14,14,14,14,14,14,14,14
13,14,14,14,13,14,14,14,13,14,14,14,13,14,14,14,13,14,14,14,13,14,14,14,13
endlayer

layer
13,11,11,11,13,11,11,11,13,11,11,11,13,11,11,11,13,11,11,11,13,11,11,11,13
11,0,0,0,0,0,0,0,0,0,0,0,0,0,0,0,0,0,0,0,0,0,0,0,11
11,0,0,0,0,0,0,0,0,0,0,0,0,0,0,0,0,0,0,0,0,0,0,0,11
11,0,0,0,0,0,0,0,0,0,0,0,0,0,0,0,0,0,0,0,0,0,0,0,11
13,0,0,0,3,0,0,0,3,2,2,0,0,0,2,2,3,0,0,0,3,0,0,0,13
11,0,0,0,0,0,0,0,0,0,2,0,0,0,2,0,0,0,0,0,0,0,0,0,11
11,0,0,0,0,0,0,0,0,0,2,0,0,0,2,0,0,0,0,0,0,0,0,0,11
11,0,0,0,0,0,0,0,0,0,2,0,0,0,2,0,0,0,0,0,0,0,0,0,11
13,0,0,0,3,0,0,0,0,0,2,0,0,0,2,0,0,0,0,0,3,0,0,0,13
11,0,0,0,0,0,0,0,2,2,2,0,0,0,2,2,2,0,0,0,0,0,0,0,11
11,0,0,0,0,0,0,0,2,5,0,0,0,0,0,0,2,0,0,0,0,0,0,0,11
11,0,0,0,0,0,0,0,2,0,0,0,0,0,0,4,2,0,0,0,0,0,0,0,11
13,0,0,0,3,0,0,0,2,2,2,0,0,0,2,2,2,0,0,0,3,0,0,0,13
11,0,0,0,0,0,0,0,2,5,0,0,0,0,0,0,2,0,0,0,0,0,0,0,11
11,0,0,0,0,0,0,0,2,0,0,0,0,0,0,4,2,0,0,0,0,0,0,0,11
11,0,0,0,0,0,0,0,2,2,2,0,0,0,2,2,2,0,0,0,0,0,0,0,11
13,0,0,0,3,0,0,0,0,0,2,0,0,0,2,0,0,0,0,0,3,0,0,0,13
11,0,0,0,0,0,0,0,0,0,2,0,0,0,2,0,0,0,0,0,0,0,0,0,11
11,0,0,0,0,0,0,0,0,0,2,0,0,0,2,0,0,0,0,0,0,0,0,0,11
11,0,0,0,0,0,0,0,0,0,2,0,0,0,2,0,0,0,0,0,0,0,0,0,11
13,0,0,0,3,0,0,0,3,2,2,0,0,0,2,2,3,0,0,0,3,0,0,0,13
11,0,0,0,0,0,0,0,0,0,0,0,0,0,0,0,0,0,0,0,0,0,0,0,11
11,0,0,0,0,0,0,0,0,0,0,0,0,0,0,0,0,0,0,0,0,0,0,0,11
11,0,0,0,0,0,0,0,0,0,0,0,0,0,0,0,0,0,0,0,0,0,0,0,11
13,11,11,11,13,11,11,11,13,11,11,11,13,11,11,11,13,11,11,11,13,11,11,11,13
endlayer

layer
13,0,0,0,13,0,0,0,13,0,0,0,13,0,0,0,13,0,0,0,13,0,0,0,13
0,0,0,0,0,0,0,0,0,0,0,0,0,0,0,0,0,0,0,0,0,0,0,0,0
0,0,0,0,0,0,0,0,0,0,0,0,0,0,0,0,0,0,0,0,0,0,0,0,0
0,0,0,0,0,0,0,0,0,0,0,0,0,0,0,0,0,0,0,0,0,0,0,0,0
13,0,0,0,3,0,0,0,3,2,2,0,0,0,2,2,3,0,0,0,3,0,0,0,13
0,0,0,0,0,0,0,0,0,0,2,0,0,0,2,0,0,0,0,0,0,0,0,0,0
0,0,0,0,0,0,0,0,0,0,2,0,0,0,2,0,0,0,0,0,0,0,0,0,0
0,0,0,0,0,0,0,0,0,0,2,0,0,0,2,0,0,0,0,0,0,0,0,0,0
13,0,0,0,3,0,0,0,0,0,2,0,0,0,2,0,0,0,0,0,3,0,0,0,13
0,0,0,0,0,0,0,0,2,2,2,0,0,0,2,2,2,0,0,0,0,0,0,0,0
0,0,0,0,0,0,0,0,2,5,0,0,0,0,0,0,2,0,0,0,0,0,0,0,0
0,0,0,0,0,0,0,0,2,0,0,0,0,0,0,4,2,0,0,0,0,0,0,0,0
13,0,0,0,3,0,0,0,2,2,2,0,0,0,2,2,2,0,0,0,3,0,0,0,13
0,0,0,0,0,0,0,0,2,5,0,0,0,0,0,0,2,0,0,0,0,0,0,0,0
0,0,0,0,0,0,0,0,2,0,0,0,0,0,0,4,2,0,0,0,0,0,0,0,0
0,0,0,0,0,0,0,0,2,2,2,0,0,0,2,2,2,0,0,0,0,0,0,0,0
13,0,0,0,3,0,0,0,0,0,2,0,0,0,2,0,0,0,0,0,3,0,0,0,13
0,0,0,0,0,0,0,0,0,0,2,0,0,0,2,0,0,0,0,0,0,0,0,0,0
0,0,0,0,0,0,0,0,0,0,2,0,0,0,2,0,0,0,0,0,0,0,0,0,0
0,0,0,0,0,0,0,0,0,0,2,0,0,0,2,0,0,0,0,0,0,0,0,0,0
13,0,0,0,3,0,0,0,3,2,2,0,0,0,2,2,3,0,0,0,3,0,0,0,13
0,0,0,0,0,0,0,0,0,0,0,0,0,0,0,0,0,0,0,0,0,0,0,0,0
0,0,0,0,0,0,0,0,0,0,0,0,0,0,0,0,0,0,0,0,0,0,0,0,0
0,0,0,0,0,0,0,0,0,0,0,0,0,0,0,0,0,0,0,0,0,0,0,0,0
13,0,0,0,13,0,0,0,13,0,0,0,13,0,0,0,13,0,0,0,13,0,0,0,13
endlayer

layer
13,0,0,0,13,0,0,0,13,0,0,0,13,0,0,0,13,0,0,0,13,0,0,0,13
0,0,0,0,0,0,0,0,0,0,0,0,0,0,0,0,0,0,0,0,0,0,0,0,0
0,0,0,0,0,0,0,0,0,0,0,0,0,0,0,0,0,0,0,0,0,0,0,0,0
0,0,0,0,0,0,0,0,0,0,0,0,0,0,0,0,0,0,0,0,0,0,0,0,0
13,0,0,0,3,0,0,0,3,2,2,0,0,0,2,2,3,0,0,0,3,0,0,0,13
0,0,0,0,0,0,0,0,0,0,2,0,0,0,2,0,0,0,0,0,0,0,0,0,0
0,0,0,0,0,0,0,0,0,0,2,0,0,0,2,0,0,0,0,0,0,0,0,0,0
0,0,0,0,0,0,0,0,0,0,2,0,0,0,2,0,0,0,0,0,0,0,0,0,0
13,0,0,0,3,0,0,0,0,0,2,0,0,0,2,0,0,0,0,0,3,0,0,0,13
0,0,0,0,0,0,0,0,2,2,2,0,0,0,2,2,2,0,0,0,0,0,0,0,0
0,0,0,0,0,0,0,0,2,5,0,0,0,0,0,0,2,0,0,0,0,0,0,0,0
0,0,0,0,0,0,0,0,2,0,0,0,0,0,0,4,2,0,0,0,0,0,0,0,0
13,0,0,0,3,0,0,0,2,2,2,0,0,0,2,2,2,0,0,0,3,0,0,0,13
0,0,0,0,0,0,0,0,2,5,0,0,0,0,0,0,2,0,0,0,0,0,0,0,0
0,0,0,0,0,0,0,0,2,0,0,0,0,0,0,4,2,0,0,0,0,0,0,0,0
0,0,0,0,0,0,0,0,2,2,2,0,0,0,2,2,2,0,0,0,0,0,0,0,0
13,0,0,0,3,0,0,0,0,0,2,0,0,0,2,0,0,0,0,0,3,0,0,0,13
0,0,0,0,0,0,0,0,0,0,2,0,0,0,2,0,0,0,0,0,0,0,0,0,0
0,0,0,0,0,0,0,0,0,0,2,0,0,0,2,0,0,0,0,0,0,0,0,0,0
0,0,0,0,0,0,0,0,0,0,2,0,0,0,2,0,0,0,0,0,0,0,0,0,0
13,0,0,0,3,0,0,0,3,2,2,0,0,0,2,2,3,0,0,0,3,0,0,0,13
0,0,0,0,0,0,0,0,0,0,0,0,0,0,0,0,0,0,0,0,0,0,0,0,0
0,0,0,0,0,0,0,0,0,0,0,0,0,0,0,0,0,0,0,0,0,0,0,0,0
0,0,0,0,0,0,0,0,0,0,0,0,0,0,0,0,0,0,0,0,0,0,0,0,0
13,0,0,0,13,0,0,0,13,0,0,0,13,0,0,0,13,0,0,0,13,0,0,0,13
endlayer

layer
13,14,14,14,13,14,14,14,13,14,14,14,13,14,14,14,13,14,14,14,13,14,14,14,13
14,0,0,0,0,0,0,0,0,0,0,0,0,0,0,0,0,0,0,0,0,0,0,0,14
14,0,0,0,0,0,0,0,0,0,0,0,0,0,0,0,0,0,0,0,0,0,0,0,14
14,0,0,0,0,0,0,0,0,0,0,0,0,0,0,0,0,0,0,0,0,0,0,0,14
13,0,0,0,3,0,0,0,3,2,2,0,0,0,2,2,3,0,0,0,3,0,0,0,13
14,0,0,0,0,9,9,9,9,9,2,9,9,9,2,9,9,9,9,9,0,0,0,0,14
14,0,0,0,0,9,9,9,9,9,2,9,9,9,2,9,9,9,9,9,0,0,0,0,14
14,0,0,0,0,9,9,9,9,9,2,9,9,9,2,9,9,9,9,9,0,0,0,0,14
13,0,0,0,3,9,9,9,9,9,2,9,9,9,2,9,9,9,9,9,3,0,0,0,13
14,0,0,0,0,9,9,9,2,2,2,9,9,9,2,2,2,9,9,9,0,0,0,0,14
14,0,0,0,0,9,9,9,2,5,0,9,9,9,0,0,2,9,9,9,0,0,0,0,14
14,0,0,0,0,9,9,9,2,0,0,9,9,9,0,4,2,9,9,9,0,0,0,0,14
13,0,0,0,3,9,9,9,2,2,2,9,9,9,2,2,2,9,9,9,3,0,0,0,13
14,0,0,0,0,9,9,9,2,5,0,9,9,9,0,0,2,9,9,9,0,0,0,0,14
14,0,0,0,0,9,9,9,2,0,0,9,9,9,0,4,2,9,9,9,0,0,0,0,14
14,0,0,0,0,9,9,9,2,2,2,9,9,9,2,2,2,9,9,9,0,0,0,0,14
13,0,0,0,3,9,9,9,9,9,2,9,9,9,2,9,9,9,9,9,3,0,0,0,13
14,0,0,0,0,9,9,9,9,9,2,9,9,9,2,9,9,9,9,9,0,0,0,0,14
14,0,0,0,0,9,9,9,9,9,2,9,9,9,2,9,9,9,9,9,0,0,0,0,14
14,0,0,0,0,9,9,9,9,9,2,9,9,9,2,9,9,9,9,9,0,0,0,0,14
13,0,0,0,3,0,0,0,3,2,2,0,0,0,2,2,3,0,0,0,3,0,0,0,13
14,0,0,0,0,0,0,0,0,0,0,0,0,0,0,0,0,0,0,0,0,0,0,0,14
14,0,0,0,0,0,0,0,0,0,0,0,0,0,0,0,0,0,0,0,0,0,0,0,14
14,0,0,0,0,0,0,0,0,0,0,0,0,0,0,0,0,0,0,0,0,0,0,0,14
13,14,14,14,13,14,14,14,13,14,14,14,13,14,14,14,13,14,14,14,13,14,14,14,13
endlayer

layer
13,14,14,14,13,14,14,14,13,14,14,14,13,14,14,14,13,14,14,14,13,14,14,14,13
14,14,14,14,14,14,14,14,14,14,14,14,14,14,14,14,14,14,14,14,14,14,14,14,14
14,14,14,14,14,14,14,14,14,14,14,14,14,14,14,14,14,14,14,14,14,14,14,14,14
14,14,14,14,14,14,14,14,14,14,14,14,14,14,14,14,14,14,14,14,14,14,14,14,14
13,14,14,14,3,14,14,14,3,2,2,14,14,14,2,2,3,14,14,14,3,14,14,14,13
14,14,14,14,14,10,10,10,10,10,2,10,10,10,2,10,10,10,10,10,14,14,14,14,14
14,14,14,14,14,10,10,10,10,10,2,10,10,10,2,10,10,10,10,10,14,14,14,14,14
14,14,14,14,14,10,10,10,10,10,2,10,10,10,2,10,10,10,10,10,14,14,14,14,14
13,14,14,14,3,10,10,10,10,10,2,10,10,10,2,10,10,10,10,10,3,14,14,14,13
14,14,14,14,14,10,10,10,2,2,2,10,10,10,2,2,2,10,10,10,14,14,14,14,14
14,14,14,14,14,10,10,10,2,5,0,10,10,10,0,0,2,10,10,10,14,14,14,14,14
14,14,14,14,14,10,10,10,2,0,0,10,10,10,0,0,2,10,10,10,14,14,14,14,14
13,14,14,14,3,10,10,10,2,2,2,10,10,10,2,2,2,10,10,10,3,14,14,14,13
14,14,14,14,14,10,10,10,2,5,0,10,10,10,0,0,2,10,10,10,14,14,14,14,14
14,14,14,14,14,10,10,10,2,0,0,10,10,10,0,4,2,10,10,10,14,14,14,14,14
14,14,14,14,14,10,10,10,2,2,2,10,10,10,2,2,2,10,10,10,14,14,14,14,14
13,14,14,14,3,10,10,10,10,10,2,10,10,10,2,10,10,10,10,10,3,14,14,14,13
14,14,14,14,14,10,10,10,10,10,2,10,10,10,2,10,10,10,10,10,14,14,14,14,14
14,14,14,14,14,10,10,10,10,10,2,10,10,10,2,10,10,10,10,10,14,14,14,14,14
14,14,14,14,14,10,10,10,10,10,2,10,10,10,2,10,10,10,10,10,14,14,14,14,14
13,14,14,14,3,14,14,14,3,2,2,14,14,14,2,2,3,14,14,14,3,14,14,14,13
14,14,14,14,14,14,14,14,14,14,14,14,14,14,14,14,14,14,14,14,14,14,14,14,14
14,14,14,14,14,14,14,14,14,14,14,14,14,14,14,14,14,14,14,14,14,14,14,14,14
14,14,14,14,14,14,14,14,14,14,14,14,14,14,14,14,14,14,14,14,14,14,14,14,14
13,14,14,14,13,14,14,14,13,14,14,14,13,14,14,14,13,14,14,14,13,14,14,14,13
endlayer

layer
13,11,11,11,13,11,11,11,13,11,11,11,13,11,11,11,13,11,11,11,13,11,11,11,13
11,0,0,0,0,0,0,0,0,0,0,0,0,0,0,0,0,0,0,0,0,0,0,0,11
11,0,0,0,0,0,0,0,0,0,0,0,0,0,0,0,0,0,0,0,0,0,0,0,11
11,0,0,0,0,0,0,0,0,0,0,0,0,0,0,0,0,0,0,0,0,0,0,0,11
13,0,0,0,3,0,0,0,3,2,2,0,0,0,2,2,3,0,0,0,3,0,0,0,13
11,0,0,0,0,0,0,0,0,0,2,0,0,0,2,0,0,0,0,0,0,0,0,0,11
11,0,0,0,0,0,0,0,0,0,2,0,0,0,2,0,0,0,0,0,0,0,0,0,11
11,0,0,0,0,0,0,0,0,0,2,0,0,0,2,0,0,0,0,0,0,0,0,0,11
13,0,0,0,3,0,0,0,0,0,2,0,0,0,2,0,0,0,0,0,3,0,0,0,13
11,0,0,0,0,0,0,0,2,2,2,0,0,0,2,2,2,0,0,0,0,0,0,0,11
11,0,0,0,0,0,0,0,2,5,0,0,0,0,0,0,2,0,0,0,0,0,0,0,11
11,0,0,0,0,0,0,0,2,0,0,0,0,0,0,4,2,0,0,0,0,0,0,0,11
13,0,0,0,3,0,0,0,2,2,2,0,0,0,2,2,2,0,0,0,3,0,0,0,13
11,0,0,0,0,0,0,0,2,5,0,0,0,0,0,0,2,0,0,0,0,0,0,0,11
11,0,0,0,0,0,0,0,2,0,0,0,0,0,0,4,2,0,0,0,0,0,0,0,11
11,0,0,0,0,0,0,0,2,2,2,0,0,0,2,2,2,0,0,0,0,0,0,0,11
13,0,0,0,3,0,0,0,0,0,2,0,0,0,2,0,0,0,0,0,3,0,0,0,13
11,0,0,0,0,0,0,0,0,0,2,0,0,0,2,0,0,0,0,0,0,0,0,0,11
11,0,0,0,0,0,0,0,0,0,2,0,0,0,2,0,0,0,0,0,0,0,0,0,11
11,0,0,0,0,0,0,0,0,0,2,0,0,0,2,0,0,0,0,0,0,0,0,0,11
13,0,0,0,3,0,0,0,3,2,2,0,0,0,2,2,3,0,0,0,3,0,0,0,13
11,0,0,0,0,0,0,0,0,0,0,0,0,0,0,0,0,0,0,0,0,0,0,0,11
11,0,0,0,0,0,0,0,0,0,0,0,0,0,0,0,0,0,0,0,0,0,0,0,11
11,0,0,0,0,0,0,0,0,0,0,0,0,0,0,0,0,0,0,0,0,0,0,0,11
13,11,11,11,13,11,11,11,13,11,11,11,13,11,11,11,13,11,11,11,13,11,11,11,13
endlayer

layer
13,0,0,0,13,0,0,0,13,0,0,0,13,0,0,0,13,0,0,0,13,0,0,0,13
0,0,0,0,0,0,0,0,0,0,0,0,0,0,0,0,0,0,0,0,0,0,0,0,0
0,0,0,0,0,0,0,0,0,0,0,0,0,0,0,0,0,0,0,0,0,0,0,0,0
0,0,0,0,0,0,0,0,0,0,0,0,0,0,0,0,0,0,0,0,0,0,0,0,0
13,0,0,0,3,0,0,0,3,2,2,0,0,0,2,2,3,0,0,0,3,0,0,0,13
0,0,0,0,0,0,0,0,0,0,2,0,0,0,2,0,0,0,0,0,0,0,0,0,0
0,0,0,0,0,0,0,0,0,0,2,0,0,0,2,0,0,0,0,0,0,0,0,0,0
0,0,0,0,0,0,0,0,0,0,2,0,0,0,2,0,0,0,0,0,0,0,0,0,0
13,0,0,0,3,0,0,0,0,0,2,0,0,0,2,0,0,0,0,0,3,0,0,0,13
0,0,0,0,0,0,0,0,2,2,2,0,0,0,2,2,2,0,0,0,0,0,0,0,0
0,0,0,0,0,0,0,0,2,5,0,0,0,0,0,0,2,0,0,0,0,0,0,0,0
0,0,0,0,0,0,0,0,2,0,0,0,0,0,0,4,2,0,0,0,0,0,0,0,0
13,0,0,0,3,0,0,0,2,2,2,0,0,0,2,2,2,0,0,0,3,0,0,0,13
0,0,0,0,0,0,0,0,2,5,0,0,0,0,0,0,2,0,0,0,0,0,0,0,0
0,0,0,0,0,0,0,0,2,0,0,0,0,0,0,4,2,0,0,0,0,0,0,0,0
0,0,0,0,0,0,0,0,2,2,2,0,0,0,2,2,2,0,0,0,0,0,0,0,0
13,0,0,0,3,0,0,0,0,0,2,0,0,0,2,0,0,0,0,0,3,0,0,0,13
0,0,0,0,0,0,0,0,0,0,2,0,0,0,2,0,0,0,0,0,0,0,0,0,0
0,0,0,0,0,0,0,0,0,0,2,0,0,0,2,0,0,0,0,0,0,0,0,0,0
0,0,0,0,0,0,0,0,0,0,2,0,0,0,2,0,0,0,0,0,0,0,0,0,0
13,0,0,0,3,0,0,0,3,2,2,0,0,0,2,2,3,0,0,0,3,0,0,0,13
0,0,0,0,0,0,0,0,0,0,0,0,0,0,0,0,0,0,0,0,0,0,0,0,0
0,0,0,0,0,0,0,0,0,0,0,0,0,0,0,0,0,0,0,0,0,0,0,0,0
0,0,0,0,0,0,0,0,0,0,0,0,0,0,0,0,0,0,0,0,0,0,0,0,0
13,0,0,0,13,0,0,0,13,0,0,0,13,0,0,0,13,0,0,0,13,0,0,0,13
endlayer

layer
13,0,0,0,13,0,0,0,13,0,0,0,13,0,0,0,13,0,0,0,13,0,0,0,13
0,0,0,0,0,0,0,0,0,0,0,0,0,0,0,0,0,0,0,0,0,0,0,0,0
0,0,0,0,0,0,0,0,0,0,0,0,0,0,0,0,0,0,0,0,0,0,0,0,0
0,0,0,0,0,0,0,0,0,0,0,0,0,0,0,0,0,0,0,0,0,0,0,0,0
13,0,0,0,3,0,0,0,3,2,2,0,0,0,2,2,3,0,0,0,3,0,0,0,13
0,0,0,0,0,0,0,0,0,0,2,0,0,0,2,0,0,0,0,0,0,0,0,0,0
0,0,0,0,0,0,0,0,0,0,2,0,0,0,2,0,0,0,0,0,0,0,0,0,0
0,0,0,0,0,0,0,0,0,0,2,0,0,0,2,0,0,0,0,0,0,0,0,0,0
13,0,0,0,3,0,0,0,0,0,2,0,0,0,2,0,0,0,0,0,3,0,0,0,13
0,0,0,0,0,0,0,0,2,2,2,0,0,0,2,2,2,0,0,0,0,0,0,0,0
0,0,0,0,0,0,0,0,2,5,0,0,0,0,0,0,2,0,0,0,0,0,0,0,0
0,0,0,0,0,0,0,0,2,0,0,0,0,0,0,4,2,0,0,0,0,0,0,0,0
13,0,0,0,3,0,0,0,2,2,2,0,0,0,2,2,2,0,0,0,3,0,0,0,13
0,0,0,0,0,0,0,0,2,5,0,0,0,0,0,0,2,0,0,0,0,0,0,0,0
0,0,0,0,0,0,0,0,2,0,0,0,0,0,0,4,2,0,0,0,0,0,0,0,0
0,0,0,0,0,0,0,0,2,2,2,0,0,0,2,2,2,0,0,0,0,0,0,0,0
13,0,0,0,3,0,0,0,0,0,2,0,0,0,2,0,0,0,0,0,3,0,0,0,13
0,0,0,0,0,0,0,0,0,0,2,0,0,0,2,0,0,0,0,0,0,0,0,0,0
0,0,0,0,0,0,0,0,0,0,2,0,0,0,2,0,0,0,0,0,0,0,0,0,0
0,0,0,0,0,0,0,0,0,0,2,0,0,0,2,0,0,0,0,0,0,0,0,0,0
13,0,0,0,3,0,0,0,3,2,2,0,0,0,2,2,3,0,0,0,3,0,0,0,13
0,0,0,0,0,0,0,0,0,0,0,0,0,0,0,0,0,0,0,0,0,0,0,0,0
0,0,0,0,0,0,0,0,0,0,0,0,0,0,0,0,0,0,0,0,0,0,0,0,0
0,0,0,0,0,0,0,0,0,0,0,0,0,0,0,0,0,0,0,0,0,0,0,0,0
13,0,0,0,13,0,0,0,13,0,0,0,13,0,0,0,13,0,0,0,13,0,0,0,13
endlayer

layer
13,14,14,14,13,14,14,14,13,14,14,14,13,14,14,14,13,14,14,14,13,14,14,14,13
14,0,0,0,0,0,0,0,0,0,0,0,0,0,0,0,0,0,0,0,0,0,0,0,14
14,0,0,0,0,0,0,0,0,0,0,0,0,0,0,0,0,0,0,0,0,0,0,0,14
14,0,0,0,0,0,0,0,0,0,0,0,0,0,0,0,0,0,0,0,0,0,0,0,14
13,0,0,0,3,0,0,0,3,2,2,0,0,0,2,2,3,0,0,0,3,0,0,0,13
14,0,0,0,0,9,9,9,9,9,2,9,9,9,2,9,9,9,9,9,0,0,0,0,14
14,0,0,0,0,9,9,9,9,9,2,9,9,9,2,9,9,9,9,9,0,0,0,0,14
14,0,0,0,0,9,9,9,9,9,2,9,9,9,2,9,9,9,9,9,0,0,0,0,14
13,0,0,0,3,9,9,9,9,9,2,9,9,9,2,9,9,9,9,9,3,0,0,0,13
14,0,0,0,0,9,9,9,2,2,2,9,9,9,2,2,2,9,9,9,0,0,0,0,14
14,0,0,0,0,9,9,9,2,5,0,9,9,9,0,0,2,9,9,9,0,0,0,0,14
14,0,0,0,0,9,9,9,2,0,0,9,9,9,0,4,2,9,9,9,0,0,0,0,14
13,0,0,0,3,9,9,9,2,2,2,9,9,9,2,2,2,9,9,9,3,0,0,0,13
14,0,0,0,0,9,9,9,2,5,0,9,9,9,0,0,2,9,9,9,0,0,0,0,14
14,0,0,0,0,9,9,9,2,0,0,9,9,9,0,4,2,9,9,9,0,0,0,0,14
14,0,0,0,0,9,9,9,2,2,2,9,9,9,2,2,2,9,9,9,0,0,0,0,14
13,0,0,0,3,9,9,9,9,9,2,9,9,9,2,9,9,9,9,9,3,0,0,0,13
14,0,0,0,0,9,9,9,9,9,2,9,9,9,2,9,9,9,9,9,0,0,0,0,14
14,0,0,0,0,9,9,9,9,9,2,9,9,9,2,9,9,9,9,9,0,0,0,0,14
14,0,0,0,0,9,9,9,9,9,2,9,9,9,2,9,9,9,9,9,0,0,0,0,14
13,0,0,0,3,0,0,0,3,2,2,0,0,0,2,2,3,0,0,0,3,0,0,0,13
14,0,0,0,0,0,0,0,0,0,0,0,0,0,0,0,0,0,0,0,0,0,0,0,14
14,0,0,0,0,0,0,0,0,0,0,0,0,0,0,0,0,0,0,0,0,0,0,0,14
14,0,0,0,0,0,0,0,0,0,0,0,0,0,0,0,0,0,0,0,0,0,0,0,14
13,14,14,14,13,14,14,14,13,14,14,14,13,14,14,14,13,14,14,14,13,14,14,14,13
endlayer

layer
13,14,14,14,13,14,14,14,13,14,14,14,13,14,14,14,13,14,14,14,13,14,14,14,13
14,14,14,14,14,14,14,14,14,14,14,14,14,14,14,14,14,14,14,14,14,14,14,14,14
14,14,14,14,14,14,14,14,14,14,14,14,14,14,14,14,14,14,14,14,14,14,14,14,14
14,14,14,14,14,14,14,14,14,14,14,14,14,14,14,14,14,14,14,14,14,14,14,14,14
13,14,14,14,3,14,14,14,3,2,2,14,14,14,2,2,3,14,14,14,3,14,14,14,13
14,14,14,14,14,10,10,10,10,10,2,10,10,10,2,10,10,10,10,10,14,14,14,14,14
14,14,14,14,14,10,10,10,10,10,2,10,10,10,2,10,10,10,10,10,14,14,14,14,14
14,14,14,14,14,10,10,10,10,10,2,10,10,10,2,10,10,10,10,10,14,14,14,14,14
13,14,14,14,3,10,10,10,10,10,2,10,10,10,2,10,10,10,10,10,3,14,14,14,13
14,14,14,14,14,10,10,10,2,2,2,10,10,10,2,2,2,10,10,10,14,14,14,14,14
14,14,14,14,14,10,10,10,2,5,0,10,10,10,0,0,2,10,10,10,14,14,14,14,14
14,14,14,14,14,10,10,10,2,0,0,10,10,10,0,0,2,10,10,10,14,14,14,14,14
13,14,14,14,3,10,10,10,2,2,2,10,10,10,2,2,2,10,10,10,3,14,14,14,13
14,14,14,14,14,10,10,10,2,5,0,10,10,10,0,0,2,10,10,10,14,14,14,14,14
14,14,14,14,14,10,10,10,2,0,0,10,10,10,0,4,2,10,10,10,14,14,14,14,14
14,14,14,14,14,10,10,10,2,2,2,10,10,10,2,2,2,10,10,10,14,14,14,14,14
13,14,14,14,3,10,10,10,10,10,2,10,10,10,2,10,10,10,10,10,3,14,14,14,13
14,14,14,14,14,10,10,10,10,10,2,10,10,10,2,10,10,10,10,10,14,14,14,14,14
14,14,14,14,14,10,10,10,10,10,2,10,10,10,2,10,10,10,10,10,14,14,14,14,14
14,14,14,14,14,10,10,10,10,10,2,10,10,10,2,10,10,10,10,10,14,14,14,14,14
13,14,14,14,3,14,14,14,3,2,2,14,14,14,2,2,3,14,14,14,3,14,14,14,13
14,14,14,14,14,14,14,14,14,14,14,14,14,14,14,14,14,14,14,14,14,14,14,14,14
14,14,14,14,14,14,14,14,14,14,14,14,14,14,14,14,14,14,14,14,14,14,14,14,14
14,14,14,14,14,14,14,14,14,14,14,14,14,14,14,14,14,14,14,14,14,14,14,14,14
13,14,14,14,13,14,14,14,13,14,14,14,13,14,14,14,13,14,14,14,13,14,14,14,13
endlayer

layer
13,11,11,11,13,11,11,11,13,11,11,11,13,11,11,11,13,11,11,11,13,11,11,11,13
11,0,0,0,0,0,0,0,0,0,0,0,0,0,0,0,0,0,0,0,0,0,0,0,11
11,0,0,0,0,0,0,0,0,0,0,0,0,0,0,0,0,0,0,0,0,0,0,0,11
11,0,0,0,0,0,0,0,0,0,0,0,0,0,0,0,0,0,0,0,0,0,0,0,11
13,0,0,0,3,0,0,0,3,2,2,0,0,0,2,2,3,0,0,0,3,0,0,0,13
11,0,0,0,0,0,0,0,0,0,2,0,0,0,2,0,0,0,0,0,0,0,0,0,11
11,0,0,0,0,0,0,0,0,0,2,0,0,0,2,0,0,0,0,0,0,0,0,0,11
11,0,0,0,0,0,0,0,0,0,2,0,0,0,2,0,0,0,0,0,0,0,0,0,11
13,0,0,0,3,0,0,0,0,0,2,0,0,0,2,0,0,0,0,0,3,0,0,0,13
11,0,0,0,0,0,0,0,2,2,2,0,0,0,2,2,2,0,0,0,0,0,0,0,11
11,0,0,0,0,0,0,0,2,5,0,0,0,0,0,0,2,0,0,0,0,0,0,0,11
11,0,0,0,0,0,0,0,2,0,0,0,0,0,0,4,2,0,0,0,0,0,0,0,11
13,0,0,0,3,0,0,0,2,2,2,0,0,0,2,2,2,0,0,0,3,0,0,0,13
11,0,0,0,0,0,0,0,2,5,0,0,0,0,0,0,2,0,0,0,0,0,0,0,11
11,0,0,0,0,0,0,0,2,0,0,0,0,0,0,4,2,0,0,0,0,0,0,0,11
11,0,0,0,0,0,0,0,2,2,2,0,0,0,2,2,2,0,0,0,0,0,0,0,11
13,0,0,0,3,0,0,0,0,4,2,0,0,0,2,0,0,0,0,0,3,0,0,0,13
11,0,0,0,0,0,0,0,0,0,2,0,0,0,2,0,0,0,0,0,0,0,0,0,11
11,0,0,0,0,0,0,0,0,0,2,0,0,0,2,0,0,0,0,0,0,0,0,0,11
11,0,0,0,0,0,0,0,0,0,2,0,0,0,2,0,0,0,0,0,0,0,0,0,11
13,0,0,0,3,0,0,0,3,2,2,0,0,0,2,2,3,0,0,0,3,0,0,0,13
11,0,0,0,0,0,0,0,0,0,0,0,0,0,0,0,0,0,0,0,0,0,0,0,11
11,0,0,0,0,0,0,0,0,0,0,0,0,0,0,0,0,0,0,0,0,0,0,0,11
11,0,0,0,0,0,0,0,0,0,0,0,0,0,0,0,0,0,0,0,0,0,0,0,11
13,11,11,11,13,11,11,11,13,11,11,11,13,11,11,11,13,11,11,11,13,11,11,11,13
endlayer

layer
13,0,0,0,13,0,0,0,13,0,0,0,13,0,0,0,13,0,0,0,13,0,0,0,13
0,0,0,0,0,0,0,0,0,0,0,0,0,0,0,0,0,0,0,0,0,0,0,0,0
0,0,0,0,0,0,0,0,0,0,0,0,0,0,0,0,0,0,0,0,0,0,0,0,0
0,0,0,0,0,0,0,0,0,0,0,0,0,0,0,0,0,0,0,0,0,0,0,0,0
13,0,0,0,3,0,0,0,3,2,2,0,0,0,2,2,3,0,0,0,3,0,0,0,13
0,0,0,0,0,0,0,0,0,0,2,0,0,0,2,0,0,0,0,0,0,0,0,0,0
0,0,0,0,0,0,0,0,0,0,2,0,0,0,2,0,0,0,0,0,0,0,0,0,0
0,0,0,0,0,0,0,0,0,0,2,0,0,0,2,0,0,0,0,0,0,0,0,0,0
13,0,0,0,3,0,0,0,0,0,2,0,0,0,2,0,0,0,0,0,3,0,0,0,13
0,0,0,0,0,0,0,0,2,2,2,0,0,0,2,2,2,0,0,0,0,0,0,0,0
0,0,0,0,0,0,0,0,2,5,0,0,0,0,0,0,2,0,0,0,0,0,0,0,0
0,0,0,0,0,0,0,0,2,0,0,0,0,0,0,4,2,0,0,0,0,0,0,0,0
13,0,0,0,3,0,0,0,2,2,2,15,0,0,2,2,2,0,0,0,3,0,0,0,13
0,0,0,0,0,0,0,0,2,5,0,0,0,0,0,0,2,0,0,0,0,0,0,0,0
0,0,0,0,0,0,0,0,2,0,0,0,0,0,0,4,2,0,0,0,0,0,0,0,0
0,0,0,0,0,0,0,0,2,2,2,0,0,0,2,2,2,0,0,0,0,0,0,0,0
13,0,0,0,3,0,0,0,0,4,2,0,0,0,2,0,0,0,0,0,3,0,0,0,13
0,0,0,0,0,0,0,0,0,0,2,0,0,0,2,0,0,0,0,0,0,0,0,0,0
0,0,0,0,0,0,0,0,0,0,2,0,0,0,2,0,0,0,0,0,0,0,0,0,0
0,0,0,0,0,0,0,0,0,0,2,0,0,0,2,0,0,0,0,0,0,0,0,0,0
13,0,0,0,3,0,0,0,3,2,2,0,0,0,2,2,3,0,0,0,3,0,0,0,13
0,0,0,0,0,0,0,0,0,0,0,0,0,0,0,0,0,0,0,0,0,0,0,0,0
0,0,0,0,0,0,0,0,0,0,0,0,0,0,0,0,0,0,0,0,0,0,0,0,0
0,0,0,0,0,0,0,0,0,0,0,0,0,0,0,0,0,0,0,0,0,0,0,0,0
13,0,0,0,13,0,0,0,13,0,0,0,13,0,0,0,13,0,0,0,13,0,0,0,13
endlayer

layer
13,0,0,0,13,0,0,0,13,0,0,0,13,0,0,0,13,0,0,0,13,0,0,0,13
0,0,0,0,0,0,0,0,0,0,0,0,0,0,0,0,0,0,0,0,0,0,0,0,0
0,0,0,0,0,0,0,0,0,0,0,0,0,0,0,0,0,0,0,0,0,0,0,0,0
0,0,0,0,0,0,0,0,0,0,0,0,0,0,0,0,0,0,0,0,0,0,0,0,0
13,0,0,0,3,0,0,0,3,2,2,0,0,0,2,2,3,0,0,0,3,0,0,0,13
0,0,0,0,0,0,0,0,0,0,2,0,0,0,2,0,0,0,0,0,0,0,0,0,0
0,0,0,0,0,0,0,0,0,0,2,0,0,0,2,0,0,0,0,0,0,0,0,0,0
0,0,0,0,0,0,0,0,0,0,2,0,0,0,2,0,0,0,0,0,0,0,0,0,0
13,0,0,0,3,0,0,0,0,0,2,0,0,0,2,0,0,0,0,0,3,0,0,0,13
0,0,0,0,0,0,0,0,2,2,2,0,0,0,2,2,2,0,0,0,0,0,0,0,0
0,0,0,0,0,0,0,0,2,5,0,0,0,0,0,0,2,0,0,0,0,0,0,0,0
0,0,0,0,0,0,0,0,2,0,0,0,0,0,0,4,2,0,0,0,0,0,0,0,0
13,0,0,0,3,0,0,0,2,2,2,0,0,0,2,2,2,0,0,0,3,0,0,0,13
0,0,0,0,0,0,0,0,2,5,0,0,0,0,0,0,2,0,0,0,0,0,0,0,0
0,0,0,0,0,0,0,0,2,0,0,0,0,0,0,4,2,0,0,0,0,0,0,0,0
0,0,0,0,0,0,0,0,2,2,2,0,0,0,2,2,2,0,0,0,0,0,0,0,0
13,0,0,0,3,0,0,0,0,4,2,0,0,0,2,0,0,0,0,0,3,0,0,0,13
0,0,0,0,0,0,0,0,0,0,2,0,0,0,2,0,0,0,0,0,0,0,0,0,0
0,0,0,0,0,0,0,0,0,0,2,0,0,0,2,0,0,0,0,0,0,0,0,0,0
0,0,0,0,0,0,0,0,0,0,2,0,0,0,2,0,0,0,0,0,0,0,0,0,0
13,0,0,0,3,0,0,0,3,2,2,0,0,0,2,2,3,0,0,0,3,0,0,0,13
0,0,0,0,0,0,0,0,0,0,0,0,0,0,0,0,0,0,0,0,0,0,0,0,0
0,0,0,0,0,0,0,0,0,0,0,0,0,0,0,0,0,0,0,0,0,0,0,0,0
0,0,0,0,0,0,0,0,0,0,0,0,0,0,0,0,0,0,0,0,0,0,0,0,0
13,0,0,0,13,0,0,0,13,0,0,0,13,0,0,0,13,0,0,0,13,0,0,0,13
endlayer

layer
13,14,14,14,13,14,14,14,13,14,14,14,13,14,14,14,13,14,14,14,13,14,14,14,13
14,0,0,0,0,0,0,0,0,0,0,0,0,0,0,0,0,0,0,0,0,0,0,0,14
