weight=80
acceptable_target_blocks=1,2,3,12,13,24,162,163,164,165,166,167,168,169,170,171,172,254,255
embed_into_distance=1
dimensions=5,25,25
max_leveling=4
max_cut_in=5
preserve_plants=1


rule1=1,70,48,48,48,48,48,48,48,48,48,48,48,48,48,48,48,48,48,48,48,48,48,48,48,48,48,48,48,48,48,48,48,48,48,48,48,48,48,48,48,48,48,48,48,48,48,48,48,48,48,48,48,48,48,48,48,48,48,48,48,48,48,48,48,48,48,48,48,48,48,48,48,48,48,48,48,48,48,48,48,48,48,48,48,48,48,48,48,48,48,48,48,48,48,48,1,1,13,13,13,1,1,1,1,1,1,1,15
rule2=0,50,48,48,48,48,48,48,48,48,48,48,48,48,48,48,48,48,48,48,48,48,48,48,48,48,48,48,48,48,48,48,48,48,48,48,48,48,48,48,48,48,48,48,48,48,48,48,48,48,48,48,48,48,48,48,48,48,48,48,48,48,48,48,48,48,48,48,48,48,48,48,48,48,48,48,48,48,48,48,48,48,48,48,48,48,48,48,48,48,48,48,48,48,48,48,1,1,13,13,13,1,1,1,1,1,1,1,15
rule3=1,80,48,48,48,48,48,48,48,48,48,48,48,48,48,48,48,48,48,48,48,48,48,48,48,48,48,48,48,48,48,48,48,48,48,48,48,48,48,48,48,48,48,48,48,48,48,48,48,48,48,48,48,48,48,48,48,48,48,48,48,48,48,48,48,48,48,48,48,48,48,48,48,48,48,48,48,48,48,48,48,48,48,48,48,48,48,48,48,48,48,48,48,48,48,48,48,1,1,13,13,13,1,1,1,1,1,1,1,15
rule4=0,50,24
rule5=0,0,35-14
rule6=2,50,20
rule7=1,100,85


layer
1,2,2,2,1,2,2,2,1,2,2,2,1,2,2,2,1,2,2,2,1,2,2,2,1
2,2,2,2,2,2,2,2,2,2,2,2,2,2,2,2,2,2,2,2,2,2,2,2,2
2,2,2,2,2,2,2,2,2,2,2,2,2,2,2,2,2,2,2,2,2,2,2,2,2
2,2,2,2,2,2,2,2,2,2,2,2,2,2,2,2,2,2,2,2,2,2,2,2,2
1,2,2,2,3,2,2,2,2,2,2,2,2,2,2,2,2,2,2,2,3,2,2,2,1
2,2,2,2,2,2,2,2,2,2,2,2,2,2,2,2,2,2,2,2,2,2,2,2,2
2,2,2,2,2,2,2,2,2,2,2,2,2,2,2,2,2,2,2,2,2,2,2,2,2
2,2,2,2,2,2,2,2,2,2,2,2,2,2,2,2,2,2,2,2,2,2,2,2,2
1,2,2,2,3,2,2,2,2,2,2,2,2,2,2,2,2,2,2,2,3,2,2,2,1
2,2,2,2,2,2,2,2,2,2,2,2,2,2,2,2,2,2,2,2,2,2,2,2,2
2,2,2,2,2,2,2,2,2,2,2,2,2,2,2,2,2,2,2,2,2,2,2,2,2
2,2,2,2,2,2,2,2,2,2,2,2,2,2,2,2,2,2,2,2,2,2,2,2,2
1,2,2,2,3,2,2,2,2,2,2,2,2,2,2,2,2,2,2,2,3,2,2,2,1
2,2,2,2,2,2,2,2,2,2,2,2,2,2,2,2,2,2,2,2,2,2,2,2,2
2,2,2,2,2,2,2,2,2,2,2,2,2,2,2,2,2,2,2,2,2,2,2,2,2
2,2,2,2,2,2,2,2,2,2,2,2,2,2,2,2,2,2,2,2,2,2,2,2,2
1,2,2,2,3,2,2,2,2,2,2,2,2,2,2,2,2,2,2,2,3,2,2,2,1
2,2,2,2,2,2,2,2,2,2,2,2,2,2,2,2,2,2,2,2,2,2,2,2,2
2,2,2,2,2,2,2,2,2,2,2,2,2,2,2,2,2,2,2,2,2,2,2,2,2
2,2,2,2,2,2,2,2,2,2,2,2,2,2,2,2,2,2,2,2,2,2,2,2,2
1,2,2,2,3,2,2,2,2,2,2,2,2,2,2,2,2,2,2,2,3,2,2,2,1
2,2,2,2,2,2,2,2,2,2,2,2,2,2,2,2,2,2,2,2,2,2,2,2,2
2,2,2,2,2,2,2,2,2,2,2,2,2,2,2,2,2,2,2,2,2,2,2,2,2
2,2,2,2,2,2,2,2,2,2,2,2,2,2,2,2,2,2,2,2,2,2,2,2,2
1,2,2,2,1,2,2,2,1,2,2,2,1,2,2,2,1,2,2,2,1,2,2,2,1
endlayer

layer
1,4,4,4,1,6,6,6,1,5,5,5,1,5,5,5,1,6,6,6,1,4,4,4,1
4,5,5,5,5,5,5,5,5,5,5,5,5,5,5,5,5,5,5,5,5,5,5,5,4
4,5,5,5,5,5,5,5,5,5,5,5,5,5,5,5,5,5,5,5,5,5,5,5,4
4,5,5,5,5,5,5,5,5,5,5,5,5,5,5,5,5,5,5,5,5,5,5,5,4
1,5,5,5,3,5,5,5,5,5,5,5,5,5,5,5,5,5,5,5,3,5,5,5,1
4,5,5,5,5,5,5,5,5,5,5,5,5,5,5,5,5,5,5,5,5,5,5,5,4
4,5,5,5,5,5,5,5,5,5,5,5,5,5,5,5,5,5,5,5,5,5,5,5,4
4,5,5,5,5,5,5,5,5,5,5,5,5,5,5,5,5,5,5,5,5,5,5,5,4
1,5,5,5,3,5,5,5,5,5,5,5,5,5,5,5,5,5,5,5,3,5,5,5,1
4,5,5,5,5,5,5,5,2,2,2,5,5,5,2,2,2,5,5,5,5,5,5,5,4
4,5,5,5,5,5,5,5,2,5,5,5,5,5,5,5,2,5,5,5,5,5,5,5,4
4,5,5,5,5,5,5,5,2,5,5,5,5,5,5,5,2,5,5,5,5,5,5,5,4
1,5,5,5,3,5,5,5,2,2,2,5,5,5,2,2,2,5,5,5,3,5,5,5,1
4,5,5,5,5,5,5,5,2,5,5,5,5,5,5,5,2,5,5,5,5,5,5,5,4
4,5,5,5,5,5,5,5,2,5,5,5,5,5,5,5,2,5,5,5,5,5,5,5,4
4,5,5,5,5,5,5,5,2,2,2,5,5,5,2,2,2,5,5,5,5,5,5,5,4
1,5,5,5,3,5,5,5,5,5,5,5,5,5,5,5,5,5,5,5,3,5,5,5,1
4,5,5,5,5,5,5,5,5,5,5,5,5,5,5,5,5,5,5,5,5,5,5,5,4
4,5,5,5,5,5,5,5,5,5,5,5,5,5,5,5,5,5,5,5,5,5,5,5,4
4,5,5,5,5,5,5,5,5,5,5,5,5,5,5,5,5,5,5,5,5,5,5,5,4
1,5,5,5,3,5,5,5,5,5,5,5,5,5,5,5,5,5,5,5,3,5,5,5,1
4,5,5,5,5,5,5,5,5,5,5,5,5,5,5,5,5,5,5,5,5,5,5,5,4
4,5,5,5,5,5,5,5,5,5,5,5,5,5,5,5,5,5,5,5,5,5,5,5,4
4,5,5,5,5,5,5,5,5,5,5,5,5,5,5,5,5,5,5,5,5,5,5,5,4
1,4,4,4,1,6,6,6,1,5,5,5,1,5,5,5,1,6,6,6,1,4,4,4,1
endlayer

layer
1,4,4,4,1,6,6,6,1,5,5,5,1,5,5,5,1,6,6,6,1,4,4,4,1
4,5,5,5,5,5,5,5,5,5,5,5,5,5,5,5,5,5,5,5,5,5,5,5,4
4,5,5,5,5,5,5,5,5,5,5,5,5,5,5,5,5,5,5,5,5,5,5,5,4
4,5,5,5,5,5,5,5,5,5,5,5,5,5,5,5,5,5,5,5,5,5,5,5,4
1,5,5,5,3,5,5,5,5,5,5,5,5,5,5,5,5,5,5,5,3,5,5,5,1
4,5,5,5,5,5,5,5,5,5,5,5,5,5,5,5,5,5,5,5,5,5,5,5,4
4,5,5,5,5,5,5,5,5,5,5,5,5,5,5,5,5,5,5,5,5,5,5,5,4
4,5,5,5,5,5,5,5,5,5,5,5,5,5,5,5,5,5,5,5,5,5,5,5,4
1,5,5,5,3,5,5,5,5,5,5,5,5,5,5,5,5,5,5,5,3,5,5,5,1
4,5,5,5,5,5,5,5,2,2,2,5,5,5,2,2,2,5,5,5,5,5,5,5,4
4,5,5,5,5,5,5,5,2,5,5,5,5,5,5,5,2,5,5,5,5,5,5,5,4
4,5,5,5,5,5,5,5,2,5,5,5,5,5,5,5,2,5,5,5,5,5,5,5,4
1,5,5,5,3,5,5,5,2,2,2,5,5,5,2,2,2,5,5,5,3,5,5,5,1
4,5,5,5,5,5,5,5,2,5,5,5,5,5,5,5,2,5,5,5,5,5,5,5,4
4,5,5,5,5,5,5,5,2,5,5,5,5,5,5,5,2,5,5,5,5,5,5,5,4
4,5,5,5,5,5,5,5,2,2,2,5,5,5,2,2,2,5,5,5,5,5,5,5,4
1,5,5,5,3,5,5,5,5,5,5,5,5,5,5,5,5,5,5,5,3,5,5,5,1
4,5,5,5,5,5,5,5,5,5,5,5,5,5,5,5,5,5,5,5,5,5,5,5,4
4,5,5,5,5,5,5,5,5,5,5,5,5,5,5,5,5,5,5,5,5,5,5,5,4
4,5,5,5,5,5,5,5,5,5,5,5,5,5,5,5,5,5,5,5,5,5,5,5,4
1,5,5,5,3,5,5,5,5,5,5,5,5,5,5,5,5,5,5,5,3,5,5,5,1
4,5,5,5,5,5,5,5,5,5,5,5,5,5,5,5,5,5,5,5,5,5,5,5,4
4,5,5,5,5,5,5,5,5,5,5,5,5,5,5,5,5,5,5,5,5,5,5,5,4
4,5,5,5,5,5,5,5,5,5,5,5,5,5,5,5,5,5,5,5,5,5,5,5,4
1,4,4,4,1,6,6,6,1,5,5,5,1,5,5,5,1,6,6,6,1,4,4,4,1
endlayer

layer
1,4,4,4,1,6,6,6,1,5,5,5,1,5,5,5,1,6,6,6,1,4,4,4,1
4,5,5,5,5,5,5,5,5,5,5,5,5,5,5,5,5,5,5,5,5,5,5,5,4
4,5,5,5,5,5,5,5,5,5,5,5,5,5,5,5,5,5,5,5,5,5,5,5,4
4,5,5,5,5,5,5,5,5,5,5,5,5,5,5,5,5,5,5,5,5,5,5,5,4
1,5,5,5,3,5,5,5,5,5,5,5,5,5,5,5,5,5,5,5,3,5,5,5,1
4,5,5,5,5,5,5,5,5,5,5,5,5,5,5,5,5,5,5,5,5,5,5,5,4
4,5,5,5,5,5,5,5,5,5,5,5,5,5,5,5,5,5,5,5,5,5,5,5,4
4,5,5,5,5,5,5,5,5,5,5,5,5,5,5,5,5,5,5,5,5,5,5,5,4
1,5,5,5,3,5,5,5,5,5,5,5,5,5,5,5,5,5,5,5,3,5,5,5,1
4,5,5,5,5,5,5,5,2,2,2,5,5,5,2,2,2,5,5,5,5,5,5,5,4
4,5,5,5,5,5,5,5,2,5,5,5,5,5,5,5,2,5,5,5,5,5,5,5,4
4,5,5,5,5,5,5,5,2,5,5,5,5,5,5,5,2,5,5,5,5,5,5,5,4
1,5,5,5,3,5,5,5,2,2,2,5,5,5,2,2,2,5,5,5,3,5,5,5,1
4,5,5,5,5,5,5,5,2,5,5,5,5,5,5,5,2,5,5,5,5,5,5,5,4
4,5,5,5,5,5,5,5,2,5,5,5,5,5,5,5,2,5,5,5,5,5,5,5,4
4,5,5,5,5,5,5,5,2,2,2,5,5,5,2,2,2,5,5,5,5,5,5,5,4
1,5,5,5,3,5,5,5,5,5,5,5,5,5,5,5,5,5,5,5,3,5,5,5,1
4,5,5,5,5,5,5,5,5,5,5,5,5,5,5,5,5,5,5,5,5,5,5,5,4
4,5,5,5,5,5,5,5,5,5,5,5,5,5,5,5,5,5,5,5,5,5,5,5,4
4,5,5,5,5,5,5,5,5,5,5,5,5,5,5,5,5,5,5,5,5,5,5,5,4
1,5,5,5,3,5,5,5,5,5,5,5,5,5,5,5,5,5,5,5,3,5,5,5,1
4,5,5,5,5,5,5,5,5,5,5,5,5,5,5,5,5,5,5,5,5,5,5,5,4
4,5,5,5,5,5,5,5,5,5,5,5,5,5,5,5,5,5,5,5,5,5,5,5,4
4,5,5,5,5,5,5,5,5,5,5,5,5,5,5,5,5,5,5,5,5,5,5,5,4
1,4,4,4,1,6,6,6,1,5,5,5,1,5,5,5,1,6,6,6,1,4,4,4,1
endlayer

layer
7,5,7,5,7,5,5,5,7,5,5,5,7,5,5,5,7,5,5,5,7,5,7,5,7
5,5,5,5,5,5,5,5,5,5,5,5,5,5,5,5,5,5,5,5,5,5,5,5,5
7,5,5,5,5,5,5,5,5,5,5,5,5,5,5,5,5,5,5,5,5,5,5,5,7
5,5,5,5,5,5,5,5,5,5,5,5,5,5,5,5,5,5,5,5,5,5,5,5,5
7,5,5,5,7,5,5,5,5,5,5,5,5,5,5,5,5,5,5,5,7,5,5,5,7
5,5,5,5,5,5,5,5,5,5,5,5,5,5,5,5,5,5,5,5,5,5,5,5,5
7,5,5,5,5,5,5,5,5,5,5,5,5,5,5,5,5,5,5,5,5,5,5,5,7
5,5,5,5,5,5,5,5,5,5,5,5,5,5,5,5,5,5,5,5,5,5,5,5,5
7,5,5,5,7,5,5,5,5,5,5,5,5,5,5,5,5,5,5,5,7,5,5,5,7
5,5,5,5,5,5,5,5,7,5,7,5,5,5,7,5,7,5,5,5,5,5,5,5,5
7,5,5,5,5,5,5,5,5,5,5,5,5,5,5,5,5,5,5,5,5,5,5,5,7
5,5,5,5,5,5,5,5,5,5,5,5,5,5,5,5,5,5,5,5,5,5,5,5,5
7,5,5,5,7,5,5,5,7,5,7,5,5,5,7,5,7,5,5,5,7,5,5,5,7
5,5,5,5,5,5,5,5,5,5,5,5,5,5,5,5,5,5,5,5,5,5,5,5,5
7,5,5,5,5,5,5,5,5,5,5,5,5,5,5,5,5,5,5,5,5,5,5,5,7
5,5,5,5,5,5,5,5,7,5,7,5,5,5,7,5,7,5,5,5,5,5,5,5,5
7,5,5,5,7,5,5,5,5,5,5,5,5,5,5,5,5,5,5,5,7,5,5,5,7
5,5,5,5,5,5,5,5,5,5,5,5,5,5,5,5,5,5,5,5,5,5,5,5,5
7,5,5,5,5,5,5,5,5,5,5,5,5,5,5,5,5,5,5,5,5,5,5,5,7
5,5,5,5,5,5,5,5,5,5,5,5,5,5,5,5,5,5,5,5,5,5,5,5,5
7,5,5,5,7,5,5,5,5,5,5,5,5,5,5,5,5,5,5,5,7,5,5,5,7
5,5,5,5,5,5,5,5,5,5,5,5,5,5,5,5,5,5,5,5,5,5,5,5,5
7,5,5,5,5,5,5,5,5,5,5,5,5,5,5,5,5,5,5,5,5,5,5,5,7
5,5,5,5,5,5,5,5,5,5,5,5,5,5,5,5,5,5,5,5,5,5,5,5,5
7,5,7,5,7,5,5,5,7,5,5,5,7,5,5,5,7,5,5,5,7,5,7,5,7
endlayer

