# Converted from schematic
# THIS TEMPLATE USES DEFAULTS!  Please edit for corrections.
# If you need help, consult template_rules.txt

weight=5
embed_into_distance=3
acceptable_target_blocks=1,2,3,12,13,162,163,164,165,166,167,168,169,170,171,172,254,255
dimensions=7,11,13
allowable_overhang=0
max_cut_in=2
cut_in_buffer=1
max_leveling=2
leveling_buffer=1
preserve_water=0
preserve_lava=0
preserve_plants=0


rule1=0,100,12
rule2=0,100,98-1
rule3=0,100,3
rule4=0,100,4
rule5=0,100,48
rule6=0,100,98
rule7=0,100,2
rule8=0,100,98-2
rule9=0,100,109-2
rule10=0,100,20
rule11=0,100,50-3
rule12=0,100,50-4


layer
3,1,1,1,1,1,1,1,1,3,1,1,1
3,1,1,1,1,1,1,1,1,1,1,1,1
3,1,3,2,2,2,2,2,2,2,2,2,2
3,1,1,1,2,2,2,1,1,1,2,2,1
3,1,1,1,2,2,2,1,1,1,1,2,1
3,5,1,1,1,4,4,4,1,1,1,2,1
3,1,1,4,4,4,4,4,4,2,1,2,1
3,1,1,4,2,2,2,2,4,2,1,2,1
3,1,2,2,2,2,2,2,4,1,1,2,1
3,1,4,2,2,2,2,2,4,1,1,2,1
3,1,1,4,4,4,4,4,4,1,1,2,1
endlayer

layer
3,3,3,3,3,3,3,3,3,3,3,3,3
3,3,3,2,2,2,2,2,2,2,2,2,3
3,3,3,2,2,2,2,2,2,2,2,2,3
3,3,3,2,2,2,2,2,2,2,2,2,3
3,3,3,2,2,2,2,2,2,2,2,2,3
3,2,2,2,2,2,2,2,6,2,2,2,3
3,3,3,4,4,2,2,2,2,2,6,2,3
3,3,4,4,4,2,2,2,2,2,6,2,3
3,3,4,4,4,2,2,2,4,6,2,2,3
3,3,4,4,2,2,2,2,4,2,2,2,3
3,3,3,4,4,2,4,4,2,2,2,2,3
endlayer

layer
7,7,7,3,3,7,7,7,7,7,3,3,7
7,7,3,4,4,2,2,2,2,2,4,2,3
7,7,3,4,8,2,2,2,2,2,2,2,3
7,7,7,2,2,0,0,0,0,0,2,8,7
2,2,2,2,2,0,0,0,0,0,2,2,7
9,0,0,0,0,0,0,0,0,0,2,2,7
2,2,2,2,8,0,0,0,0,0,2,2,7
7,7,7,2,8,0,0,0,0,0,2,2,7
7,7,2,4,8,8,2,2,2,2,2,2,3
7,7,4,4,4,2,2,8,4,4,8,2,3
7,7,7,4,4,7,7,7,7,7,4,2,7
endlayer

layer
0,0,0,2,8,0,0,0,0,0,2,8,0
0,0,2,2,2,10,10,10,10,10,2,2,2
0,0,2,6,0,0,0,0,0,0,0,8,8
0,0,0,10,0,0,0,0,0,0,0,10,0
0,0,2,2,0,0,0,0,0,0,0,10,0
0,0,0,0,0,0,0,0,0,0,0,10,0
0,0,2,2,0,0,0,0,0,0,0,10,0
0,0,0,10,0,0,0,0,0,0,0,10,0
0,0,2,2,0,0,0,0,0,0,0,2,2
0,0,2,2,2,10,10,10,10,10,2,2,8
0,0,0,2,2,0,0,0,0,0,2,2,0
endlayer

layer
0,0,0,0,0,0,0,0,0,0,0,0,0
0,0,0,2,8,8,2,2,8,2,2,8,0
0,0,0,2,12,0,0,0,0,0,11,2,0
0,0,0,10,0,0,0,0,0,0,0,8,0
0,0,2,2,0,0,0,0,0,0,0,8,0
0,0,2,2,0,0,0,0,0,0,0,2,0
0,0,2,2,0,0,0,0,0,0,0,2,0
0,0,0,10,0,0,0,0,0,0,0,2,0
0,0,0,2,12,0,0,0,0,0,11,8,0
0,0,0,8,2,2,2,8,8,2,2,2,0
0,0,0,0,0,0,0,0,0,0,0,0,0
endlayer

layer
0,0,0,0,0,0,0,0,0,0,0,0,0
0,0,0,2,8,2,2,6,2,8,2,8,0
0,0,0,2,2,2,6,6,2,2,2,2,0
0,0,0,10,10,2,10,10,10,2,2,2,0
0,0,0,2,2,2,10,10,10,2,2,2,0
0,0,0,6,2,2,10,10,10,2,2,2,0
0,0,0,6,2,2,10,10,10,6,6,2,0
0,0,0,10,10,2,10,10,10,2,6,8,0
0,0,0,6,2,2,2,2,2,2,6,6,0
0,0,0,2,2,2,2,6,6,2,6,8,0
0,0,0,0,0,0,0,0,0,0,0,0,0
endlayer

layer
0,0,0,0,0,0,0,0,0,0,0,0,0
0,0,0,2,0,2,0,6,0,2,0,8,0
0,0,0,0,0,0,0,0,0,0,0,0,0
0,0,0,0,0,0,0,0,0,0,0,2,0
0,0,0,0,0,0,0,0,0,0,0,0,0
0,0,0,6,0,0,0,0,0,0,0,2,0
0,0,0,0,0,0,0,0,0,0,0,0,0
0,0,0,0,0,0,0,0,0,0,0,2,0
0,0,0,0,0,0,0,0,0,0,0,0,0
0,0,0,6,0,2,0,6,0,2,0,2,0
0,0,0,0,0,0,0,0,0,0,0,0,0
endlayer

