#to fill with water change rule4,6,7,8, or just rule4 for a puddle

weight=10
acceptable_target_blocks=1,2,3,12,13,24,78,162,163,164,165,166,167,168,169,170,171,172,254,255
embed_into_distance=5
dimensions=7,29,18
max_cut_in=25
max_leveling=0
leveling_buffer=0


rule1=0,0,3
rule2=0,100,98,98,98,98,98-1,98-2
rule3=0,100,35-13
rule4=0,100,0
rule5=0,100,109
rule6=0,100,0
rule7=0,100,65-3
rule8=0,100,65-2
rule9=0,90,48
rule10=0,100,98-3
rule11=0,100,109-5
rule12=0,100,44-5


layer
1,1,1,1,1,1,1,1,1,1,1,1,1,1,1,1,1,1
1,1,1,1,1,1,1,1,1,1,1,1,1,1,1,1,1,1
1,1,2,2,3,2,2,3,2,2,3,2,2,3,2,2,1,1
1,1,2,2,3,2,2,3,2,2,3,2,2,3,2,2,1,1
1,1,2,2,3,2,2,3,2,2,3,2,2,3,2,2,1,1
1,1,2,2,3,2,2,3,2,2,3,2,2,3,2,2,1,1
1,1,2,2,3,2,2,3,2,2,3,2,2,3,2,2,1,1
1,1,2,2,3,2,2,3,2,2,3,2,2,3,2,2,1,1
1,1,2,2,3,2,2,3,2,2,3,2,2,3,2,2,1,1
1,1,2,2,3,2,2,3,2,2,3,2,2,3,2,2,1,1
1,1,2,2,3,2,2,3,2,2,3,2,2,3,2,2,1,1
1,1,1,1,1,1,1,1,1,1,1,1,1,1,1,1,1,1
1,1,1,1,1,1,1,1,1,1,1,1,1,1,1,1,1,1
1,1,1,1,1,1,1,1,1,1,1,1,1,1,1,1,1,1
1,1,1,1,1,1,1,1,1,1,1,1,1,1,1,1,1,1
1,1,1,1,1,1,1,1,1,1,1,1,1,1,1,1,1,1
1,1,1,1,1,1,1,1,1,1,1,1,1,1,1,1,1,1
1,1,1,1,1,1,1,1,1,1,1,1,1,1,1,1,1,1
1,1,1,1,1,1,1,1,1,1,1,1,1,1,1,1,1,1
1,1,1,1,1,1,1,1,1,1,1,1,1,1,1,1,1,1
1,1,1,1,1,1,1,1,1,1,1,1,1,1,1,1,1,1
1,1,1,1,1,1,1,1,1,1,1,1,1,1,1,1,1,1
1,1,1,1,1,1,1,1,1,1,1,1,1,1,1,1,1,1
1,1,1,1,1,1,1,1,1,1,1,1,1,1,1,1,1,1
1,1,1,1,1,1,1,1,1,1,1,1,1,1,1,1,1,1
1,1,1,1,1,1,1,1,1,1,1,1,1,1,1,1,1,1
1,1,1,1,1,1,1,1,1,1,1,1,1,1,1,1,1,1
1,1,1,1,1,1,1,1,1,1,1,1,1,1,1,1,1,1
1,1,1,1,1,1,1,1,1,1,1,1,1,1,1,1,1,1
endlayer

layer
1,1,1,1,1,1,1,1,1,1,1,1,1,1,1,1,1,1
1,2,2,2,2,2,2,2,2,2,2,2,2,2,2,2,2,1
1,2,4,4,4,4,4,4,4,4,4,4,4,4,4,4,2,1
1,2,4,4,4,4,4,4,4,4,4,4,4,4,4,4,2,1
1,2,4,4,4,4,4,4,4,4,4,4,4,4,4,4,2,1
1,2,4,4,4,4,4,4,4,4,4,4,4,4,4,4,2,1
1,2,4,4,4,4,4,4,4,4,4,4,4,4,4,4,2,1
1,2,4,4,4,4,4,4,4,4,4,4,4,4,4,4,2,1
1,2,4,4,4,4,4,4,4,4,4,4,4,4,4,4,2,1
1,2,4,4,4,4,4,4,4,4,4,4,4,4,4,4,2,1
1,2,4,4,4,4,4,4,4,4,4,4,4,4,4,4,2,1
1,2,5,5,5,5,5,5,5,5,5,5,5,5,5,5,2,1
1,1,2,2,3,2,2,3,2,2,3,2,2,3,2,2,1,1
1,1,2,2,3,2,2,3,2,2,3,2,2,3,2,2,1,1
1,1,1,1,1,1,1,1,1,1,1,1,1,1,1,1,1,1
1,1,1,1,1,1,1,1,1,1,1,1,1,1,1,1,1,1
1,1,1,1,1,1,1,1,1,1,1,1,1,1,1,1,1,1
1,1,1,1,1,1,1,1,1,1,1,1,1,1,1,1,1,1
1,1,1,1,1,1,1,1,1,1,1,1,1,1,1,1,1,1
1,1,1,1,1,1,1,1,1,1,1,1,1,1,1,1,1,1
1,1,1,1,1,1,1,1,1,1,1,1,1,1,1,1,1,1
1,1,1,1,1,1,1,1,1,1,1,1,1,1,1,1,1,1
1,1,1,1,1,1,1,1,1,1,1,1,1,1,1,1,1,1
1,1,1,1,1,1,1,1,1,1,1,1,1,1,1,1,1,1
1,1,1,1,1,1,1,1,1,1,1,1,1,1,1,1,1,1
1,1,1,1,1,1,1,1,1,1,1,1,1,1,1,1,1,1
1,1,1,1,1,1,1,1,1,1,1,1,1,1,1,1,1,1
1,1,1,1,1,1,1,1,1,1,1,1,1,1,1,1,1,1
1,1,1,1,1,1,1,1,1,1,1,1,1,1,1,1,1,1
endlayer

layer
1,1,1,1,1,1,1,1,1,1,1,1,1,1,1,1,1,1
1,2,2,2,3,2,2,3,2,2,3,2,2,3,2,2,2,1
1,2,6,6,6,6,6,6,6,6,6,6,6,6,6,6,2,1
1,2,6,6,6,6,6,6,6,6,6,6,6,6,6,6,2,1
1,2,6,6,6,6,6,6,6,6,6,6,6,6,6,6,2,1
1,2,6,6,6,6,6,6,6,6,6,6,6,6,6,6,2,1
1,2,6,6,6,6,6,6,6,6,6,6,6,6,6,6,2,1
1,2,6,6,6,6,6,6,6,6,6,6,6,6,6,6,2,1
1,2,6,6,6,6,6,6,6,6,6,6,6,6,6,6,2,1
1,2,6,6,6,6,6,6,6,6,6,6,6,6,6,6,2,1
1,2,6,6,6,6,6,6,6,6,6,6,6,6,6,6,2,1
1,2,6,6,6,6,6,6,6,6,6,6,6,6,6,6,2,1
1,2,6,6,6,6,6,6,6,6,6,6,6,6,6,6,2,1
1,2,6,6,6,6,6,6,6,6,6,6,6,6,6,6,2,1
1,2,5,5,5,5,5,5,5,5,5,5,5,5,5,5,2,1
1,1,2,2,3,2,2,3,2,2,3,2,2,3,2,2,1,1
1,1,2,2,3,2,2,3,2,2,3,2,2,3,2,2,1,1
1,1,2,2,3,2,2,3,2,2,3,2,2,3,2,2,1,1
1,1,2,2,3,2,2,3,2,2,3,2,2,3,2,2,1,1
1,1,2,2,3,2,2,3,2,2,3,2,2,3,2,2,1,1
1,1,2,2,3,2,2,3,2,2,3,2,2,3,2,2,1,1
1,1,2,2,3,2,2,3,2,2,3,2,2,3,2,2,1,1
1,1,2,2,3,2,2,3,2,2,3,2,2,3,2,2,1,1
1,1,2,2,3,2,2,3,2,2,3,2,2,3,2,2,1,1
1,1,2,2,3,2,2,3,2,2,3,2,2,3,2,2,1,1
1,1,2,2,3,2,2,3,2,2,3,2,2,3,2,2,1,1
1,1,2,2,3,2,2,3,2,2,3,2,2,3,2,2,1,1
1,1,1,1,1,1,1,1,1,1,1,1,1,1,1,1,1,1
1,1,1,1,1,1,1,1,1,1,1,1,1,1,1,1,1,1
endlayer

layer
1,1,1,1,1,1,1,1,1,1,1,1,1,1,1,1,1,1
1,2,2,2,2,2,2,2,2,2,2,2,2,2,2,2,2,1
1,2,6,6,6,6,6,6,6,6,6,6,6,6,6,6,2,1
1,2,8,6,6,6,6,6,6,6,6,6,6,6,6,7,2,1
1,2,6,6,6,6,6,6,6,6,6,6,6,6,6,6,2,1
1,2,6,6,6,6,6,6,6,6,6,6,6,6,6,6,2,1
1,2,6,6,6,6,6,6,6,6,6,6,6,6,6,6,2,1
1,2,6,6,6,6,6,6,6,6,6,6,6,6,6,6,2,1
1,2,6,6,6,6,6,6,6,6,6,6,6,6,6,6,2,1
1,2,6,6,6,6,6,6,6,6,6,6,6,6,6,6,2,1
1,2,6,6,6,6,6,6,6,6,6,6,6,6,6,6,2,1
1,2,6,6,6,6,6,6,6,6,6,6,6,6,6,6,2,1
1,2,6,6,6,6,6,6,6,6,6,6,6,6,6,6,2,1
1,2,6,6,6,6,6,6,6,6,6,6,6,6,6,6,2,1
1,2,6,6,6,6,6,6,6,6,6,6,6,6,6,6,2,1
1,2,6,6,6,6,6,6,6,6,6,6,6,6,6,6,2,1
1,2,6,6,6,6,6,6,6,6,6,6,6,6,6,6,2,1
1,2,6,6,6,6,6,6,6,6,6,6,6,6,6,6,2,1
1,2,6,6,6,6,6,6,6,6,6,6,6,6,6,6,2,1
1,2,6,6,6,6,6,6,6,6,6,6,6,6,6,6,2,1
1,2,6,6,6,6,6,6,6,6,6,6,6,6,6,6,2,1
1,2,6,6,6,6,6,6,6,6,6,6,6,6,6,6,2,1
1,2,6,6,6,6,6,6,6,6,6,6,6,6,6,6,2,1
1,2,6,6,6,6,6,6,6,6,6,6,6,6,6,6,2,1
1,2,6,6,6,6,6,6,6,6,6,6,6,6,6,6,2,1
1,2,6,6,6,6,6,6,6,6,6,6,6,6,6,6,2,1
1,2,6,6,6,6,6,6,6,6,6,6,6,6,6,6,2,1
1,2,2,2,2,2,2,2,2,2,2,2,2,2,2,2,2,1
1,1,1,1,1,1,1,1,1,1,1,1,1,1,1,1,1,1
endlayer

layer
9,9,9,9,9,9,9,9,9,9,9,9,9,9,9,9,9,9
9,10,10,10,10,10,10,10,10,10,10,10,10,10,10,10,10,9
9,10,6,6,6,6,6,6,6,6,6,6,6,6,6,6,10,9
9,2,8,6,6,6,6,6,6,6,6,6,6,6,6,7,2,9
9,10,6,6,6,6,6,6,6,6,6,6,6,6,6,6,10,9
9,10,6,6,6,6,6,6,6,6,6,6,6,6,6,6,10,9
9,10,6,6,6,6,6,6,6,6,6,6,6,6,6,6,10,9
9,10,6,6,6,6,6,6,6,6,6,6,6,6,6,6,10,9
9,10,6,6,6,6,6,6,6,6,6,6,6,6,6,6,10,9
9,10,6,6,6,6,6,6,6,6,6,6,6,6,6,6,10,9
9,10,6,6,6,6,6,6,6,6,6,6,6,6,6,6,10,9
9,10,6,6,6,6,6,6,6,6,6,6,6,6,6,6,10,9
9,10,6,6,6,6,6,6,6,6,6,6,6,6,6,6,10,9
9,10,6,6,6,6,6,6,6,6,6,6,6,6,6,6,10,9
9,10,6,6,6,6,6,6,6,6,6,6,6,6,6,6,10,9
9,10,6,6,6,6,6,6,6,6,6,6,6,6,6,6,10,9
9,10,6,6,6,6,6,6,6,6,6,6,6,6,6,6,10,9
9,10,6,6,6,6,6,6,6,6,6,6,6,6,6,6,10,9
9,10,6,6,6,6,6,6,6,6,6,6,6,6,6,6,10,9
9,10,6,6,6,6,6,6,6,6,6,6,6,6,6,6,10,9
9,10,6,6,6,6,6,6,6,6,6,6,6,6,6,6,10,9
9,10,6,6,6,6,6,6,6,6,6,6,6,6,6,6,10,9
9,10,6,6,6,6,6,6,6,6,6,6,6,6,6,6,10,9
9,10,6,6,6,6,6,6,6,6,6,6,6,6,6,6,10,9
9,10,6,6,6,6,6,6,6,6,6,6,6,6,6,6,10,9
9,2,8,6,6,6,6,6,6,6,6,6,6,6,6,7,2,9
9,10,6,6,6,6,6,6,6,6,6,6,6,6,6,6,10,9
9,10,10,10,10,10,10,10,10,10,10,10,10,10,10,10,10,9
9,9,9,9,9,9,9,9,9,9,9,9,9,9,9,9,9,9
endlayer

layer
0,0,0,0,0,0,0,0,0,0,0,0,0,0,0,0,0,0
0,0,0,0,0,0,0,0,5,0,0,0,0,0,0,0,0,0
0,0,0,0,0,0,0,0,11,0,0,0,0,0,0,0,0,0
0,0,0,0,0,0,0,0,0,0,0,0,0,0,0,0,0,0
0,0,0,0,0,0,0,0,0,0,0,0,0,0,0,0,0,0
0,0,0,0,0,0,0,0,0,0,0,0,0,0,0,0,0,0
0,0,0,0,0,0,0,0,0,0,0,0,0,0,0,0,0,0
0,0,0,0,0,0,0,0,0,0,0,0,0,0,0,0,0,0
0,0,0,0,0,0,0,0,0,0,0,0,0,0,0,0,0,0
0,0,0,0,0,0,0,0,0,0,0,0,0,0,0,0,0,0
0,0,0,0,0,0,0,0,0,0,0,0,0,0,0,0,0,0
0,0,0,0,0,0,0,0,0,0,0,0,0,0,0,0,0,0
0,0,0,0,0,0,0,0,0,0,0,0,0,0,0,0,0,0
0,0,0,0,0,0,0,0,0,0,0,0,0,0,0,0,0,0
0,0,0,0,0,0,0,0,0,0,0,0,0,0,0,0,0,0
0,0,0,0,0,0,0,0,0,0,0,0,0,0,0,0,0,0
0,0,0,0,0,0,0,0,0,0,0,0,0,0,0,0,0,0
0,0,0,0,0,0,0,0,0,0,0,0,0,0,0,0,0,0
0,0,0,0,0,0,0,0,0,0,0,0,0,0,0,0,0,0
0,0,0,0,0,0,0,0,0,0,0,0,0,0,0,0,0,0
0,0,0,0,0,0,0,0,0,0,0,0,0,0,0,0,0,0
0,0,0,0,0,0,0,0,0,0,0,0,0,0,0,0,0,0
0,0,0,0,0,0,0,0,0,0,0,0,0,0,0,0,0,0
0,0,0,0,0,0,0,0,0,0,0,0,0,0,0,0,0,0
0,0,0,0,0,0,0,0,0,0,0,0,0,0,0,0,0,0
0,0,0,0,0,0,0,0,0,0,0,0,0,0,0,0,0,0
0,0,0,0,0,0,0,0,0,0,0,0,0,0,0,0,0,0
0,0,0,0,0,0,0,0,0,0,0,0,0,0,0,0,0,0
0,0,0,0,0,0,0,0,0,0,0,0,0,0,0,0,0,0
endlayer

layer
0,0,0,0,0,0,0,0,0,0,0,0,0,0,0,0,0,0
0,0,0,0,0,0,0,0,0,0,0,0,0,0,0,0,0,0
0,0,0,0,0,0,0,0,12,0,0,0,0,0,0,0,0,0
0,0,0,0,0,0,0,0,12,0,0,0,0,0,0,0,0,0
0,0,0,0,0,0,0,0,12,0,0,0,0,0,0,0,0,0
0,0,0,0,0,0,0,0,0,0,0,0,0,0,0,0,0,0
0,0,0,0,0,0,0,0,0,0,0,0,0,0,0,0,0,0
0,0,0,0,0,0,0,0,0,0,0,0,0,0,0,0,0,0
0,0,0,0,0,0,0,0,0,0,0,0,0,0,0,0,0,0
0,0,0,0,0,0,0,0,0,0,0,0,0,0,0,0,0,0
0,0,0,0,0,0,0,0,0,0,0,0,0,0,0,0,0,0
0,0,0,0,0,0,0,0,0,0,0,0,0,0,0,0,0,0
0,0,0,0,0,0,0,0,0,0,0,0,0,0,0,0,0,0
0,0,0,0,0,0,0,0,0,0,0,0,0,0,0,0,0,0
0,0,0,0,0,0,0,0,0,0,0,0,0,0,0,0,0,0
0,0,0,0,0,0,0,0,0,0,0,0,0,0,0,0,0,0
0,0,0,0,0,0,0,0,0,0,0,0,0,0,0,0,0,0
0,0,0,0,0,0,0,0,0,0,0,0,0,0,0,0,0,0
0,0,0,0,0,0,0,0,0,0,0,0,0,0,0,0,0,0
0,0,0,0,0,0,0,0,0,0,0,0,0,0,0,0,0,0
0,0,0,0,0,0,0,0,0,0,0,0,0,0,0,0,0,0
0,0,0,0,0,0,0,0,0,0,0,0,0,0,0,0,0,0
0,0,0,0,0,0,0,0,0,0,0,0,0,0,0,0,0,0
0,0,0,0,0,0,0,0,0,0,0,0,0,0,0,0,0,0
0,0,0,0,0,0,0,0,0,0,0,0,0,0,0,0,0,0
0,0,0,0,0,0,0,0,0,0,0,0,0,0,0,0,0,0
0,0,0,0,0,0,0,0,0,0,0,0,0,0,0,0,0,0
0,0,0,0,0,0,0,0,0,0,0,0,0,0,0,0,0,0
0,0,0,0,0,0,0,0,0,0,0,0,0,0,0,0,0,0
endlayer

