weight=3
embed_into_distance=1
acceptable_target_blocks=2
dimensions=23,5,5
allowable_overhang=5
max_cut_in=0
cut_in_buffer=0
max_leveling=0
leveling_buffer=0
preserve_water=0
preserve_lava=0
preserve_plants=1


rule1=0,0,35-14
rule2=0,100,4
rule3=0,100,85
rule4=0,95,53-2
rule5=0,95,53-7
rule6=2,50,65-2
rule7=0,95,5
rule8=0,95,53-6
rule9=0,95,53-3
rule10=2,50,65-3
rule11=0,100,5-3
rule12=0,100,5-1
rule13=0,100,96-3
rule14=0,50,58
rule15=0,50,HardChest
rule16=0,100,26-3
rule17=0,100,26-11
rule18=0,95,102
rule19=0,95,126-3


layer
1,1,1,1,1
1,1,1,1,1
1,1,1,1,1
1,1,1,1,1
1,1,1,1,1
endlayer

layer
2,0,0,3,2
0,5,4,0,0
0,0,0,0,0
0,0,0,0,0
2,3,0,0,2
endlayer

layer
3,0,3,3,3
5,4,0,0,0
0,0,0,0,0
0,0,0,0,0
3,3,3,0,3
endlayer

layer
3,3,3,0,3
7,6,0,0,0
0,0,0,0,0
0,0,0,0,0
3,0,3,3,3
endlayer

layer
3,3,0,0,3
7,6,0,0,0
0,0,0,0,0
0,0,0,0,0
3,0,0,3,3
endlayer

layer
3,0,0,0,3
3,0,9,8,0
0,0,0,0,0
0,0,0,0,3
3,0,0,0,3
endlayer

layer
3,0,0,0,3
3,0,0,9,8
3,0,0,0,3
0,0,0,0,3
3,0,0,0,3
endlayer

layer
3,0,0,0,3
0,0,0,10,7
3,0,0,0,3
3,0,0,0,0
3,0,0,0,3
endlayer

layer
3,0,0,0,3
0,0,0,10,7
0,0,0,0,0
3,0,0,0,0
3,0,0,0,3
endlayer

layer
3,0,0,3,3
0,5,4,0,3
0,0,0,0,0
0,0,0,0,0
3,3,0,0,3
endlayer

layer
3,0,3,3,3
5,4,0,0,0
0,0,0,0,0
0,0,0,0,0
3,3,3,0,3
endlayer

layer
3,3,3,0,3
7,6,0,0,0
0,0,0,0,0
0,0,0,0,0
3,0,3,3,3
endlayer

layer
3,3,0,0,3
7,6,0,0,0
0,0,0,0,0
0,0,0,0,0
3,0,0,3,3
endlayer

layer
3,0,0,0,3
3,0,9,8,0
0,0,0,0,0
0,0,0,0,3
3,0,0,0,3
endlayer

layer
3,0,0,0,3
3,0,0,9,8
3,0,0,0,3
0,0,0,0,3
3,0,0,0,3
endlayer

layer
3,0,0,0,3
0,0,0,10,7
3,0,0,0,3
3,0,0,0,0
3,0,0,0,3
endlayer

layer
3,0,0,0,3
0,0,0,10,7
0,0,0,0,0
3,0,0,0,0
3,0,0,0,3
endlayer

layer
11,11,11,11,11
11,12,12,10,11
11,12,12,12,11
11,12,12,12,11
11,11,11,11,11
endlayer

layer
11,11,11,11,11
11,15,0,13,11
11,16,0,0,11
11,17,0,14,11
11,11,11,11,11
endlayer

layer
18,18,18,18,18
18,0,0,0,18
18,0,0,0,18
18,0,0,0,18
18,18,18,18,18
endlayer

layer
18,18,18,18,18
18,0,0,0,18
18,0,0,0,18
18,0,0,0,18
18,18,18,18,18
endlayer

layer
19,19,19,19,19
19,11,11,11,19
19,11,11,11,19
19,11,11,11,19
19,19,19,19,19
endlayer

layer
0,0,0,0,0
0,0,0,0,0
0,0,19,0,0
0,0,0,0,0
0,0,0,0,0
endlayer

