# Author: d00dv4d3r
# From: Default Template

weight=9
embed_into_distance=1
acceptable_target_blocks=1,3,12,13,82
dimensions=5,5,7
allowable_overhang=2
max_cut_in=2
cut_in_buffer=0
max_leveling=2
leveling_buffer=0
preserve_water=1
preserve_lava=0
preserve_plants=0

rule1=0,100,0,5-1,126-1
rule2=0,100,4
rule3=1,50,5-3
rule4=2,33,5-3

layer
2,2,2,2,2,2,2
2,1,1,1,1,1,2
2,1,1,1,1,1,2
2,1,1,1,1,1,2
2,2,2,2,2,2,2
endlayer

layer
3,3,3,3,3,3,3
3,0,0,0,0,0,3
3,0,0,0,0,0,3
3,0,0,0,0,0,3
3,3,3,3,3,3,3
endlayer

layer
3,3,3,3,3,3,3
3,0,0,0,0,0,3
3,0,0,0,0,0,3
3,0,0,0,0,0,3
3,3,3,3,3,3,3
endlayer

layer
3,3,3,3,3,3,3
3,0,0,0,0,0,3
3,0,0,0,0,0,3
3,0,0,0,0,0,3
3,3,3,3,3,3,3
endlayer

layer
3,4,0,0,0,4,3
4,0,0,0,0,0,4
0,0,0,0,0,0,0
4,0,0,0,0,0,4
3,4,0,0,0,4,3
endlayer
