# Converted from schematic
# THIS TEMPLATE USES DEFAULTS!  Please edit for corrections.
# If you need help, consult template_rules.txt

weight=10
embed_into_distance=1
acceptable_target_blocks=1,2,3,12,13,162,163,164,165,166,167,168,169,170,171,172,254,255
dimensions=6,11,10
allowable_overhang=0
max_cut_in=2
cut_in_buffer=1
max_leveling=2
leveling_buffer=1
preserve_water=0
preserve_lava=0
preserve_plants=0


rule1=0,100,98-1
rule2=0,100,2
rule3=0,100,98-2
rule4=0,100,3
rule5=0,100,5
rule6=0,100,35-7
rule7=0,100,44-2
rule8=0,100,17
rule9=0,100,72
rule10=0,100,44-3
rule11=0,100,43-3
rule12=0,100,67-1
rule13=0,100,67-2
rule14=0,100,67
rule15=0,100,85
rule16=0,100,67-3
rule17=0,100,4


layer
1,1,1,1,1,1,1,1,1,1
0,1,1,5,1,1,1,1,1,1
0,1,1,5,4,1,1,1,1,1
0,1,4,5,5,4,4,4,1,1
0,0,1,5,5,5,5,5,1,1
0,0,1,5,6,0,6,0,4,2
0,0,1,1,6,0,6,5,4,2
0,0,5,5,6,6,6,5,4,2
5,5,5,5,5,5,5,5,4,2
1,4,4,4,4,1,4,4,1,3
1,3,2,2,1,1,2,3,3,1
endlayer

layer
0,0,0,0,0,0,0,0,0,0
0,0,0,0,8,0,0,0,0,0
0,7,5,9,5,7,7,7,0,0
0,7,5,0,0,5,5,5,8,0
0,0,0,0,0,0,0,0,5,7
0,0,5,0,0,0,0,0,5,7
0,0,5,0,0,0,0,0,5,7
0,0,0,0,0,0,0,0,5,7
0,0,0,0,0,0,0,0,5,7
8,5,5,5,5,5,5,5,8,0
0,0,7,7,7,0,7,7,0,0
endlayer

layer
0,0,0,0,0,0,0,0,0,0
0,0,0,0,8,0,0,0,0,0
0,0,0,0,5,0,0,0,0,0
0,0,0,0,0,0,0,0,8,0
0,0,0,0,0,0,0,0,0,0
0,0,0,0,0,0,0,0,0,0
0,0,0,0,0,0,0,0,0,0
0,0,0,0,0,0,0,0,0,0
0,0,0,0,0,0,0,0,0,0
8,5,0,0,5,0,0,5,8,0
0,0,0,0,0,0,0,0,0,0
endlayer

layer
0,0,10,10,10,0,0,0,0,0
0,0,11,11,11,10,0,0,0,0
0,0,5,5,5,10,7,7,0,0
0,0,0,7,7,5,5,5,8,0
0,0,0,0,0,0,0,0,5,0
0,0,0,0,0,0,0,0,5,0
0,0,0,0,0,0,0,0,0,0
0,0,0,7,0,0,0,0,5,0
11,11,5,7,0,0,0,0,5,0
11,11,5,5,5,5,5,0,8,0
10,12,12,0,0,0,0,0,0,0
endlayer

layer
0,0,0,0,0,0,0,0,0,0
0,0,0,0,0,0,0,0,0,0
0,0,0,0,0,14,14,14,14,0
0,0,0,0,5,5,5,5,5,13
0,0,0,0,15,0,0,15,5,13
0,0,0,0,0,0,0,0,5,13
0,0,0,0,0,5,0,0,5,13
0,0,0,5,0,0,0,0,5,13
0,10,16,5,0,0,0,0,5,13
0,10,0,11,5,5,0,0,11,13
0,0,0,12,12,12,12,0,12,10
endlayer

layer
0,0,0,0,0,0,0,0,0,0
0,0,0,0,0,0,0,0,0,0
0,0,0,0,0,0,0,0,0,0
0,0,0,0,14,14,14,14,10,0
0,0,0,0,0,0,0,0,13,0
0,0,0,0,0,0,0,0,13,0
0,0,0,0,17,17,17,17,13,0
0,0,0,0,0,0,0,0,13,0
0,0,0,16,0,0,0,0,13,0
0,0,0,10,0,0,12,0,10,0
0,0,0,0,0,0,0,0,0,0
endlayer

