weight=10
acceptable_target_blocks=1,2,3,12,13,162,163,164,165,166,167,168,169,170,171,172,254,255
embed_into_distance=1
dimensions=10,15,11
max_leveling=2
leveling_buffer=1
max_cut_in=25
cut_in_buffer=1

#foundation
rule1=0,100,4
rule2=0,0,35-5
#floor
rule3=0,100,5-1,43
#hidden spawner
rule4=0,100,HardMobSpawn
#exterior
rule5=0,90,5-3
rule6=0,75,5-1
#wallpaper
rule7=0,100,35-2
rule8=0,100,35-6
#l00t
rule9=0,2,126-1,30,35-12,35-7,5-2,86,58,61,MediumChest,54,46
rule10=0,100,64
#chimney
rule11=0,100,45
rule12=0,100,64-2
#windows
rule13=0,90,43
rule14=0,50,102
#wallpaper
rule15=0,100,35-10
rule16=0,100,35
rule17=0,100,64-8
#cobwebs
rule18=0,5,30
#roof
rule19=0,75,53-1
rule20=0,75,53-3
rule21=0,75,53
rule22=0,75,53-2
rule23=0,75,5


layer
2,2,1,1,1,1,1,1,1,1,1
2,2,1,1,1,1,4,1,1,1,1
2,2,1,1,3,3,3,3,3,1,1
2,2,1,3,3,3,3,3,3,3,1
2,2,1,3,3,3,3,3,3,3,1
2,2,1,1,3,3,3,3,3,1,1
1,1,1,1,3,3,3,3,3,1,1
1,1,1,1,1,1,1,3,1,1,1
1,1,3,3,3,3,3,3,3,1,1
1,3,3,3,3,3,3,3,3,3,1
1,3,3,3,3,3,3,3,3,3,1
1,1,3,3,3,3,3,3,3,1,1
1,1,3,3,1,1,3,3,1,1,1
1,1,1,1,1,1,1,1,1,1,1
2,2,2,2,2,2,2,2,2,2,2
endlayer

layer
0,0,5,5,5,5,5,5,5,5,5
0,0,5,7,7,7,7,7,7,6,5
0,0,5,7,9,0,0,0,9,7,5
0,0,5,0,9,9,9,9,9,0,5
0,0,5,0,9,9,9,9,9,0,5
0,0,5,7,9,9,9,9,9,7,5
5,5,6,7,9,9,9,0,9,7,5
5,6,8,8,8,11,8,10,8,8,5
5,7,9,9,9,9,9,0,9,7,5
5,0,9,9,9,9,9,9,9,0,5
5,0,9,9,9,9,9,9,9,0,5
5,7,9,0,9,9,9,9,9,7,5
5,7,9,0,7,7,0,0,7,6,5
5,5,5,12,5,5,5,5,5,5,5
0,0,0,0,0,0,0,0,0,0,0
endlayer

layer
0,0,5,5,5,5,5,5,5,5,5
0,0,5,15,15,15,15,15,15,6,5
0,0,13,15,0,0,0,0,0,15,13
0,0,14,0,0,0,0,0,0,0,14
0,0,14,0,0,0,0,0,0,0,14
0,0,13,15,0,0,0,0,0,15,13
5,5,6,15,0,0,0,0,0,15,5
5,6,16,16,16,11,16,17,16,16,5
13,15,0,0,0,0,0,0,0,15,13
14,0,0,0,0,0,0,0,0,0,14
14,0,0,0,0,0,0,0,0,0,14
13,15,0,0,0,0,0,0,0,15,13
5,15,18,0,15,15,0,0,15,6,5
5,5,5,17,5,13,14,14,13,5,5
0,0,0,0,0,0,0,0,0,0,0
endlayer

layer
0,20,5,5,5,5,5,5,5,5,5
0,20,6,15,15,15,15,15,15,6,5
0,20,6,15,18,0,0,0,18,15,5
0,20,6,15,0,0,0,0,0,15,5
0,20,6,15,0,0,0,0,0,15,5
21,6,6,15,0,0,0,0,0,15,5
5,6,6,15,18,0,0,0,18,15,5
5,6,16,16,16,11,16,16,16,16,5
5,15,18,0,0,0,0,0,18,15,5
5,15,0,0,0,0,0,0,0,15,5
5,15,0,0,0,0,0,0,0,15,5
5,15,18,0,0,0,0,0,18,15,5
5,15,15,15,15,15,15,15,15,6,5
5,6,6,6,6,6,6,6,6,6,5
19,19,19,19,19,19,19,19,19,19,19
endlayer

layer
0,0,20,23,23,13,14,13,23,23,22
0,0,20,6,6,6,0,6,6,6,22
0,0,20,6,18,18,0,18,18,6,22
0,0,20,6,18,18,0,18,18,6,22
0,0,20,6,18,18,0,18,18,6,22
0,0,20,6,18,18,0,18,18,6,22
21,21,6,6,18,18,0,18,18,6,22
23,6,6,6,6,11,6,6,6,6,23
23,6,18,18,18,18,18,18,18,6,23
23,6,18,18,18,18,18,18,18,6,23
23,6,18,18,18,18,18,18,18,6,23
23,6,18,18,18,18,18,18,18,6,23
23,6,6,6,6,6,6,6,6,6,23
19,19,19,19,19,19,19,19,19,19,19
0,0,0,0,0,0,0,0,0,0,0
endlayer

layer
0,0,0,20,23,23,23,23,23,22,0
0,0,0,20,6,6,6,6,6,22,0
0,0,0,20,6,18,0,18,6,22,0
0,0,0,20,6,18,0,18,6,22,0
0,0,0,20,6,18,0,18,6,22,0
0,0,0,20,6,18,0,18,6,22,0
0,0,0,20,6,18,0,18,6,22,0
21,21,21,6,6,11,6,6,6,6,21
23,6,6,6,6,6,6,6,6,6,23
23,6,18,18,18,18,18,18,18,6,23
23,6,18,18,18,18,18,18,18,6,23
23,6,6,6,6,6,6,6,6,6,23
19,19,19,19,19,19,19,19,19,19,19
0,0,0,0,0,0,0,0,0,0,0
0,0,0,0,0,0,0,0,0,0,0
endlayer

layer
0,0,0,0,20,23,23,23,22,0,0
0,0,0,0,20,6,6,6,22,0,0
0,0,0,0,20,6,6,6,22,0,0
0,0,0,0,20,6,6,6,22,0,0
0,0,0,0,20,6,6,6,22,0,0
0,0,0,0,20,6,6,6,22,0,0
0,0,0,0,20,6,6,6,22,0,0
0,0,0,0,20,11,6,6,22,0,0
21,21,21,21,6,6,6,6,6,21,21
23,6,6,6,6,6,6,6,6,6,23
23,6,6,6,6,6,6,6,6,6,23
19,19,19,19,19,19,19,19,19,19,19
0,0,0,0,0,0,0,0,0,0,0
0,0,0,0,0,0,0,0,0,0,0
0,0,0,0,0,0,0,0,0,0,0
endlayer

layer
0,0,0,0,0,20,6,22,0,0,0
0,0,0,0,0,20,6,22,0,0,0
0,0,0,0,0,20,6,22,0,0,0
0,0,0,0,0,20,6,22,0,0,0
0,0,0,0,0,20,6,22,0,0,0
0,0,0,0,0,20,6,22,0,0,0
0,0,0,0,0,20,6,22,0,0,0
0,0,0,0,0,11,6,22,0,0,0
0,0,0,0,0,20,6,22,0,0,0
21,21,21,21,21,6,6,6,21,21,21
19,19,19,19,19,19,19,19,19,19,19
0,0,0,0,0,0,0,0,0,0,0
0,0,0,0,0,0,0,0,0,0,0
0,0,0,0,0,0,0,0,0,0,0
0,0,0,0,0,0,0,0,0,0,0
endlayer

layer
0,0,0,0,0,0,0,0,0,0,0
0,0,0,0,0,0,0,0,0,0,0
0,0,0,0,0,0,0,0,0,0,0
0,0,0,0,0,0,0,0,0,0,0
0,0,0,0,0,0,0,0,0,0,0
0,0,0,0,0,0,0,0,0,0,0
0,0,0,0,0,0,0,0,0,0,0
0,0,0,0,0,11,0,0,0,0,0
0,0,0,0,0,0,0,0,0,0,0
0,0,0,0,0,0,0,0,0,0,0
0,0,0,0,0,0,0,0,0,0,0
0,0,0,0,0,0,0,0,0,0,0
0,0,0,0,0,0,0,0,0,0,0
0,0,0,0,0,0,0,0,0,0,0
0,0,0,0,0,0,0,0,0,0,0
endlayer

layer
0,0,0,0,0,0,0,0,0,0,0
0,0,0,0,0,0,0,0,0,0,0
0,0,0,0,0,0,0,0,0,0,0
0,0,0,0,0,0,0,0,0,0,0
0,0,0,0,0,0,0,0,0,0,0
0,0,0,0,0,0,0,0,0,0,0
0,0,0,0,0,0,0,0,0,0,0
0,0,0,0,0,11,0,0,0,0,0
0,0,0,0,0,0,0,0,0,0,0
0,0,0,0,0,0,0,0,0,0,0
0,0,0,0,0,0,0,0,0,0,0
0,0,0,0,0,0,0,0,0,0,0
0,0,0,0,0,0,0,0,0,0,0
0,0,0,0,0,0,0,0,0,0,0
0,0,0,0,0,0,0,0,0,0,0
endlayer

