# Converted from schematic
# THIS TEMPLATE USES DEFAULTS!  Please edit for corrections.
# If you need help, consult template_rules.txt

weight=5
embed_into_distance=2
acceptable_target_blocks=1,2,3,12,13,162,163,164,165,166,167,168,169,170,171,172,254,255
dimensions=21,10,10
allowable_overhang=0
max_cut_in=2
cut_in_buffer=1
max_leveling=2
leveling_buffer=1
preserve_water=0
preserve_lava=0
preserve_plants=0


rule1=0,100,3
rule2=0,100,48
rule3=0,100,4
rule4=0,100,2
rule5=0,100,58
rule6=0,100,67-1
rule7=0,100,65-4
rule8=0,100,5
rule9=0,100,61-5
rule10=0,100,50-2
rule11=0,100,50-3
rule12=0,100,50-4
rule13=0,100,50-1
rule14=0,100,20
rule15=0,100,67-3
rule16=0,100,67
rule17=0,100,67-2
rule18=0,100,50-5


layer
1,1,1,1,1,1,1,1,1,1
1,1,1,1,1,1,1,1,1,1
1,1,1,1,1,1,1,1,1,1
1,1,1,1,1,1,1,1,1,1
1,1,1,1,1,1,1,1,1,1
1,1,1,1,1,1,1,1,1,1
1,1,1,1,1,1,1,1,1,1
1,1,1,1,1,1,1,1,1,1
1,1,1,1,1,1,1,1,1,1
1,1,1,1,1,1,1,1,1,1
endlayer

layer
1,1,1,1,1,1,1,1,1,1
1,1,1,1,1,1,1,1,1,1
1,1,1,1,1,1,1,1,1,1
1,1,2,2,3,3,3,2,1,1
1,1,2,3,3,3,3,2,1,1
1,1,3,3,2,2,2,3,1,1
1,1,2,3,3,2,3,2,1,1
1,1,1,2,3,3,2,1,1,1
1,1,1,1,1,1,1,1,1,1
1,1,1,1,1,1,1,1,1,1
endlayer

layer
4,4,4,4,4,4,4,4,4,4
4,4,4,3,3,3,3,4,4,4
4,4,3,9,6,6,5,2,4,4
4,2,0,0,0,0,0,0,3,4
4,2,0,0,7,7,0,0,2,4
4,3,0,0,8,8,0,0,3,4
4,3,0,0,0,0,0,0,3,4
4,4,3,0,0,0,0,3,4,4
4,4,4,3,3,3,3,4,4,4
4,4,4,4,4,4,4,4,4,4
endlayer

layer
0,0,0,0,0,0,0,0,0,0
0,0,0,2,0,0,2,0,0,0
0,0,3,0,0,0,0,3,0,0
0,2,0,0,0,0,0,0,2,0
0,3,0,0,7,7,0,0,3,0
0,2,0,0,8,8,0,0,3,0
0,2,0,0,0,0,0,0,3,0
0,0,2,0,0,0,0,3,0,0
0,0,0,3,3,3,3,0,0,0
0,0,0,0,0,0,0,0,0,0
endlayer

layer
0,0,0,0,0,0,0,0,0,0
0,0,0,3,0,0,2,0,0,0
0,0,3,12,0,0,0,3,0,0
0,3,13,0,0,0,0,0,3,0
0,2,0,0,7,7,0,0,2,0
0,2,0,0,8,8,0,0,3,0
0,3,0,0,0,0,0,10,2,0
0,0,2,0,0,0,11,3,0,0
0,0,0,2,3,3,2,0,0,0
0,0,0,0,0,0,0,0,0,0
endlayer

layer
0,0,0,0,0,0,0,0,0,0
0,0,0,3,3,3,2,0,0,0
0,0,0,3,3,3,2,0,0,0
0,0,3,3,0,0,3,2,0,0
0,0,3,0,7,7,0,2,0,0
0,0,3,0,8,8,0,3,0,0
0,0,3,3,0,0,3,3,0,0
0,0,0,3,3,3,3,0,0,0
0,0,0,0,0,0,0,0,0,0
0,0,0,0,0,0,0,0,0,0
endlayer

layer
0,0,0,0,0,0,0,0,0,0
0,0,0,0,0,0,0,0,0,0
0,0,0,3,3,3,2,0,0,0
0,0,3,3,0,0,3,3,0,0
0,0,3,0,7,7,0,2,0,0
0,0,3,0,8,8,0,3,0,0
0,0,3,3,0,0,3,3,0,0
0,0,0,3,3,3,2,0,0,0
0,0,0,0,0,0,0,0,0,0
0,0,0,0,0,0,0,0,0,0
endlayer

layer
0,0,0,0,0,0,0,0,0,0
0,0,0,0,0,0,0,0,0,0
0,0,0,0,8,8,0,0,0,0
0,0,0,3,0,0,2,0,0,0
0,0,8,0,7,7,0,8,0,0
0,0,8,0,8,8,0,8,0,0
0,0,0,3,0,0,2,0,0,0
0,0,0,0,8,8,0,0,0,0
0,0,0,0,0,0,0,0,0,0
0,0,0,0,0,0,0,0,0,0
endlayer

layer
0,0,0,0,0,0,0,0,0,0
0,0,0,0,0,0,0,0,0,0
0,0,0,0,0,0,0,0,0,0
0,0,0,3,3,2,2,0,0,0
0,0,0,3,7,7,3,0,0,0
0,0,0,3,8,8,2,0,0,0
0,0,0,3,3,3,2,0,0,0
0,0,0,0,0,0,0,0,0,0
0,0,0,0,0,0,0,0,0,0
0,0,0,0,0,0,0,0,0,0
endlayer

layer
0,0,0,0,0,0,0,0,0,0
0,0,0,0,0,0,0,0,0,0
0,0,0,0,0,0,0,0,0,0
0,0,0,3,14,14,3,0,0,0
0,0,0,14,7,7,14,0,0,0
0,0,0,14,8,8,14,0,0,0
0,0,0,3,14,14,3,0,0,0
0,0,0,0,0,0,0,0,0,0
0,0,0,0,0,0,0,0,0,0
0,0,0,0,0,0,0,0,0,0
endlayer

layer
0,0,0,0,0,0,0,0,0,0
0,0,0,0,0,0,0,0,0,0
0,0,0,0,0,0,0,0,0,0
0,0,0,3,14,14,3,0,0,0
0,0,0,14,7,7,14,0,0,0
0,0,0,14,8,8,14,0,0,0
0,0,0,3,14,14,2,0,0,0
0,0,0,0,0,0,0,0,0,0
0,0,0,0,0,0,0,0,0,0
0,0,0,0,0,0,0,0,0,0
endlayer

layer
0,0,0,0,0,0,0,0,0,0
0,0,0,0,0,0,0,0,0,0
0,0,0,0,0,0,0,0,0,0
0,0,0,3,14,14,2,0,0,0
0,0,0,14,7,7,14,0,0,0
0,0,0,14,8,8,14,0,0,0
0,0,0,3,14,14,3,0,0,0
0,0,0,0,0,0,0,0,0,0
0,0,0,0,0,0,0,0,0,0
0,0,0,0,0,0,0,0,0,0
endlayer

layer
0,0,0,0,0,0,0,0,0,0
0,0,0,0,0,0,0,0,0,0
0,0,0,0,0,0,0,0,0,0
0,0,0,2,3,3,2,0,0,0
0,0,0,2,7,7,3,0,0,0
0,0,0,3,8,8,3,0,0,0
0,0,0,2,3,3,2,0,0,0
0,0,0,0,0,0,0,0,0,0
0,0,0,0,0,0,0,0,0,0
0,0,0,0,0,0,0,0,0,0
endlayer

layer
0,0,0,0,3,3,0,0,0,0
0,0,0,0,3,3,0,0,0,0
0,0,3,3,3,3,3,2,0,0
0,0,3,3,3,3,3,3,0,0
0,0,3,3,7,7,3,3,0,0
0,0,3,3,8,8,3,3,0,0
0,0,2,3,3,3,3,2,0,0
0,0,3,3,2,3,3,2,0,0
0,0,0,0,0,0,0,0,0,0
0,0,0,0,0,0,0,0,0,0
endlayer

layer
0,0,0,3,0,0,3,0,0,0
0,2,3,3,0,0,3,3,2,0
0,3,3,6,0,0,6,3,2,0
0,3,17,0,0,0,0,15,3,0
0,3,17,0,0,0,0,15,3,0
0,3,17,0,0,0,0,15,3,0
0,3,17,0,0,0,0,15,3,0
0,3,3,16,16,16,16,3,3,0
0,3,2,2,3,3,3,2,2,0
0,0,0,0,0,0,0,0,0,0
endlayer

layer
0,2,3,3,0,0,3,3,3,0
2,3,12,0,0,0,0,11,3,3
2,13,0,0,0,0,0,0,13,3
3,0,0,0,0,0,0,0,0,3
3,0,0,0,0,0,0,0,0,3
3,0,0,0,0,0,0,0,0,3
3,0,0,0,0,0,0,0,0,3
3,10,0,0,0,0,0,0,10,3
3,3,12,0,0,0,0,11,3,3
0,3,3,3,3,3,3,3,2,0
endlayer

layer
0,14,14,14,0,0,14,14,14,0
14,18,0,0,0,0,0,0,18,14
14,0,0,0,0,0,0,0,0,14
14,0,0,0,0,0,0,0,0,14
14,0,0,0,0,0,0,0,0,14
14,0,0,0,0,0,0,0,0,14
14,0,0,0,0,0,0,0,0,14
14,0,0,0,0,0,0,0,0,14
14,18,0,0,0,0,0,0,18,14
0,14,14,14,14,14,14,14,14,0
endlayer

layer
0,0,0,0,0,0,0,0,0,0
0,8,8,8,8,8,8,8,8,0
0,8,0,0,0,0,0,0,8,0
0,8,0,0,0,0,0,0,8,0
0,8,0,0,0,0,0,0,8,0
0,8,0,0,0,0,0,0,8,0
0,8,0,0,0,0,0,0,8,0
0,8,0,0,0,0,0,0,8,0
0,8,8,8,8,8,8,8,8,0
0,0,0,0,0,0,0,0,0,0
endlayer

layer
0,0,0,0,0,0,0,0,0,0
0,0,0,0,0,0,0,0,0,0
0,0,3,14,14,14,14,3,0,0
0,0,14,0,0,0,0,14,0,0
0,0,14,0,0,0,0,14,0,0
0,0,14,0,0,0,0,14,0,0
0,0,14,0,0,0,0,14,0,0
0,0,3,14,14,14,14,3,0,0
0,0,0,0,0,0,0,0,0,0
0,0,0,0,0,0,0,0,0,0
endlayer

layer
0,0,0,0,0,0,0,0,0,0
0,0,0,0,0,0,0,0,0,0
0,0,0,0,0,0,0,0,0,0
0,0,0,3,3,3,3,0,0,0
0,0,0,3,0,0,3,0,0,0
0,0,0,3,0,0,3,0,0,0
0,0,0,3,3,3,3,0,0,0
0,0,0,0,0,0,0,0,0,0
0,0,0,0,0,0,0,0,0,0
0,0,0,0,0,0,0,0,0,0
endlayer

layer
0,0,0,0,0,0,0,0,0,0
0,0,0,0,0,0,0,0,0,0
0,0,0,0,0,0,0,0,0,0
0,0,0,0,0,0,0,0,0,0
0,0,0,0,14,14,0,0,0,0
0,0,0,0,14,14,0,0,0,0
0,0,0,0,0,0,0,0,0,0
0,0,0,0,0,0,0,0,0,0
0,0,0,0,0,0,0,0,0,0
0,0,0,0,0,0,0,0,0,0
endlayer

